[32mINFO    [0m pytest_operator.plugin:plugin.py:766 Connecting to existing model localhost-localhost:test on unspecified cloud
[32mINFO    [0m integration.test_smoke:test_smoke.py:67 Deploying bundle
[32mINFO    [0m juju.bundle:bundle.py:416 Applying change: upload charm data-integrator for series jammy from channel latest/edge
[32mINFO    [0m juju.bundle:bundle.py:416 Applying change: upload charm mysql-router for series jammy from channel dpe/edge
[32mINFO    [0m juju.bundle:bundle.py:416 Applying change: upload charm mysql-test-app for series jammy from channel latest/edge
[32mINFO    [0m juju.bundle:bundle.py:416 Applying change: upload charm s3-integrator for series jammy from channel latest/edge
[32mINFO    [0m juju.bundle:bundle.py:416 Applying change: upload charm self-signed-certificates for series jammy from channel latest/edge
[32mINFO    [0m juju.bundle:bundle.py:416 Applying change: upload charm sysbench for series jammy from channel latest/edge
[32mINFO    [0m juju.bundle:bundle.py:416 Applying change: upload charm ubuntu-advantage for series jammy from channel latest/edge
[32mINFO    [0m juju.bundle:bundle.py:416 Applying change: upload charm grafana-agent for series jammy from channel latest/edge
[32mINFO    [0m juju.bundle:bundle.py:416 Applying change: upload charm landscape-client for series jammy from channel latest/edge
[32mINFO    [0m juju.bundle:bundle.py:416 Applying change: upload charm mysql for series jammy from channel 8.0/edge
[32mINFO    [0m juju.bundle:bundle.py:416 Applying change: add new machine
[32mINFO    [0m juju.bundle:bundle.py:416 Applying change: add new machine
[32mINFO    [0m juju.bundle:bundle.py:416 Applying change: deploy application data-integrator on jammy using $addCharm-0
[32mINFO    [0m juju.model:model.py:2098 Deploying ch:amd64/jammy/data-integrator-72
[32mINFO    [0m juju.bundle:bundle.py:416 Applying change: deploy application mysql on jammy using $addCharm-9
[32mINFO    [0m juju.model:model.py:2098 Deploying ch:amd64/jammy/mysql-303
[32mINFO    [0m juju.bundle:bundle.py:416 Applying change: deploy application mysql-router on jammy using $addCharm-12
[32mINFO    [0m juju.model:model.py:2098 Deploying ch:amd64/jammy/mysql-router-247
[32mINFO    [0m juju.bundle:bundle.py:416 Applying change: deploy application mysql-router-data-integrator on jammy using $addCharm-0
[32mINFO    [0m juju.model:model.py:2098 Deploying ch:amd64/jammy/data-integrator-72
[32mINFO    [0m juju.bundle:bundle.py:416 Applying change: deploy application mysql-test-app on jammy using $addCharm-17
[32mINFO    [0m juju.model:model.py:2098 Deploying ch:amd64/jammy/mysql-test-app-63
[32mINFO    [0m juju.bundle:bundle.py:416 Applying change: deploy application s3-integrator on jammy using $addCharm-20
[32mINFO    [0m juju.model:model.py:2098 Deploying ch:amd64/jammy/s3-integrator-71
[32mINFO    [0m juju.bundle:bundle.py:416 Applying change: deploy application self-signed-certificates on jammy using $addCharm-23
[32mINFO    [0m juju.model:model.py:2098 Deploying ch:amd64/jammy/self-signed-certificates-202
[32mINFO    [0m juju.bundle:bundle.py:416 Applying change: deploy application sysbench on jammy using $addCharm-26
[32mINFO    [0m juju.model:model.py:2098 Deploying ch:amd64/jammy/sysbench-89
[32mINFO    [0m juju.bundle:bundle.py:416 Applying change: deploy application ubuntu-advantage on jammy using $addCharm-29
[32mINFO    [0m juju.model:model.py:2098 Deploying ch:amd64/jammy/ubuntu-advantage-133
[32mINFO    [0m juju.bundle:bundle.py:416 Applying change: deploy application grafana-agent on jammy using $addCharm-3
[32mINFO    [0m juju.model:model.py:2098 Deploying ch:amd64/jammy/grafana-agent-286
[32mINFO    [0m juju.bundle:bundle.py:416 Applying change: deploy application landscape-client on jammy using $addCharm-6
[32mINFO    [0m juju.model:model.py:2098 Deploying ch:amd64/jammy/landscape-client-69
[32mINFO    [0m juju.bundle:bundle.py:416 Applying change: add new machine
[32mINFO    [0m juju.bundle:bundle.py:416 Applying change: add relation $deploy-10:database - $deploy-13:backend-database
[32mINFO    [0m juju.bundle:bundle.py:865 Relating mysql:database <-> mysql-router:backend-database
[33mWARNING [0m juju.model:model.py:1564 relate is deprecated and will be removed. Use integrate instead.
[32mINFO    [0m juju.bundle:bundle.py:416 Applying change: add relation $deploy-10:certificates - $deploy-24:certificates
[32mINFO    [0m juju.bundle:bundle.py:865 Relating mysql:certificates <-> self-signed-certificates:certificates
[33mWARNING [0m juju.model:model.py:1564 relate is deprecated and will be removed. Use integrate instead.
[32mINFO    [0m juju.bundle:bundle.py:416 Applying change: add relation $deploy-13:certificates - $deploy-24:certificates
[32mINFO    [0m juju.bundle:bundle.py:865 Relating mysql-router:certificates <-> self-signed-certificates:certificates
[33mWARNING [0m juju.model:model.py:1564 relate is deprecated and will be removed. Use integrate instead.
[32mINFO    [0m juju.bundle:bundle.py:416 Applying change: add relation $deploy-10:s3-parameters - $deploy-21:s3-credentials
[32mINFO    [0m juju.bundle:bundle.py:865 Relating mysql:s3-parameters <-> s3-integrator:s3-credentials
[33mWARNING [0m juju.model:model.py:1564 relate is deprecated and will be removed. Use integrate instead.
[32mINFO    [0m juju.bundle:bundle.py:416 Applying change: add relation $deploy-10:database - $deploy-1:mysql
[32mINFO    [0m juju.bundle:bundle.py:865 Relating mysql:database <-> data-integrator:mysql
[33mWARNING [0m juju.model:model.py:1564 relate is deprecated and will be removed. Use integrate instead.
[32mINFO    [0m juju.bundle:bundle.py:416 Applying change: add relation $deploy-10:database - $deploy-27:mysql
[32mINFO    [0m juju.bundle:bundle.py:865 Relating mysql:database <-> sysbench:mysql
[33mWARNING [0m juju.model:model.py:1564 relate is deprecated and will be removed. Use integrate instead.
[32mINFO    [0m juju.bundle:bundle.py:416 Applying change: add relation $deploy-10:cos-agent - $deploy-4:cos-agent
[32mINFO    [0m juju.bundle:bundle.py:865 Relating mysql:cos-agent <-> grafana-agent:cos-agent
[33mWARNING [0m juju.model:model.py:1564 relate is deprecated and will be removed. Use integrate instead.
[32mINFO    [0m juju.bundle:bundle.py:416 Applying change: add relation $deploy-10:juju-info - $deploy-30:juju-info
[32mINFO    [0m juju.bundle:bundle.py:865 Relating mysql:juju-info <-> ubuntu-advantage:juju-info
[33mWARNING [0m juju.model:model.py:1564 relate is deprecated and will be removed. Use integrate instead.
[32mINFO    [0m juju.bundle:bundle.py:416 Applying change: add relation $deploy-10:juju-info - $deploy-7:container
[32mINFO    [0m juju.bundle:bundle.py:865 Relating mysql:juju-info <-> landscape-client:container
[33mWARNING [0m juju.model:model.py:1564 relate is deprecated and will be removed. Use integrate instead.
[32mINFO    [0m juju.bundle:bundle.py:416 Applying change: add relation $deploy-13:database - $deploy-15:mysql
[32mINFO    [0m juju.bundle:bundle.py:865 Relating mysql-router:database <-> mysql-router-data-integrator:mysql
[33mWARNING [0m juju.model:model.py:1564 relate is deprecated and will be removed. Use integrate instead.
[32mINFO    [0m juju.bundle:bundle.py:416 Applying change: add relation $deploy-15:juju-info - $deploy-4:juju-info
[32mINFO    [0m juju.bundle:bundle.py:865 Relating mysql-router-data-integrator:juju-info <-> grafana-agent:juju-info
[33mWARNING [0m juju.model:model.py:1564 relate is deprecated and will be removed. Use integrate instead.
[32mINFO    [0m juju.bundle:bundle.py:416 Applying change: add relation $deploy-13:cos-agent - $deploy-4:cos-agent
[32mINFO    [0m juju.bundle:bundle.py:865 Relating mysql-router:cos-agent <-> grafana-agent:cos-agent
[33mWARNING [0m juju.model:model.py:1564 relate is deprecated and will be removed. Use integrate instead.
[32mINFO    [0m juju.bundle:bundle.py:416 Applying change: add relation $deploy-15:juju-info - $deploy-30:juju-info
[32mINFO    [0m juju.bundle:bundle.py:865 Relating mysql-router-data-integrator:juju-info <-> ubuntu-advantage:juju-info
[33mWARNING [0m juju.model:model.py:1564 relate is deprecated and will be removed. Use integrate instead.
[32mINFO    [0m juju.bundle:bundle.py:416 Applying change: add relation $deploy-15:juju-info - $deploy-7:container
[32mINFO    [0m juju.bundle:bundle.py:865 Relating mysql-router-data-integrator:juju-info <-> landscape-client:container
[33mWARNING [0m juju.model:model.py:1564 relate is deprecated and will be removed. Use integrate instead.
[32mINFO    [0m juju.bundle:bundle.py:416 Applying change: add $deploy-1 unit to $addMachines-32
[32mINFO    [0m juju.bundle:bundle.py:416 Applying change: add $deploy-15 unit to $addMachines-33
[32mINFO    [0m juju.bundle:bundle.py:416 Applying change: set annotations for $deploy-10
[32mINFO    [0m juju.bundle:bundle.py:416 Applying change: set annotations for $deploy-13
[32mINFO    [0m juju.bundle:bundle.py:416 Applying change: set annotations for $deploy-15
[32mINFO    [0m juju.bundle:bundle.py:416 Applying change: set annotations for $deploy-18
[32mINFO    [0m juju.bundle:bundle.py:416 Applying change: set annotations for $deploy-1
[32mINFO    [0m juju.bundle:bundle.py:416 Applying change: set annotations for $deploy-21
[32mINFO    [0m juju.bundle:bundle.py:416 Applying change: set annotations for $deploy-24
[32mINFO    [0m juju.bundle:bundle.py:416 Applying change: set annotations for $deploy-27
[32mINFO    [0m juju.bundle:bundle.py:416 Applying change: set annotations for $deploy-30
[32mINFO    [0m juju.bundle:bundle.py:416 Applying change: set annotations for $deploy-4
[32mINFO    [0m juju.bundle:bundle.py:416 Applying change: set annotations for $deploy-7
[32mINFO    [0m juju.bundle:bundle.py:416 Applying change: add new machine
[32mINFO    [0m juju.bundle:bundle.py:416 Applying change: add $deploy-10 unit to $addMachines-34
[32mINFO    [0m juju.bundle:bundle.py:416 Applying change: add new machine
[32mINFO    [0m juju.bundle:bundle.py:416 Applying change: add $deploy-10 unit to $addMachines-35
[32mINFO    [0m juju.bundle:bundle.py:416 Applying change: add new machine
[32mINFO    [0m juju.bundle:bundle.py:416 Applying change: add $deploy-10 unit to $addMachines-36
[32mINFO    [0m juju.bundle:bundle.py:416 Applying change: add new machine
[32mINFO    [0m juju.bundle:bundle.py:416 Applying change: add $deploy-21 unit to $addMachines-37
[32mINFO    [0m juju.bundle:bundle.py:416 Applying change: add new machine
[32mINFO    [0m juju.bundle:bundle.py:416 Applying change: add $deploy-24 unit to $addMachines-38
[32mINFO    [0m juju.bundle:bundle.py:416 Applying change: add $deploy-27 unit to $addMachines-39
[32mINFO    [0m integration.test_smoke:test_smoke.py:41 Waiting for active: mysql, self-signed-certificates, sysbench
[32mINFO    [0m pytest_operator.plugin:plugin.py:903 Model status:

Model  Controller           Cloud/Region         Version  SLA          Timestamp
test   localhost-localhost  localhost/localhost  3.5.4    unsupported  01:42:50Z

App                           Version  Status       Scale  Charm                     Channel      Rev  Exposed  Message
data-integrator                        blocked          1  data-integrator           latest/edge   72  no       Please specify either topic, index, or database name
grafana-agent                          blocked          4  grafana-agent             latest/edge  286  no       Missing ['grafana-cloud-config']|['grafana-dashboards-provider']|['logging-consumer']|['send-remote-write'] for cos-a...
landscape-client                       blocked          4  landscape-client          latest/edge   69  no       Registration failed!
mysql                                  error            3  mysql                     8.0/edge     303  no       hook failed: "certificates-relation-joined"
mysql-router                           maintenance      1  mysql-router              dpe/edge     247  no       Installing snap
mysql-router-data-integrator           blocked          1  data-integrator           latest/edge   72  no       Please specify either topic, index, or database name
mysql-test-app                         unknown          0  mysql-test-app            latest/edge   63  no       
s3-integrator                          blocked          1  s3-integrator             latest/edge   71  no       Missing parameters: ['access-key', 'secret-key']
self-signed-certificates               active           1  self-signed-certificates  latest/edge  202  no       
sysbench                               waiting          1  sysbench                  latest/edge   89  no       Waiting on data from relation
ubuntu-advantage                       blocked          4  ubuntu-advantage          latest/edge  133  no       No token configured

Unit                             Workload     Agent      Machine  Public address  Ports  Message
data-integrator/0*               blocked      idle       0        10.206.200.217         Please specify either topic, index, or database name
mysql-router-data-integrator/0*  blocked      executing  1        10.206.200.209         (start) Please specify either topic, index, or database name
  grafana-agent/2                maintenance  executing           10.206.200.209         (install) Installing grafana-agent snap
  landscape-client/2             maintenance  executing           10.206.200.209         (install) Installing landscape client..
  mysql-router/0*                maintenance  executing           10.206.200.209         (install) Installing snap
  ubuntu-advantage/2             maintenance  executing           10.206.200.209         installing charm software
mysql/0*                         waiting      executing  2        10.206.200.102         Waiting to start MySQL
  grafana-agent/3                maintenance  executing           10.206.200.102         (install) Installing grafana-agent snap
  landscape-client/3             maintenance  executing           10.206.200.102         (install) Installing landscape client..
  ubuntu-advantage/3             maintenance  executing           10.206.200.102         (install) installing charm software
mysql/1                          error        idle       3        10.206.200.159         hook failed: "certificates-relation-joined"
  grafana-agent/1                blocked      idle                10.206.200.159         Missing ['grafana-cloud-config']|['grafana-dashboards-provider']|['logging-consumer']|['send-remote-write'] for cos-a...
  landscape-client/1             blocked      idle                10.206.200.159         Registration failed!
  ubuntu-advantage/1             blocked      idle                10.206.200.159         No token configured
mysql/2                          error        idle       4        10.206.200.232         hook failed: "certificates-relation-joined"
  grafana-agent/0*               blocked      idle                10.206.200.232         Missing ['grafana-cloud-config']|['grafana-dashboards-provider']|['logging-consumer']|['send-remote-write'] for cos-a...
  landscape-client/0*            blocked      idle                10.206.200.232         Registration failed!
  ubuntu-advantage/0*            blocked      idle                10.206.200.232         No token configured
s3-integrator/0*                 blocked      idle       5        10.206.200.181         Missing parameters: ['access-key', 'secret-key']
self-signed-certificates/0*      active       idle       6        10.206.200.197         
sysbench/0*                      waiting      idle       7        10.206.200.225         Waiting on data from relation

Machine  State    Address         Inst id        Base          AZ  Message
0        started  10.206.200.217  juju-7a3058-0  ubuntu@22.04      Running
1        started  10.206.200.209  juju-7a3058-1  ubuntu@22.04      Running
2        started  10.206.200.102  juju-7a3058-2  ubuntu@22.04      Running
3        started  10.206.200.159  juju-7a3058-3  ubuntu@22.04      Running
4        started  10.206.200.232  juju-7a3058-4  ubuntu@22.04      Running
5        started  10.206.200.181  juju-7a3058-5  ubuntu@22.04      Running
6        started  10.206.200.197  juju-7a3058-6  ubuntu@22.04      Running
7        started  10.206.200.225  juju-7a3058-7  ubuntu@22.04      Running

[32mINFO    [0m pytest_operator.plugin:plugin.py:909 Juju error logs:

machine-0: 01:29:07 ERROR juju.worker.dependency "kvm-container-provisioner" manifold worker returned unexpected error: container types not yet available
machine-0: 01:29:07 ERROR juju.worker.dependency "lxd-container-provisioner" manifold worker returned unexpected error: container types not yet available
unit-data-integrator-0: 01:29:08 ERROR juju.worker.meterstatus error running "meter-status-changed": charm missing from disk
machine-2: 01:29:23 ERROR juju.worker.dependency "lxd-container-provisioner" manifold worker returned unexpected error: container types not yet available
machine-2: 01:29:23 ERROR juju.worker.dependency "kvm-container-provisioner" manifold worker returned unexpected error: container types not yet available
unit-mysql-0: 01:29:23 ERROR juju.worker.meterstatus error running "meter-status-changed": charm missing from disk
machine-5: 01:29:25 ERROR juju.worker.dependency "kvm-container-provisioner" manifold worker returned unexpected error: container types not yet available
machine-5: 01:29:25 ERROR juju.worker.dependency "lxd-container-provisioner" manifold worker returned unexpected error: container types not yet available
unit-s3-integrator-0: 01:29:25 ERROR juju.worker.meterstatus error running "meter-status-changed": charm missing from disk
machine-6: 01:29:27 ERROR juju.worker.dependency "kvm-container-provisioner" manifold worker returned unexpected error: container types not yet available
machine-6: 01:29:27 ERROR juju.worker.dependency "lxd-container-provisioner" manifold worker returned unexpected error: container types not yet available
unit-self-signed-certificates-0: 01:29:28 ERROR juju.worker.meterstatus error running "meter-status-changed": charm missing from disk
machine-4: 01:29:38 ERROR juju.worker.dependency "kvm-container-provisioner" manifold worker returned unexpected error: container types not yet available
machine-4: 01:29:38 ERROR juju.worker.dependency "lxd-container-provisioner" manifold worker returned unexpected error: container types not yet available
unit-mysql-2: 01:29:38 ERROR juju.worker.meterstatus error running "meter-status-changed": charm missing from disk
machine-3: 01:30:00 ERROR juju.worker.dependency "kvm-container-provisioner" manifold worker returned unexpected error: container types not yet available
machine-3: 01:30:00 ERROR juju.worker.dependency "lxd-container-provisioner" manifold worker returned unexpected error: container types not yet available
unit-mysql-1: 01:30:00 ERROR juju.worker.meterstatus error running "meter-status-changed": charm missing from disk
machine-7: 01:30:23 ERROR juju.worker.dependency "kvm-container-provisioner" manifold worker returned unexpected error: container types not yet available
machine-7: 01:30:23 ERROR juju.worker.dependency "lxd-container-provisioner" manifold worker returned unexpected error: container types not yet available
unit-sysbench-0: 01:30:23 ERROR juju.worker.meterstatus error running "meter-status-changed": charm missing from disk
unit-ubuntu-advantage-0: 01:30:26 ERROR juju.worker.meterstatus error running "meter-status-changed": charm missing from disk
unit-grafana-agent-0: 01:30:27 ERROR juju.worker.meterstatus error running "meter-status-changed": charm missing from disk
unit-landscape-client-0: 01:30:30 ERROR juju.worker.meterstatus error running "meter-status-changed": exit status 127
unit-landscape-client-1: 01:30:53 ERROR juju.worker.meterstatus error running "meter-status-changed": charm missing from disk
unit-grafana-agent-1: 01:30:54 ERROR juju.worker.meterstatus error running "meter-status-changed": charm missing from disk
unit-ubuntu-advantage-1: 01:30:57 ERROR juju.worker.meterstatus error running "meter-status-changed": exit status 127
machine-1: 01:31:14 ERROR juju.worker.dependency "lxd-container-provisioner" manifold worker returned unexpected error: container types not yet available
machine-1: 01:31:14 ERROR juju.worker.dependency "kvm-container-provisioner" manifold worker returned unexpected error: container types not yet available
unit-mysql-router-data-integrator-0: 01:31:14 ERROR juju.worker.meterstatus error running "meter-status-changed": charm missing from disk
unit-grafana-agent-2: 01:31:17 ERROR juju.worker.meterstatus error running "meter-status-changed": charm missing from disk
unit-ubuntu-advantage-2: 01:31:17 ERROR juju.worker.meterstatus error running "meter-status-changed": charm missing from disk
unit-landscape-client-2: 01:31:17 ERROR juju.worker.meterstatus error running "meter-status-changed": charm missing from disk
unit-mysql-router-0: 01:31:18 ERROR juju.worker.meterstatus error running "meter-status-changed": exit status 1
unit-landscape-client-0: 01:34:04 CRITICAL unit.landscape-client/0.juju-log   File "/var/lib/juju/agents/unit-landscape-client-0/charm/./src/charm.py", line 261, in <module>
    main(LandscapeClientCharm)
  File "/var/lib/juju/agents/unit-landscape-client-0/charm/venv/ops/main.py", line 436, in main
    _emit_charm_event(charm, dispatcher.event_name)
  File "/var/lib/juju/agents/unit-landscape-client-0/charm/venv/ops/main.py", line 144, in _emit_charm_event
    event_to_emit.emit(*args, **kwargs)
  File "/var/lib/juju/agents/unit-landscape-client-0/charm/venv/ops/framework.py", line 351, in emit
    framework._emit(event)
  File "/var/lib/juju/agents/unit-landscape-client-0/charm/venv/ops/framework.py", line 853, in _emit
    self._reemit(event_path)
  File "/var/lib/juju/agents/unit-landscape-client-0/charm/venv/ops/framework.py", line 942, in _reemit
    custom_handler(event)
  File "/var/lib/juju/agents/unit-landscape-client-0/charm/./src/charm.py", line 215, in _on_config_changed
    self.run_landscape_client()
  File "/var/lib/juju/agents/unit-landscape-client-0/charm/./src/charm.py", line 190, in run_landscape_client
    self.send_registration()
  File "/var/lib/juju/agents/unit-landscape-client-0/charm/./src/charm.py", line 178, in send_registration
    if process_helper([CLIENT_CONFIG_CMD, "--silent"]):
  File "/var/lib/juju/agents/unit-landscape-client-0/charm/./src/charm.py", line 104, in process_helper
    log_error("".join(traceback.format_stack()))

unit-landscape-client-0: 01:34:04 CRITICAL unit.landscape-client/0.juju-log An account name and computer title are required.
Aborting Landscape configuration

unit-mysql-2: 01:34:37 ERROR unit.mysql/2.juju-log cos-agent:19: Exception while exporting Span batch.
Traceback (most recent call last):
  File "/var/lib/juju/agents/unit-mysql-2/charm/venv/urllib3/connection.py", line 174, in _new_conn
    conn = connection.create_connection(
  File "/var/lib/juju/agents/unit-mysql-2/charm/venv/urllib3/util/connection.py", line 95, in create_connection
    raise err
  File "/var/lib/juju/agents/unit-mysql-2/charm/venv/urllib3/util/connection.py", line 85, in create_connection
    sock.connect(sa)
ConnectionRefusedError: [Errno 111] Connection refused

During handling of the above exception, another exception occurred:

Traceback (most recent call last):
  File "/var/lib/juju/agents/unit-mysql-2/charm/venv/urllib3/connectionpool.py", line 715, in urlopen
    httplib_response = self._make_request(
  File "/var/lib/juju/agents/unit-mysql-2/charm/venv/urllib3/connectionpool.py", line 416, in _make_request
    conn.request(method, url, **httplib_request_kw)
  File "/var/lib/juju/agents/unit-mysql-2/charm/venv/urllib3/connection.py", line 244, in request
    super(HTTPConnection, self).request(method, url, body=body, headers=headers)
  File "/usr/lib/python3.10/http/client.py", line 1283, in request
    self._send_request(method, url, body, headers, encode_chunked)
  File "/usr/lib/python3.10/http/client.py", line 1329, in _send_request
    self.endheaders(body, encode_chunked=encode_chunked)
  File "/usr/lib/python3.10/http/client.py", line 1278, in endheaders
    self._send_output(message_body, encode_chunked=encode_chunked)
  File "/usr/lib/python3.10/http/client.py", line 1038, in _send_output
    self.send(msg)
  File "/usr/lib/python3.10/http/client.py", line 976, in send
    self.connect()
  File "/var/lib/juju/agents/unit-mysql-2/charm/venv/urllib3/connection.py", line 205, in connect
    conn = self._new_conn()
  File "/var/lib/juju/agents/unit-mysql-2/charm/venv/urllib3/connection.py", line 186, in _new_conn
    raise NewConnectionError(
urllib3.exceptions.NewConnectionError: <urllib3.connection.HTTPConnection object at 0x7f4d40195870>: Failed to establish a new connection: [Errno 111] Connection refused

During handling of the above exception, another exception occurred:

Traceback (most recent call last):
  File "/var/lib/juju/agents/unit-mysql-2/charm/venv/requests/adapters.py", line 486, in send
    resp = conn.urlopen(
  File "/var/lib/juju/agents/unit-mysql-2/charm/venv/urllib3/connectionpool.py", line 801, in urlopen
    retries = retries.increment(
  File "/var/lib/juju/agents/unit-mysql-2/charm/venv/urllib3/util/retry.py", line 594, in increment
    raise MaxRetryError(_pool, url, error or ResponseError(cause))
urllib3.exceptions.MaxRetryError: HTTPConnectionPool(host='juju-7a3058-4.lxd', port=4318): Max retries exceeded with url: /v1/traces (Caused by NewConnectionError('<urllib3.connection.HTTPConnection object at 0x7f4d40195870>: Failed to establish a new connection: [Errno 111] Connection refused'))

During handling of the above exception, another exception occurred:

Traceback (most recent call last):
  File "/var/lib/juju/agents/unit-mysql-2/charm/venv/opentelemetry/sdk/trace/export/__init__.py", line 368, in _export_batch
    self.span_exporter.export(self.spans_list[:idx])  # type: ignore
  File "/var/lib/juju/agents/unit-mysql-2/charm/venv/opentelemetry/exporter/otlp/proto/http/trace_exporter/__init__.py", line 145, in export
    resp = self._export(serialized_data)
  File "/var/lib/juju/agents/unit-mysql-2/charm/venv/opentelemetry/exporter/otlp/proto/http/trace_exporter/__init__.py", line 114, in _export
    return self._session.post(
  File "/var/lib/juju/agents/unit-mysql-2/charm/venv/requests/sessions.py", line 637, in post
    return self.request("POST", url, data=data, json=json, **kwargs)
  File "/var/lib/juju/agents/unit-mysql-2/charm/venv/requests/sessions.py", line 589, in request
    resp = self.send(prep, **send_kwargs)
  File "/var/lib/juju/agents/unit-mysql-2/charm/venv/requests/sessions.py", line 703, in send
    r = adapter.send(request, **kwargs)
  File "/var/lib/juju/agents/unit-mysql-2/charm/venv/requests/adapters.py", line 519, in send
    raise ConnectionError(e, request=request)
requests.exceptions.ConnectionError: HTTPConnectionPool(host='juju-7a3058-4.lxd', port=4318): Max retries exceeded with url: /v1/traces (Caused by NewConnectionError('<urllib3.connection.HTTPConnection object at 0x7f4d40195870>: Failed to establish a new connection: [Errno 111] Connection refused'))
unit-mysql-2: 01:34:39 ERROR unit.mysql/2.juju-log cos-agent:19: Exception while exporting Span batch.
Traceback (most recent call last):
  File "/var/lib/juju/agents/unit-mysql-2/charm/venv/urllib3/connection.py", line 174, in _new_conn
    conn = connection.create_connection(
  File "/var/lib/juju/agents/unit-mysql-2/charm/venv/urllib3/util/connection.py", line 95, in create_connection
    raise err
  File "/var/lib/juju/agents/unit-mysql-2/charm/venv/urllib3/util/connection.py", line 85, in create_connection
    sock.connect(sa)
ConnectionRefusedError: [Errno 111] Connection refused

During handling of the above exception, another exception occurred:

Traceback (most recent call last):
  File "/var/lib/juju/agents/unit-mysql-2/charm/venv/urllib3/connectionpool.py", line 715, in urlopen
    httplib_response = self._make_request(
  File "/var/lib/juju/agents/unit-mysql-2/charm/venv/urllib3/connectionpool.py", line 416, in _make_request
    conn.request(method, url, **httplib_request_kw)
  File "/var/lib/juju/agents/unit-mysql-2/charm/venv/urllib3/connection.py", line 244, in request
    super(HTTPConnection, self).request(method, url, body=body, headers=headers)
  File "/usr/lib/python3.10/http/client.py", line 1283, in request
    self._send_request(method, url, body, headers, encode_chunked)
  File "/usr/lib/python3.10/http/client.py", line 1329, in _send_request
    self.endheaders(body, encode_chunked=encode_chunked)
  File "/usr/lib/python3.10/http/client.py", line 1278, in endheaders
    self._send_output(message_body, encode_chunked=encode_chunked)
  File "/usr/lib/python3.10/http/client.py", line 1038, in _send_output
    self.send(msg)
  File "/usr/lib/python3.10/http/client.py", line 976, in send
    self.connect()
  File "/var/lib/juju/agents/unit-mysql-2/charm/venv/urllib3/connection.py", line 205, in connect
    conn = self._new_conn()
  File "/var/lib/juju/agents/unit-mysql-2/charm/venv/urllib3/connection.py", line 186, in _new_conn
    raise NewConnectionError(
urllib3.exceptions.NewConnectionError: <urllib3.connection.HTTPConnection object at 0x7fbe1c59d2d0>: Failed to establish a new connection: [Errno 111] Connection refused

During handling of the above exception, another exception occurred:

Traceback (most recent call last):
  File "/var/lib/juju/agents/unit-mysql-2/charm/venv/requests/adapters.py", line 486, in send
    resp = conn.urlopen(
  File "/var/lib/juju/agents/unit-mysql-2/charm/venv/urllib3/connectionpool.py", line 801, in urlopen
    retries = retries.increment(
  File "/var/lib/juju/agents/unit-mysql-2/charm/venv/urllib3/util/retry.py", line 594, in increment
    raise MaxRetryError(_pool, url, error or ResponseError(cause))
urllib3.exceptions.MaxRetryError: HTTPConnectionPool(host='juju-7a3058-4.lxd', port=4318): Max retries exceeded with url: /v1/traces (Caused by NewConnectionError('<urllib3.connection.HTTPConnection object at 0x7fbe1c59d2d0>: Failed to establish a new connection: [Errno 111] Connection refused'))

During handling of the above exception, another exception occurred:

Traceback (most recent call last):
  File "/var/lib/juju/agents/unit-mysql-2/charm/venv/opentelemetry/sdk/trace/export/__init__.py", line 368, in _export_batch
    self.span_exporter.export(self.spans_list[:idx])  # type: ignore
  File "/var/lib/juju/agents/unit-mysql-2/charm/venv/opentelemetry/exporter/otlp/proto/http/trace_exporter/__init__.py", line 145, in export
    resp = self._export(serialized_data)
  File "/var/lib/juju/agents/unit-mysql-2/charm/venv/opentelemetry/exporter/otlp/proto/http/trace_exporter/__init__.py", line 114, in _export
    return self._session.post(
  File "/var/lib/juju/agents/unit-mysql-2/charm/venv/requests/sessions.py", line 637, in post
    return self.request("POST", url, data=data, json=json, **kwargs)
  File "/var/lib/juju/agents/unit-mysql-2/charm/venv/requests/sessions.py", line 589, in request
    resp = self.send(prep, **send_kwargs)
  File "/var/lib/juju/agents/unit-mysql-2/charm/venv/requests/sessions.py", line 703, in send
    r = adapter.send(request, **kwargs)
  File "/var/lib/juju/agents/unit-mysql-2/charm/venv/requests/adapters.py", line 519, in send
    raise ConnectionError(e, request=request)
requests.exceptions.ConnectionError: HTTPConnectionPool(host='juju-7a3058-4.lxd', port=4318): Max retries exceeded with url: /v1/traces (Caused by NewConnectionError('<urllib3.connection.HTTPConnection object at 0x7fbe1c59d2d0>: Failed to establish a new connection: [Errno 111] Connection refused'))
unit-mysql-2: 01:34:40 ERROR unit.mysql/2.juju-log s3-parameters:16: Exception while exporting Span batch.
Traceback (most recent call last):
  File "/var/lib/juju/agents/unit-mysql-2/charm/venv/urllib3/connection.py", line 174, in _new_conn
    conn = connection.create_connection(
  File "/var/lib/juju/agents/unit-mysql-2/charm/venv/urllib3/util/connection.py", line 95, in create_connection
    raise err
  File "/var/lib/juju/agents/unit-mysql-2/charm/venv/urllib3/util/connection.py", line 85, in create_connection
    sock.connect(sa)
ConnectionRefusedError: [Errno 111] Connection refused

During handling of the above exception, another exception occurred:

Traceback (most recent call last):
  File "/var/lib/juju/agents/unit-mysql-2/charm/venv/urllib3/connectionpool.py", line 715, in urlopen
    httplib_response = self._make_request(
  File "/var/lib/juju/agents/unit-mysql-2/charm/venv/urllib3/connectionpool.py", line 416, in _make_request
    conn.request(method, url, **httplib_request_kw)
  File "/var/lib/juju/agents/unit-mysql-2/charm/venv/urllib3/connection.py", line 244, in request
    super(HTTPConnection, self).request(method, url, body=body, headers=headers)
  File "/usr/lib/python3.10/http/client.py", line 1283, in request
    self._send_request(method, url, body, headers, encode_chunked)
  File "/usr/lib/python3.10/http/client.py", line 1329, in _send_request
    self.endheaders(body, encode_chunked=encode_chunked)
  File "/usr/lib/python3.10/http/client.py", line 1278, in endheaders
    self._send_output(message_body, encode_chunked=encode_chunked)
  File "/usr/lib/python3.10/http/client.py", line 1038, in _send_output
    self.send(msg)
  File "/usr/lib/python3.10/http/client.py", line 976, in send
    self.connect()
  File "/var/lib/juju/agents/unit-mysql-2/charm/venv/urllib3/connection.py", line 205, in connect
    conn = self._new_conn()
  File "/var/lib/juju/agents/unit-mysql-2/charm/venv/urllib3/connection.py", line 186, in _new_conn
    raise NewConnectionError(
urllib3.exceptions.NewConnectionError: <urllib3.connection.HTTPConnection object at 0x7f07e854cdf0>: Failed to establish a new connection: [Errno 111] Connection refused

During handling of the above exception, another exception occurred:

Traceback (most recent call last):
  File "/var/lib/juju/agents/unit-mysql-2/charm/venv/requests/adapters.py", line 486, in send
    resp = conn.urlopen(
  File "/var/lib/juju/agents/unit-mysql-2/charm/venv/urllib3/connectionpool.py", line 801, in urlopen
    retries = retries.increment(
  File "/var/lib/juju/agents/unit-mysql-2/charm/venv/urllib3/util/retry.py", line 594, in increment
    raise MaxRetryError(_pool, url, error or ResponseError(cause))
urllib3.exceptions.MaxRetryError: HTTPConnectionPool(host='juju-7a3058-4.lxd', port=4318): Max retries exceeded with url: /v1/traces (Caused by NewConnectionError('<urllib3.connection.HTTPConnection object at 0x7f07e854cdf0>: Failed to establish a new connection: [Errno 111] Connection refused'))

During handling of the above exception, another exception occurred:

Traceback (most recent call last):
  File "/var/lib/juju/agents/unit-mysql-2/charm/venv/opentelemetry/sdk/trace/export/__init__.py", line 368, in _export_batch
    self.span_exporter.export(self.spans_list[:idx])  # type: ignore
  File "/var/lib/juju/agents/unit-mysql-2/charm/venv/opentelemetry/exporter/otlp/proto/http/trace_exporter/__init__.py", line 145, in export
    resp = self._export(serialized_data)
  File "/var/lib/juju/agents/unit-mysql-2/charm/venv/opentelemetry/exporter/otlp/proto/http/trace_exporter/__init__.py", line 114, in _export
    return self._session.post(
  File "/var/lib/juju/agents/unit-mysql-2/charm/venv/requests/sessions.py", line 637, in post
    return self.request("POST", url, data=data, json=json, **kwargs)
  File "/var/lib/juju/agents/unit-mysql-2/charm/venv/requests/sessions.py", line 589, in request
    resp = self.send(prep, **send_kwargs)
  File "/var/lib/juju/agents/unit-mysql-2/charm/venv/requests/sessions.py", line 703, in send
    r = adapter.send(request, **kwargs)
  File "/var/lib/juju/agents/unit-mysql-2/charm/venv/requests/adapters.py", line 519, in send
    raise ConnectionError(e, request=request)
requests.exceptions.ConnectionError: HTTPConnectionPool(host='juju-7a3058-4.lxd', port=4318): Max retries exceeded with url: /v1/traces (Caused by NewConnectionError('<urllib3.connection.HTTPConnection object at 0x7f07e854cdf0>: Failed to establish a new connection: [Errno 111] Connection refused'))
unit-mysql-2: 01:34:41 ERROR unit.mysql/2.juju-log database:17: Exception while exporting Span batch.
Traceback (most recent call last):
  File "/var/lib/juju/agents/unit-mysql-2/charm/venv/urllib3/connection.py", line 174, in _new_conn
    conn = connection.create_connection(
  File "/var/lib/juju/agents/unit-mysql-2/charm/venv/urllib3/util/connection.py", line 95, in create_connection
    raise err
  File "/var/lib/juju/agents/unit-mysql-2/charm/venv/urllib3/util/connection.py", line 85, in create_connection
    sock.connect(sa)
ConnectionRefusedError: [Errno 111] Connection refused

During handling of the above exception, another exception occurred:

Traceback (most recent call last):
  File "/var/lib/juju/agents/unit-mysql-2/charm/venv/urllib3/connectionpool.py", line 715, in urlopen
    httplib_response = self._make_request(
  File "/var/lib/juju/agents/unit-mysql-2/charm/venv/urllib3/connectionpool.py", line 416, in _make_request
    conn.request(method, url, **httplib_request_kw)
  File "/var/lib/juju/agents/unit-mysql-2/charm/venv/urllib3/connection.py", line 244, in request
    super(HTTPConnection, self).request(method, url, body=body, headers=headers)
  File "/usr/lib/python3.10/http/client.py", line 1283, in request
    self._send_request(method, url, body, headers, encode_chunked)
  File "/usr/lib/python3.10/http/client.py", line 1329, in _send_request
    self.endheaders(body, encode_chunked=encode_chunked)
  File "/usr/lib/python3.10/http/client.py", line 1278, in endheaders
    self._send_output(message_body, encode_chunked=encode_chunked)
  File "/usr/lib/python3.10/http/client.py", line 1038, in _send_output
    self.send(msg)
  File "/usr/lib/python3.10/http/client.py", line 976, in send
    self.connect()
  File "/var/lib/juju/agents/unit-mysql-2/charm/venv/urllib3/connection.py", line 205, in connect
    conn = self._new_conn()
  File "/var/lib/juju/agents/unit-mysql-2/charm/venv/urllib3/connection.py", line 186, in _new_conn
    raise NewConnectionError(
urllib3.exceptions.NewConnectionError: <urllib3.connection.HTTPConnection object at 0x7f58059ccd00>: Failed to establish a new connection: [Errno 111] Connection refused

During handling of the above exception, another exception occurred:

Traceback (most recent call last):
  File "/var/lib/juju/agents/unit-mysql-2/charm/venv/requests/adapters.py", line 486, in send
    resp = conn.urlopen(
  File "/var/lib/juju/agents/unit-mysql-2/charm/venv/urllib3/connectionpool.py", line 801, in urlopen
    retries = retries.increment(
  File "/var/lib/juju/agents/unit-mysql-2/charm/venv/urllib3/util/retry.py", line 594, in increment
    raise MaxRetryError(_pool, url, error or ResponseError(cause))
urllib3.exceptions.MaxRetryError: HTTPConnectionPool(host='juju-7a3058-4.lxd', port=4318): Max retries exceeded with url: /v1/traces (Caused by NewConnectionError('<urllib3.connection.HTTPConnection object at 0x7f58059ccd00>: Failed to establish a new connection: [Errno 111] Connection refused'))

During handling of the above exception, another exception occurred:

Traceback (most recent call last):
  File "/var/lib/juju/agents/unit-mysql-2/charm/venv/opentelemetry/sdk/trace/export/__init__.py", line 368, in _export_batch
    self.span_exporter.export(self.spans_list[:idx])  # type: ignore
  File "/var/lib/juju/agents/unit-mysql-2/charm/venv/opentelemetry/exporter/otlp/proto/http/trace_exporter/__init__.py", line 145, in export
    resp = self._export(serialized_data)
  File "/var/lib/juju/agents/unit-mysql-2/charm/venv/opentelemetry/exporter/otlp/proto/http/trace_exporter/__init__.py", line 114, in _export
    return self._session.post(
  File "/var/lib/juju/agents/unit-mysql-2/charm/venv/requests/sessions.py", line 637, in post
    return self.request("POST", url, data=data, json=json, **kwargs)
  File "/var/lib/juju/agents/unit-mysql-2/charm/venv/requests/sessions.py", line 589, in request
    resp = self.send(prep, **send_kwargs)
  File "/var/lib/juju/agents/unit-mysql-2/charm/venv/requests/sessions.py", line 703, in send
    r = adapter.send(request, **kwargs)
  File "/var/lib/juju/agents/unit-mysql-2/charm/venv/requests/adapters.py", line 519, in send
    raise ConnectionError(e, request=request)
requests.exceptions.ConnectionError: HTTPConnectionPool(host='juju-7a3058-4.lxd', port=4318): Max retries exceeded with url: /v1/traces (Caused by NewConnectionError('<urllib3.connection.HTTPConnection object at 0x7f58059ccd00>: Failed to establish a new connection: [Errno 111] Connection refused'))
unit-mysql-2: 01:34:42 ERROR unit.mysql/2.juju-log database-peers:1: Exception while exporting Span batch.
Traceback (most recent call last):
  File "/var/lib/juju/agents/unit-mysql-2/charm/venv/urllib3/connection.py", line 174, in _new_conn
    conn = connection.create_connection(
  File "/var/lib/juju/agents/unit-mysql-2/charm/venv/urllib3/util/connection.py", line 95, in create_connection
    raise err
  File "/var/lib/juju/agents/unit-mysql-2/charm/venv/urllib3/util/connection.py", line 85, in create_connection
    sock.connect(sa)
ConnectionRefusedError: [Errno 111] Connection refused

During handling of the above exception, another exception occurred:

Traceback (most recent call last):
  File "/var/lib/juju/agents/unit-mysql-2/charm/venv/urllib3/connectionpool.py", line 715, in urlopen
    httplib_response = self._make_request(
  File "/var/lib/juju/agents/unit-mysql-2/charm/venv/urllib3/connectionpool.py", line 416, in _make_request
    conn.request(method, url, **httplib_request_kw)
  File "/var/lib/juju/agents/unit-mysql-2/charm/venv/urllib3/connection.py", line 244, in request
    super(HTTPConnection, self).request(method, url, body=body, headers=headers)
  File "/usr/lib/python3.10/http/client.py", line 1283, in request
    self._send_request(method, url, body, headers, encode_chunked)
  File "/usr/lib/python3.10/http/client.py", line 1329, in _send_request
    self.endheaders(body, encode_chunked=encode_chunked)
  File "/usr/lib/python3.10/http/client.py", line 1278, in endheaders
    self._send_output(message_body, encode_chunked=encode_chunked)
  File "/usr/lib/python3.10/http/client.py", line 1038, in _send_output
    self.send(msg)
  File "/usr/lib/python3.10/http/client.py", line 976, in send
    self.connect()
  File "/var/lib/juju/agents/unit-mysql-2/charm/venv/urllib3/connection.py", line 205, in connect
    conn = self._new_conn()
  File "/var/lib/juju/agents/unit-mysql-2/charm/venv/urllib3/connection.py", line 186, in _new_conn
    raise NewConnectionError(
urllib3.exceptions.NewConnectionError: <urllib3.connection.HTTPConnection object at 0x7f8347a8f7f0>: Failed to establish a new connection: [Errno 111] Connection refused

During handling of the above exception, another exception occurred:

Traceback (most recent call last):
  File "/var/lib/juju/agents/unit-mysql-2/charm/venv/requests/adapters.py", line 486, in send
    resp = conn.urlopen(
  File "/var/lib/juju/agents/unit-mysql-2/charm/venv/urllib3/connectionpool.py", line 801, in urlopen
    retries = retries.increment(
  File "/var/lib/juju/agents/unit-mysql-2/charm/venv/urllib3/util/retry.py", line 594, in increment
    raise MaxRetryError(_pool, url, error or ResponseError(cause))
urllib3.exceptions.MaxRetryError: HTTPConnectionPool(host='juju-7a3058-4.lxd', port=4318): Max retries exceeded with url: /v1/traces (Caused by NewConnectionError('<urllib3.connection.HTTPConnection object at 0x7f8347a8f7f0>: Failed to establish a new connection: [Errno 111] Connection refused'))

During handling of the above exception, another exception occurred:

Traceback (most recent call last):
  File "/var/lib/juju/agents/unit-mysql-2/charm/venv/opentelemetry/sdk/trace/export/__init__.py", line 368, in _export_batch
    self.span_exporter.export(self.spans_list[:idx])  # type: ignore
  File "/var/lib/juju/agents/unit-mysql-2/charm/venv/opentelemetry/exporter/otlp/proto/http/trace_exporter/__init__.py", line 145, in export
    resp = self._export(serialized_data)
  File "/var/lib/juju/agents/unit-mysql-2/charm/venv/opentelemetry/exporter/otlp/proto/http/trace_exporter/__init__.py", line 114, in _export
    return self._session.post(
  File "/var/lib/juju/agents/unit-mysql-2/charm/venv/requests/sessions.py", line 637, in post
    return self.request("POST", url, data=data, json=json, **kwargs)
  File "/var/lib/juju/agents/unit-mysql-2/charm/venv/requests/sessions.py", line 589, in request
    resp = self.send(prep, **send_kwargs)
  File "/var/lib/juju/agents/unit-mysql-2/charm/venv/requests/sessions.py", line 703, in send
    r = adapter.send(request, **kwargs)
  File "/var/lib/juju/agents/unit-mysql-2/charm/venv/requests/adapters.py", line 519, in send
    raise ConnectionError(e, request=request)
requests.exceptions.ConnectionError: HTTPConnectionPool(host='juju-7a3058-4.lxd', port=4318): Max retries exceeded with url: /v1/traces (Caused by NewConnectionError('<urllib3.connection.HTTPConnection object at 0x7f8347a8f7f0>: Failed to establish a new connection: [Errno 111] Connection refused'))
unit-mysql-2: 01:34:43 ERROR unit.mysql/2.juju-log s3-parameters:16: Exception while exporting Span batch.
Traceback (most recent call last):
  File "/var/lib/juju/agents/unit-mysql-2/charm/venv/urllib3/connection.py", line 174, in _new_conn
    conn = connection.create_connection(
  File "/var/lib/juju/agents/unit-mysql-2/charm/venv/urllib3/util/connection.py", line 95, in create_connection
    raise err
  File "/var/lib/juju/agents/unit-mysql-2/charm/venv/urllib3/util/connection.py", line 85, in create_connection
    sock.connect(sa)
ConnectionRefusedError: [Errno 111] Connection refused

During handling of the above exception, another exception occurred:

Traceback (most recent call last):
  File "/var/lib/juju/agents/unit-mysql-2/charm/venv/urllib3/connectionpool.py", line 715, in urlopen
    httplib_response = self._make_request(
  File "/var/lib/juju/agents/unit-mysql-2/charm/venv/urllib3/connectionpool.py", line 416, in _make_request
    conn.request(method, url, **httplib_request_kw)
  File "/var/lib/juju/agents/unit-mysql-2/charm/venv/urllib3/connection.py", line 244, in request
    super(HTTPConnection, self).request(method, url, body=body, headers=headers)
  File "/usr/lib/python3.10/http/client.py", line 1283, in request
    self._send_request(method, url, body, headers, encode_chunked)
  File "/usr/lib/python3.10/http/client.py", line 1329, in _send_request
    self.endheaders(body, encode_chunked=encode_chunked)
  File "/usr/lib/python3.10/http/client.py", line 1278, in endheaders
    self._send_output(message_body, encode_chunked=encode_chunked)
  File "/usr/lib/python3.10/http/client.py", line 1038, in _send_output
    self.send(msg)
  File "/usr/lib/python3.10/http/client.py", line 976, in send
    self.connect()
  File "/var/lib/juju/agents/unit-mysql-2/charm/venv/urllib3/connection.py", line 205, in connect
    conn = self._new_conn()
  File "/var/lib/juju/agents/unit-mysql-2/charm/venv/urllib3/connection.py", line 186, in _new_conn
    raise NewConnectionError(
urllib3.exceptions.NewConnectionError: <urllib3.connection.HTTPConnection object at 0x7effc4644dc0>: Failed to establish a new connection: [Errno 111] Connection refused

During handling of the above exception, another exception occurred:

Traceback (most recent call last):
  File "/var/lib/juju/agents/unit-mysql-2/charm/venv/requests/adapters.py", line 486, in send
    resp = conn.urlopen(
  File "/var/lib/juju/agents/unit-mysql-2/charm/venv/urllib3/connectionpool.py", line 801, in urlopen
    retries = retries.increment(
  File "/var/lib/juju/agents/unit-mysql-2/charm/venv/urllib3/util/retry.py", line 594, in increment
    raise MaxRetryError(_pool, url, error or ResponseError(cause))
urllib3.exceptions.MaxRetryError: HTTPConnectionPool(host='juju-7a3058-4.lxd', port=4318): Max retries exceeded with url: /v1/traces (Caused by NewConnectionError('<urllib3.connection.HTTPConnection object at 0x7effc4644dc0>: Failed to establish a new connection: [Errno 111] Connection refused'))

During handling of the above exception, another exception occurred:

Traceback (most recent call last):
  File "/var/lib/juju/agents/unit-mysql-2/charm/venv/opentelemetry/sdk/trace/export/__init__.py", line 368, in _export_batch
    self.span_exporter.export(self.spans_list[:idx])  # type: ignore
  File "/var/lib/juju/agents/unit-mysql-2/charm/venv/opentelemetry/exporter/otlp/proto/http/trace_exporter/__init__.py", line 145, in export
    resp = self._export(serialized_data)
  File "/var/lib/juju/agents/unit-mysql-2/charm/venv/opentelemetry/exporter/otlp/proto/http/trace_exporter/__init__.py", line 114, in _export
    return self._session.post(
  File "/var/lib/juju/agents/unit-mysql-2/charm/venv/requests/sessions.py", line 637, in post
    return self.request("POST", url, data=data, json=json, **kwargs)
  File "/var/lib/juju/agents/unit-mysql-2/charm/venv/requests/sessions.py", line 589, in request
    resp = self.send(prep, **send_kwargs)
  File "/var/lib/juju/agents/unit-mysql-2/charm/venv/requests/sessions.py", line 703, in send
    r = adapter.send(request, **kwargs)
  File "/var/lib/juju/agents/unit-mysql-2/charm/venv/requests/adapters.py", line 519, in send
    raise ConnectionError(e, request=request)
requests.exceptions.ConnectionError: HTTPConnectionPool(host='juju-7a3058-4.lxd', port=4318): Max retries exceeded with url: /v1/traces (Caused by NewConnectionError('<urllib3.connection.HTTPConnection object at 0x7effc4644dc0>: Failed to establish a new connection: [Errno 111] Connection refused'))
unit-mysql-2: 01:34:45 ERROR unit.mysql/2.juju-log certificates:14: Exception while exporting Span batch.
Traceback (most recent call last):
  File "/var/lib/juju/agents/unit-mysql-2/charm/venv/urllib3/connection.py", line 174, in _new_conn
    conn = connection.create_connection(
  File "/var/lib/juju/agents/unit-mysql-2/charm/venv/urllib3/util/connection.py", line 95, in create_connection
    raise err
  File "/var/lib/juju/agents/unit-mysql-2/charm/venv/urllib3/util/connection.py", line 85, in create_connection
    sock.connect(sa)
ConnectionRefusedError: [Errno 111] Connection refused

During handling of the above exception, another exception occurred:

Traceback (most recent call last):
  File "/var/lib/juju/agents/unit-mysql-2/charm/venv/urllib3/connectionpool.py", line 715, in urlopen
    httplib_response = self._make_request(
  File "/var/lib/juju/agents/unit-mysql-2/charm/venv/urllib3/connectionpool.py", line 416, in _make_request
    conn.request(method, url, **httplib_request_kw)
  File "/var/lib/juju/agents/unit-mysql-2/charm/venv/urllib3/connection.py", line 244, in request
    super(HTTPConnection, self).request(method, url, body=body, headers=headers)
  File "/usr/lib/python3.10/http/client.py", line 1283, in request
    self._send_request(method, url, body, headers, encode_chunked)
  File "/usr/lib/python3.10/http/client.py", line 1329, in _send_request
    self.endheaders(body, encode_chunked=encode_chunked)
  File "/usr/lib/python3.10/http/client.py", line 1278, in endheaders
    self._send_output(message_body, encode_chunked=encode_chunked)
  File "/usr/lib/python3.10/http/client.py", line 1038, in _send_output
    self.send(msg)
  File "/usr/lib/python3.10/http/client.py", line 976, in send
    self.connect()
  File "/var/lib/juju/agents/unit-mysql-2/charm/venv/urllib3/connection.py", line 205, in connect
    conn = self._new_conn()
  File "/var/lib/juju/agents/unit-mysql-2/charm/venv/urllib3/connection.py", line 186, in _new_conn
    raise NewConnectionError(
urllib3.exceptions.NewConnectionError: <urllib3.connection.HTTPConnection object at 0x7f9d7ea78dc0>: Failed to establish a new connection: [Errno 111] Connection refused

During handling of the above exception, another exception occurred:

Traceback (most recent call last):
  File "/var/lib/juju/agents/unit-mysql-2/charm/venv/requests/adapters.py", line 486, in send
    resp = conn.urlopen(
  File "/var/lib/juju/agents/unit-mysql-2/charm/venv/urllib3/connectionpool.py", line 801, in urlopen
    retries = retries.increment(
  File "/var/lib/juju/agents/unit-mysql-2/charm/venv/urllib3/util/retry.py", line 594, in increment
    raise MaxRetryError(_pool, url, error or ResponseError(cause))
urllib3.exceptions.MaxRetryError: HTTPConnectionPool(host='juju-7a3058-4.lxd', port=4318): Max retries exceeded with url: /v1/traces (Caused by NewConnectionError('<urllib3.connection.HTTPConnection object at 0x7f9d7ea78dc0>: Failed to establish a new connection: [Errno 111] Connection refused'))

During handling of the above exception, another exception occurred:

Traceback (most recent call last):
  File "/var/lib/juju/agents/unit-mysql-2/charm/venv/opentelemetry/sdk/trace/export/__init__.py", line 368, in _export_batch
    self.span_exporter.export(self.spans_list[:idx])  # type: ignore
  File "/var/lib/juju/agents/unit-mysql-2/charm/venv/opentelemetry/exporter/otlp/proto/http/trace_exporter/__init__.py", line 145, in export
    resp = self._export(serialized_data)
  File "/var/lib/juju/agents/unit-mysql-2/charm/venv/opentelemetry/exporter/otlp/proto/http/trace_exporter/__init__.py", line 114, in _export
    return self._session.post(
  File "/var/lib/juju/agents/unit-mysql-2/charm/venv/requests/sessions.py", line 637, in post
    return self.request("POST", url, data=data, json=json, **kwargs)
  File "/var/lib/juju/agents/unit-mysql-2/charm/venv/requests/sessions.py", line 589, in request
    resp = self.send(prep, **send_kwargs)
  File "/var/lib/juju/agents/unit-mysql-2/charm/venv/requests/sessions.py", line 703, in send
    r = adapter.send(request, **kwargs)
  File "/var/lib/juju/agents/unit-mysql-2/charm/venv/requests/adapters.py", line 519, in send
    raise ConnectionError(e, request=request)
requests.exceptions.ConnectionError: HTTPConnectionPool(host='juju-7a3058-4.lxd', port=4318): Max retries exceeded with url: /v1/traces (Caused by NewConnectionError('<urllib3.connection.HTTPConnection object at 0x7f9d7ea78dc0>: Failed to establish a new connection: [Errno 111] Connection refused'))
unit-mysql-2: 01:34:47 ERROR unit.mysql/2.juju-log database-peers:1: Exception while exporting Span batch.
Traceback (most recent call last):
  File "/var/lib/juju/agents/unit-mysql-2/charm/venv/urllib3/connection.py", line 174, in _new_conn
    conn = connection.create_connection(
  File "/var/lib/juju/agents/unit-mysql-2/charm/venv/urllib3/util/connection.py", line 95, in create_connection
    raise err
  File "/var/lib/juju/agents/unit-mysql-2/charm/venv/urllib3/util/connection.py", line 85, in create_connection
    sock.connect(sa)
ConnectionRefusedError: [Errno 111] Connection refused

During handling of the above exception, another exception occurred:

Traceback (most recent call last):
  File "/var/lib/juju/agents/unit-mysql-2/charm/venv/urllib3/connectionpool.py", line 715, in urlopen
    httplib_response = self._make_request(
  File "/var/lib/juju/agents/unit-mysql-2/charm/venv/urllib3/connectionpool.py", line 416, in _make_request
    conn.request(method, url, **httplib_request_kw)
  File "/var/lib/juju/agents/unit-mysql-2/charm/venv/urllib3/connection.py", line 244, in request
    super(HTTPConnection, self).request(method, url, body=body, headers=headers)
  File "/usr/lib/python3.10/http/client.py", line 1283, in request
    self._send_request(method, url, body, headers, encode_chunked)
  File "/usr/lib/python3.10/http/client.py", line 1329, in _send_request
    self.endheaders(body, encode_chunked=encode_chunked)
  File "/usr/lib/python3.10/http/client.py", line 1278, in endheaders
    self._send_output(message_body, encode_chunked=encode_chunked)
  File "/usr/lib/python3.10/http/client.py", line 1038, in _send_output
    self.send(msg)
  File "/usr/lib/python3.10/http/client.py", line 976, in send
    self.connect()
  File "/var/lib/juju/agents/unit-mysql-2/charm/venv/urllib3/connection.py", line 205, in connect
    conn = self._new_conn()
  File "/var/lib/juju/agents/unit-mysql-2/charm/venv/urllib3/connection.py", line 186, in _new_conn
    raise NewConnectionError(
urllib3.exceptions.NewConnectionError: <urllib3.connection.HTTPConnection object at 0x7f0e250e6f20>: Failed to establish a new connection: [Errno 111] Connection refused

During handling of the above exception, another exception occurred:

Traceback (most recent call last):
  File "/var/lib/juju/agents/unit-mysql-2/charm/venv/requests/adapters.py", line 486, in send
    resp = conn.urlopen(
  File "/var/lib/juju/agents/unit-mysql-2/charm/venv/urllib3/connectionpool.py", line 801, in urlopen
    retries = retries.increment(
  File "/var/lib/juju/agents/unit-mysql-2/charm/venv/urllib3/util/retry.py", line 594, in increment
    raise MaxRetryError(_pool, url, error or ResponseError(cause))
urllib3.exceptions.MaxRetryError: HTTPConnectionPool(host='juju-7a3058-4.lxd', port=4318): Max retries exceeded with url: /v1/traces (Caused by NewConnectionError('<urllib3.connection.HTTPConnection object at 0x7f0e250e6f20>: Failed to establish a new connection: [Errno 111] Connection refused'))

During handling of the above exception, another exception occurred:

Traceback (most recent call last):
  File "/var/lib/juju/agents/unit-mysql-2/charm/venv/opentelemetry/sdk/trace/export/__init__.py", line 368, in _export_batch
    self.span_exporter.export(self.spans_list[:idx])  # type: ignore
  File "/var/lib/juju/agents/unit-mysql-2/charm/venv/opentelemetry/exporter/otlp/proto/http/trace_exporter/__init__.py", line 145, in export
    resp = self._export(serialized_data)
  File "/var/lib/juju/agents/unit-mysql-2/charm/venv/opentelemetry/exporter/otlp/proto/http/trace_exporter/__init__.py", line 114, in _export
    return self._session.post(
  File "/var/lib/juju/agents/unit-mysql-2/charm/venv/requests/sessions.py", line 637, in post
    return self.request("POST", url, data=data, json=json, **kwargs)
  File "/var/lib/juju/agents/unit-mysql-2/charm/venv/requests/sessions.py", line 589, in request
    resp = self.send(prep, **send_kwargs)
  File "/var/lib/juju/agents/unit-mysql-2/charm/venv/requests/sessions.py", line 703, in send
    r = adapter.send(request, **kwargs)
  File "/var/lib/juju/agents/unit-mysql-2/charm/venv/requests/adapters.py", line 519, in send
    raise ConnectionError(e, request=request)
requests.exceptions.ConnectionError: HTTPConnectionPool(host='juju-7a3058-4.lxd', port=4318): Max retries exceeded with url: /v1/traces (Caused by NewConnectionError('<urllib3.connection.HTTPConnection object at 0x7f0e250e6f20>: Failed to establish a new connection: [Errno 111] Connection refused'))
unit-mysql-2: 01:34:51 ERROR unit.mysql/2.juju-log certificates:14: Exception while exporting Span batch.
Traceback (most recent call last):
  File "/var/lib/juju/agents/unit-mysql-2/charm/venv/urllib3/connection.py", line 174, in _new_conn
    conn = connection.create_connection(
  File "/var/lib/juju/agents/unit-mysql-2/charm/venv/urllib3/util/connection.py", line 95, in create_connection
    raise err
  File "/var/lib/juju/agents/unit-mysql-2/charm/venv/urllib3/util/connection.py", line 85, in create_connection
    sock.connect(sa)
ConnectionRefusedError: [Errno 111] Connection refused

During handling of the above exception, another exception occurred:

Traceback (most recent call last):
  File "/var/lib/juju/agents/unit-mysql-2/charm/venv/urllib3/connectionpool.py", line 715, in urlopen
    httplib_response = self._make_request(
  File "/var/lib/juju/agents/unit-mysql-2/charm/venv/urllib3/connectionpool.py", line 416, in _make_request
    conn.request(method, url, **httplib_request_kw)
  File "/var/lib/juju/agents/unit-mysql-2/charm/venv/urllib3/connection.py", line 244, in request
    super(HTTPConnection, self).request(method, url, body=body, headers=headers)
  File "/usr/lib/python3.10/http/client.py", line 1283, in request
    self._send_request(method, url, body, headers, encode_chunked)
  File "/usr/lib/python3.10/http/client.py", line 1329, in _send_request
    self.endheaders(body, encode_chunked=encode_chunked)
  File "/usr/lib/python3.10/http/client.py", line 1278, in endheaders
    self._send_output(message_body, encode_chunked=encode_chunked)
  File "/usr/lib/python3.10/http/client.py", line 1038, in _send_output
    self.send(msg)
  File "/usr/lib/python3.10/http/client.py", line 976, in send
    self.connect()
  File "/var/lib/juju/agents/unit-mysql-2/charm/venv/urllib3/connection.py", line 205, in connect
    conn = self._new_conn()
  File "/var/lib/juju/agents/unit-mysql-2/charm/venv/urllib3/connection.py", line 186, in _new_conn
    raise NewConnectionError(
urllib3.exceptions.NewConnectionError: <urllib3.connection.HTTPConnection object at 0x7f1c423ccb80>: Failed to establish a new connection: [Errno 111] Connection refused

During handling of the above exception, another exception occurred:

Traceback (most recent call last):
  File "/var/lib/juju/agents/unit-mysql-2/charm/venv/requests/adapters.py", line 486, in send
    resp = conn.urlopen(
  File "/var/lib/juju/agents/unit-mysql-2/charm/venv/urllib3/connectionpool.py", line 801, in urlopen
    retries = retries.increment(
  File "/var/lib/juju/agents/unit-mysql-2/charm/venv/urllib3/util/retry.py", line 594, in increment
    raise MaxRetryError(_pool, url, error or ResponseError(cause))
urllib3.exceptions.MaxRetryError: HTTPConnectionPool(host='juju-7a3058-4.lxd', port=4318): Max retries exceeded with url: /v1/traces (Caused by NewConnectionError('<urllib3.connection.HTTPConnection object at 0x7f1c423ccb80>: Failed to establish a new connection: [Errno 111] Connection refused'))

During handling of the above exception, another exception occurred:

Traceback (most recent call last):
  File "/var/lib/juju/agents/unit-mysql-2/charm/venv/opentelemetry/sdk/trace/export/__init__.py", line 368, in _export_batch
    self.span_exporter.export(self.spans_list[:idx])  # type: ignore
  File "/var/lib/juju/agents/unit-mysql-2/charm/venv/opentelemetry/exporter/otlp/proto/http/trace_exporter/__init__.py", line 145, in export
    resp = self._export(serialized_data)
  File "/var/lib/juju/agents/unit-mysql-2/charm/venv/opentelemetry/exporter/otlp/proto/http/trace_exporter/__init__.py", line 114, in _export
    return self._session.post(
  File "/var/lib/juju/agents/unit-mysql-2/charm/venv/requests/sessions.py", line 637, in post
    return self.request("POST", url, data=data, json=json, **kwargs)
  File "/var/lib/juju/agents/unit-mysql-2/charm/venv/requests/sessions.py", line 589, in request
    resp = self.send(prep, **send_kwargs)
  File "/var/lib/juju/agents/unit-mysql-2/charm/venv/requests/sessions.py", line 703, in send
    r = adapter.send(request, **kwargs)
  File "/var/lib/juju/agents/unit-mysql-2/charm/venv/requests/adapters.py", line 519, in send
    raise ConnectionError(e, request=request)
requests.exceptions.ConnectionError: HTTPConnectionPool(host='juju-7a3058-4.lxd', port=4318): Max retries exceeded with url: /v1/traces (Caused by NewConnectionError('<urllib3.connection.HTTPConnection object at 0x7f1c423ccb80>: Failed to establish a new connection: [Errno 111] Connection refused'))
unit-mysql-2: 01:34:51 ERROR unit.mysql/2.juju-log certificates:14: Uncaught exception while in charm code:
Traceback (most recent call last):
  File "/var/lib/juju/agents/unit-mysql-2/charm/./src/charm.py", line 855, in <module>
    main(MySQLOperatorCharm)
  File "/var/lib/juju/agents/unit-mysql-2/charm/venv/ops/main.py", line 551, in main
    manager.run()
  File "/var/lib/juju/agents/unit-mysql-2/charm/venv/ops/main.py", line 530, in run
    self._emit()
  File "/var/lib/juju/agents/unit-mysql-2/charm/venv/ops/main.py", line 519, in _emit
    _emit_charm_event(self.charm, self.dispatcher.event_name)
  File "/var/lib/juju/agents/unit-mysql-2/charm/venv/ops/main.py", line 147, in _emit_charm_event
    event_to_emit.emit(*args, **kwargs)
  File "/var/lib/juju/agents/unit-mysql-2/charm/venv/ops/framework.py", line 348, in emit
    framework._emit(event)
  File "/var/lib/juju/agents/unit-mysql-2/charm/venv/ops/framework.py", line 860, in _emit
    self._reemit(event_path)
  File "/var/lib/juju/agents/unit-mysql-2/charm/venv/ops/framework.py", line 950, in _reemit
    custom_handler(event)
  File "/var/lib/juju/agents/unit-mysql-2/charm/lib/charms/tempo_coordinator_k8s/v0/charm_tracing.py", line 734, in wrapped_function
    return callable(*args, **kwargs)  # type: ignore
  File "/var/lib/juju/agents/unit-mysql-2/charm/lib/charms/mysql/v0/tls.py", line 94, in _on_tls_relation_joined
    if not self.charm.unit_initialized:
  File "/var/lib/juju/agents/unit-mysql-2/charm/lib/charms/mysql/v0/mysql.py", line 667, in unit_initialized
    return self._mysql.cluster_metadata_exists(self.get_unit_address(self.unit))
  File "/var/lib/juju/agents/unit-mysql-2/charm/./src/charm.py", line 578, in _mysql
    self.app_peer_data["cluster-name"],
  File "/var/lib/juju/agents/unit-mysql-2/charm/venv/ops/model.py", line 1812, in __getitem__
    return super().__getitem__(key)
  File "/var/lib/juju/agents/unit-mysql-2/charm/venv/ops/model.py", line 841, in __getitem__
    return self._data[key]
KeyError: 'cluster-name'
unit-landscape-client-1: 01:34:51 CRITICAL unit.landscape-client/1.juju-log   File "/var/lib/juju/agents/unit-landscape-client-1/charm/./src/charm.py", line 261, in <module>
    main(LandscapeClientCharm)
  File "/var/lib/juju/agents/unit-landscape-client-1/charm/venv/ops/main.py", line 436, in main
    _emit_charm_event(charm, dispatcher.event_name)
  File "/var/lib/juju/agents/unit-landscape-client-1/charm/venv/ops/main.py", line 144, in _emit_charm_event
    event_to_emit.emit(*args, **kwargs)
  File "/var/lib/juju/agents/unit-landscape-client-1/charm/venv/ops/framework.py", line 351, in emit
    framework._emit(event)
  File "/var/lib/juju/agents/unit-landscape-client-1/charm/venv/ops/framework.py", line 853, in _emit
    self._reemit(event_path)
  File "/var/lib/juju/agents/unit-landscape-client-1/charm/venv/ops/framework.py", line 942, in _reemit
    custom_handler(event)
  File "/var/lib/juju/agents/unit-landscape-client-1/charm/./src/charm.py", line 215, in _on_config_changed
    self.run_landscape_client()
  File "/var/lib/juju/agents/unit-landscape-client-1/charm/./src/charm.py", line 190, in run_landscape_client
    self.send_registration()
  File "/var/lib/juju/agents/unit-landscape-client-1/charm/./src/charm.py", line 178, in send_registration
    if process_helper([CLIENT_CONFIG_CMD, "--silent"]):
  File "/var/lib/juju/agents/unit-landscape-client-1/charm/./src/charm.py", line 104, in process_helper
    log_error("".join(traceback.format_stack()))

unit-landscape-client-1: 01:34:51 CRITICAL unit.landscape-client/1.juju-log An account name and computer title are required.
Aborting Landscape configuration

unit-mysql-2: 01:34:51 ERROR juju.worker.uniter.operation hook "certificates-relation-joined" (via hook dispatching script: dispatch) failed: exit status 1
unit-mysql-2: 01:34:57 ERROR unit.mysql/2.juju-log certificates:14: Exception while exporting Span batch.
Traceback (most recent call last):
  File "/var/lib/juju/agents/unit-mysql-2/charm/venv/urllib3/connection.py", line 174, in _new_conn
    conn = connection.create_connection(
  File "/var/lib/juju/agents/unit-mysql-2/charm/venv/urllib3/util/connection.py", line 95, in create_connection
    raise err
  File "/var/lib/juju/agents/unit-mysql-2/charm/venv/urllib3/util/connection.py", line 85, in create_connection
    sock.connect(sa)
ConnectionRefusedError: [Errno 111] Connection refused

During handling of the above exception, another exception occurred:

Traceback (most recent call last):
  File "/var/lib/juju/agents/unit-mysql-2/charm/venv/urllib3/connectionpool.py", line 715, in urlopen
    httplib_response = self._make_request(
  File "/var/lib/juju/agents/unit-mysql-2/charm/venv/urllib3/connectionpool.py", line 416, in _make_request
    conn.request(method, url, **httplib_request_kw)
  File "/var/lib/juju/agents/unit-mysql-2/charm/venv/urllib3/connection.py", line 244, in request
    super(HTTPConnection, self).request(method, url, body=body, headers=headers)
  File "/usr/lib/python3.10/http/client.py", line 1283, in request
    self._send_request(method, url, body, headers, encode_chunked)
  File "/usr/lib/python3.10/http/client.py", line 1329, in _send_request
    self.endheaders(body, encode_chunked=encode_chunked)
  File "/usr/lib/python3.10/http/client.py", line 1278, in endheaders
    self._send_output(message_body, encode_chunked=encode_chunked)
  File "/usr/lib/python3.10/http/client.py", line 1038, in _send_output
    self.send(msg)
  File "/usr/lib/python3.10/http/client.py", line 976, in send
    self.connect()
  File "/var/lib/juju/agents/unit-mysql-2/charm/venv/urllib3/connection.py", line 205, in connect
    conn = self._new_conn()
  File "/var/lib/juju/agents/unit-mysql-2/charm/venv/urllib3/connection.py", line 186, in _new_conn
    raise NewConnectionError(
urllib3.exceptions.NewConnectionError: <urllib3.connection.HTTPConnection object at 0x7f382bf30610>: Failed to establish a new connection: [Errno 111] Connection refused

During handling of the above exception, another exception occurred:

Traceback (most recent call last):
  File "/var/lib/juju/agents/unit-mysql-2/charm/venv/requests/adapters.py", line 486, in send
    resp = conn.urlopen(
  File "/var/lib/juju/agents/unit-mysql-2/charm/venv/urllib3/connectionpool.py", line 801, in urlopen
    retries = retries.increment(
  File "/var/lib/juju/agents/unit-mysql-2/charm/venv/urllib3/util/retry.py", line 594, in increment
    raise MaxRetryError(_pool, url, error or ResponseError(cause))
urllib3.exceptions.MaxRetryError: HTTPConnectionPool(host='juju-7a3058-4.lxd', port=4318): Max retries exceeded with url: /v1/traces (Caused by NewConnectionError('<urllib3.connection.HTTPConnection object at 0x7f382bf30610>: Failed to establish a new connection: [Errno 111] Connection refused'))

During handling of the above exception, another exception occurred:

Traceback (most recent call last):
  File "/var/lib/juju/agents/unit-mysql-2/charm/venv/opentelemetry/sdk/trace/export/__init__.py", line 368, in _export_batch
    self.span_exporter.export(self.spans_list[:idx])  # type: ignore
  File "/var/lib/juju/agents/unit-mysql-2/charm/venv/opentelemetry/exporter/otlp/proto/http/trace_exporter/__init__.py", line 145, in export
    resp = self._export(serialized_data)
  File "/var/lib/juju/agents/unit-mysql-2/charm/venv/opentelemetry/exporter/otlp/proto/http/trace_exporter/__init__.py", line 114, in _export
    return self._session.post(
  File "/var/lib/juju/agents/unit-mysql-2/charm/venv/requests/sessions.py", line 637, in post
    return self.request("POST", url, data=data, json=json, **kwargs)
  File "/var/lib/juju/agents/unit-mysql-2/charm/venv/requests/sessions.py", line 589, in request
    resp = self.send(prep, **send_kwargs)
  File "/var/lib/juju/agents/unit-mysql-2/charm/venv/requests/sessions.py", line 703, in send
    r = adapter.send(request, **kwargs)
  File "/var/lib/juju/agents/unit-mysql-2/charm/venv/requests/adapters.py", line 519, in send
    raise ConnectionError(e, request=request)
requests.exceptions.ConnectionError: HTTPConnectionPool(host='juju-7a3058-4.lxd', port=4318): Max retries exceeded with url: /v1/traces (Caused by NewConnectionError('<urllib3.connection.HTTPConnection object at 0x7f382bf30610>: Failed to establish a new connection: [Errno 111] Connection refused'))
unit-mysql-2: 01:34:57 ERROR unit.mysql/2.juju-log certificates:14: Uncaught exception while in charm code:
Traceback (most recent call last):
  File "/var/lib/juju/agents/unit-mysql-2/charm/./src/charm.py", line 855, in <module>
    main(MySQLOperatorCharm)
  File "/var/lib/juju/agents/unit-mysql-2/charm/venv/ops/main.py", line 551, in main
    manager.run()
  File "/var/lib/juju/agents/unit-mysql-2/charm/venv/ops/main.py", line 530, in run
    self._emit()
  File "/var/lib/juju/agents/unit-mysql-2/charm/venv/ops/main.py", line 519, in _emit
    _emit_charm_event(self.charm, self.dispatcher.event_name)
  File "/var/lib/juju/agents/unit-mysql-2/charm/venv/ops/main.py", line 147, in _emit_charm_event
    event_to_emit.emit(*args, **kwargs)
  File "/var/lib/juju/agents/unit-mysql-2/charm/venv/ops/framework.py", line 348, in emit
    framework._emit(event)
  File "/var/lib/juju/agents/unit-mysql-2/charm/venv/ops/framework.py", line 860, in _emit
    self._reemit(event_path)
  File "/var/lib/juju/agents/unit-mysql-2/charm/venv/ops/framework.py", line 950, in _reemit
    custom_handler(event)
  File "/var/lib/juju/agents/unit-mysql-2/charm/lib/charms/tempo_coordinator_k8s/v0/charm_tracing.py", line 734, in wrapped_function
    return callable(*args, **kwargs)  # type: ignore
  File "/var/lib/juju/agents/unit-mysql-2/charm/lib/charms/mysql/v0/tls.py", line 94, in _on_tls_relation_joined
    if not self.charm.unit_initialized:
  File "/var/lib/juju/agents/unit-mysql-2/charm/lib/charms/mysql/v0/mysql.py", line 667, in unit_initialized
    return self._mysql.cluster_metadata_exists(self.get_unit_address(self.unit))
  File "/var/lib/juju/agents/unit-mysql-2/charm/./src/charm.py", line 578, in _mysql
    self.app_peer_data["cluster-name"],
  File "/var/lib/juju/agents/unit-mysql-2/charm/venv/ops/model.py", line 1812, in __getitem__
    return super().__getitem__(key)
  File "/var/lib/juju/agents/unit-mysql-2/charm/venv/ops/model.py", line 841, in __getitem__
    return self._data[key]
KeyError: 'cluster-name'
unit-mysql-2: 01:34:57 ERROR juju.worker.uniter.operation hook "certificates-relation-joined" (via hook dispatching script: dispatch) failed: exit status 1
unit-mysql-2: 01:35:08 ERROR unit.mysql/2.juju-log certificates:14: Exception while exporting Span batch.
Traceback (most recent call last):
  File "/var/lib/juju/agents/unit-mysql-2/charm/venv/urllib3/connection.py", line 174, in _new_conn
    conn = connection.create_connection(
  File "/var/lib/juju/agents/unit-mysql-2/charm/venv/urllib3/util/connection.py", line 95, in create_connection
    raise err
  File "/var/lib/juju/agents/unit-mysql-2/charm/venv/urllib3/util/connection.py", line 85, in create_connection
    sock.connect(sa)
ConnectionRefusedError: [Errno 111] Connection refused

During handling of the above exception, another exception occurred:

Traceback (most recent call last):
  File "/var/lib/juju/agents/unit-mysql-2/charm/venv/urllib3/connectionpool.py", line 715, in urlopen
    httplib_response = self._make_request(
  File "/var/lib/juju/agents/unit-mysql-2/charm/venv/urllib3/connectionpool.py", line 416, in _make_request
    conn.request(method, url, **httplib_request_kw)
  File "/var/lib/juju/agents/unit-mysql-2/charm/venv/urllib3/connection.py", line 244, in request
    super(HTTPConnection, self).request(method, url, body=body, headers=headers)
  File "/usr/lib/python3.10/http/client.py", line 1283, in request
    self._send_request(method, url, body, headers, encode_chunked)
  File "/usr/lib/python3.10/http/client.py", line 1329, in _send_request
    self.endheaders(body, encode_chunked=encode_chunked)
  File "/usr/lib/python3.10/http/client.py", line 1278, in endheaders
    self._send_output(message_body, encode_chunked=encode_chunked)
  File "/usr/lib/python3.10/http/client.py", line 1038, in _send_output
    self.send(msg)
  File "/usr/lib/python3.10/http/client.py", line 976, in send
    self.connect()
  File "/var/lib/juju/agents/unit-mysql-2/charm/venv/urllib3/connection.py", line 205, in connect
    conn = self._new_conn()
  File "/var/lib/juju/agents/unit-mysql-2/charm/venv/urllib3/connection.py", line 186, in _new_conn
    raise NewConnectionError(
urllib3.exceptions.NewConnectionError: <urllib3.connection.HTTPConnection object at 0x7fb69c93cb80>: Failed to establish a new connection: [Errno 111] Connection refused

During handling of the above exception, another exception occurred:

Traceback (most recent call last):
  File "/var/lib/juju/agents/unit-mysql-2/charm/venv/requests/adapters.py", line 486, in send
    resp = conn.urlopen(
  File "/var/lib/juju/agents/unit-mysql-2/charm/venv/urllib3/connectionpool.py", line 801, in urlopen
    retries = retries.increment(
  File "/var/lib/juju/agents/unit-mysql-2/charm/venv/urllib3/util/retry.py", line 594, in increment
    raise MaxRetryError(_pool, url, error or ResponseError(cause))
urllib3.exceptions.MaxRetryError: HTTPConnectionPool(host='juju-7a3058-4.lxd', port=4318): Max retries exceeded with url: /v1/traces (Caused by NewConnectionError('<urllib3.connection.HTTPConnection object at 0x7fb69c93cb80>: Failed to establish a new connection: [Errno 111] Connection refused'))

During handling of the above exception, another exception occurred:

Traceback (most recent call last):
  File "/var/lib/juju/agents/unit-mysql-2/charm/venv/opentelemetry/sdk/trace/export/__init__.py", line 368, in _export_batch
    self.span_exporter.export(self.spans_list[:idx])  # type: ignore
  File "/var/lib/juju/agents/unit-mysql-2/charm/venv/opentelemetry/exporter/otlp/proto/http/trace_exporter/__init__.py", line 145, in export
    resp = self._export(serialized_data)
  File "/var/lib/juju/agents/unit-mysql-2/charm/venv/opentelemetry/exporter/otlp/proto/http/trace_exporter/__init__.py", line 114, in _export
    return self._session.post(
  File "/var/lib/juju/agents/unit-mysql-2/charm/venv/requests/sessions.py", line 637, in post
    return self.request("POST", url, data=data, json=json, **kwargs)
  File "/var/lib/juju/agents/unit-mysql-2/charm/venv/requests/sessions.py", line 589, in request
    resp = self.send(prep, **send_kwargs)
  File "/var/lib/juju/agents/unit-mysql-2/charm/venv/requests/sessions.py", line 703, in send
    r = adapter.send(request, **kwargs)
  File "/var/lib/juju/agents/unit-mysql-2/charm/venv/requests/adapters.py", line 519, in send
    raise ConnectionError(e, request=request)
requests.exceptions.ConnectionError: HTTPConnectionPool(host='juju-7a3058-4.lxd', port=4318): Max retries exceeded with url: /v1/traces (Caused by NewConnectionError('<urllib3.connection.HTTPConnection object at 0x7fb69c93cb80>: Failed to establish a new connection: [Errno 111] Connection refused'))
unit-mysql-2: 01:35:08 ERROR unit.mysql/2.juju-log certificates:14: Uncaught exception while in charm code:
Traceback (most recent call last):
  File "/var/lib/juju/agents/unit-mysql-2/charm/./src/charm.py", line 855, in <module>
    main(MySQLOperatorCharm)
  File "/var/lib/juju/agents/unit-mysql-2/charm/venv/ops/main.py", line 551, in main
    manager.run()
  File "/var/lib/juju/agents/unit-mysql-2/charm/venv/ops/main.py", line 530, in run
    self._emit()
  File "/var/lib/juju/agents/unit-mysql-2/charm/venv/ops/main.py", line 519, in _emit
    _emit_charm_event(self.charm, self.dispatcher.event_name)
  File "/var/lib/juju/agents/unit-mysql-2/charm/venv/ops/main.py", line 147, in _emit_charm_event
    event_to_emit.emit(*args, **kwargs)
  File "/var/lib/juju/agents/unit-mysql-2/charm/venv/ops/framework.py", line 348, in emit
    framework._emit(event)
  File "/var/lib/juju/agents/unit-mysql-2/charm/venv/ops/framework.py", line 860, in _emit
    self._reemit(event_path)
  File "/var/lib/juju/agents/unit-mysql-2/charm/venv/ops/framework.py", line 950, in _reemit
    custom_handler(event)
  File "/var/lib/juju/agents/unit-mysql-2/charm/lib/charms/tempo_coordinator_k8s/v0/charm_tracing.py", line 734, in wrapped_function
    return callable(*args, **kwargs)  # type: ignore
  File "/var/lib/juju/agents/unit-mysql-2/charm/lib/charms/mysql/v0/tls.py", line 94, in _on_tls_relation_joined
    if not self.charm.unit_initialized:
  File "/var/lib/juju/agents/unit-mysql-2/charm/lib/charms/mysql/v0/mysql.py", line 667, in unit_initialized
    return self._mysql.cluster_metadata_exists(self.get_unit_address(self.unit))
  File "/var/lib/juju/agents/unit-mysql-2/charm/./src/charm.py", line 578, in _mysql
    self.app_peer_data["cluster-name"],
  File "/var/lib/juju/agents/unit-mysql-2/charm/venv/ops/model.py", line 1812, in __getitem__
    return super().__getitem__(key)
  File "/var/lib/juju/agents/unit-mysql-2/charm/venv/ops/model.py", line 841, in __getitem__
    return self._data[key]
KeyError: 'cluster-name'
unit-mysql-2: 01:35:08 ERROR juju.worker.uniter.operation hook "certificates-relation-joined" (via hook dispatching script: dispatch) failed: exit status 1
unit-mysql-2: 01:35:29 ERROR unit.mysql/2.juju-log certificates:14: Exception while exporting Span batch.
Traceback (most recent call last):
  File "/var/lib/juju/agents/unit-mysql-2/charm/venv/urllib3/connection.py", line 174, in _new_conn
    conn = connection.create_connection(
  File "/var/lib/juju/agents/unit-mysql-2/charm/venv/urllib3/util/connection.py", line 95, in create_connection
    raise err
  File "/var/lib/juju/agents/unit-mysql-2/charm/venv/urllib3/util/connection.py", line 85, in create_connection
    sock.connect(sa)
ConnectionRefusedError: [Errno 111] Connection refused

During handling of the above exception, another exception occurred:

Traceback (most recent call last):
  File "/var/lib/juju/agents/unit-mysql-2/charm/venv/urllib3/connectionpool.py", line 715, in urlopen
    httplib_response = self._make_request(
  File "/var/lib/juju/agents/unit-mysql-2/charm/venv/urllib3/connectionpool.py", line 416, in _make_request
    conn.request(method, url, **httplib_request_kw)
  File "/var/lib/juju/agents/unit-mysql-2/charm/venv/urllib3/connection.py", line 244, in request
    super(HTTPConnection, self).request(method, url, body=body, headers=headers)
  File "/usr/lib/python3.10/http/client.py", line 1283, in request
    self._send_request(method, url, body, headers, encode_chunked)
  File "/usr/lib/python3.10/http/client.py", line 1329, in _send_request
    self.endheaders(body, encode_chunked=encode_chunked)
  File "/usr/lib/python3.10/http/client.py", line 1278, in endheaders
    self._send_output(message_body, encode_chunked=encode_chunked)
  File "/usr/lib/python3.10/http/client.py", line 1038, in _send_output
    self.send(msg)
  File "/usr/lib/python3.10/http/client.py", line 976, in send
    self.connect()
  File "/var/lib/juju/agents/unit-mysql-2/charm/venv/urllib3/connection.py", line 205, in connect
    conn = self._new_conn()
  File "/var/lib/juju/agents/unit-mysql-2/charm/venv/urllib3/connection.py", line 186, in _new_conn
    raise NewConnectionError(
urllib3.exceptions.NewConnectionError: <urllib3.connection.HTTPConnection object at 0x7f94de29c520>: Failed to establish a new connection: [Errno 111] Connection refused

During handling of the above exception, another exception occurred:

Traceback (most recent call last):
  File "/var/lib/juju/agents/unit-mysql-2/charm/venv/requests/adapters.py", line 486, in send
    resp = conn.urlopen(
  File "/var/lib/juju/agents/unit-mysql-2/charm/venv/urllib3/connectionpool.py", line 801, in urlopen
    retries = retries.increment(
  File "/var/lib/juju/agents/unit-mysql-2/charm/venv/urllib3/util/retry.py", line 594, in increment
    raise MaxRetryError(_pool, url, error or ResponseError(cause))
urllib3.exceptions.MaxRetryError: HTTPConnectionPool(host='juju-7a3058-4.lxd', port=4318): Max retries exceeded with url: /v1/traces (Caused by NewConnectionError('<urllib3.connection.HTTPConnection object at 0x7f94de29c520>: Failed to establish a new connection: [Errno 111] Connection refused'))

During handling of the above exception, another exception occurred:

Traceback (most recent call last):
  File "/var/lib/juju/agents/unit-mysql-2/charm/venv/opentelemetry/sdk/trace/export/__init__.py", line 368, in _export_batch
    self.span_exporter.export(self.spans_list[:idx])  # type: ignore
  File "/var/lib/juju/agents/unit-mysql-2/charm/venv/opentelemetry/exporter/otlp/proto/http/trace_exporter/__init__.py", line 145, in export
    resp = self._export(serialized_data)
  File "/var/lib/juju/agents/unit-mysql-2/charm/venv/opentelemetry/exporter/otlp/proto/http/trace_exporter/__init__.py", line 114, in _export
    return self._session.post(
  File "/var/lib/juju/agents/unit-mysql-2/charm/venv/requests/sessions.py", line 637, in post
    return self.request("POST", url, data=data, json=json, **kwargs)
  File "/var/lib/juju/agents/unit-mysql-2/charm/venv/requests/sessions.py", line 589, in request
    resp = self.send(prep, **send_kwargs)
  File "/var/lib/juju/agents/unit-mysql-2/charm/venv/requests/sessions.py", line 703, in send
    r = adapter.send(request, **kwargs)
  File "/var/lib/juju/agents/unit-mysql-2/charm/venv/requests/adapters.py", line 519, in send
    raise ConnectionError(e, request=request)
requests.exceptions.ConnectionError: HTTPConnectionPool(host='juju-7a3058-4.lxd', port=4318): Max retries exceeded with url: /v1/traces (Caused by NewConnectionError('<urllib3.connection.HTTPConnection object at 0x7f94de29c520>: Failed to establish a new connection: [Errno 111] Connection refused'))
unit-mysql-2: 01:35:29 ERROR unit.mysql/2.juju-log certificates:14: Uncaught exception while in charm code:
Traceback (most recent call last):
  File "/var/lib/juju/agents/unit-mysql-2/charm/./src/charm.py", line 855, in <module>
    main(MySQLOperatorCharm)
  File "/var/lib/juju/agents/unit-mysql-2/charm/venv/ops/main.py", line 551, in main
    manager.run()
  File "/var/lib/juju/agents/unit-mysql-2/charm/venv/ops/main.py", line 530, in run
    self._emit()
  File "/var/lib/juju/agents/unit-mysql-2/charm/venv/ops/main.py", line 519, in _emit
    _emit_charm_event(self.charm, self.dispatcher.event_name)
  File "/var/lib/juju/agents/unit-mysql-2/charm/venv/ops/main.py", line 147, in _emit_charm_event
    event_to_emit.emit(*args, **kwargs)
  File "/var/lib/juju/agents/unit-mysql-2/charm/venv/ops/framework.py", line 348, in emit
    framework._emit(event)
  File "/var/lib/juju/agents/unit-mysql-2/charm/venv/ops/framework.py", line 860, in _emit
    self._reemit(event_path)
  File "/var/lib/juju/agents/unit-mysql-2/charm/venv/ops/framework.py", line 950, in _reemit
    custom_handler(event)
  File "/var/lib/juju/agents/unit-mysql-2/charm/lib/charms/tempo_coordinator_k8s/v0/charm_tracing.py", line 734, in wrapped_function
    return callable(*args, **kwargs)  # type: ignore
  File "/var/lib/juju/agents/unit-mysql-2/charm/lib/charms/mysql/v0/tls.py", line 94, in _on_tls_relation_joined
    if not self.charm.unit_initialized:
  File "/var/lib/juju/agents/unit-mysql-2/charm/lib/charms/mysql/v0/mysql.py", line 667, in unit_initialized
    return self._mysql.cluster_metadata_exists(self.get_unit_address(self.unit))
  File "/var/lib/juju/agents/unit-mysql-2/charm/./src/charm.py", line 578, in _mysql
    self.app_peer_data["cluster-name"],
  File "/var/lib/juju/agents/unit-mysql-2/charm/venv/ops/model.py", line 1812, in __getitem__
    return super().__getitem__(key)
  File "/var/lib/juju/agents/unit-mysql-2/charm/venv/ops/model.py", line 841, in __getitem__
    return self._data[key]
KeyError: 'cluster-name'
unit-mysql-2: 01:35:29 ERROR juju.worker.uniter.operation hook "certificates-relation-joined" (via hook dispatching script: dispatch) failed: exit status 1
unit-mysql-1: 01:35:35 ERROR unit.mysql/1.juju-log certificates:14: Uncaught exception while in charm code:
Traceback (most recent call last):
  File "/var/lib/juju/agents/unit-mysql-1/charm/./src/charm.py", line 855, in <module>
    main(MySQLOperatorCharm)
  File "/var/lib/juju/agents/unit-mysql-1/charm/venv/ops/main.py", line 551, in main
    manager.run()
  File "/var/lib/juju/agents/unit-mysql-1/charm/venv/ops/main.py", line 530, in run
    self._emit()
  File "/var/lib/juju/agents/unit-mysql-1/charm/venv/ops/main.py", line 519, in _emit
    _emit_charm_event(self.charm, self.dispatcher.event_name)
  File "/var/lib/juju/agents/unit-mysql-1/charm/venv/ops/main.py", line 147, in _emit_charm_event
    event_to_emit.emit(*args, **kwargs)
  File "/var/lib/juju/agents/unit-mysql-1/charm/venv/ops/framework.py", line 348, in emit
    framework._emit(event)
  File "/var/lib/juju/agents/unit-mysql-1/charm/venv/ops/framework.py", line 860, in _emit
    self._reemit(event_path)
  File "/var/lib/juju/agents/unit-mysql-1/charm/venv/ops/framework.py", line 950, in _reemit
    custom_handler(event)
  File "/var/lib/juju/agents/unit-mysql-1/charm/lib/charms/tempo_coordinator_k8s/v0/charm_tracing.py", line 734, in wrapped_function
    return callable(*args, **kwargs)  # type: ignore
  File "/var/lib/juju/agents/unit-mysql-1/charm/lib/charms/mysql/v0/tls.py", line 94, in _on_tls_relation_joined
    if not self.charm.unit_initialized:
  File "/var/lib/juju/agents/unit-mysql-1/charm/lib/charms/mysql/v0/mysql.py", line 667, in unit_initialized
    return self._mysql.cluster_metadata_exists(self.get_unit_address(self.unit))
  File "/var/lib/juju/agents/unit-mysql-1/charm/./src/charm.py", line 578, in _mysql
    self.app_peer_data["cluster-name"],
  File "/var/lib/juju/agents/unit-mysql-1/charm/venv/ops/model.py", line 1812, in __getitem__
    return super().__getitem__(key)
  File "/var/lib/juju/agents/unit-mysql-1/charm/venv/ops/model.py", line 841, in __getitem__
    return self._data[key]
KeyError: 'cluster-name'
unit-mysql-1: 01:35:35 ERROR juju.worker.uniter.operation hook "certificates-relation-joined" (via hook dispatching script: dispatch) failed: exit status 1
unit-mysql-1: 01:35:41 ERROR unit.mysql/1.juju-log certificates:14: Uncaught exception while in charm code:
Traceback (most recent call last):
  File "/var/lib/juju/agents/unit-mysql-1/charm/./src/charm.py", line 855, in <module>
    main(MySQLOperatorCharm)
  File "/var/lib/juju/agents/unit-mysql-1/charm/venv/ops/main.py", line 551, in main
    manager.run()
  File "/var/lib/juju/agents/unit-mysql-1/charm/venv/ops/main.py", line 530, in run
    self._emit()
  File "/var/lib/juju/agents/unit-mysql-1/charm/venv/ops/main.py", line 519, in _emit
    _emit_charm_event(self.charm, self.dispatcher.event_name)
  File "/var/lib/juju/agents/unit-mysql-1/charm/venv/ops/main.py", line 147, in _emit_charm_event
    event_to_emit.emit(*args, **kwargs)
  File "/var/lib/juju/agents/unit-mysql-1/charm/venv/ops/framework.py", line 348, in emit
    framework._emit(event)
  File "/var/lib/juju/agents/unit-mysql-1/charm/venv/ops/framework.py", line 860, in _emit
    self._reemit(event_path)
  File "/var/lib/juju/agents/unit-mysql-1/charm/venv/ops/framework.py", line 950, in _reemit
    custom_handler(event)
  File "/var/lib/juju/agents/unit-mysql-1/charm/lib/charms/tempo_coordinator_k8s/v0/charm_tracing.py", line 734, in wrapped_function
    return callable(*args, **kwargs)  # type: ignore
  File "/var/lib/juju/agents/unit-mysql-1/charm/lib/charms/mysql/v0/tls.py", line 94, in _on_tls_relation_joined
    if not self.charm.unit_initialized:
  File "/var/lib/juju/agents/unit-mysql-1/charm/lib/charms/mysql/v0/mysql.py", line 667, in unit_initialized
    return self._mysql.cluster_metadata_exists(self.get_unit_address(self.unit))
  File "/var/lib/juju/agents/unit-mysql-1/charm/./src/charm.py", line 578, in _mysql
    self.app_peer_data["cluster-name"],
  File "/var/lib/juju/agents/unit-mysql-1/charm/venv/ops/model.py", line 1812, in __getitem__
    return super().__getitem__(key)
  File "/var/lib/juju/agents/unit-mysql-1/charm/venv/ops/model.py", line 841, in __getitem__
    return self._data[key]
KeyError: 'cluster-name'
unit-mysql-1: 01:35:41 ERROR juju.worker.uniter.operation hook "certificates-relation-joined" (via hook dispatching script: dispatch) failed: exit status 1
unit-mysql-1: 01:35:52 ERROR unit.mysql/1.juju-log certificates:14: Uncaught exception while in charm code:
Traceback (most recent call last):
  File "/var/lib/juju/agents/unit-mysql-1/charm/./src/charm.py", line 855, in <module>
    main(MySQLOperatorCharm)
  File "/var/lib/juju/agents/unit-mysql-1/charm/venv/ops/main.py", line 551, in main
    manager.run()
  File "/var/lib/juju/agents/unit-mysql-1/charm/venv/ops/main.py", line 530, in run
    self._emit()
  File "/var/lib/juju/agents/unit-mysql-1/charm/venv/ops/main.py", line 519, in _emit
    _emit_charm_event(self.charm, self.dispatcher.event_name)
  File "/var/lib/juju/agents/unit-mysql-1/charm/venv/ops/main.py", line 147, in _emit_charm_event
    event_to_emit.emit(*args, **kwargs)
  File "/var/lib/juju/agents/unit-mysql-1/charm/venv/ops/framework.py", line 348, in emit
    framework._emit(event)
  File "/var/lib/juju/agents/unit-mysql-1/charm/venv/ops/framework.py", line 860, in _emit
    self._reemit(event_path)
  File "/var/lib/juju/agents/unit-mysql-1/charm/venv/ops/framework.py", line 950, in _reemit
    custom_handler(event)
  File "/var/lib/juju/agents/unit-mysql-1/charm/lib/charms/tempo_coordinator_k8s/v0/charm_tracing.py", line 734, in wrapped_function
    return callable(*args, **kwargs)  # type: ignore
  File "/var/lib/juju/agents/unit-mysql-1/charm/lib/charms/mysql/v0/tls.py", line 94, in _on_tls_relation_joined
    if not self.charm.unit_initialized:
  File "/var/lib/juju/agents/unit-mysql-1/charm/lib/charms/mysql/v0/mysql.py", line 667, in unit_initialized
    return self._mysql.cluster_metadata_exists(self.get_unit_address(self.unit))
  File "/var/lib/juju/agents/unit-mysql-1/charm/./src/charm.py", line 578, in _mysql
    self.app_peer_data["cluster-name"],
  File "/var/lib/juju/agents/unit-mysql-1/charm/venv/ops/model.py", line 1812, in __getitem__
    return super().__getitem__(key)
  File "/var/lib/juju/agents/unit-mysql-1/charm/venv/ops/model.py", line 841, in __getitem__
    return self._data[key]
KeyError: 'cluster-name'
unit-mysql-1: 01:35:52 ERROR juju.worker.uniter.operation hook "certificates-relation-joined" (via hook dispatching script: dispatch) failed: exit status 1
unit-mysql-2: 01:36:08 ERROR unit.mysql/2.juju-log certificates:14: Exception while exporting Span batch.
Traceback (most recent call last):
  File "/var/lib/juju/agents/unit-mysql-2/charm/venv/urllib3/connection.py", line 174, in _new_conn
    conn = connection.create_connection(
  File "/var/lib/juju/agents/unit-mysql-2/charm/venv/urllib3/util/connection.py", line 95, in create_connection
    raise err
  File "/var/lib/juju/agents/unit-mysql-2/charm/venv/urllib3/util/connection.py", line 85, in create_connection
    sock.connect(sa)
ConnectionRefusedError: [Errno 111] Connection refused

During handling of the above exception, another exception occurred:

Traceback (most recent call last):
  File "/var/lib/juju/agents/unit-mysql-2/charm/venv/urllib3/connectionpool.py", line 715, in urlopen
    httplib_response = self._make_request(
  File "/var/lib/juju/agents/unit-mysql-2/charm/venv/urllib3/connectionpool.py", line 416, in _make_request
    conn.request(method, url, **httplib_request_kw)
  File "/var/lib/juju/agents/unit-mysql-2/charm/venv/urllib3/connection.py", line 244, in request
    super(HTTPConnection, self).request(method, url, body=body, headers=headers)
  File "/usr/lib/python3.10/http/client.py", line 1283, in request
    self._send_request(method, url, body, headers, encode_chunked)
  File "/usr/lib/python3.10/http/client.py", line 1329, in _send_request
    self.endheaders(body, encode_chunked=encode_chunked)
  File "/usr/lib/python3.10/http/client.py", line 1278, in endheaders
    self._send_output(message_body, encode_chunked=encode_chunked)
  File "/usr/lib/python3.10/http/client.py", line 1038, in _send_output
    self.send(msg)
  File "/usr/lib/python3.10/http/client.py", line 976, in send
    self.connect()
  File "/var/lib/juju/agents/unit-mysql-2/charm/venv/urllib3/connection.py", line 205, in connect
    conn = self._new_conn()
  File "/var/lib/juju/agents/unit-mysql-2/charm/venv/urllib3/connection.py", line 186, in _new_conn
    raise NewConnectionError(
urllib3.exceptions.NewConnectionError: <urllib3.connection.HTTPConnection object at 0x7f7a58f405e0>: Failed to establish a new connection: [Errno 111] Connection refused

During handling of the above exception, another exception occurred:

Traceback (most recent call last):
  File "/var/lib/juju/agents/unit-mysql-2/charm/venv/requests/adapters.py", line 486, in send
    resp = conn.urlopen(
  File "/var/lib/juju/agents/unit-mysql-2/charm/venv/urllib3/connectionpool.py", line 801, in urlopen
    retries = retries.increment(
  File "/var/lib/juju/agents/unit-mysql-2/charm/venv/urllib3/util/retry.py", line 594, in increment
    raise MaxRetryError(_pool, url, error or ResponseError(cause))
urllib3.exceptions.MaxRetryError: HTTPConnectionPool(host='juju-7a3058-4.lxd', port=4318): Max retries exceeded with url: /v1/traces (Caused by NewConnectionError('<urllib3.connection.HTTPConnection object at 0x7f7a58f405e0>: Failed to establish a new connection: [Errno 111] Connection refused'))

During handling of the above exception, another exception occurred:

Traceback (most recent call last):
  File "/var/lib/juju/agents/unit-mysql-2/charm/venv/opentelemetry/sdk/trace/export/__init__.py", line 368, in _export_batch
    self.span_exporter.export(self.spans_list[:idx])  # type: ignore
  File "/var/lib/juju/agents/unit-mysql-2/charm/venv/opentelemetry/exporter/otlp/proto/http/trace_exporter/__init__.py", line 145, in export
    resp = self._export(serialized_data)
  File "/var/lib/juju/agents/unit-mysql-2/charm/venv/opentelemetry/exporter/otlp/proto/http/trace_exporter/__init__.py", line 114, in _export
    return self._session.post(
  File "/var/lib/juju/agents/unit-mysql-2/charm/venv/requests/sessions.py", line 637, in post
    return self.request("POST", url, data=data, json=json, **kwargs)
  File "/var/lib/juju/agents/unit-mysql-2/charm/venv/requests/sessions.py", line 589, in request
    resp = self.send(prep, **send_kwargs)
  File "/var/lib/juju/agents/unit-mysql-2/charm/venv/requests/sessions.py", line 703, in send
    r = adapter.send(request, **kwargs)
  File "/var/lib/juju/agents/unit-mysql-2/charm/venv/requests/adapters.py", line 519, in send
    raise ConnectionError(e, request=request)
requests.exceptions.ConnectionError: HTTPConnectionPool(host='juju-7a3058-4.lxd', port=4318): Max retries exceeded with url: /v1/traces (Caused by NewConnectionError('<urllib3.connection.HTTPConnection object at 0x7f7a58f405e0>: Failed to establish a new connection: [Errno 111] Connection refused'))
unit-mysql-2: 01:36:08 ERROR unit.mysql/2.juju-log certificates:14: Uncaught exception while in charm code:
Traceback (most recent call last):
  File "/var/lib/juju/agents/unit-mysql-2/charm/./src/charm.py", line 855, in <module>
    main(MySQLOperatorCharm)
  File "/var/lib/juju/agents/unit-mysql-2/charm/venv/ops/main.py", line 551, in main
    manager.run()
  File "/var/lib/juju/agents/unit-mysql-2/charm/venv/ops/main.py", line 530, in run
    self._emit()
  File "/var/lib/juju/agents/unit-mysql-2/charm/venv/ops/main.py", line 519, in _emit
    _emit_charm_event(self.charm, self.dispatcher.event_name)
  File "/var/lib/juju/agents/unit-mysql-2/charm/venv/ops/main.py", line 147, in _emit_charm_event
    event_to_emit.emit(*args, **kwargs)
  File "/var/lib/juju/agents/unit-mysql-2/charm/venv/ops/framework.py", line 348, in emit
    framework._emit(event)
  File "/var/lib/juju/agents/unit-mysql-2/charm/venv/ops/framework.py", line 860, in _emit
    self._reemit(event_path)
  File "/var/lib/juju/agents/unit-mysql-2/charm/venv/ops/framework.py", line 950, in _reemit
    custom_handler(event)
  File "/var/lib/juju/agents/unit-mysql-2/charm/lib/charms/tempo_coordinator_k8s/v0/charm_tracing.py", line 734, in wrapped_function
    return callable(*args, **kwargs)  # type: ignore
  File "/var/lib/juju/agents/unit-mysql-2/charm/lib/charms/mysql/v0/tls.py", line 94, in _on_tls_relation_joined
    if not self.charm.unit_initialized:
  File "/var/lib/juju/agents/unit-mysql-2/charm/lib/charms/mysql/v0/mysql.py", line 667, in unit_initialized
    return self._mysql.cluster_metadata_exists(self.get_unit_address(self.unit))
  File "/var/lib/juju/agents/unit-mysql-2/charm/./src/charm.py", line 578, in _mysql
    self.app_peer_data["cluster-name"],
  File "/var/lib/juju/agents/unit-mysql-2/charm/venv/ops/model.py", line 1812, in __getitem__
    return super().__getitem__(key)
  File "/var/lib/juju/agents/unit-mysql-2/charm/venv/ops/model.py", line 841, in __getitem__
    return self._data[key]
KeyError: 'cluster-name'
unit-mysql-2: 01:36:08 ERROR juju.worker.uniter.operation hook "certificates-relation-joined" (via hook dispatching script: dispatch) failed: exit status 1
unit-mysql-1: 01:36:13 ERROR unit.mysql/1.juju-log certificates:14: Uncaught exception while in charm code:
Traceback (most recent call last):
  File "/var/lib/juju/agents/unit-mysql-1/charm/./src/charm.py", line 855, in <module>
    main(MySQLOperatorCharm)
  File "/var/lib/juju/agents/unit-mysql-1/charm/venv/ops/main.py", line 551, in main
    manager.run()
  File "/var/lib/juju/agents/unit-mysql-1/charm/venv/ops/main.py", line 530, in run
    self._emit()
  File "/var/lib/juju/agents/unit-mysql-1/charm/venv/ops/main.py", line 519, in _emit
    _emit_charm_event(self.charm, self.dispatcher.event_name)
  File "/var/lib/juju/agents/unit-mysql-1/charm/venv/ops/main.py", line 147, in _emit_charm_event
    event_to_emit.emit(*args, **kwargs)
  File "/var/lib/juju/agents/unit-mysql-1/charm/venv/ops/framework.py", line 348, in emit
    framework._emit(event)
  File "/var/lib/juju/agents/unit-mysql-1/charm/venv/ops/framework.py", line 860, in _emit
    self._reemit(event_path)
  File "/var/lib/juju/agents/unit-mysql-1/charm/venv/ops/framework.py", line 950, in _reemit
    custom_handler(event)
  File "/var/lib/juju/agents/unit-mysql-1/charm/lib/charms/tempo_coordinator_k8s/v0/charm_tracing.py", line 734, in wrapped_function
    return callable(*args, **kwargs)  # type: ignore
  File "/var/lib/juju/agents/unit-mysql-1/charm/lib/charms/mysql/v0/tls.py", line 94, in _on_tls_relation_joined
    if not self.charm.unit_initialized:
  File "/var/lib/juju/agents/unit-mysql-1/charm/lib/charms/mysql/v0/mysql.py", line 667, in unit_initialized
    return self._mysql.cluster_metadata_exists(self.get_unit_address(self.unit))
  File "/var/lib/juju/agents/unit-mysql-1/charm/./src/charm.py", line 578, in _mysql
    self.app_peer_data["cluster-name"],
  File "/var/lib/juju/agents/unit-mysql-1/charm/venv/ops/model.py", line 1812, in __getitem__
    return super().__getitem__(key)
  File "/var/lib/juju/agents/unit-mysql-1/charm/venv/ops/model.py", line 841, in __getitem__
    return self._data[key]
KeyError: 'cluster-name'
unit-mysql-1: 01:36:13 ERROR juju.worker.uniter.operation hook "certificates-relation-joined" (via hook dispatching script: dispatch) failed: exit status 1
unit-mysql-1: 01:36:55 ERROR unit.mysql/1.juju-log certificates:14: Uncaught exception while in charm code:
Traceback (most recent call last):
  File "/var/lib/juju/agents/unit-mysql-1/charm/./src/charm.py", line 855, in <module>
    main(MySQLOperatorCharm)
  File "/var/lib/juju/agents/unit-mysql-1/charm/venv/ops/main.py", line 551, in main
    manager.run()
  File "/var/lib/juju/agents/unit-mysql-1/charm/venv/ops/main.py", line 530, in run
    self._emit()
  File "/var/lib/juju/agents/unit-mysql-1/charm/venv/ops/main.py", line 519, in _emit
    _emit_charm_event(self.charm, self.dispatcher.event_name)
  File "/var/lib/juju/agents/unit-mysql-1/charm/venv/ops/main.py", line 147, in _emit_charm_event
    event_to_emit.emit(*args, **kwargs)
  File "/var/lib/juju/agents/unit-mysql-1/charm/venv/ops/framework.py", line 348, in emit
    framework._emit(event)
  File "/var/lib/juju/agents/unit-mysql-1/charm/venv/ops/framework.py", line 860, in _emit
    self._reemit(event_path)
  File "/var/lib/juju/agents/unit-mysql-1/charm/venv/ops/framework.py", line 950, in _reemit
    custom_handler(event)
  File "/var/lib/juju/agents/unit-mysql-1/charm/lib/charms/tempo_coordinator_k8s/v0/charm_tracing.py", line 734, in wrapped_function
    return callable(*args, **kwargs)  # type: ignore
  File "/var/lib/juju/agents/unit-mysql-1/charm/lib/charms/mysql/v0/tls.py", line 94, in _on_tls_relation_joined
    if not self.charm.unit_initialized:
  File "/var/lib/juju/agents/unit-mysql-1/charm/lib/charms/mysql/v0/mysql.py", line 667, in unit_initialized
    return self._mysql.cluster_metadata_exists(self.get_unit_address(self.unit))
  File "/var/lib/juju/agents/unit-mysql-1/charm/./src/charm.py", line 578, in _mysql
    self.app_peer_data["cluster-name"],
  File "/var/lib/juju/agents/unit-mysql-1/charm/venv/ops/model.py", line 1812, in __getitem__
    return super().__getitem__(key)
  File "/var/lib/juju/agents/unit-mysql-1/charm/venv/ops/model.py", line 841, in __getitem__
    return self._data[key]
KeyError: 'cluster-name'
unit-mysql-1: 01:36:55 ERROR juju.worker.uniter.operation hook "certificates-relation-joined" (via hook dispatching script: dispatch) failed: exit status 1
unit-mysql-2: 01:37:27 ERROR unit.mysql/2.juju-log certificates:14: Exception while exporting Span batch.
Traceback (most recent call last):
  File "/var/lib/juju/agents/unit-mysql-2/charm/venv/urllib3/connection.py", line 174, in _new_conn
    conn = connection.create_connection(
  File "/var/lib/juju/agents/unit-mysql-2/charm/venv/urllib3/util/connection.py", line 95, in create_connection
    raise err
  File "/var/lib/juju/agents/unit-mysql-2/charm/venv/urllib3/util/connection.py", line 85, in create_connection
    sock.connect(sa)
ConnectionRefusedError: [Errno 111] Connection refused

During handling of the above exception, another exception occurred:

Traceback (most recent call last):
  File "/var/lib/juju/agents/unit-mysql-2/charm/venv/urllib3/connectionpool.py", line 715, in urlopen
    httplib_response = self._make_request(
  File "/var/lib/juju/agents/unit-mysql-2/charm/venv/urllib3/connectionpool.py", line 416, in _make_request
    conn.request(method, url, **httplib_request_kw)
  File "/var/lib/juju/agents/unit-mysql-2/charm/venv/urllib3/connection.py", line 244, in request
    super(HTTPConnection, self).request(method, url, body=body, headers=headers)
  File "/usr/lib/python3.10/http/client.py", line 1283, in request
    self._send_request(method, url, body, headers, encode_chunked)
  File "/usr/lib/python3.10/http/client.py", line 1329, in _send_request
    self.endheaders(body, encode_chunked=encode_chunked)
  File "/usr/lib/python3.10/http/client.py", line 1278, in endheaders
    self._send_output(message_body, encode_chunked=encode_chunked)
  File "/usr/lib/python3.10/http/client.py", line 1038, in _send_output
    self.send(msg)
  File "/usr/lib/python3.10/http/client.py", line 976, in send
    self.connect()
  File "/var/lib/juju/agents/unit-mysql-2/charm/venv/urllib3/connection.py", line 205, in connect
    conn = self._new_conn()
  File "/var/lib/juju/agents/unit-mysql-2/charm/venv/urllib3/connection.py", line 186, in _new_conn
    raise NewConnectionError(
urllib3.exceptions.NewConnectionError: <urllib3.connection.HTTPConnection object at 0x7f243287c520>: Failed to establish a new connection: [Errno 111] Connection refused

During handling of the above exception, another exception occurred:

Traceback (most recent call last):
  File "/var/lib/juju/agents/unit-mysql-2/charm/venv/requests/adapters.py", line 486, in send
    resp = conn.urlopen(
  File "/var/lib/juju/agents/unit-mysql-2/charm/venv/urllib3/connectionpool.py", line 801, in urlopen
    retries = retries.increment(
  File "/var/lib/juju/agents/unit-mysql-2/charm/venv/urllib3/util/retry.py", line 594, in increment
    raise MaxRetryError(_pool, url, error or ResponseError(cause))
urllib3.exceptions.MaxRetryError: HTTPConnectionPool(host='juju-7a3058-4.lxd', port=4318): Max retries exceeded with url: /v1/traces (Caused by NewConnectionError('<urllib3.connection.HTTPConnection object at 0x7f243287c520>: Failed to establish a new connection: [Errno 111] Connection refused'))

During handling of the above exception, another exception occurred:

Traceback (most recent call last):
  File "/var/lib/juju/agents/unit-mysql-2/charm/venv/opentelemetry/sdk/trace/export/__init__.py", line 368, in _export_batch
    self.span_exporter.export(self.spans_list[:idx])  # type: ignore
  File "/var/lib/juju/agents/unit-mysql-2/charm/venv/opentelemetry/exporter/otlp/proto/http/trace_exporter/__init__.py", line 145, in export
    resp = self._export(serialized_data)
  File "/var/lib/juju/agents/unit-mysql-2/charm/venv/opentelemetry/exporter/otlp/proto/http/trace_exporter/__init__.py", line 114, in _export
    return self._session.post(
  File "/var/lib/juju/agents/unit-mysql-2/charm/venv/requests/sessions.py", line 637, in post
    return self.request("POST", url, data=data, json=json, **kwargs)
  File "/var/lib/juju/agents/unit-mysql-2/charm/venv/requests/sessions.py", line 589, in request
    resp = self.send(prep, **send_kwargs)
  File "/var/lib/juju/agents/unit-mysql-2/charm/venv/requests/sessions.py", line 703, in send
    r = adapter.send(request, **kwargs)
  File "/var/lib/juju/agents/unit-mysql-2/charm/venv/requests/adapters.py", line 519, in send
    raise ConnectionError(e, request=request)
requests.exceptions.ConnectionError: HTTPConnectionPool(host='juju-7a3058-4.lxd', port=4318): Max retries exceeded with url: /v1/traces (Caused by NewConnectionError('<urllib3.connection.HTTPConnection object at 0x7f243287c520>: Failed to establish a new connection: [Errno 111] Connection refused'))
unit-mysql-2: 01:37:27 ERROR unit.mysql/2.juju-log certificates:14: Uncaught exception while in charm code:
Traceback (most recent call last):
  File "/var/lib/juju/agents/unit-mysql-2/charm/./src/charm.py", line 855, in <module>
    main(MySQLOperatorCharm)
  File "/var/lib/juju/agents/unit-mysql-2/charm/venv/ops/main.py", line 551, in main
    manager.run()
  File "/var/lib/juju/agents/unit-mysql-2/charm/venv/ops/main.py", line 530, in run
    self._emit()
  File "/var/lib/juju/agents/unit-mysql-2/charm/venv/ops/main.py", line 519, in _emit
    _emit_charm_event(self.charm, self.dispatcher.event_name)
  File "/var/lib/juju/agents/unit-mysql-2/charm/venv/ops/main.py", line 147, in _emit_charm_event
    event_to_emit.emit(*args, **kwargs)
  File "/var/lib/juju/agents/unit-mysql-2/charm/venv/ops/framework.py", line 348, in emit
    framework._emit(event)
  File "/var/lib/juju/agents/unit-mysql-2/charm/venv/ops/framework.py", line 860, in _emit
    self._reemit(event_path)
  File "/var/lib/juju/agents/unit-mysql-2/charm/venv/ops/framework.py", line 950, in _reemit
    custom_handler(event)
  File "/var/lib/juju/agents/unit-mysql-2/charm/lib/charms/tempo_coordinator_k8s/v0/charm_tracing.py", line 734, in wrapped_function
    return callable(*args, **kwargs)  # type: ignore
  File "/var/lib/juju/agents/unit-mysql-2/charm/lib/charms/mysql/v0/tls.py", line 94, in _on_tls_relation_joined
    if not self.charm.unit_initialized:
  File "/var/lib/juju/agents/unit-mysql-2/charm/lib/charms/mysql/v0/mysql.py", line 667, in unit_initialized
    return self._mysql.cluster_metadata_exists(self.get_unit_address(self.unit))
  File "/var/lib/juju/agents/unit-mysql-2/charm/./src/charm.py", line 578, in _mysql
    self.app_peer_data["cluster-name"],
  File "/var/lib/juju/agents/unit-mysql-2/charm/venv/ops/model.py", line 1812, in __getitem__
    return super().__getitem__(key)
  File "/var/lib/juju/agents/unit-mysql-2/charm/venv/ops/model.py", line 841, in __getitem__
    return self._data[key]
KeyError: 'cluster-name'
unit-mysql-2: 01:37:27 ERROR juju.worker.uniter.operation hook "certificates-relation-joined" (via hook dispatching script: dispatch) failed: exit status 1
unit-landscape-client-3: 01:37:54 ERROR juju.worker.meterstatus error running "meter-status-changed": charm missing from disk
unit-grafana-agent-3: 01:37:55 ERROR juju.worker.meterstatus error running "meter-status-changed": charm missing from disk
unit-ubuntu-advantage-3: 01:37:55 ERROR juju.worker.meterstatus error running "meter-status-changed": charm missing from disk
unit-mysql-1: 01:38:16 ERROR unit.mysql/1.juju-log certificates:14: Uncaught exception while in charm code:
Traceback (most recent call last):
  File "/var/lib/juju/agents/unit-mysql-1/charm/./src/charm.py", line 855, in <module>
    main(MySQLOperatorCharm)
  File "/var/lib/juju/agents/unit-mysql-1/charm/venv/ops/main.py", line 551, in main
    manager.run()
  File "/var/lib/juju/agents/unit-mysql-1/charm/venv/ops/main.py", line 530, in run
    self._emit()
  File "/var/lib/juju/agents/unit-mysql-1/charm/venv/ops/main.py", line 519, in _emit
    _emit_charm_event(self.charm, self.dispatcher.event_name)
  File "/var/lib/juju/agents/unit-mysql-1/charm/venv/ops/main.py", line 147, in _emit_charm_event
    event_to_emit.emit(*args, **kwargs)
  File "/var/lib/juju/agents/unit-mysql-1/charm/venv/ops/framework.py", line 348, in emit
    framework._emit(event)
  File "/var/lib/juju/agents/unit-mysql-1/charm/venv/ops/framework.py", line 860, in _emit
    self._reemit(event_path)
  File "/var/lib/juju/agents/unit-mysql-1/charm/venv/ops/framework.py", line 950, in _reemit
    custom_handler(event)
  File "/var/lib/juju/agents/unit-mysql-1/charm/lib/charms/tempo_coordinator_k8s/v0/charm_tracing.py", line 734, in wrapped_function
    return callable(*args, **kwargs)  # type: ignore
  File "/var/lib/juju/agents/unit-mysql-1/charm/lib/charms/mysql/v0/tls.py", line 94, in _on_tls_relation_joined
    if not self.charm.unit_initialized:
  File "/var/lib/juju/agents/unit-mysql-1/charm/lib/charms/mysql/v0/mysql.py", line 667, in unit_initialized
    return self._mysql.cluster_metadata_exists(self.get_unit_address(self.unit))
  File "/var/lib/juju/agents/unit-mysql-1/charm/./src/charm.py", line 578, in _mysql
    self.app_peer_data["cluster-name"],
  File "/var/lib/juju/agents/unit-mysql-1/charm/venv/ops/model.py", line 1812, in __getitem__
    return super().__getitem__(key)
  File "/var/lib/juju/agents/unit-mysql-1/charm/venv/ops/model.py", line 841, in __getitem__
    return self._data[key]
KeyError: 'cluster-name'
unit-mysql-1: 01:38:17 ERROR juju.worker.uniter.operation hook "certificates-relation-joined" (via hook dispatching script: dispatch) failed: exit status 1
unit-mysql-2: 01:40:08 ERROR unit.mysql/2.juju-log certificates:14: Exception while exporting Span batch.
Traceback (most recent call last):
  File "/var/lib/juju/agents/unit-mysql-2/charm/venv/urllib3/connection.py", line 174, in _new_conn
    conn = connection.create_connection(
  File "/var/lib/juju/agents/unit-mysql-2/charm/venv/urllib3/util/connection.py", line 95, in create_connection
    raise err
  File "/var/lib/juju/agents/unit-mysql-2/charm/venv/urllib3/util/connection.py", line 85, in create_connection
    sock.connect(sa)
ConnectionRefusedError: [Errno 111] Connection refused

During handling of the above exception, another exception occurred:

Traceback (most recent call last):
  File "/var/lib/juju/agents/unit-mysql-2/charm/venv/urllib3/connectionpool.py", line 715, in urlopen
    httplib_response = self._make_request(
  File "/var/lib/juju/agents/unit-mysql-2/charm/venv/urllib3/connectionpool.py", line 416, in _make_request
    conn.request(method, url, **httplib_request_kw)
  File "/var/lib/juju/agents/unit-mysql-2/charm/venv/urllib3/connection.py", line 244, in request
    super(HTTPConnection, self).request(method, url, body=body, headers=headers)
  File "/usr/lib/python3.10/http/client.py", line 1283, in request
    self._send_request(method, url, body, headers, encode_chunked)
  File "/usr/lib/python3.10/http/client.py", line 1329, in _send_request
    self.endheaders(body, encode_chunked=encode_chunked)
  File "/usr/lib/python3.10/http/client.py", line 1278, in endheaders
    self._send_output(message_body, encode_chunked=encode_chunked)
  File "/usr/lib/python3.10/http/client.py", line 1038, in _send_output
    self.send(msg)
  File "/usr/lib/python3.10/http/client.py", line 976, in send
    self.connect()
  File "/var/lib/juju/agents/unit-mysql-2/charm/venv/urllib3/connection.py", line 205, in connect
    conn = self._new_conn()
  File "/var/lib/juju/agents/unit-mysql-2/charm/venv/urllib3/connection.py", line 186, in _new_conn
    raise NewConnectionError(
urllib3.exceptions.NewConnectionError: <urllib3.connection.HTTPConnection object at 0x7f2fb83dc5e0>: Failed to establish a new connection: [Errno 111] Connection refused

During handling of the above exception, another exception occurred:

Traceback (most recent call last):
  File "/var/lib/juju/agents/unit-mysql-2/charm/venv/requests/adapters.py", line 486, in send
    resp = conn.urlopen(
  File "/var/lib/juju/agents/unit-mysql-2/charm/venv/urllib3/connectionpool.py", line 801, in urlopen
    retries = retries.increment(
  File "/var/lib/juju/agents/unit-mysql-2/charm/venv/urllib3/util/retry.py", line 594, in increment
    raise MaxRetryError(_pool, url, error or ResponseError(cause))
urllib3.exceptions.MaxRetryError: HTTPConnectionPool(host='juju-7a3058-4.lxd', port=4318): Max retries exceeded with url: /v1/traces (Caused by NewConnectionError('<urllib3.connection.HTTPConnection object at 0x7f2fb83dc5e0>: Failed to establish a new connection: [Errno 111] Connection refused'))

During handling of the above exception, another exception occurred:

Traceback (most recent call last):
  File "/var/lib/juju/agents/unit-mysql-2/charm/venv/opentelemetry/sdk/trace/export/__init__.py", line 368, in _export_batch
    self.span_exporter.export(self.spans_list[:idx])  # type: ignore
  File "/var/lib/juju/agents/unit-mysql-2/charm/venv/opentelemetry/exporter/otlp/proto/http/trace_exporter/__init__.py", line 145, in export
    resp = self._export(serialized_data)
  File "/var/lib/juju/agents/unit-mysql-2/charm/venv/opentelemetry/exporter/otlp/proto/http/trace_exporter/__init__.py", line 114, in _export
    return self._session.post(
  File "/var/lib/juju/agents/unit-mysql-2/charm/venv/requests/sessions.py", line 637, in post
    return self.request("POST", url, data=data, json=json, **kwargs)
  File "/var/lib/juju/agents/unit-mysql-2/charm/venv/requests/sessions.py", line 589, in request
    resp = self.send(prep, **send_kwargs)
  File "/var/lib/juju/agents/unit-mysql-2/charm/venv/requests/sessions.py", line 703, in send
    r = adapter.send(request, **kwargs)
  File "/var/lib/juju/agents/unit-mysql-2/charm/venv/requests/adapters.py", line 519, in send
    raise ConnectionError(e, request=request)
requests.exceptions.ConnectionError: HTTPConnectionPool(host='juju-7a3058-4.lxd', port=4318): Max retries exceeded with url: /v1/traces (Caused by NewConnectionError('<urllib3.connection.HTTPConnection object at 0x7f2fb83dc5e0>: Failed to establish a new connection: [Errno 111] Connection refused'))
unit-mysql-2: 01:40:08 ERROR unit.mysql/2.juju-log certificates:14: Uncaught exception while in charm code:
Traceback (most recent call last):
  File "/var/lib/juju/agents/unit-mysql-2/charm/./src/charm.py", line 855, in <module>
    main(MySQLOperatorCharm)
  File "/var/lib/juju/agents/unit-mysql-2/charm/venv/ops/main.py", line 551, in main
    manager.run()
  File "/var/lib/juju/agents/unit-mysql-2/charm/venv/ops/main.py", line 530, in run
    self._emit()
  File "/var/lib/juju/agents/unit-mysql-2/charm/venv/ops/main.py", line 519, in _emit
    _emit_charm_event(self.charm, self.dispatcher.event_name)
  File "/var/lib/juju/agents/unit-mysql-2/charm/venv/ops/main.py", line 147, in _emit_charm_event
    event_to_emit.emit(*args, **kwargs)
  File "/var/lib/juju/agents/unit-mysql-2/charm/venv/ops/framework.py", line 348, in emit
    framework._emit(event)
  File "/var/lib/juju/agents/unit-mysql-2/charm/venv/ops/framework.py", line 860, in _emit
    self._reemit(event_path)
  File "/var/lib/juju/agents/unit-mysql-2/charm/venv/ops/framework.py", line 950, in _reemit
    custom_handler(event)
  File "/var/lib/juju/agents/unit-mysql-2/charm/lib/charms/tempo_coordinator_k8s/v0/charm_tracing.py", line 734, in wrapped_function
    return callable(*args, **kwargs)  # type: ignore
  File "/var/lib/juju/agents/unit-mysql-2/charm/lib/charms/mysql/v0/tls.py", line 94, in _on_tls_relation_joined
    if not self.charm.unit_initialized:
  File "/var/lib/juju/agents/unit-mysql-2/charm/lib/charms/mysql/v0/mysql.py", line 667, in unit_initialized
    return self._mysql.cluster_metadata_exists(self.get_unit_address(self.unit))
  File "/var/lib/juju/agents/unit-mysql-2/charm/./src/charm.py", line 578, in _mysql
    self.app_peer_data["cluster-name"],
  File "/var/lib/juju/agents/unit-mysql-2/charm/venv/ops/model.py", line 1812, in __getitem__
    return super().__getitem__(key)
  File "/var/lib/juju/agents/unit-mysql-2/charm/venv/ops/model.py", line 841, in __getitem__
    return self._data[key]
KeyError: 'cluster-name'
unit-mysql-2: 01:40:08 ERROR juju.worker.uniter.operation hook "certificates-relation-joined" (via hook dispatching script: dispatch) failed: exit status 1
unit-mysql-1: 01:40:54 ERROR unit.mysql/1.juju-log certificates:14: Uncaught exception while in charm code:
Traceback (most recent call last):
  File "/var/lib/juju/agents/unit-mysql-1/charm/./src/charm.py", line 855, in <module>
    main(MySQLOperatorCharm)
  File "/var/lib/juju/agents/unit-mysql-1/charm/venv/ops/main.py", line 551, in main
    manager.run()
  File "/var/lib/juju/agents/unit-mysql-1/charm/venv/ops/main.py", line 530, in run
    self._emit()
  File "/var/lib/juju/agents/unit-mysql-1/charm/venv/ops/main.py", line 519, in _emit
    _emit_charm_event(self.charm, self.dispatcher.event_name)
  File "/var/lib/juju/agents/unit-mysql-1/charm/venv/ops/main.py", line 147, in _emit_charm_event
    event_to_emit.emit(*args, **kwargs)
  File "/var/lib/juju/agents/unit-mysql-1/charm/venv/ops/framework.py", line 348, in emit
    framework._emit(event)
  File "/var/lib/juju/agents/unit-mysql-1/charm/venv/ops/framework.py", line 860, in _emit
    self._reemit(event_path)
  File "/var/lib/juju/agents/unit-mysql-1/charm/venv/ops/framework.py", line 950, in _reemit
    custom_handler(event)
  File "/var/lib/juju/agents/unit-mysql-1/charm/lib/charms/tempo_coordinator_k8s/v0/charm_tracing.py", line 734, in wrapped_function
    return callable(*args, **kwargs)  # type: ignore
  File "/var/lib/juju/agents/unit-mysql-1/charm/lib/charms/mysql/v0/tls.py", line 94, in _on_tls_relation_joined
    if not self.charm.unit_initialized:
  File "/var/lib/juju/agents/unit-mysql-1/charm/lib/charms/mysql/v0/mysql.py", line 667, in unit_initialized
    return self._mysql.cluster_metadata_exists(self.get_unit_address(self.unit))
  File "/var/lib/juju/agents/unit-mysql-1/charm/./src/charm.py", line 578, in _mysql
    self.app_peer_data["cluster-name"],
  File "/var/lib/juju/agents/unit-mysql-1/charm/venv/ops/model.py", line 1812, in __getitem__
    return super().__getitem__(key)
  File "/var/lib/juju/agents/unit-mysql-1/charm/venv/ops/model.py", line 841, in __getitem__
    return self._data[key]
KeyError: 'cluster-name'
unit-mysql-1: 01:40:55 ERROR juju.worker.uniter.operation hook "certificates-relation-joined" (via hook dispatching script: dispatch) failed: exit status 1

[32mINFO    [0m pytest_operator.plugin:plugin.py:991 Forgetting model main...