[32mINFO    [0m pytest_operator.plugin:plugin.py:766 Connecting to existing model localhost-localhost:test on unspecified cloud
[32mINFO    [0m integration.test_smoke:test_smoke.py:67 Deploying bundle
[32mINFO    [0m juju.bundle:bundle.py:416 Applying change: upload charm data-integrator for series jammy from channel latest/edge
[32mINFO    [0m juju.bundle:bundle.py:416 Applying change: upload charm mysql-router for series jammy from channel dpe/edge
[32mINFO    [0m juju.bundle:bundle.py:416 Applying change: upload charm mysql-test-app for series jammy from channel latest/edge
[32mINFO    [0m juju.bundle:bundle.py:416 Applying change: upload charm s3-integrator for series jammy from channel latest/edge
[32mINFO    [0m juju.bundle:bundle.py:416 Applying change: upload charm self-signed-certificates for series jammy from channel latest/edge
[32mINFO    [0m juju.bundle:bundle.py:416 Applying change: upload charm sysbench for series jammy from channel latest/edge
[32mINFO    [0m juju.bundle:bundle.py:416 Applying change: upload charm ubuntu-advantage for series jammy from channel latest/edge
[32mINFO    [0m juju.bundle:bundle.py:416 Applying change: upload charm grafana-agent for series jammy from channel latest/edge
[32mINFO    [0m juju.bundle:bundle.py:416 Applying change: upload charm landscape-client for series jammy from channel latest/edge
[32mINFO    [0m juju.bundle:bundle.py:416 Applying change: upload charm mysql for series jammy from channel 8.0/edge
[32mINFO    [0m juju.bundle:bundle.py:416 Applying change: add new machine
[32mINFO    [0m juju.bundle:bundle.py:416 Applying change: add new machine
[32mINFO    [0m juju.bundle:bundle.py:416 Applying change: deploy application data-integrator on jammy using $addCharm-0
[32mINFO    [0m juju.model:model.py:2098 Deploying ch:amd64/jammy/data-integrator-80
[32mINFO    [0m juju.bundle:bundle.py:416 Applying change: deploy application mysql on jammy using $addCharm-9
[32mINFO    [0m juju.model:model.py:2098 Deploying ch:amd64/jammy/mysql-308
[32mINFO    [0m juju.bundle:bundle.py:416 Applying change: deploy application mysql-router on jammy using $addCharm-12
[32mINFO    [0m juju.model:model.py:2098 Deploying ch:amd64/jammy/mysql-router-264
[32mINFO    [0m juju.bundle:bundle.py:416 Applying change: deploy application mysql-router-data-integrator on jammy using $addCharm-0
[32mINFO    [0m juju.model:model.py:2098 Deploying ch:amd64/jammy/data-integrator-80
[32mINFO    [0m juju.bundle:bundle.py:416 Applying change: deploy application mysql-test-app on jammy using $addCharm-17
[32mINFO    [0m juju.model:model.py:2098 Deploying ch:amd64/jammy/mysql-test-app-63
[32mINFO    [0m juju.bundle:bundle.py:416 Applying change: deploy application s3-integrator on jammy using $addCharm-20
[32mINFO    [0m juju.model:model.py:2098 Deploying ch:amd64/jammy/s3-integrator-85
[32mINFO    [0m juju.bundle:bundle.py:416 Applying change: deploy application self-signed-certificates on jammy using $addCharm-23
[32mINFO    [0m juju.model:model.py:2098 Deploying ch:amd64/jammy/self-signed-certificates-207
[32mINFO    [0m juju.bundle:bundle.py:416 Applying change: deploy application sysbench on jammy using $addCharm-26
[32mINFO    [0m juju.model:model.py:2098 Deploying ch:amd64/jammy/sysbench-123
[32mINFO    [0m juju.bundle:bundle.py:416 Applying change: deploy application ubuntu-advantage on jammy using $addCharm-29
[32mINFO    [0m juju.model:model.py:2098 Deploying ch:amd64/jammy/ubuntu-advantage-137
[32mINFO    [0m juju.bundle:bundle.py:416 Applying change: deploy application grafana-agent on jammy using $addCharm-3
[32mINFO    [0m juju.model:model.py:2098 Deploying ch:amd64/jammy/grafana-agent-329
[32mINFO    [0m juju.bundle:bundle.py:416 Applying change: deploy application landscape-client on jammy using $addCharm-6
[32mINFO    [0m juju.model:model.py:2098 Deploying ch:amd64/jammy/landscape-client-70
[32mINFO    [0m juju.bundle:bundle.py:416 Applying change: add new machine
[32mINFO    [0m juju.bundle:bundle.py:416 Applying change: add relation $deploy-10:database - $deploy-13:backend-database
[32mINFO    [0m juju.bundle:bundle.py:865 Relating mysql:database <-> mysql-router:backend-database
[33mWARNING [0m juju.model:model.py:1564 relate is deprecated and will be removed. Use integrate instead.
[32mINFO    [0m juju.bundle:bundle.py:416 Applying change: add relation $deploy-10:certificates - $deploy-24:certificates
[32mINFO    [0m juju.bundle:bundle.py:865 Relating mysql:certificates <-> self-signed-certificates:certificates
[33mWARNING [0m juju.model:model.py:1564 relate is deprecated and will be removed. Use integrate instead.
[32mINFO    [0m juju.bundle:bundle.py:416 Applying change: add relation $deploy-13:certificates - $deploy-24:certificates
[32mINFO    [0m juju.bundle:bundle.py:865 Relating mysql-router:certificates <-> self-signed-certificates:certificates
[33mWARNING [0m juju.model:model.py:1564 relate is deprecated and will be removed. Use integrate instead.
[32mINFO    [0m juju.bundle:bundle.py:416 Applying change: add relation $deploy-10:s3-parameters - $deploy-21:s3-credentials
[32mINFO    [0m juju.bundle:bundle.py:865 Relating mysql:s3-parameters <-> s3-integrator:s3-credentials
[33mWARNING [0m juju.model:model.py:1564 relate is deprecated and will be removed. Use integrate instead.
[32mINFO    [0m juju.bundle:bundle.py:416 Applying change: add relation $deploy-10:database - $deploy-1:mysql
[32mINFO    [0m juju.bundle:bundle.py:865 Relating mysql:database <-> data-integrator:mysql
[33mWARNING [0m juju.model:model.py:1564 relate is deprecated and will be removed. Use integrate instead.
[32mINFO    [0m juju.bundle:bundle.py:416 Applying change: add relation $deploy-10:database - $deploy-27:mysql
[32mINFO    [0m juju.bundle:bundle.py:865 Relating mysql:database <-> sysbench:mysql
[33mWARNING [0m juju.model:model.py:1564 relate is deprecated and will be removed. Use integrate instead.
[32mINFO    [0m juju.bundle:bundle.py:416 Applying change: add relation $deploy-10:cos-agent - $deploy-4:cos-agent
[32mINFO    [0m juju.bundle:bundle.py:865 Relating mysql:cos-agent <-> grafana-agent:cos-agent
[33mWARNING [0m juju.model:model.py:1564 relate is deprecated and will be removed. Use integrate instead.
[32mINFO    [0m juju.bundle:bundle.py:416 Applying change: add relation $deploy-10:juju-info - $deploy-30:juju-info
[32mINFO    [0m juju.bundle:bundle.py:865 Relating mysql:juju-info <-> ubuntu-advantage:juju-info
[33mWARNING [0m juju.model:model.py:1564 relate is deprecated and will be removed. Use integrate instead.
[32mINFO    [0m juju.bundle:bundle.py:416 Applying change: add relation $deploy-10:juju-info - $deploy-7:container
[32mINFO    [0m juju.bundle:bundle.py:865 Relating mysql:juju-info <-> landscape-client:container
[33mWARNING [0m juju.model:model.py:1564 relate is deprecated and will be removed. Use integrate instead.
[32mINFO    [0m juju.bundle:bundle.py:416 Applying change: add relation $deploy-13:database - $deploy-15:mysql
[32mINFO    [0m juju.bundle:bundle.py:865 Relating mysql-router:database <-> mysql-router-data-integrator:mysql
[33mWARNING [0m juju.model:model.py:1564 relate is deprecated and will be removed. Use integrate instead.
[32mINFO    [0m juju.bundle:bundle.py:416 Applying change: add relation $deploy-15:juju-info - $deploy-4:juju-info
[32mINFO    [0m juju.bundle:bundle.py:865 Relating mysql-router-data-integrator:juju-info <-> grafana-agent:juju-info
[33mWARNING [0m juju.model:model.py:1564 relate is deprecated and will be removed. Use integrate instead.
[32mINFO    [0m juju.bundle:bundle.py:416 Applying change: add relation $deploy-13:cos-agent - $deploy-4:cos-agent
[32mINFO    [0m juju.bundle:bundle.py:865 Relating mysql-router:cos-agent <-> grafana-agent:cos-agent
[33mWARNING [0m juju.model:model.py:1564 relate is deprecated and will be removed. Use integrate instead.
[32mINFO    [0m juju.bundle:bundle.py:416 Applying change: add relation $deploy-15:juju-info - $deploy-30:juju-info
[32mINFO    [0m juju.bundle:bundle.py:865 Relating mysql-router-data-integrator:juju-info <-> ubuntu-advantage:juju-info
[33mWARNING [0m juju.model:model.py:1564 relate is deprecated and will be removed. Use integrate instead.
[32mINFO    [0m juju.bundle:bundle.py:416 Applying change: add relation $deploy-15:juju-info - $deploy-7:container
[32mINFO    [0m juju.bundle:bundle.py:865 Relating mysql-router-data-integrator:juju-info <-> landscape-client:container
[33mWARNING [0m juju.model:model.py:1564 relate is deprecated and will be removed. Use integrate instead.
[32mINFO    [0m juju.bundle:bundle.py:416 Applying change: add $deploy-1 unit to $addMachines-32
[32mINFO    [0m juju.bundle:bundle.py:416 Applying change: add $deploy-15 unit to $addMachines-33
[32mINFO    [0m juju.bundle:bundle.py:416 Applying change: set annotations for $deploy-10
[32mINFO    [0m juju.bundle:bundle.py:416 Applying change: set annotations for $deploy-13
[32mINFO    [0m juju.bundle:bundle.py:416 Applying change: set annotations for $deploy-15
[32mINFO    [0m juju.bundle:bundle.py:416 Applying change: set annotations for $deploy-18
[32mINFO    [0m juju.bundle:bundle.py:416 Applying change: set annotations for $deploy-1
[32mINFO    [0m juju.bundle:bundle.py:416 Applying change: set annotations for $deploy-21
[32mINFO    [0m juju.bundle:bundle.py:416 Applying change: set annotations for $deploy-24
[32mINFO    [0m juju.bundle:bundle.py:416 Applying change: set annotations for $deploy-27
[32mINFO    [0m juju.bundle:bundle.py:416 Applying change: set annotations for $deploy-30
[32mINFO    [0m juju.bundle:bundle.py:416 Applying change: set annotations for $deploy-4
[32mINFO    [0m juju.bundle:bundle.py:416 Applying change: set annotations for $deploy-7
[32mINFO    [0m juju.bundle:bundle.py:416 Applying change: add new machine
[32mINFO    [0m juju.bundle:bundle.py:416 Applying change: add $deploy-10 unit to $addMachines-34
[32mINFO    [0m juju.bundle:bundle.py:416 Applying change: add new machine
[32mINFO    [0m juju.bundle:bundle.py:416 Applying change: add $deploy-10 unit to $addMachines-35
[32mINFO    [0m juju.bundle:bundle.py:416 Applying change: add new machine
[32mINFO    [0m juju.bundle:bundle.py:416 Applying change: add $deploy-10 unit to $addMachines-36
[32mINFO    [0m juju.bundle:bundle.py:416 Applying change: add new machine
[32mINFO    [0m juju.bundle:bundle.py:416 Applying change: add $deploy-21 unit to $addMachines-37
[32mINFO    [0m juju.bundle:bundle.py:416 Applying change: add new machine
[32mINFO    [0m juju.bundle:bundle.py:416 Applying change: add $deploy-24 unit to $addMachines-38
[32mINFO    [0m juju.bundle:bundle.py:416 Applying change: add $deploy-27 unit to $addMachines-39
[32mINFO    [0m integration.test_smoke:test_smoke.py:41 Waiting for active: mysql, self-signed-certificates, sysbench
[32mINFO    [0m integration.test_smoke:test_smoke.py:47 Waiting for blocked: data-integrator, grafana-agent, mysql-router-data-integrator, landscape-client, s3-integrator, ubuntu-advantage
[32mINFO    [0m integration.test_smoke:test_smoke.py:54 Waiting for waiting: mysql-router
[32mINFO    [0m integration.test_smoke:test_smoke.py:72 Configuring s3-integrator credentials
[32mINFO    [0m integration.test_smoke:test_smoke.py:41 Waiting for active: mysql, self-signed-certificates, sysbench, s3-integrator
[32mINFO    [0m integration.test_smoke:test_smoke.py:47 Waiting for blocked: data-integrator, grafana-agent, mysql-router-data-integrator, landscape-client, ubuntu-advantage
[32mINFO    [0m integration.test_smoke:test_smoke.py:54 Waiting for waiting: mysql-router
[32mINFO    [0m integration.test_smoke:test_smoke.py:86 Configuring data-integrator
[32mINFO    [0m integration.test_smoke:test_smoke.py:41 Waiting for active: mysql, self-signed-certificates, sysbench, s3-integrator, data-integrator
[32mINFO    [0m integration.test_smoke:test_smoke.py:47 Waiting for blocked: grafana-agent, mysql-router-data-integrator, landscape-client, ubuntu-advantage
[32mINFO    [0m integration.test_smoke:test_smoke.py:54 Waiting for waiting: mysql-router
[32mINFO    [0m integration.test_smoke:test_smoke.py:95 Confirming data-integrator's database exists
[32mINFO    [0m integration.test_smoke:test_smoke.py:112 Configuring mysql-router-data-integrator
[32mINFO    [0m integration.test_smoke:test_smoke.py:41 Waiting for active: mysql, self-signed-certificates, sysbench, s3-integrator, data-integrator, mysql-router-data-integrator, mysql-router
[32mINFO    [0m integration.test_smoke:test_smoke.py:47 Waiting for blocked: grafana-agent, landscape-client, ubuntu-advantage
[32mINFO    [0m integration.test_smoke:test_smoke.py:124 Confirming data-integrator's database exists
[32mINFO    [0m integration.test_smoke:test_smoke.py:130 Adding mysql-test-app unit
[32mINFO    [0m integration.test_smoke:test_smoke.py:41 Waiting for active: mysql, self-signed-certificates, sysbench, s3-integrator, data-integrator, mysql-router-data-integrator, mysql-router
[32mINFO    [0m integration.test_smoke:test_smoke.py:47 Waiting for blocked: grafana-agent, landscape-client, ubuntu-advantage
[32mINFO    [0m integration.test_smoke:test_smoke.py:54 Waiting for waiting: mysql-test-app
[32mINFO    [0m pytest_operator.plugin:plugin.py:903 Model status:

Model  Controller           Cloud/Region         Version  SLA          Timestamp
test   localhost-localhost  localhost/localhost  3.5.4    unsupported  01:36:38Z

App                           Version          Status   Scale  Charm                     Channel      Rev  Exposed  Message
data-integrator                                active       1  data-integrator           latest/edge   80  no       
grafana-agent                                  blocked      4  grafana-agent             latest/edge  329  no       Missing ['grafana-cloud-config']|['grafana-dashboards-provider']|['logging-consumer']|['send-remote-write'] for cos-a...
landscape-client                               blocked      4  landscape-client          latest/edge   70  no       Registration failed!
mysql                         8.0.37-0ubun...  active       3  mysql                     8.0/edge     308  no       
mysql-router                  8.0.37-0ubun...  active       1  mysql-router              dpe/edge     264  no       
mysql-router-data-integrator                   active       1  data-integrator           latest/edge   80  no       
mysql-test-app                                 waiting    0/1  mysql-test-app            latest/edge   63  no       waiting for machine
s3-integrator                                  active       1  s3-integrator             latest/edge   85  no       
self-signed-certificates                       active       1  self-signed-certificates  latest/edge  207  no       
sysbench                                       active       1  sysbench                  latest/edge  123  no       
ubuntu-advantage                               blocked      4  ubuntu-advantage          latest/edge  137  no       No token configured

Unit                             Workload     Agent       Machine  Public address  Ports           Message
data-integrator/0*               active       idle        0        10.98.61.33                     
mysql-router-data-integrator/0*  active       executing   1        10.98.61.227                    
  grafana-agent/0*               blocked      idle                 10.98.61.227                    Missing ['grafana-cloud-config']|['grafana-dashboards-provider']|['logging-consumer']|['send-remote-write'] for cos-a...
  landscape-client/0*            blocked      idle                 10.98.61.227                    Registration failed!
  mysql-router/0*                active       executing            10.98.61.227    6446-6447/tcp   
  ubuntu-advantage/0*            blocked      executing            10.98.61.227                    No token configured
mysql-test-app/0                 waiting      allocating  8                                        waiting for machine
mysql/0*                         active       executing   2        10.98.61.152    3306,33060/tcp  Primary
  grafana-agent/1                blocked      idle                 10.98.61.152                    Missing ['grafana-cloud-config']|['grafana-dashboards-provider']|['logging-consumer']|['send-remote-write'] for cos-a...
  landscape-client/1             blocked      idle                 10.98.61.152                    Registration failed!
  ubuntu-advantage/1             blocked      idle                 10.98.61.152                    No token configured
mysql/1                          maintenance  executing   3        10.98.61.237                    joining the cluster
  grafana-agent/2                blocked      idle                 10.98.61.237                    Missing ['grafana-cloud-config']|['grafana-dashboards-provider']|['logging-consumer']|['send-remote-write'] for cos-a...
  landscape-client/2             blocked      idle                 10.98.61.237                    Registration failed!
  ubuntu-advantage/2             blocked      idle                 10.98.61.237                    No token configured
mysql/2                          waiting      executing   4        10.98.61.82                     Waiting to join the cluster
  grafana-agent/3                blocked      idle                 10.98.61.82                     Missing ['grafana-cloud-config']|['grafana-dashboards-provider']|['logging-consumer']|['send-remote-write'] for cos-a...
  landscape-client/3             blocked      idle                 10.98.61.82                     Registration failed!
  ubuntu-advantage/3             blocked      idle                 10.98.61.82                     No token configured
s3-integrator/0*                 active       idle        5        10.98.61.220                    
self-signed-certificates/0*      active       idle        6        10.98.61.63                     
sysbench/0*                      active       idle        7        10.98.61.2                      

Machine  State    Address       Inst id        Base          AZ  Message
0        started  10.98.61.33   juju-d6d1fd-0  ubuntu@22.04      Running
1        started  10.98.61.227  juju-d6d1fd-1  ubuntu@22.04      Running
2        started  10.98.61.152  juju-d6d1fd-2  ubuntu@22.04      Running
3        started  10.98.61.237  juju-d6d1fd-3  ubuntu@22.04      Running
4        started  10.98.61.82   juju-d6d1fd-4  ubuntu@22.04      Running
5        started  10.98.61.220  juju-d6d1fd-5  ubuntu@22.04      Running
6        started  10.98.61.63   juju-d6d1fd-6  ubuntu@22.04      Running
7        started  10.98.61.2    juju-d6d1fd-7  ubuntu@22.04      Running
8        pending                pending        ubuntu@22.04      Creating container

[32mINFO    [0m pytest_operator.plugin:plugin.py:909 Juju error logs:

machine-1: 01:30:47 ERROR juju.worker.dependency "kvm-container-provisioner" manifold worker returned unexpected error: container types not yet available
machine-1: 01:30:47 ERROR juju.worker.dependency "lxd-container-provisioner" manifold worker returned unexpected error: container types not yet available
unit-mysql-router-data-integrator-0: 01:30:48 ERROR juju.worker.meterstatus error running "meter-status-changed": charm missing from disk
machine-0: 01:30:58 ERROR juju.worker.dependency "kvm-container-provisioner" manifold worker returned unexpected error: container types not yet available
machine-0: 01:30:58 ERROR juju.worker.dependency "lxd-container-provisioner" manifold worker returned unexpected error: container types not yet available
unit-data-integrator-0: 01:31:00 ERROR juju.worker.meterstatus error running "meter-status-changed": charm missing from disk
machine-2: 01:31:00 ERROR juju.worker.dependency "kvm-container-provisioner" manifold worker returned unexpected error: container types not yet available
machine-2: 01:31:00 ERROR juju.worker.dependency "lxd-container-provisioner" manifold worker returned unexpected error: container types not yet available
unit-mysql-router-0: 01:31:00 ERROR juju.worker.meterstatus error running "meter-status-changed": charm missing from disk
machine-5: 01:31:02 ERROR juju.worker.dependency "kvm-container-provisioner" manifold worker returned unexpected error: container types not yet available
machine-5: 01:31:02 ERROR juju.worker.dependency "lxd-container-provisioner" manifold worker returned unexpected error: container types not yet available
unit-mysql-0: 01:31:02 ERROR juju.worker.meterstatus error running "meter-status-changed": charm missing from disk
unit-grafana-agent-0: 01:31:03 ERROR juju.worker.meterstatus error running "meter-status-changed": charm missing from disk
machine-7: 01:31:04 ERROR juju.worker.dependency "lxd-container-provisioner" manifold worker returned unexpected error: container types not yet available
machine-7: 01:31:04 ERROR juju.worker.dependency "kvm-container-provisioner" manifold worker returned unexpected error: container types not yet available
unit-s3-integrator-0: 01:31:04 ERROR juju.worker.meterstatus error running "meter-status-changed": charm missing from disk
unit-sysbench-0: 01:31:06 ERROR juju.worker.meterstatus error running "meter-status-changed": charm missing from disk
machine-6: 01:31:08 ERROR juju.worker.dependency "kvm-container-provisioner" manifold worker returned unexpected error: container types not yet available
machine-6: 01:31:08 ERROR juju.worker.dependency "lxd-container-provisioner" manifold worker returned unexpected error: container types not yet available
unit-ubuntu-advantage-0: 01:31:08 ERROR juju.worker.meterstatus error running "meter-status-changed": charm missing from disk
unit-landscape-client-0: 01:31:08 ERROR juju.worker.meterstatus error running "meter-status-changed": charm missing from disk
unit-self-signed-certificates-0: 01:31:09 ERROR juju.worker.meterstatus error running "meter-status-changed": charm missing from disk
machine-3: 01:31:14 ERROR juju.worker.dependency "lxd-container-provisioner" manifold worker returned unexpected error: container types not yet available
machine-3: 01:31:14 ERROR juju.worker.dependency "kvm-container-provisioner" manifold worker returned unexpected error: container types not yet available
unit-mysql-1: 01:31:15 ERROR juju.worker.meterstatus error running "meter-status-changed": charm missing from disk
machine-4: 01:31:15 ERROR juju.worker.dependency "kvm-container-provisioner" manifold worker returned unexpected error: container types not yet available
machine-4: 01:31:15 ERROR juju.worker.dependency "lxd-container-provisioner" manifold worker returned unexpected error: container types not yet available
unit-mysql-2: 01:31:16 ERROR juju.worker.meterstatus error running "meter-status-changed": charm missing from disk
unit-ubuntu-advantage-1: 01:32:13 ERROR juju.worker.meterstatus error running "meter-status-changed": charm missing from disk
unit-landscape-client-1: 01:32:14 ERROR juju.worker.meterstatus error running "meter-status-changed": charm missing from disk
unit-grafana-agent-1: 01:32:15 ERROR juju.worker.meterstatus error running "meter-status-changed": charm missing from disk
unit-landscape-client-2: 01:32:20 ERROR juju.worker.meterstatus error running "meter-status-changed": charm missing from disk
unit-ubuntu-advantage-2: 01:32:21 ERROR juju.worker.meterstatus error running "meter-status-changed": charm missing from disk
unit-ubuntu-advantage-3: 01:32:26 ERROR juju.worker.meterstatus error running "meter-status-changed": charm missing from disk
unit-grafana-agent-3: 01:32:27 ERROR juju.worker.meterstatus error running "meter-status-changed": charm missing from disk
unit-grafana-agent-2: 01:32:28 ERROR juju.worker.meterstatus error running "meter-status-changed": exit status 1
unit-landscape-client-3: 01:32:33 ERROR juju.worker.meterstatus error running "meter-status-changed": exit status 1
unit-landscape-client-0: 01:33:08 CRITICAL unit.landscape-client/0.juju-log   File "/var/lib/juju/agents/unit-landscape-client-0/charm/./src/charm.py", line 274, in <module>
    main(LandscapeClientCharm)
  File "/var/lib/juju/agents/unit-landscape-client-0/charm/venv/ops/main.py", line 45, in main
    return _main.main(charm_class=charm_class, use_juju_for_storage=use_juju_for_storage)
  File "/var/lib/juju/agents/unit-landscape-client-0/charm/venv/ops/_main.py", line 543, in main
    manager.run()
  File "/var/lib/juju/agents/unit-landscape-client-0/charm/venv/ops/_main.py", line 529, in run
    self._emit()
  File "/var/lib/juju/agents/unit-landscape-client-0/charm/venv/ops/_main.py", line 518, in _emit
    _emit_charm_event(self.charm, self.dispatcher.event_name, self._juju_context)
  File "/var/lib/juju/agents/unit-landscape-client-0/charm/venv/ops/_main.py", line 134, in _emit_charm_event
    event_to_emit.emit(*args, **kwargs)
  File "/var/lib/juju/agents/unit-landscape-client-0/charm/venv/ops/framework.py", line 347, in emit
    framework._emit(event)
  File "/var/lib/juju/agents/unit-landscape-client-0/charm/venv/ops/framework.py", line 857, in _emit
    self._reemit(event_path)
  File "/var/lib/juju/agents/unit-landscape-client-0/charm/venv/ops/framework.py", line 947, in _reemit
    custom_handler(event)
  File "/var/lib/juju/agents/unit-landscape-client-0/charm/./src/charm.py", line 228, in _on_config_changed
    self.run_landscape_client()
  File "/var/lib/juju/agents/unit-landscape-client-0/charm/./src/charm.py", line 203, in run_landscape_client
    self.send_registration()
  File "/var/lib/juju/agents/unit-landscape-client-0/charm/./src/charm.py", line 191, in send_registration
    if process_helper([CLIENT_CONFIG_CMD, "--silent"]):
  File "/var/lib/juju/agents/unit-landscape-client-0/charm/./src/charm.py", line 117, in process_helper
    log_error("".join(traceback.format_stack()))

unit-landscape-client-0: 01:33:08 CRITICAL unit.landscape-client/0.juju-log An account name and computer title are required.
Aborting Landscape configuration

unit-landscape-client-1: 01:33:18 CRITICAL unit.landscape-client/1.juju-log   File "/var/lib/juju/agents/unit-landscape-client-1/charm/./src/charm.py", line 274, in <module>
    main(LandscapeClientCharm)
  File "/var/lib/juju/agents/unit-landscape-client-1/charm/venv/ops/main.py", line 45, in main
    return _main.main(charm_class=charm_class, use_juju_for_storage=use_juju_for_storage)
  File "/var/lib/juju/agents/unit-landscape-client-1/charm/venv/ops/_main.py", line 543, in main
    manager.run()
  File "/var/lib/juju/agents/unit-landscape-client-1/charm/venv/ops/_main.py", line 529, in run
    self._emit()
  File "/var/lib/juju/agents/unit-landscape-client-1/charm/venv/ops/_main.py", line 518, in _emit
    _emit_charm_event(self.charm, self.dispatcher.event_name, self._juju_context)
  File "/var/lib/juju/agents/unit-landscape-client-1/charm/venv/ops/_main.py", line 134, in _emit_charm_event
    event_to_emit.emit(*args, **kwargs)
  File "/var/lib/juju/agents/unit-landscape-client-1/charm/venv/ops/framework.py", line 347, in emit
    framework._emit(event)
  File "/var/lib/juju/agents/unit-landscape-client-1/charm/venv/ops/framework.py", line 857, in _emit
    self._reemit(event_path)
  File "/var/lib/juju/agents/unit-landscape-client-1/charm/venv/ops/framework.py", line 947, in _reemit
    custom_handler(event)
  File "/var/lib/juju/agents/unit-landscape-client-1/charm/./src/charm.py", line 228, in _on_config_changed
    self.run_landscape_client()
  File "/var/lib/juju/agents/unit-landscape-client-1/charm/./src/charm.py", line 203, in run_landscape_client
    self.send_registration()
  File "/var/lib/juju/agents/unit-landscape-client-1/charm/./src/charm.py", line 191, in send_registration
    if process_helper([CLIENT_CONFIG_CMD, "--silent"]):
  File "/var/lib/juju/agents/unit-landscape-client-1/charm/./src/charm.py", line 117, in process_helper
    log_error("".join(traceback.format_stack()))

unit-landscape-client-1: 01:33:18 CRITICAL unit.landscape-client/1.juju-log An account name and computer title are required.
Aborting Landscape configuration

unit-landscape-client-2: 01:33:21 CRITICAL unit.landscape-client/2.juju-log   File "/var/lib/juju/agents/unit-landscape-client-2/charm/./src/charm.py", line 274, in <module>
    main(LandscapeClientCharm)
  File "/var/lib/juju/agents/unit-landscape-client-2/charm/venv/ops/main.py", line 45, in main
    return _main.main(charm_class=charm_class, use_juju_for_storage=use_juju_for_storage)
  File "/var/lib/juju/agents/unit-landscape-client-2/charm/venv/ops/_main.py", line 543, in main
    manager.run()
  File "/var/lib/juju/agents/unit-landscape-client-2/charm/venv/ops/_main.py", line 529, in run
    self._emit()
  File "/var/lib/juju/agents/unit-landscape-client-2/charm/venv/ops/_main.py", line 518, in _emit
    _emit_charm_event(self.charm, self.dispatcher.event_name, self._juju_context)
  File "/var/lib/juju/agents/unit-landscape-client-2/charm/venv/ops/_main.py", line 134, in _emit_charm_event
    event_to_emit.emit(*args, **kwargs)
  File "/var/lib/juju/agents/unit-landscape-client-2/charm/venv/ops/framework.py", line 347, in emit
    framework._emit(event)
  File "/var/lib/juju/agents/unit-landscape-client-2/charm/venv/ops/framework.py", line 857, in _emit
    self._reemit(event_path)
  File "/var/lib/juju/agents/unit-landscape-client-2/charm/venv/ops/framework.py", line 947, in _reemit
    custom_handler(event)
  File "/var/lib/juju/agents/unit-landscape-client-2/charm/./src/charm.py", line 228, in _on_config_changed
    self.run_landscape_client()
  File "/var/lib/juju/agents/unit-landscape-client-2/charm/./src/charm.py", line 203, in run_landscape_client
    self.send_registration()
  File "/var/lib/juju/agents/unit-landscape-client-2/charm/./src/charm.py", line 191, in send_registration
    if process_helper([CLIENT_CONFIG_CMD, "--silent"]):
  File "/var/lib/juju/agents/unit-landscape-client-2/charm/./src/charm.py", line 117, in process_helper
    log_error("".join(traceback.format_stack()))

unit-landscape-client-2: 01:33:21 CRITICAL unit.landscape-client/2.juju-log An account name and computer title are required.
Aborting Landscape configuration

unit-landscape-client-3: 01:33:29 CRITICAL unit.landscape-client/3.juju-log   File "/var/lib/juju/agents/unit-landscape-client-3/charm/./src/charm.py", line 274, in <module>
    main(LandscapeClientCharm)
  File "/var/lib/juju/agents/unit-landscape-client-3/charm/venv/ops/main.py", line 45, in main
    return _main.main(charm_class=charm_class, use_juju_for_storage=use_juju_for_storage)
  File "/var/lib/juju/agents/unit-landscape-client-3/charm/venv/ops/_main.py", line 543, in main
    manager.run()
  File "/var/lib/juju/agents/unit-landscape-client-3/charm/venv/ops/_main.py", line 529, in run
    self._emit()
  File "/var/lib/juju/agents/unit-landscape-client-3/charm/venv/ops/_main.py", line 518, in _emit
    _emit_charm_event(self.charm, self.dispatcher.event_name, self._juju_context)
  File "/var/lib/juju/agents/unit-landscape-client-3/charm/venv/ops/_main.py", line 134, in _emit_charm_event
    event_to_emit.emit(*args, **kwargs)
  File "/var/lib/juju/agents/unit-landscape-client-3/charm/venv/ops/framework.py", line 347, in emit
    framework._emit(event)
  File "/var/lib/juju/agents/unit-landscape-client-3/charm/venv/ops/framework.py", line 857, in _emit
    self._reemit(event_path)
  File "/var/lib/juju/agents/unit-landscape-client-3/charm/venv/ops/framework.py", line 947, in _reemit
    custom_handler(event)
  File "/var/lib/juju/agents/unit-landscape-client-3/charm/./src/charm.py", line 228, in _on_config_changed
    self.run_landscape_client()
  File "/var/lib/juju/agents/unit-landscape-client-3/charm/./src/charm.py", line 203, in run_landscape_client
    self.send_registration()
  File "/var/lib/juju/agents/unit-landscape-client-3/charm/./src/charm.py", line 191, in send_registration
    if process_helper([CLIENT_CONFIG_CMD, "--silent"]):
  File "/var/lib/juju/agents/unit-landscape-client-3/charm/./src/charm.py", line 117, in process_helper
    log_error("".join(traceback.format_stack()))

unit-landscape-client-3: 01:33:29 CRITICAL unit.landscape-client/3.juju-log An account name and computer title are required.
Aborting Landscape configuration

unit-mysql-2: 01:34:47 ERROR unit.mysql/2.juju-log cos-agent:19: Exception while exporting Span batch.
Traceback (most recent call last):
  File "/var/lib/juju/agents/unit-mysql-2/charm/venv/urllib3/connection.py", line 174, in _new_conn
    conn = connection.create_connection(
  File "/var/lib/juju/agents/unit-mysql-2/charm/venv/urllib3/util/connection.py", line 95, in create_connection
    raise err
  File "/var/lib/juju/agents/unit-mysql-2/charm/venv/urllib3/util/connection.py", line 85, in create_connection
    sock.connect(sa)
ConnectionRefusedError: [Errno 111] Connection refused

During handling of the above exception, another exception occurred:

Traceback (most recent call last):
  File "/var/lib/juju/agents/unit-mysql-2/charm/venv/urllib3/connectionpool.py", line 715, in urlopen
    httplib_response = self._make_request(
  File "/var/lib/juju/agents/unit-mysql-2/charm/venv/urllib3/connectionpool.py", line 416, in _make_request
    conn.request(method, url, **httplib_request_kw)
  File "/var/lib/juju/agents/unit-mysql-2/charm/venv/urllib3/connection.py", line 244, in request
    super(HTTPConnection, self).request(method, url, body=body, headers=headers)
  File "/usr/lib/python3.10/http/client.py", line 1283, in request
    self._send_request(method, url, body, headers, encode_chunked)
  File "/usr/lib/python3.10/http/client.py", line 1329, in _send_request
    self.endheaders(body, encode_chunked=encode_chunked)
  File "/usr/lib/python3.10/http/client.py", line 1278, in endheaders
    self._send_output(message_body, encode_chunked=encode_chunked)
  File "/usr/lib/python3.10/http/client.py", line 1038, in _send_output
    self.send(msg)
  File "/usr/lib/python3.10/http/client.py", line 976, in send
    self.connect()
  File "/var/lib/juju/agents/unit-mysql-2/charm/venv/urllib3/connection.py", line 205, in connect
    conn = self._new_conn()
  File "/var/lib/juju/agents/unit-mysql-2/charm/venv/urllib3/connection.py", line 186, in _new_conn
    raise NewConnectionError(
urllib3.exceptions.NewConnectionError: <urllib3.connection.HTTPConnection object at 0x7f079d5e9930>: Failed to establish a new connection: [Errno 111] Connection refused

During handling of the above exception, another exception occurred:

Traceback (most recent call last):
  File "/var/lib/juju/agents/unit-mysql-2/charm/venv/requests/adapters.py", line 486, in send
    resp = conn.urlopen(
  File "/var/lib/juju/agents/unit-mysql-2/charm/venv/urllib3/connectionpool.py", line 801, in urlopen
    retries = retries.increment(
  File "/var/lib/juju/agents/unit-mysql-2/charm/venv/urllib3/util/retry.py", line 594, in increment
    raise MaxRetryError(_pool, url, error or ResponseError(cause))
urllib3.exceptions.MaxRetryError: HTTPConnectionPool(host='juju-d6d1fd-4.lxd', port=4318): Max retries exceeded with url: /v1/traces (Caused by NewConnectionError('<urllib3.connection.HTTPConnection object at 0x7f079d5e9930>: Failed to establish a new connection: [Errno 111] Connection refused'))

During handling of the above exception, another exception occurred:

Traceback (most recent call last):
  File "/var/lib/juju/agents/unit-mysql-2/charm/venv/opentelemetry/sdk/trace/export/__init__.py", line 368, in _export_batch
    self.span_exporter.export(self.spans_list[:idx])  # type: ignore
  File "/var/lib/juju/agents/unit-mysql-2/charm/venv/opentelemetry/exporter/otlp/proto/http/trace_exporter/__init__.py", line 145, in export
    resp = self._export(serialized_data)
  File "/var/lib/juju/agents/unit-mysql-2/charm/venv/opentelemetry/exporter/otlp/proto/http/trace_exporter/__init__.py", line 114, in _export
    return self._session.post(
  File "/var/lib/juju/agents/unit-mysql-2/charm/venv/requests/sessions.py", line 637, in post
    return self.request("POST", url, data=data, json=json, **kwargs)
  File "/var/lib/juju/agents/unit-mysql-2/charm/venv/requests/sessions.py", line 589, in request
    resp = self.send(prep, **send_kwargs)
  File "/var/lib/juju/agents/unit-mysql-2/charm/venv/requests/sessions.py", line 703, in send
    r = adapter.send(request, **kwargs)
  File "/var/lib/juju/agents/unit-mysql-2/charm/venv/requests/adapters.py", line 519, in send
    raise ConnectionError(e, request=request)
requests.exceptions.ConnectionError: HTTPConnectionPool(host='juju-d6d1fd-4.lxd', port=4318): Max retries exceeded with url: /v1/traces (Caused by NewConnectionError('<urllib3.connection.HTTPConnection object at 0x7f079d5e9930>: Failed to establish a new connection: [Errno 111] Connection refused'))
unit-mysql-2: 01:34:55 ERROR unit.mysql/2.juju-log database:18: Exception while exporting Span batch.
Traceback (most recent call last):
  File "/var/lib/juju/agents/unit-mysql-2/charm/venv/urllib3/connection.py", line 174, in _new_conn
    conn = connection.create_connection(
  File "/var/lib/juju/agents/unit-mysql-2/charm/venv/urllib3/util/connection.py", line 95, in create_connection
    raise err
  File "/var/lib/juju/agents/unit-mysql-2/charm/venv/urllib3/util/connection.py", line 85, in create_connection
    sock.connect(sa)
ConnectionRefusedError: [Errno 111] Connection refused

During handling of the above exception, another exception occurred:

Traceback (most recent call last):
  File "/var/lib/juju/agents/unit-mysql-2/charm/venv/urllib3/connectionpool.py", line 715, in urlopen
    httplib_response = self._make_request(
  File "/var/lib/juju/agents/unit-mysql-2/charm/venv/urllib3/connectionpool.py", line 416, in _make_request
    conn.request(method, url, **httplib_request_kw)
  File "/var/lib/juju/agents/unit-mysql-2/charm/venv/urllib3/connection.py", line 244, in request
    super(HTTPConnection, self).request(method, url, body=body, headers=headers)
  File "/usr/lib/python3.10/http/client.py", line 1283, in request
    self._send_request(method, url, body, headers, encode_chunked)
  File "/usr/lib/python3.10/http/client.py", line 1329, in _send_request
    self.endheaders(body, encode_chunked=encode_chunked)
  File "/usr/lib/python3.10/http/client.py", line 1278, in endheaders
    self._send_output(message_body, encode_chunked=encode_chunked)
  File "/usr/lib/python3.10/http/client.py", line 1038, in _send_output
    self.send(msg)
  File "/usr/lib/python3.10/http/client.py", line 976, in send
    self.connect()
  File "/var/lib/juju/agents/unit-mysql-2/charm/venv/urllib3/connection.py", line 205, in connect
    conn = self._new_conn()
  File "/var/lib/juju/agents/unit-mysql-2/charm/venv/urllib3/connection.py", line 186, in _new_conn
    raise NewConnectionError(
urllib3.exceptions.NewConnectionError: <urllib3.connection.HTTPConnection object at 0x7f33d9ad7160>: Failed to establish a new connection: [Errno 111] Connection refused

During handling of the above exception, another exception occurred:

Traceback (most recent call last):
  File "/var/lib/juju/agents/unit-mysql-2/charm/venv/requests/adapters.py", line 486, in send
    resp = conn.urlopen(
  File "/var/lib/juju/agents/unit-mysql-2/charm/venv/urllib3/connectionpool.py", line 801, in urlopen
    retries = retries.increment(
  File "/var/lib/juju/agents/unit-mysql-2/charm/venv/urllib3/util/retry.py", line 594, in increment
    raise MaxRetryError(_pool, url, error or ResponseError(cause))
urllib3.exceptions.MaxRetryError: HTTPConnectionPool(host='juju-d6d1fd-4.lxd', port=4318): Max retries exceeded with url: /v1/traces (Caused by NewConnectionError('<urllib3.connection.HTTPConnection object at 0x7f33d9ad7160>: Failed to establish a new connection: [Errno 111] Connection refused'))

During handling of the above exception, another exception occurred:

Traceback (most recent call last):
  File "/var/lib/juju/agents/unit-mysql-2/charm/venv/opentelemetry/sdk/trace/export/__init__.py", line 368, in _export_batch
    self.span_exporter.export(self.spans_list[:idx])  # type: ignore
  File "/var/lib/juju/agents/unit-mysql-2/charm/venv/opentelemetry/exporter/otlp/proto/http/trace_exporter/__init__.py", line 145, in export
    resp = self._export(serialized_data)
  File "/var/lib/juju/agents/unit-mysql-2/charm/venv/opentelemetry/exporter/otlp/proto/http/trace_exporter/__init__.py", line 114, in _export
    return self._session.post(
  File "/var/lib/juju/agents/unit-mysql-2/charm/venv/requests/sessions.py", line 637, in post
    return self.request("POST", url, data=data, json=json, **kwargs)
  File "/var/lib/juju/agents/unit-mysql-2/charm/venv/requests/sessions.py", line 589, in request
    resp = self.send(prep, **send_kwargs)
  File "/var/lib/juju/agents/unit-mysql-2/charm/venv/requests/sessions.py", line 703, in send
    r = adapter.send(request, **kwargs)
  File "/var/lib/juju/agents/unit-mysql-2/charm/venv/requests/adapters.py", line 519, in send
    raise ConnectionError(e, request=request)
requests.exceptions.ConnectionError: HTTPConnectionPool(host='juju-d6d1fd-4.lxd', port=4318): Max retries exceeded with url: /v1/traces (Caused by NewConnectionError('<urllib3.connection.HTTPConnection object at 0x7f33d9ad7160>: Failed to establish a new connection: [Errno 111] Connection refused'))
unit-mysql-2: 01:34:59 ERROR unit.mysql/2.juju-log cos-agent:19: Exception while exporting Span batch.
Traceback (most recent call last):
  File "/var/lib/juju/agents/unit-mysql-2/charm/venv/urllib3/connection.py", line 174, in _new_conn
    conn = connection.create_connection(
  File "/var/lib/juju/agents/unit-mysql-2/charm/venv/urllib3/util/connection.py", line 95, in create_connection
    raise err
  File "/var/lib/juju/agents/unit-mysql-2/charm/venv/urllib3/util/connection.py", line 85, in create_connection
    sock.connect(sa)
ConnectionRefusedError: [Errno 111] Connection refused

During handling of the above exception, another exception occurred:

Traceback (most recent call last):
  File "/var/lib/juju/agents/unit-mysql-2/charm/venv/urllib3/connectionpool.py", line 715, in urlopen
    httplib_response = self._make_request(
  File "/var/lib/juju/agents/unit-mysql-2/charm/venv/urllib3/connectionpool.py", line 416, in _make_request
    conn.request(method, url, **httplib_request_kw)
  File "/var/lib/juju/agents/unit-mysql-2/charm/venv/urllib3/connection.py", line 244, in request
    super(HTTPConnection, self).request(method, url, body=body, headers=headers)
  File "/usr/lib/python3.10/http/client.py", line 1283, in request
    self._send_request(method, url, body, headers, encode_chunked)
  File "/usr/lib/python3.10/http/client.py", line 1329, in _send_request
    self.endheaders(body, encode_chunked=encode_chunked)
  File "/usr/lib/python3.10/http/client.py", line 1278, in endheaders
    self._send_output(message_body, encode_chunked=encode_chunked)
  File "/usr/lib/python3.10/http/client.py", line 1038, in _send_output
    self.send(msg)
  File "/usr/lib/python3.10/http/client.py", line 976, in send
    self.connect()
  File "/var/lib/juju/agents/unit-mysql-2/charm/venv/urllib3/connection.py", line 205, in connect
    conn = self._new_conn()
  File "/var/lib/juju/agents/unit-mysql-2/charm/venv/urllib3/connection.py", line 186, in _new_conn
    raise NewConnectionError(
urllib3.exceptions.NewConnectionError: <urllib3.connection.HTTPConnection object at 0x7fd65638bf40>: Failed to establish a new connection: [Errno 111] Connection refused

During handling of the above exception, another exception occurred:

Traceback (most recent call last):
  File "/var/lib/juju/agents/unit-mysql-2/charm/venv/requests/adapters.py", line 486, in send
    resp = conn.urlopen(
  File "/var/lib/juju/agents/unit-mysql-2/charm/venv/urllib3/connectionpool.py", line 801, in urlopen
    retries = retries.increment(
  File "/var/lib/juju/agents/unit-mysql-2/charm/venv/urllib3/util/retry.py", line 594, in increment
    raise MaxRetryError(_pool, url, error or ResponseError(cause))
urllib3.exceptions.MaxRetryError: HTTPConnectionPool(host='juju-d6d1fd-4.lxd', port=4318): Max retries exceeded with url: /v1/traces (Caused by NewConnectionError('<urllib3.connection.HTTPConnection object at 0x7fd65638bf40>: Failed to establish a new connection: [Errno 111] Connection refused'))

During handling of the above exception, another exception occurred:

Traceback (most recent call last):
  File "/var/lib/juju/agents/unit-mysql-2/charm/venv/opentelemetry/sdk/trace/export/__init__.py", line 368, in _export_batch
    self.span_exporter.export(self.spans_list[:idx])  # type: ignore
  File "/var/lib/juju/agents/unit-mysql-2/charm/venv/opentelemetry/exporter/otlp/proto/http/trace_exporter/__init__.py", line 145, in export
    resp = self._export(serialized_data)
  File "/var/lib/juju/agents/unit-mysql-2/charm/venv/opentelemetry/exporter/otlp/proto/http/trace_exporter/__init__.py", line 114, in _export
    return self._session.post(
  File "/var/lib/juju/agents/unit-mysql-2/charm/venv/requests/sessions.py", line 637, in post
    return self.request("POST", url, data=data, json=json, **kwargs)
  File "/var/lib/juju/agents/unit-mysql-2/charm/venv/requests/sessions.py", line 589, in request
    resp = self.send(prep, **send_kwargs)
  File "/var/lib/juju/agents/unit-mysql-2/charm/venv/requests/sessions.py", line 703, in send
    r = adapter.send(request, **kwargs)
  File "/var/lib/juju/agents/unit-mysql-2/charm/venv/requests/adapters.py", line 519, in send
    raise ConnectionError(e, request=request)
requests.exceptions.ConnectionError: HTTPConnectionPool(host='juju-d6d1fd-4.lxd', port=4318): Max retries exceeded with url: /v1/traces (Caused by NewConnectionError('<urllib3.connection.HTTPConnection object at 0x7fd65638bf40>: Failed to establish a new connection: [Errno 111] Connection refused'))
unit-mysql-2: 01:35:03 ERROR unit.mysql/2.juju-log certificates:14: Exception while exporting Span batch.
Traceback (most recent call last):
  File "/var/lib/juju/agents/unit-mysql-2/charm/venv/urllib3/connection.py", line 174, in _new_conn
    conn = connection.create_connection(
  File "/var/lib/juju/agents/unit-mysql-2/charm/venv/urllib3/util/connection.py", line 95, in create_connection
    raise err
  File "/var/lib/juju/agents/unit-mysql-2/charm/venv/urllib3/util/connection.py", line 85, in create_connection
    sock.connect(sa)
ConnectionRefusedError: [Errno 111] Connection refused

During handling of the above exception, another exception occurred:

Traceback (most recent call last):
  File "/var/lib/juju/agents/unit-mysql-2/charm/venv/urllib3/connectionpool.py", line 715, in urlopen
    httplib_response = self._make_request(
  File "/var/lib/juju/agents/unit-mysql-2/charm/venv/urllib3/connectionpool.py", line 416, in _make_request
    conn.request(method, url, **httplib_request_kw)
  File "/var/lib/juju/agents/unit-mysql-2/charm/venv/urllib3/connection.py", line 244, in request
    super(HTTPConnection, self).request(method, url, body=body, headers=headers)
  File "/usr/lib/python3.10/http/client.py", line 1283, in request
    self._send_request(method, url, body, headers, encode_chunked)
  File "/usr/lib/python3.10/http/client.py", line 1329, in _send_request
    self.endheaders(body, encode_chunked=encode_chunked)
  File "/usr/lib/python3.10/http/client.py", line 1278, in endheaders
    self._send_output(message_body, encode_chunked=encode_chunked)
  File "/usr/lib/python3.10/http/client.py", line 1038, in _send_output
    self.send(msg)
  File "/usr/lib/python3.10/http/client.py", line 976, in send
    self.connect()
  File "/var/lib/juju/agents/unit-mysql-2/charm/venv/urllib3/connection.py", line 205, in connect
    conn = self._new_conn()
  File "/var/lib/juju/agents/unit-mysql-2/charm/venv/urllib3/connection.py", line 186, in _new_conn
    raise NewConnectionError(
urllib3.exceptions.NewConnectionError: <urllib3.connection.HTTPConnection object at 0x7f7755aeae30>: Failed to establish a new connection: [Errno 111] Connection refused

During handling of the above exception, another exception occurred:

Traceback (most recent call last):
  File "/var/lib/juju/agents/unit-mysql-2/charm/venv/requests/adapters.py", line 486, in send
    resp = conn.urlopen(
  File "/var/lib/juju/agents/unit-mysql-2/charm/venv/urllib3/connectionpool.py", line 801, in urlopen
    retries = retries.increment(
  File "/var/lib/juju/agents/unit-mysql-2/charm/venv/urllib3/util/retry.py", line 594, in increment
    raise MaxRetryError(_pool, url, error or ResponseError(cause))
urllib3.exceptions.MaxRetryError: HTTPConnectionPool(host='juju-d6d1fd-4.lxd', port=4318): Max retries exceeded with url: /v1/traces (Caused by NewConnectionError('<urllib3.connection.HTTPConnection object at 0x7f7755aeae30>: Failed to establish a new connection: [Errno 111] Connection refused'))

During handling of the above exception, another exception occurred:

Traceback (most recent call last):
  File "/var/lib/juju/agents/unit-mysql-2/charm/venv/opentelemetry/sdk/trace/export/__init__.py", line 368, in _export_batch
    self.span_exporter.export(self.spans_list[:idx])  # type: ignore
  File "/var/lib/juju/agents/unit-mysql-2/charm/venv/opentelemetry/exporter/otlp/proto/http/trace_exporter/__init__.py", line 145, in export
    resp = self._export(serialized_data)
  File "/var/lib/juju/agents/unit-mysql-2/charm/venv/opentelemetry/exporter/otlp/proto/http/trace_exporter/__init__.py", line 114, in _export
    return self._session.post(
  File "/var/lib/juju/agents/unit-mysql-2/charm/venv/requests/sessions.py", line 637, in post
    return self.request("POST", url, data=data, json=json, **kwargs)
  File "/var/lib/juju/agents/unit-mysql-2/charm/venv/requests/sessions.py", line 589, in request
    resp = self.send(prep, **send_kwargs)
  File "/var/lib/juju/agents/unit-mysql-2/charm/venv/requests/sessions.py", line 703, in send
    r = adapter.send(request, **kwargs)
  File "/var/lib/juju/agents/unit-mysql-2/charm/venv/requests/adapters.py", line 519, in send
    raise ConnectionError(e, request=request)
requests.exceptions.ConnectionError: HTTPConnectionPool(host='juju-d6d1fd-4.lxd', port=4318): Max retries exceeded with url: /v1/traces (Caused by NewConnectionError('<urllib3.connection.HTTPConnection object at 0x7f7755aeae30>: Failed to establish a new connection: [Errno 111] Connection refused'))
unit-mysql-2: 01:35:07 ERROR unit.mysql/2.juju-log Exception while exporting Span batch.
Traceback (most recent call last):
  File "/var/lib/juju/agents/unit-mysql-2/charm/venv/urllib3/connection.py", line 174, in _new_conn
    conn = connection.create_connection(
  File "/var/lib/juju/agents/unit-mysql-2/charm/venv/urllib3/util/connection.py", line 95, in create_connection
    raise err
  File "/var/lib/juju/agents/unit-mysql-2/charm/venv/urllib3/util/connection.py", line 85, in create_connection
    sock.connect(sa)
ConnectionRefusedError: [Errno 111] Connection refused

During handling of the above exception, another exception occurred:

Traceback (most recent call last):
  File "/var/lib/juju/agents/unit-mysql-2/charm/venv/urllib3/connectionpool.py", line 715, in urlopen
    httplib_response = self._make_request(
  File "/var/lib/juju/agents/unit-mysql-2/charm/venv/urllib3/connectionpool.py", line 416, in _make_request
    conn.request(method, url, **httplib_request_kw)
  File "/var/lib/juju/agents/unit-mysql-2/charm/venv/urllib3/connection.py", line 244, in request
    super(HTTPConnection, self).request(method, url, body=body, headers=headers)
  File "/usr/lib/python3.10/http/client.py", line 1283, in request
    self._send_request(method, url, body, headers, encode_chunked)
  File "/usr/lib/python3.10/http/client.py", line 1329, in _send_request
    self.endheaders(body, encode_chunked=encode_chunked)
  File "/usr/lib/python3.10/http/client.py", line 1278, in endheaders
    self._send_output(message_body, encode_chunked=encode_chunked)
  File "/usr/lib/python3.10/http/client.py", line 1038, in _send_output
    self.send(msg)
  File "/usr/lib/python3.10/http/client.py", line 976, in send
    self.connect()
  File "/var/lib/juju/agents/unit-mysql-2/charm/venv/urllib3/connection.py", line 205, in connect
    conn = self._new_conn()
  File "/var/lib/juju/agents/unit-mysql-2/charm/venv/urllib3/connection.py", line 186, in _new_conn
    raise NewConnectionError(
urllib3.exceptions.NewConnectionError: <urllib3.connection.HTTPConnection object at 0x7f4908519960>: Failed to establish a new connection: [Errno 111] Connection refused

During handling of the above exception, another exception occurred:

Traceback (most recent call last):
  File "/var/lib/juju/agents/unit-mysql-2/charm/venv/requests/adapters.py", line 486, in send
    resp = conn.urlopen(
  File "/var/lib/juju/agents/unit-mysql-2/charm/venv/urllib3/connectionpool.py", line 801, in urlopen
    retries = retries.increment(
  File "/var/lib/juju/agents/unit-mysql-2/charm/venv/urllib3/util/retry.py", line 594, in increment
    raise MaxRetryError(_pool, url, error or ResponseError(cause))
urllib3.exceptions.MaxRetryError: HTTPConnectionPool(host='juju-d6d1fd-4.lxd', port=4318): Max retries exceeded with url: /v1/traces (Caused by NewConnectionError('<urllib3.connection.HTTPConnection object at 0x7f4908519960>: Failed to establish a new connection: [Errno 111] Connection refused'))

During handling of the above exception, another exception occurred:

Traceback (most recent call last):
  File "/var/lib/juju/agents/unit-mysql-2/charm/venv/opentelemetry/sdk/trace/export/__init__.py", line 368, in _export_batch
    self.span_exporter.export(self.spans_list[:idx])  # type: ignore
  File "/var/lib/juju/agents/unit-mysql-2/charm/venv/opentelemetry/exporter/otlp/proto/http/trace_exporter/__init__.py", line 145, in export
    resp = self._export(serialized_data)
  File "/var/lib/juju/agents/unit-mysql-2/charm/venv/opentelemetry/exporter/otlp/proto/http/trace_exporter/__init__.py", line 114, in _export
    return self._session.post(
  File "/var/lib/juju/agents/unit-mysql-2/charm/venv/requests/sessions.py", line 637, in post
    return self.request("POST", url, data=data, json=json, **kwargs)
  File "/var/lib/juju/agents/unit-mysql-2/charm/venv/requests/sessions.py", line 589, in request
    resp = self.send(prep, **send_kwargs)
  File "/var/lib/juju/agents/unit-mysql-2/charm/venv/requests/sessions.py", line 703, in send
    r = adapter.send(request, **kwargs)
  File "/var/lib/juju/agents/unit-mysql-2/charm/venv/requests/adapters.py", line 519, in send
    raise ConnectionError(e, request=request)
requests.exceptions.ConnectionError: HTTPConnectionPool(host='juju-d6d1fd-4.lxd', port=4318): Max retries exceeded with url: /v1/traces (Caused by NewConnectionError('<urllib3.connection.HTTPConnection object at 0x7f4908519960>: Failed to establish a new connection: [Errno 111] Connection refused'))
unit-mysql-2: 01:35:11 ERROR unit.mysql/2.juju-log database:18: Exception while exporting Span batch.
Traceback (most recent call last):
  File "/var/lib/juju/agents/unit-mysql-2/charm/venv/urllib3/connection.py", line 174, in _new_conn
    conn = connection.create_connection(
  File "/var/lib/juju/agents/unit-mysql-2/charm/venv/urllib3/util/connection.py", line 95, in create_connection
    raise err
  File "/var/lib/juju/agents/unit-mysql-2/charm/venv/urllib3/util/connection.py", line 85, in create_connection
    sock.connect(sa)
ConnectionRefusedError: [Errno 111] Connection refused

During handling of the above exception, another exception occurred:

Traceback (most recent call last):
  File "/var/lib/juju/agents/unit-mysql-2/charm/venv/urllib3/connectionpool.py", line 715, in urlopen
    httplib_response = self._make_request(
  File "/var/lib/juju/agents/unit-mysql-2/charm/venv/urllib3/connectionpool.py", line 416, in _make_request
    conn.request(method, url, **httplib_request_kw)
  File "/var/lib/juju/agents/unit-mysql-2/charm/venv/urllib3/connection.py", line 244, in request
    super(HTTPConnection, self).request(method, url, body=body, headers=headers)
  File "/usr/lib/python3.10/http/client.py", line 1283, in request
    self._send_request(method, url, body, headers, encode_chunked)
  File "/usr/lib/python3.10/http/client.py", line 1329, in _send_request
    self.endheaders(body, encode_chunked=encode_chunked)
  File "/usr/lib/python3.10/http/client.py", line 1278, in endheaders
    self._send_output(message_body, encode_chunked=encode_chunked)
  File "/usr/lib/python3.10/http/client.py", line 1038, in _send_output
    self.send(msg)
  File "/usr/lib/python3.10/http/client.py", line 976, in send
    self.connect()
  File "/var/lib/juju/agents/unit-mysql-2/charm/venv/urllib3/connection.py", line 205, in connect
    conn = self._new_conn()
  File "/var/lib/juju/agents/unit-mysql-2/charm/venv/urllib3/connection.py", line 186, in _new_conn
    raise NewConnectionError(
urllib3.exceptions.NewConnectionError: <urllib3.connection.HTTPConnection object at 0x7f27fed0f0d0>: Failed to establish a new connection: [Errno 111] Connection refused

During handling of the above exception, another exception occurred:

Traceback (most recent call last):
  File "/var/lib/juju/agents/unit-mysql-2/charm/venv/requests/adapters.py", line 486, in send
    resp = conn.urlopen(
  File "/var/lib/juju/agents/unit-mysql-2/charm/venv/urllib3/connectionpool.py", line 801, in urlopen
    retries = retries.increment(
  File "/var/lib/juju/agents/unit-mysql-2/charm/venv/urllib3/util/retry.py", line 594, in increment
    raise MaxRetryError(_pool, url, error or ResponseError(cause))
urllib3.exceptions.MaxRetryError: HTTPConnectionPool(host='juju-d6d1fd-4.lxd', port=4318): Max retries exceeded with url: /v1/traces (Caused by NewConnectionError('<urllib3.connection.HTTPConnection object at 0x7f27fed0f0d0>: Failed to establish a new connection: [Errno 111] Connection refused'))

During handling of the above exception, another exception occurred:

Traceback (most recent call last):
  File "/var/lib/juju/agents/unit-mysql-2/charm/venv/opentelemetry/sdk/trace/export/__init__.py", line 368, in _export_batch
    self.span_exporter.export(self.spans_list[:idx])  # type: ignore
  File "/var/lib/juju/agents/unit-mysql-2/charm/venv/opentelemetry/exporter/otlp/proto/http/trace_exporter/__init__.py", line 145, in export
    resp = self._export(serialized_data)
  File "/var/lib/juju/agents/unit-mysql-2/charm/venv/opentelemetry/exporter/otlp/proto/http/trace_exporter/__init__.py", line 114, in _export
    return self._session.post(
  File "/var/lib/juju/agents/unit-mysql-2/charm/venv/requests/sessions.py", line 637, in post
    return self.request("POST", url, data=data, json=json, **kwargs)
  File "/var/lib/juju/agents/unit-mysql-2/charm/venv/requests/sessions.py", line 589, in request
    resp = self.send(prep, **send_kwargs)
  File "/var/lib/juju/agents/unit-mysql-2/charm/venv/requests/sessions.py", line 703, in send
    r = adapter.send(request, **kwargs)
  File "/var/lib/juju/agents/unit-mysql-2/charm/venv/requests/adapters.py", line 519, in send
    raise ConnectionError(e, request=request)
requests.exceptions.ConnectionError: HTTPConnectionPool(host='juju-d6d1fd-4.lxd', port=4318): Max retries exceeded with url: /v1/traces (Caused by NewConnectionError('<urllib3.connection.HTTPConnection object at 0x7f27fed0f0d0>: Failed to establish a new connection: [Errno 111] Connection refused'))
unit-mysql-2: 01:35:14 ERROR unit.mysql/2.juju-log Exception while exporting Span batch.
Traceback (most recent call last):
  File "/var/lib/juju/agents/unit-mysql-2/charm/venv/urllib3/connection.py", line 174, in _new_conn
    conn = connection.create_connection(
  File "/var/lib/juju/agents/unit-mysql-2/charm/venv/urllib3/util/connection.py", line 95, in create_connection
    raise err
  File "/var/lib/juju/agents/unit-mysql-2/charm/venv/urllib3/util/connection.py", line 85, in create_connection
    sock.connect(sa)
ConnectionRefusedError: [Errno 111] Connection refused

During handling of the above exception, another exception occurred:

Traceback (most recent call last):
  File "/var/lib/juju/agents/unit-mysql-2/charm/venv/urllib3/connectionpool.py", line 715, in urlopen
    httplib_response = self._make_request(
  File "/var/lib/juju/agents/unit-mysql-2/charm/venv/urllib3/connectionpool.py", line 416, in _make_request
    conn.request(method, url, **httplib_request_kw)
  File "/var/lib/juju/agents/unit-mysql-2/charm/venv/urllib3/connection.py", line 244, in request
    super(HTTPConnection, self).request(method, url, body=body, headers=headers)
  File "/usr/lib/python3.10/http/client.py", line 1283, in request
    self._send_request(method, url, body, headers, encode_chunked)
  File "/usr/lib/python3.10/http/client.py", line 1329, in _send_request
    self.endheaders(body, encode_chunked=encode_chunked)
  File "/usr/lib/python3.10/http/client.py", line 1278, in endheaders
    self._send_output(message_body, encode_chunked=encode_chunked)
  File "/usr/lib/python3.10/http/client.py", line 1038, in _send_output
    self.send(msg)
  File "/usr/lib/python3.10/http/client.py", line 976, in send
    self.connect()
  File "/var/lib/juju/agents/unit-mysql-2/charm/venv/urllib3/connection.py", line 205, in connect
    conn = self._new_conn()
  File "/var/lib/juju/agents/unit-mysql-2/charm/venv/urllib3/connection.py", line 186, in _new_conn
    raise NewConnectionError(
urllib3.exceptions.NewConnectionError: <urllib3.connection.HTTPConnection object at 0x7f479a5dd990>: Failed to establish a new connection: [Errno 111] Connection refused

During handling of the above exception, another exception occurred:

Traceback (most recent call last):
  File "/var/lib/juju/agents/unit-mysql-2/charm/venv/requests/adapters.py", line 486, in send
    resp = conn.urlopen(
  File "/var/lib/juju/agents/unit-mysql-2/charm/venv/urllib3/connectionpool.py", line 801, in urlopen
    retries = retries.increment(
  File "/var/lib/juju/agents/unit-mysql-2/charm/venv/urllib3/util/retry.py", line 594, in increment
    raise MaxRetryError(_pool, url, error or ResponseError(cause))
urllib3.exceptions.MaxRetryError: HTTPConnectionPool(host='juju-d6d1fd-4.lxd', port=4318): Max retries exceeded with url: /v1/traces (Caused by NewConnectionError('<urllib3.connection.HTTPConnection object at 0x7f479a5dd990>: Failed to establish a new connection: [Errno 111] Connection refused'))

During handling of the above exception, another exception occurred:

Traceback (most recent call last):
  File "/var/lib/juju/agents/unit-mysql-2/charm/venv/opentelemetry/sdk/trace/export/__init__.py", line 368, in _export_batch
    self.span_exporter.export(self.spans_list[:idx])  # type: ignore
  File "/var/lib/juju/agents/unit-mysql-2/charm/venv/opentelemetry/exporter/otlp/proto/http/trace_exporter/__init__.py", line 145, in export
    resp = self._export(serialized_data)
  File "/var/lib/juju/agents/unit-mysql-2/charm/venv/opentelemetry/exporter/otlp/proto/http/trace_exporter/__init__.py", line 114, in _export
    return self._session.post(
  File "/var/lib/juju/agents/unit-mysql-2/charm/venv/requests/sessions.py", line 637, in post
    return self.request("POST", url, data=data, json=json, **kwargs)
  File "/var/lib/juju/agents/unit-mysql-2/charm/venv/requests/sessions.py", line 589, in request
    resp = self.send(prep, **send_kwargs)
  File "/var/lib/juju/agents/unit-mysql-2/charm/venv/requests/sessions.py", line 703, in send
    r = adapter.send(request, **kwargs)
  File "/var/lib/juju/agents/unit-mysql-2/charm/venv/requests/adapters.py", line 519, in send
    raise ConnectionError(e, request=request)
requests.exceptions.ConnectionError: HTTPConnectionPool(host='juju-d6d1fd-4.lxd', port=4318): Max retries exceeded with url: /v1/traces (Caused by NewConnectionError('<urllib3.connection.HTTPConnection object at 0x7f479a5dd990>: Failed to establish a new connection: [Errno 111] Connection refused'))
unit-mysql-2: 01:35:18 ERROR unit.mysql/2.juju-log certificates:14: Exception while exporting Span batch.
Traceback (most recent call last):
  File "/var/lib/juju/agents/unit-mysql-2/charm/venv/urllib3/connection.py", line 174, in _new_conn
    conn = connection.create_connection(
  File "/var/lib/juju/agents/unit-mysql-2/charm/venv/urllib3/util/connection.py", line 95, in create_connection
    raise err
  File "/var/lib/juju/agents/unit-mysql-2/charm/venv/urllib3/util/connection.py", line 85, in create_connection
    sock.connect(sa)
ConnectionRefusedError: [Errno 111] Connection refused

During handling of the above exception, another exception occurred:

Traceback (most recent call last):
  File "/var/lib/juju/agents/unit-mysql-2/charm/venv/urllib3/connectionpool.py", line 715, in urlopen
    httplib_response = self._make_request(
  File "/var/lib/juju/agents/unit-mysql-2/charm/venv/urllib3/connectionpool.py", line 416, in _make_request
    conn.request(method, url, **httplib_request_kw)
  File "/var/lib/juju/agents/unit-mysql-2/charm/venv/urllib3/connection.py", line 244, in request
    super(HTTPConnection, self).request(method, url, body=body, headers=headers)
  File "/usr/lib/python3.10/http/client.py", line 1283, in request
    self._send_request(method, url, body, headers, encode_chunked)
  File "/usr/lib/python3.10/http/client.py", line 1329, in _send_request
    self.endheaders(body, encode_chunked=encode_chunked)
  File "/usr/lib/python3.10/http/client.py", line 1278, in endheaders
    self._send_output(message_body, encode_chunked=encode_chunked)
  File "/usr/lib/python3.10/http/client.py", line 1038, in _send_output
    self.send(msg)
  File "/usr/lib/python3.10/http/client.py", line 976, in send
    self.connect()
  File "/var/lib/juju/agents/unit-mysql-2/charm/venv/urllib3/connection.py", line 205, in connect
    conn = self._new_conn()
  File "/var/lib/juju/agents/unit-mysql-2/charm/venv/urllib3/connection.py", line 186, in _new_conn
    raise NewConnectionError(
urllib3.exceptions.NewConnectionError: <urllib3.connection.HTTPConnection object at 0x7eff9b2a5cc0>: Failed to establish a new connection: [Errno 111] Connection refused

During handling of the above exception, another exception occurred:

Traceback (most recent call last):
  File "/var/lib/juju/agents/unit-mysql-2/charm/venv/requests/adapters.py", line 486, in send
    resp = conn.urlopen(
  File "/var/lib/juju/agents/unit-mysql-2/charm/venv/urllib3/connectionpool.py", line 801, in urlopen
    retries = retries.increment(
  File "/var/lib/juju/agents/unit-mysql-2/charm/venv/urllib3/util/retry.py", line 594, in increment
    raise MaxRetryError(_pool, url, error or ResponseError(cause))
urllib3.exceptions.MaxRetryError: HTTPConnectionPool(host='juju-d6d1fd-4.lxd', port=4318): Max retries exceeded with url: /v1/traces (Caused by NewConnectionError('<urllib3.connection.HTTPConnection object at 0x7eff9b2a5cc0>: Failed to establish a new connection: [Errno 111] Connection refused'))

During handling of the above exception, another exception occurred:

Traceback (most recent call last):
  File "/var/lib/juju/agents/unit-mysql-2/charm/venv/opentelemetry/sdk/trace/export/__init__.py", line 368, in _export_batch
    self.span_exporter.export(self.spans_list[:idx])  # type: ignore
  File "/var/lib/juju/agents/unit-mysql-2/charm/venv/opentelemetry/exporter/otlp/proto/http/trace_exporter/__init__.py", line 145, in export
    resp = self._export(serialized_data)
  File "/var/lib/juju/agents/unit-mysql-2/charm/venv/opentelemetry/exporter/otlp/proto/http/trace_exporter/__init__.py", line 114, in _export
    return self._session.post(
  File "/var/lib/juju/agents/unit-mysql-2/charm/venv/requests/sessions.py", line 637, in post
    return self.request("POST", url, data=data, json=json, **kwargs)
  File "/var/lib/juju/agents/unit-mysql-2/charm/venv/requests/sessions.py", line 589, in request
    resp = self.send(prep, **send_kwargs)
  File "/var/lib/juju/agents/unit-mysql-2/charm/venv/requests/sessions.py", line 703, in send
    r = adapter.send(request, **kwargs)
  File "/var/lib/juju/agents/unit-mysql-2/charm/venv/requests/adapters.py", line 519, in send
    raise ConnectionError(e, request=request)
requests.exceptions.ConnectionError: HTTPConnectionPool(host='juju-d6d1fd-4.lxd', port=4318): Max retries exceeded with url: /v1/traces (Caused by NewConnectionError('<urllib3.connection.HTTPConnection object at 0x7eff9b2a5cc0>: Failed to establish a new connection: [Errno 111] Connection refused'))
unit-mysql-2: 01:35:22 ERROR unit.mysql/2.juju-log Exception while exporting Span batch.
Traceback (most recent call last):
  File "/var/lib/juju/agents/unit-mysql-2/charm/venv/urllib3/connection.py", line 174, in _new_conn
    conn = connection.create_connection(
  File "/var/lib/juju/agents/unit-mysql-2/charm/venv/urllib3/util/connection.py", line 95, in create_connection
    raise err
  File "/var/lib/juju/agents/unit-mysql-2/charm/venv/urllib3/util/connection.py", line 85, in create_connection
    sock.connect(sa)
ConnectionRefusedError: [Errno 111] Connection refused

During handling of the above exception, another exception occurred:

Traceback (most recent call last):
  File "/var/lib/juju/agents/unit-mysql-2/charm/venv/urllib3/connectionpool.py", line 715, in urlopen
    httplib_response = self._make_request(
  File "/var/lib/juju/agents/unit-mysql-2/charm/venv/urllib3/connectionpool.py", line 416, in _make_request
    conn.request(method, url, **httplib_request_kw)
  File "/var/lib/juju/agents/unit-mysql-2/charm/venv/urllib3/connection.py", line 244, in request
    super(HTTPConnection, self).request(method, url, body=body, headers=headers)
  File "/usr/lib/python3.10/http/client.py", line 1283, in request
    self._send_request(method, url, body, headers, encode_chunked)
  File "/usr/lib/python3.10/http/client.py", line 1329, in _send_request
    self.endheaders(body, encode_chunked=encode_chunked)
  File "/usr/lib/python3.10/http/client.py", line 1278, in endheaders
    self._send_output(message_body, encode_chunked=encode_chunked)
  File "/usr/lib/python3.10/http/client.py", line 1038, in _send_output
    self.send(msg)
  File "/usr/lib/python3.10/http/client.py", line 976, in send
    self.connect()
  File "/var/lib/juju/agents/unit-mysql-2/charm/venv/urllib3/connection.py", line 205, in connect
    conn = self._new_conn()
  File "/var/lib/juju/agents/unit-mysql-2/charm/venv/urllib3/connection.py", line 186, in _new_conn
    raise NewConnectionError(
urllib3.exceptions.NewConnectionError: <urllib3.connection.HTTPConnection object at 0x7fd7861e38e0>: Failed to establish a new connection: [Errno 111] Connection refused

During handling of the above exception, another exception occurred:

Traceback (most recent call last):
  File "/var/lib/juju/agents/unit-mysql-2/charm/venv/requests/adapters.py", line 486, in send
    resp = conn.urlopen(
  File "/var/lib/juju/agents/unit-mysql-2/charm/venv/urllib3/connectionpool.py", line 801, in urlopen
    retries = retries.increment(
  File "/var/lib/juju/agents/unit-mysql-2/charm/venv/urllib3/util/retry.py", line 594, in increment
    raise MaxRetryError(_pool, url, error or ResponseError(cause))
urllib3.exceptions.MaxRetryError: HTTPConnectionPool(host='juju-d6d1fd-4.lxd', port=4318): Max retries exceeded with url: /v1/traces (Caused by NewConnectionError('<urllib3.connection.HTTPConnection object at 0x7fd7861e38e0>: Failed to establish a new connection: [Errno 111] Connection refused'))

During handling of the above exception, another exception occurred:

Traceback (most recent call last):
  File "/var/lib/juju/agents/unit-mysql-2/charm/venv/opentelemetry/sdk/trace/export/__init__.py", line 368, in _export_batch
    self.span_exporter.export(self.spans_list[:idx])  # type: ignore
  File "/var/lib/juju/agents/unit-mysql-2/charm/venv/opentelemetry/exporter/otlp/proto/http/trace_exporter/__init__.py", line 145, in export
    resp = self._export(serialized_data)
  File "/var/lib/juju/agents/unit-mysql-2/charm/venv/opentelemetry/exporter/otlp/proto/http/trace_exporter/__init__.py", line 114, in _export
    return self._session.post(
  File "/var/lib/juju/agents/unit-mysql-2/charm/venv/requests/sessions.py", line 637, in post
    return self.request("POST", url, data=data, json=json, **kwargs)
  File "/var/lib/juju/agents/unit-mysql-2/charm/venv/requests/sessions.py", line 589, in request
    resp = self.send(prep, **send_kwargs)
  File "/var/lib/juju/agents/unit-mysql-2/charm/venv/requests/sessions.py", line 703, in send
    r = adapter.send(request, **kwargs)
  File "/var/lib/juju/agents/unit-mysql-2/charm/venv/requests/adapters.py", line 519, in send
    raise ConnectionError(e, request=request)
requests.exceptions.ConnectionError: HTTPConnectionPool(host='juju-d6d1fd-4.lxd', port=4318): Max retries exceeded with url: /v1/traces (Caused by NewConnectionError('<urllib3.connection.HTTPConnection object at 0x7fd7861e38e0>: Failed to establish a new connection: [Errno 111] Connection refused'))
unit-mysql-2: 01:35:26 ERROR unit.mysql/2.juju-log restart:2: Exception while exporting Span batch.
Traceback (most recent call last):
  File "/var/lib/juju/agents/unit-mysql-2/charm/venv/urllib3/connection.py", line 174, in _new_conn
    conn = connection.create_connection(
  File "/var/lib/juju/agents/unit-mysql-2/charm/venv/urllib3/util/connection.py", line 95, in create_connection
    raise err
  File "/var/lib/juju/agents/unit-mysql-2/charm/venv/urllib3/util/connection.py", line 85, in create_connection
    sock.connect(sa)
ConnectionRefusedError: [Errno 111] Connection refused

During handling of the above exception, another exception occurred:

Traceback (most recent call last):
  File "/var/lib/juju/agents/unit-mysql-2/charm/venv/urllib3/connectionpool.py", line 715, in urlopen
    httplib_response = self._make_request(
  File "/var/lib/juju/agents/unit-mysql-2/charm/venv/urllib3/connectionpool.py", line 416, in _make_request
    conn.request(method, url, **httplib_request_kw)
  File "/var/lib/juju/agents/unit-mysql-2/charm/venv/urllib3/connection.py", line 244, in request
    super(HTTPConnection, self).request(method, url, body=body, headers=headers)
  File "/usr/lib/python3.10/http/client.py", line 1283, in request
    self._send_request(method, url, body, headers, encode_chunked)
  File "/usr/lib/python3.10/http/client.py", line 1329, in _send_request
    self.endheaders(body, encode_chunked=encode_chunked)
  File "/usr/lib/python3.10/http/client.py", line 1278, in endheaders
    self._send_output(message_body, encode_chunked=encode_chunked)
  File "/usr/lib/python3.10/http/client.py", line 1038, in _send_output
    self.send(msg)
  File "/usr/lib/python3.10/http/client.py", line 976, in send
    self.connect()
  File "/var/lib/juju/agents/unit-mysql-2/charm/venv/urllib3/connection.py", line 205, in connect
    conn = self._new_conn()
  File "/var/lib/juju/agents/unit-mysql-2/charm/venv/urllib3/connection.py", line 186, in _new_conn
    raise NewConnectionError(
urllib3.exceptions.NewConnectionError: <urllib3.connection.HTTPConnection object at 0x7f72a5439f00>: Failed to establish a new connection: [Errno 111] Connection refused

During handling of the above exception, another exception occurred:

Traceback (most recent call last):
  File "/var/lib/juju/agents/unit-mysql-2/charm/venv/requests/adapters.py", line 486, in send
    resp = conn.urlopen(
  File "/var/lib/juju/agents/unit-mysql-2/charm/venv/urllib3/connectionpool.py", line 801, in urlopen
    retries = retries.increment(
  File "/var/lib/juju/agents/unit-mysql-2/charm/venv/urllib3/util/retry.py", line 594, in increment
    raise MaxRetryError(_pool, url, error or ResponseError(cause))
urllib3.exceptions.MaxRetryError: HTTPConnectionPool(host='juju-d6d1fd-4.lxd', port=4318): Max retries exceeded with url: /v1/traces (Caused by NewConnectionError('<urllib3.connection.HTTPConnection object at 0x7f72a5439f00>: Failed to establish a new connection: [Errno 111] Connection refused'))

During handling of the above exception, another exception occurred:

Traceback (most recent call last):
  File "/var/lib/juju/agents/unit-mysql-2/charm/venv/opentelemetry/sdk/trace/export/__init__.py", line 368, in _export_batch
    self.span_exporter.export(self.spans_list[:idx])  # type: ignore
  File "/var/lib/juju/agents/unit-mysql-2/charm/venv/opentelemetry/exporter/otlp/proto/http/trace_exporter/__init__.py", line 145, in export
    resp = self._export(serialized_data)
  File "/var/lib/juju/agents/unit-mysql-2/charm/venv/opentelemetry/exporter/otlp/proto/http/trace_exporter/__init__.py", line 114, in _export
    return self._session.post(
  File "/var/lib/juju/agents/unit-mysql-2/charm/venv/requests/sessions.py", line 637, in post
    return self.request("POST", url, data=data, json=json, **kwargs)
  File "/var/lib/juju/agents/unit-mysql-2/charm/venv/requests/sessions.py", line 589, in request
    resp = self.send(prep, **send_kwargs)
  File "/var/lib/juju/agents/unit-mysql-2/charm/venv/requests/sessions.py", line 703, in send
    r = adapter.send(request, **kwargs)
  File "/var/lib/juju/agents/unit-mysql-2/charm/venv/requests/adapters.py", line 519, in send
    raise ConnectionError(e, request=request)
requests.exceptions.ConnectionError: HTTPConnectionPool(host='juju-d6d1fd-4.lxd', port=4318): Max retries exceeded with url: /v1/traces (Caused by NewConnectionError('<urllib3.connection.HTTPConnection object at 0x7f72a5439f00>: Failed to establish a new connection: [Errno 111] Connection refused'))
unit-mysql-2: 01:35:29 ERROR unit.mysql/2.juju-log upgrade:3: Exception while exporting Span batch.
Traceback (most recent call last):
  File "/var/lib/juju/agents/unit-mysql-2/charm/venv/urllib3/connection.py", line 174, in _new_conn
    conn = connection.create_connection(
  File "/var/lib/juju/agents/unit-mysql-2/charm/venv/urllib3/util/connection.py", line 95, in create_connection
    raise err
  File "/var/lib/juju/agents/unit-mysql-2/charm/venv/urllib3/util/connection.py", line 85, in create_connection
    sock.connect(sa)
ConnectionRefusedError: [Errno 111] Connection refused

During handling of the above exception, another exception occurred:

Traceback (most recent call last):
  File "/var/lib/juju/agents/unit-mysql-2/charm/venv/urllib3/connectionpool.py", line 715, in urlopen
    httplib_response = self._make_request(
  File "/var/lib/juju/agents/unit-mysql-2/charm/venv/urllib3/connectionpool.py", line 416, in _make_request
    conn.request(method, url, **httplib_request_kw)
  File "/var/lib/juju/agents/unit-mysql-2/charm/venv/urllib3/connection.py", line 244, in request
    super(HTTPConnection, self).request(method, url, body=body, headers=headers)
  File "/usr/lib/python3.10/http/client.py", line 1283, in request
    self._send_request(method, url, body, headers, encode_chunked)
  File "/usr/lib/python3.10/http/client.py", line 1329, in _send_request
    self.endheaders(body, encode_chunked=encode_chunked)
  File "/usr/lib/python3.10/http/client.py", line 1278, in endheaders
    self._send_output(message_body, encode_chunked=encode_chunked)
  File "/usr/lib/python3.10/http/client.py", line 1038, in _send_output
    self.send(msg)
  File "/usr/lib/python3.10/http/client.py", line 976, in send
    self.connect()
  File "/var/lib/juju/agents/unit-mysql-2/charm/venv/urllib3/connection.py", line 205, in connect
    conn = self._new_conn()
  File "/var/lib/juju/agents/unit-mysql-2/charm/venv/urllib3/connection.py", line 186, in _new_conn
    raise NewConnectionError(
urllib3.exceptions.NewConnectionError: <urllib3.connection.HTTPConnection object at 0x7fcbfdbe1ea0>: Failed to establish a new connection: [Errno 111] Connection refused

During handling of the above exception, another exception occurred:

Traceback (most recent call last):
  File "/var/lib/juju/agents/unit-mysql-2/charm/venv/requests/adapters.py", line 486, in send
    resp = conn.urlopen(
  File "/var/lib/juju/agents/unit-mysql-2/charm/venv/urllib3/connectionpool.py", line 801, in urlopen
    retries = retries.increment(
  File "/var/lib/juju/agents/unit-mysql-2/charm/venv/urllib3/util/retry.py", line 594, in increment
    raise MaxRetryError(_pool, url, error or ResponseError(cause))
urllib3.exceptions.MaxRetryError: HTTPConnectionPool(host='juju-d6d1fd-4.lxd', port=4318): Max retries exceeded with url: /v1/traces (Caused by NewConnectionError('<urllib3.connection.HTTPConnection object at 0x7fcbfdbe1ea0>: Failed to establish a new connection: [Errno 111] Connection refused'))

During handling of the above exception, another exception occurred:

Traceback (most recent call last):
  File "/var/lib/juju/agents/unit-mysql-2/charm/venv/opentelemetry/sdk/trace/export/__init__.py", line 368, in _export_batch
    self.span_exporter.export(self.spans_list[:idx])  # type: ignore
  File "/var/lib/juju/agents/unit-mysql-2/charm/venv/opentelemetry/exporter/otlp/proto/http/trace_exporter/__init__.py", line 145, in export
    resp = self._export(serialized_data)
  File "/var/lib/juju/agents/unit-mysql-2/charm/venv/opentelemetry/exporter/otlp/proto/http/trace_exporter/__init__.py", line 114, in _export
    return self._session.post(
  File "/var/lib/juju/agents/unit-mysql-2/charm/venv/requests/sessions.py", line 637, in post
    return self.request("POST", url, data=data, json=json, **kwargs)
  File "/var/lib/juju/agents/unit-mysql-2/charm/venv/requests/sessions.py", line 589, in request
    resp = self.send(prep, **send_kwargs)
  File "/var/lib/juju/agents/unit-mysql-2/charm/venv/requests/sessions.py", line 703, in send
    r = adapter.send(request, **kwargs)
  File "/var/lib/juju/agents/unit-mysql-2/charm/venv/requests/adapters.py", line 519, in send
    raise ConnectionError(e, request=request)
requests.exceptions.ConnectionError: HTTPConnectionPool(host='juju-d6d1fd-4.lxd', port=4318): Max retries exceeded with url: /v1/traces (Caused by NewConnectionError('<urllib3.connection.HTTPConnection object at 0x7fcbfdbe1ea0>: Failed to establish a new connection: [Errno 111] Connection refused'))
unit-mysql-2: 01:35:33 ERROR unit.mysql/2.juju-log restart:2: Exception while exporting Span batch.
Traceback (most recent call last):
  File "/var/lib/juju/agents/unit-mysql-2/charm/venv/urllib3/connection.py", line 174, in _new_conn
    conn = connection.create_connection(
  File "/var/lib/juju/agents/unit-mysql-2/charm/venv/urllib3/util/connection.py", line 95, in create_connection
    raise err
  File "/var/lib/juju/agents/unit-mysql-2/charm/venv/urllib3/util/connection.py", line 85, in create_connection
    sock.connect(sa)
ConnectionRefusedError: [Errno 111] Connection refused

During handling of the above exception, another exception occurred:

Traceback (most recent call last):
  File "/var/lib/juju/agents/unit-mysql-2/charm/venv/urllib3/connectionpool.py", line 715, in urlopen
    httplib_response = self._make_request(
  File "/var/lib/juju/agents/unit-mysql-2/charm/venv/urllib3/connectionpool.py", line 416, in _make_request
    conn.request(method, url, **httplib_request_kw)
  File "/var/lib/juju/agents/unit-mysql-2/charm/venv/urllib3/connection.py", line 244, in request
    super(HTTPConnection, self).request(method, url, body=body, headers=headers)
  File "/usr/lib/python3.10/http/client.py", line 1283, in request
    self._send_request(method, url, body, headers, encode_chunked)
  File "/usr/lib/python3.10/http/client.py", line 1329, in _send_request
    self.endheaders(body, encode_chunked=encode_chunked)
  File "/usr/lib/python3.10/http/client.py", line 1278, in endheaders
    self._send_output(message_body, encode_chunked=encode_chunked)
  File "/usr/lib/python3.10/http/client.py", line 1038, in _send_output
    self.send(msg)
  File "/usr/lib/python3.10/http/client.py", line 976, in send
    self.connect()
  File "/var/lib/juju/agents/unit-mysql-2/charm/venv/urllib3/connection.py", line 205, in connect
    conn = self._new_conn()
  File "/var/lib/juju/agents/unit-mysql-2/charm/venv/urllib3/connection.py", line 186, in _new_conn
    raise NewConnectionError(
urllib3.exceptions.NewConnectionError: <urllib3.connection.HTTPConnection object at 0x7fb53171a260>: Failed to establish a new connection: [Errno 111] Connection refused

During handling of the above exception, another exception occurred:

Traceback (most recent call last):
  File "/var/lib/juju/agents/unit-mysql-2/charm/venv/requests/adapters.py", line 486, in send
    resp = conn.urlopen(
  File "/var/lib/juju/agents/unit-mysql-2/charm/venv/urllib3/connectionpool.py", line 801, in urlopen
    retries = retries.increment(
  File "/var/lib/juju/agents/unit-mysql-2/charm/venv/urllib3/util/retry.py", line 594, in increment
    raise MaxRetryError(_pool, url, error or ResponseError(cause))
urllib3.exceptions.MaxRetryError: HTTPConnectionPool(host='juju-d6d1fd-4.lxd', port=4318): Max retries exceeded with url: /v1/traces (Caused by NewConnectionError('<urllib3.connection.HTTPConnection object at 0x7fb53171a260>: Failed to establish a new connection: [Errno 111] Connection refused'))

During handling of the above exception, another exception occurred:

Traceback (most recent call last):
  File "/var/lib/juju/agents/unit-mysql-2/charm/venv/opentelemetry/sdk/trace/export/__init__.py", line 368, in _export_batch
    self.span_exporter.export(self.spans_list[:idx])  # type: ignore
  File "/var/lib/juju/agents/unit-mysql-2/charm/venv/opentelemetry/exporter/otlp/proto/http/trace_exporter/__init__.py", line 145, in export
    resp = self._export(serialized_data)
  File "/var/lib/juju/agents/unit-mysql-2/charm/venv/opentelemetry/exporter/otlp/proto/http/trace_exporter/__init__.py", line 114, in _export
    return self._session.post(
  File "/var/lib/juju/agents/unit-mysql-2/charm/venv/requests/sessions.py", line 637, in post
    return self.request("POST", url, data=data, json=json, **kwargs)
  File "/var/lib/juju/agents/unit-mysql-2/charm/venv/requests/sessions.py", line 589, in request
    resp = self.send(prep, **send_kwargs)
  File "/var/lib/juju/agents/unit-mysql-2/charm/venv/requests/sessions.py", line 703, in send
    r = adapter.send(request, **kwargs)
  File "/var/lib/juju/agents/unit-mysql-2/charm/venv/requests/adapters.py", line 519, in send
    raise ConnectionError(e, request=request)
requests.exceptions.ConnectionError: HTTPConnectionPool(host='juju-d6d1fd-4.lxd', port=4318): Max retries exceeded with url: /v1/traces (Caused by NewConnectionError('<urllib3.connection.HTTPConnection object at 0x7fb53171a260>: Failed to establish a new connection: [Errno 111] Connection refused'))
unit-mysql-2: 01:35:38 ERROR unit.mysql/2.juju-log restart:2: Exception while exporting Span batch.
Traceback (most recent call last):
  File "/var/lib/juju/agents/unit-mysql-2/charm/venv/urllib3/connection.py", line 174, in _new_conn
    conn = connection.create_connection(
  File "/var/lib/juju/agents/unit-mysql-2/charm/venv/urllib3/util/connection.py", line 95, in create_connection
    raise err
  File "/var/lib/juju/agents/unit-mysql-2/charm/venv/urllib3/util/connection.py", line 85, in create_connection
    sock.connect(sa)
ConnectionRefusedError: [Errno 111] Connection refused

During handling of the above exception, another exception occurred:

Traceback (most recent call last):
  File "/var/lib/juju/agents/unit-mysql-2/charm/venv/urllib3/connectionpool.py", line 715, in urlopen
    httplib_response = self._make_request(
  File "/var/lib/juju/agents/unit-mysql-2/charm/venv/urllib3/connectionpool.py", line 416, in _make_request
    conn.request(method, url, **httplib_request_kw)
  File "/var/lib/juju/agents/unit-mysql-2/charm/venv/urllib3/connection.py", line 244, in request
    super(HTTPConnection, self).request(method, url, body=body, headers=headers)
  File "/usr/lib/python3.10/http/client.py", line 1283, in request
    self._send_request(method, url, body, headers, encode_chunked)
  File "/usr/lib/python3.10/http/client.py", line 1329, in _send_request
    self.endheaders(body, encode_chunked=encode_chunked)
  File "/usr/lib/python3.10/http/client.py", line 1278, in endheaders
    self._send_output(message_body, encode_chunked=encode_chunked)
  File "/usr/lib/python3.10/http/client.py", line 1038, in _send_output
    self.send(msg)
  File "/usr/lib/python3.10/http/client.py", line 976, in send
    self.connect()
  File "/var/lib/juju/agents/unit-mysql-2/charm/venv/urllib3/connection.py", line 205, in connect
    conn = self._new_conn()
  File "/var/lib/juju/agents/unit-mysql-2/charm/venv/urllib3/connection.py", line 186, in _new_conn
    raise NewConnectionError(
urllib3.exceptions.NewConnectionError: <urllib3.connection.HTTPConnection object at 0x7f8dbc241ed0>: Failed to establish a new connection: [Errno 111] Connection refused

During handling of the above exception, another exception occurred:

Traceback (most recent call last):
  File "/var/lib/juju/agents/unit-mysql-2/charm/venv/requests/adapters.py", line 486, in send
    resp = conn.urlopen(
  File "/var/lib/juju/agents/unit-mysql-2/charm/venv/urllib3/connectionpool.py", line 801, in urlopen
    retries = retries.increment(
  File "/var/lib/juju/agents/unit-mysql-2/charm/venv/urllib3/util/retry.py", line 594, in increment
    raise MaxRetryError(_pool, url, error or ResponseError(cause))
urllib3.exceptions.MaxRetryError: HTTPConnectionPool(host='juju-d6d1fd-4.lxd', port=4318): Max retries exceeded with url: /v1/traces (Caused by NewConnectionError('<urllib3.connection.HTTPConnection object at 0x7f8dbc241ed0>: Failed to establish a new connection: [Errno 111] Connection refused'))

During handling of the above exception, another exception occurred:

Traceback (most recent call last):
  File "/var/lib/juju/agents/unit-mysql-2/charm/venv/opentelemetry/sdk/trace/export/__init__.py", line 368, in _export_batch
    self.span_exporter.export(self.spans_list[:idx])  # type: ignore
  File "/var/lib/juju/agents/unit-mysql-2/charm/venv/opentelemetry/exporter/otlp/proto/http/trace_exporter/__init__.py", line 145, in export
    resp = self._export(serialized_data)
  File "/var/lib/juju/agents/unit-mysql-2/charm/venv/opentelemetry/exporter/otlp/proto/http/trace_exporter/__init__.py", line 114, in _export
    return self._session.post(
  File "/var/lib/juju/agents/unit-mysql-2/charm/venv/requests/sessions.py", line 637, in post
    return self.request("POST", url, data=data, json=json, **kwargs)
  File "/var/lib/juju/agents/unit-mysql-2/charm/venv/requests/sessions.py", line 589, in request
    resp = self.send(prep, **send_kwargs)
  File "/var/lib/juju/agents/unit-mysql-2/charm/venv/requests/sessions.py", line 703, in send
    r = adapter.send(request, **kwargs)
  File "/var/lib/juju/agents/unit-mysql-2/charm/venv/requests/adapters.py", line 519, in send
    raise ConnectionError(e, request=request)
requests.exceptions.ConnectionError: HTTPConnectionPool(host='juju-d6d1fd-4.lxd', port=4318): Max retries exceeded with url: /v1/traces (Caused by NewConnectionError('<urllib3.connection.HTTPConnection object at 0x7f8dbc241ed0>: Failed to establish a new connection: [Errno 111] Connection refused'))
unit-mysql-2: 01:35:44 ERROR unit.mysql/2.juju-log upgrade:3: Exception while exporting Span batch.
Traceback (most recent call last):
  File "/var/lib/juju/agents/unit-mysql-2/charm/venv/urllib3/connection.py", line 174, in _new_conn
    conn = connection.create_connection(
  File "/var/lib/juju/agents/unit-mysql-2/charm/venv/urllib3/util/connection.py", line 95, in create_connection
    raise err
  File "/var/lib/juju/agents/unit-mysql-2/charm/venv/urllib3/util/connection.py", line 85, in create_connection
    sock.connect(sa)
ConnectionRefusedError: [Errno 111] Connection refused

During handling of the above exception, another exception occurred:

Traceback (most recent call last):
  File "/var/lib/juju/agents/unit-mysql-2/charm/venv/urllib3/connectionpool.py", line 715, in urlopen
    httplib_response = self._make_request(
  File "/var/lib/juju/agents/unit-mysql-2/charm/venv/urllib3/connectionpool.py", line 416, in _make_request
    conn.request(method, url, **httplib_request_kw)
  File "/var/lib/juju/agents/unit-mysql-2/charm/venv/urllib3/connection.py", line 244, in request
    super(HTTPConnection, self).request(method, url, body=body, headers=headers)
  File "/usr/lib/python3.10/http/client.py", line 1283, in request
    self._send_request(method, url, body, headers, encode_chunked)
  File "/usr/lib/python3.10/http/client.py", line 1329, in _send_request
    self.endheaders(body, encode_chunked=encode_chunked)
  File "/usr/lib/python3.10/http/client.py", line 1278, in endheaders
    self._send_output(message_body, encode_chunked=encode_chunked)
  File "/usr/lib/python3.10/http/client.py", line 1038, in _send_output
    self.send(msg)
  File "/usr/lib/python3.10/http/client.py", line 976, in send
    self.connect()
  File "/var/lib/juju/agents/unit-mysql-2/charm/venv/urllib3/connection.py", line 205, in connect
    conn = self._new_conn()
  File "/var/lib/juju/agents/unit-mysql-2/charm/venv/urllib3/connection.py", line 186, in _new_conn
    raise NewConnectionError(
urllib3.exceptions.NewConnectionError: <urllib3.connection.HTTPConnection object at 0x7f7d9bad92a0>: Failed to establish a new connection: [Errno 111] Connection refused

During handling of the above exception, another exception occurred:

Traceback (most recent call last):
  File "/var/lib/juju/agents/unit-mysql-2/charm/venv/requests/adapters.py", line 486, in send
    resp = conn.urlopen(
  File "/var/lib/juju/agents/unit-mysql-2/charm/venv/urllib3/connectionpool.py", line 801, in urlopen
    retries = retries.increment(
  File "/var/lib/juju/agents/unit-mysql-2/charm/venv/urllib3/util/retry.py", line 594, in increment
    raise MaxRetryError(_pool, url, error or ResponseError(cause))
urllib3.exceptions.MaxRetryError: HTTPConnectionPool(host='juju-d6d1fd-4.lxd', port=4318): Max retries exceeded with url: /v1/traces (Caused by NewConnectionError('<urllib3.connection.HTTPConnection object at 0x7f7d9bad92a0>: Failed to establish a new connection: [Errno 111] Connection refused'))

During handling of the above exception, another exception occurred:

Traceback (most recent call last):
  File "/var/lib/juju/agents/unit-mysql-2/charm/venv/opentelemetry/sdk/trace/export/__init__.py", line 368, in _export_batch
    self.span_exporter.export(self.spans_list[:idx])  # type: ignore
  File "/var/lib/juju/agents/unit-mysql-2/charm/venv/opentelemetry/exporter/otlp/proto/http/trace_exporter/__init__.py", line 145, in export
    resp = self._export(serialized_data)
  File "/var/lib/juju/agents/unit-mysql-2/charm/venv/opentelemetry/exporter/otlp/proto/http/trace_exporter/__init__.py", line 114, in _export
    return self._session.post(
  File "/var/lib/juju/agents/unit-mysql-2/charm/venv/requests/sessions.py", line 637, in post
    return self.request("POST", url, data=data, json=json, **kwargs)
  File "/var/lib/juju/agents/unit-mysql-2/charm/venv/requests/sessions.py", line 589, in request
    resp = self.send(prep, **send_kwargs)
  File "/var/lib/juju/agents/unit-mysql-2/charm/venv/requests/sessions.py", line 703, in send
    r = adapter.send(request, **kwargs)
  File "/var/lib/juju/agents/unit-mysql-2/charm/venv/requests/adapters.py", line 519, in send
    raise ConnectionError(e, request=request)
requests.exceptions.ConnectionError: HTTPConnectionPool(host='juju-d6d1fd-4.lxd', port=4318): Max retries exceeded with url: /v1/traces (Caused by NewConnectionError('<urllib3.connection.HTTPConnection object at 0x7f7d9bad92a0>: Failed to establish a new connection: [Errno 111] Connection refused'))
unit-mysql-2: 01:35:49 ERROR unit.mysql/2.juju-log restart:2: Exception while exporting Span batch.
Traceback (most recent call last):
  File "/var/lib/juju/agents/unit-mysql-2/charm/venv/urllib3/connection.py", line 174, in _new_conn
    conn = connection.create_connection(
  File "/var/lib/juju/agents/unit-mysql-2/charm/venv/urllib3/util/connection.py", line 95, in create_connection
    raise err
  File "/var/lib/juju/agents/unit-mysql-2/charm/venv/urllib3/util/connection.py", line 85, in create_connection
    sock.connect(sa)
ConnectionRefusedError: [Errno 111] Connection refused

During handling of the above exception, another exception occurred:

Traceback (most recent call last):
  File "/var/lib/juju/agents/unit-mysql-2/charm/venv/urllib3/connectionpool.py", line 715, in urlopen
    httplib_response = self._make_request(
  File "/var/lib/juju/agents/unit-mysql-2/charm/venv/urllib3/connectionpool.py", line 416, in _make_request
    conn.request(method, url, **httplib_request_kw)
  File "/var/lib/juju/agents/unit-mysql-2/charm/venv/urllib3/connection.py", line 244, in request
    super(HTTPConnection, self).request(method, url, body=body, headers=headers)
  File "/usr/lib/python3.10/http/client.py", line 1283, in request
    self._send_request(method, url, body, headers, encode_chunked)
  File "/usr/lib/python3.10/http/client.py", line 1329, in _send_request
    self.endheaders(body, encode_chunked=encode_chunked)
  File "/usr/lib/python3.10/http/client.py", line 1278, in endheaders
    self._send_output(message_body, encode_chunked=encode_chunked)
  File "/usr/lib/python3.10/http/client.py", line 1038, in _send_output
    self.send(msg)
  File "/usr/lib/python3.10/http/client.py", line 976, in send
    self.connect()
  File "/var/lib/juju/agents/unit-mysql-2/charm/venv/urllib3/connection.py", line 205, in connect
    conn = self._new_conn()
  File "/var/lib/juju/agents/unit-mysql-2/charm/venv/urllib3/connection.py", line 186, in _new_conn
    raise NewConnectionError(
urllib3.exceptions.NewConnectionError: <urllib3.connection.HTTPConnection object at 0x7f17c3fde320>: Failed to establish a new connection: [Errno 111] Connection refused

During handling of the above exception, another exception occurred:

Traceback (most recent call last):
  File "/var/lib/juju/agents/unit-mysql-2/charm/venv/requests/adapters.py", line 486, in send
    resp = conn.urlopen(
  File "/var/lib/juju/agents/unit-mysql-2/charm/venv/urllib3/connectionpool.py", line 801, in urlopen
    retries = retries.increment(
  File "/var/lib/juju/agents/unit-mysql-2/charm/venv/urllib3/util/retry.py", line 594, in increment
    raise MaxRetryError(_pool, url, error or ResponseError(cause))
urllib3.exceptions.MaxRetryError: HTTPConnectionPool(host='juju-d6d1fd-4.lxd', port=4318): Max retries exceeded with url: /v1/traces (Caused by NewConnectionError('<urllib3.connection.HTTPConnection object at 0x7f17c3fde320>: Failed to establish a new connection: [Errno 111] Connection refused'))

During handling of the above exception, another exception occurred:

Traceback (most recent call last):
  File "/var/lib/juju/agents/unit-mysql-2/charm/venv/opentelemetry/sdk/trace/export/__init__.py", line 368, in _export_batch
    self.span_exporter.export(self.spans_list[:idx])  # type: ignore
  File "/var/lib/juju/agents/unit-mysql-2/charm/venv/opentelemetry/exporter/otlp/proto/http/trace_exporter/__init__.py", line 145, in export
    resp = self._export(serialized_data)
  File "/var/lib/juju/agents/unit-mysql-2/charm/venv/opentelemetry/exporter/otlp/proto/http/trace_exporter/__init__.py", line 114, in _export
    return self._session.post(
  File "/var/lib/juju/agents/unit-mysql-2/charm/venv/requests/sessions.py", line 637, in post
    return self.request("POST", url, data=data, json=json, **kwargs)
  File "/var/lib/juju/agents/unit-mysql-2/charm/venv/requests/sessions.py", line 589, in request
    resp = self.send(prep, **send_kwargs)
  File "/var/lib/juju/agents/unit-mysql-2/charm/venv/requests/sessions.py", line 703, in send
    r = adapter.send(request, **kwargs)
  File "/var/lib/juju/agents/unit-mysql-2/charm/venv/requests/adapters.py", line 519, in send
    raise ConnectionError(e, request=request)
requests.exceptions.ConnectionError: HTTPConnectionPool(host='juju-d6d1fd-4.lxd', port=4318): Max retries exceeded with url: /v1/traces (Caused by NewConnectionError('<urllib3.connection.HTTPConnection object at 0x7f17c3fde320>: Failed to establish a new connection: [Errno 111] Connection refused'))
unit-mysql-2: 01:35:53 ERROR unit.mysql/2.juju-log database:17: Exception while exporting Span batch.
Traceback (most recent call last):
  File "/var/lib/juju/agents/unit-mysql-2/charm/venv/urllib3/connection.py", line 174, in _new_conn
    conn = connection.create_connection(
  File "/var/lib/juju/agents/unit-mysql-2/charm/venv/urllib3/util/connection.py", line 95, in create_connection
    raise err
  File "/var/lib/juju/agents/unit-mysql-2/charm/venv/urllib3/util/connection.py", line 85, in create_connection
    sock.connect(sa)
ConnectionRefusedError: [Errno 111] Connection refused

During handling of the above exception, another exception occurred:

Traceback (most recent call last):
  File "/var/lib/juju/agents/unit-mysql-2/charm/venv/urllib3/connectionpool.py", line 715, in urlopen
    httplib_response = self._make_request(
  File "/var/lib/juju/agents/unit-mysql-2/charm/venv/urllib3/connectionpool.py", line 416, in _make_request
    conn.request(method, url, **httplib_request_kw)
  File "/var/lib/juju/agents/unit-mysql-2/charm/venv/urllib3/connection.py", line 244, in request
    super(HTTPConnection, self).request(method, url, body=body, headers=headers)
  File "/usr/lib/python3.10/http/client.py", line 1283, in request
    self._send_request(method, url, body, headers, encode_chunked)
  File "/usr/lib/python3.10/http/client.py", line 1329, in _send_request
    self.endheaders(body, encode_chunked=encode_chunked)
  File "/usr/lib/python3.10/http/client.py", line 1278, in endheaders
    self._send_output(message_body, encode_chunked=encode_chunked)
  File "/usr/lib/python3.10/http/client.py", line 1038, in _send_output
    self.send(msg)
  File "/usr/lib/python3.10/http/client.py", line 976, in send
    self.connect()
  File "/var/lib/juju/agents/unit-mysql-2/charm/venv/urllib3/connection.py", line 205, in connect
    conn = self._new_conn()
  File "/var/lib/juju/agents/unit-mysql-2/charm/venv/urllib3/connection.py", line 186, in _new_conn
    raise NewConnectionError(
urllib3.exceptions.NewConnectionError: <urllib3.connection.HTTPConnection object at 0x7f2bfed16680>: Failed to establish a new connection: [Errno 111] Connection refused

During handling of the above exception, another exception occurred:

Traceback (most recent call last):
  File "/var/lib/juju/agents/unit-mysql-2/charm/venv/requests/adapters.py", line 486, in send
    resp = conn.urlopen(
  File "/var/lib/juju/agents/unit-mysql-2/charm/venv/urllib3/connectionpool.py", line 801, in urlopen
    retries = retries.increment(
  File "/var/lib/juju/agents/unit-mysql-2/charm/venv/urllib3/util/retry.py", line 594, in increment
    raise MaxRetryError(_pool, url, error or ResponseError(cause))
urllib3.exceptions.MaxRetryError: HTTPConnectionPool(host='juju-d6d1fd-4.lxd', port=4318): Max retries exceeded with url: /v1/traces (Caused by NewConnectionError('<urllib3.connection.HTTPConnection object at 0x7f2bfed16680>: Failed to establish a new connection: [Errno 111] Connection refused'))

During handling of the above exception, another exception occurred:

Traceback (most recent call last):
  File "/var/lib/juju/agents/unit-mysql-2/charm/venv/opentelemetry/sdk/trace/export/__init__.py", line 368, in _export_batch
    self.span_exporter.export(self.spans_list[:idx])  # type: ignore
  File "/var/lib/juju/agents/unit-mysql-2/charm/venv/opentelemetry/exporter/otlp/proto/http/trace_exporter/__init__.py", line 145, in export
    resp = self._export(serialized_data)
  File "/var/lib/juju/agents/unit-mysql-2/charm/venv/opentelemetry/exporter/otlp/proto/http/trace_exporter/__init__.py", line 114, in _export
    return self._session.post(
  File "/var/lib/juju/agents/unit-mysql-2/charm/venv/requests/sessions.py", line 637, in post
    return self.request("POST", url, data=data, json=json, **kwargs)
  File "/var/lib/juju/agents/unit-mysql-2/charm/venv/requests/sessions.py", line 589, in request
    resp = self.send(prep, **send_kwargs)
  File "/var/lib/juju/agents/unit-mysql-2/charm/venv/requests/sessions.py", line 703, in send
    r = adapter.send(request, **kwargs)
  File "/var/lib/juju/agents/unit-mysql-2/charm/venv/requests/adapters.py", line 519, in send
    raise ConnectionError(e, request=request)
requests.exceptions.ConnectionError: HTTPConnectionPool(host='juju-d6d1fd-4.lxd', port=4318): Max retries exceeded with url: /v1/traces (Caused by NewConnectionError('<urllib3.connection.HTTPConnection object at 0x7f2bfed16680>: Failed to establish a new connection: [Errno 111] Connection refused'))
unit-mysql-2: 01:35:57 ERROR unit.mysql/2.juju-log certificates:14: Exception while exporting Span batch.
Traceback (most recent call last):
  File "/var/lib/juju/agents/unit-mysql-2/charm/venv/urllib3/connection.py", line 174, in _new_conn
    conn = connection.create_connection(
  File "/var/lib/juju/agents/unit-mysql-2/charm/venv/urllib3/util/connection.py", line 95, in create_connection
    raise err
  File "/var/lib/juju/agents/unit-mysql-2/charm/venv/urllib3/util/connection.py", line 85, in create_connection
    sock.connect(sa)
ConnectionRefusedError: [Errno 111] Connection refused

During handling of the above exception, another exception occurred:

Traceback (most recent call last):
  File "/var/lib/juju/agents/unit-mysql-2/charm/venv/urllib3/connectionpool.py", line 715, in urlopen
    httplib_response = self._make_request(
  File "/var/lib/juju/agents/unit-mysql-2/charm/venv/urllib3/connectionpool.py", line 416, in _make_request
    conn.request(method, url, **httplib_request_kw)
  File "/var/lib/juju/agents/unit-mysql-2/charm/venv/urllib3/connection.py", line 244, in request
    super(HTTPConnection, self).request(method, url, body=body, headers=headers)
  File "/usr/lib/python3.10/http/client.py", line 1283, in request
    self._send_request(method, url, body, headers, encode_chunked)
  File "/usr/lib/python3.10/http/client.py", line 1329, in _send_request
    self.endheaders(body, encode_chunked=encode_chunked)
  File "/usr/lib/python3.10/http/client.py", line 1278, in endheaders
    self._send_output(message_body, encode_chunked=encode_chunked)
  File "/usr/lib/python3.10/http/client.py", line 1038, in _send_output
    self.send(msg)
  File "/usr/lib/python3.10/http/client.py", line 976, in send
    self.connect()
  File "/var/lib/juju/agents/unit-mysql-2/charm/venv/urllib3/connection.py", line 205, in connect
    conn = self._new_conn()
  File "/var/lib/juju/agents/unit-mysql-2/charm/venv/urllib3/connection.py", line 186, in _new_conn
    raise NewConnectionError(
urllib3.exceptions.NewConnectionError: <urllib3.connection.HTTPConnection object at 0x7fc211641e40>: Failed to establish a new connection: [Errno 111] Connection refused

During handling of the above exception, another exception occurred:

Traceback (most recent call last):
  File "/var/lib/juju/agents/unit-mysql-2/charm/venv/requests/adapters.py", line 486, in send
    resp = conn.urlopen(
  File "/var/lib/juju/agents/unit-mysql-2/charm/venv/urllib3/connectionpool.py", line 801, in urlopen
    retries = retries.increment(
  File "/var/lib/juju/agents/unit-mysql-2/charm/venv/urllib3/util/retry.py", line 594, in increment
    raise MaxRetryError(_pool, url, error or ResponseError(cause))
urllib3.exceptions.MaxRetryError: HTTPConnectionPool(host='juju-d6d1fd-4.lxd', port=4318): Max retries exceeded with url: /v1/traces (Caused by NewConnectionError('<urllib3.connection.HTTPConnection object at 0x7fc211641e40>: Failed to establish a new connection: [Errno 111] Connection refused'))

During handling of the above exception, another exception occurred:

Traceback (most recent call last):
  File "/var/lib/juju/agents/unit-mysql-2/charm/venv/opentelemetry/sdk/trace/export/__init__.py", line 368, in _export_batch
    self.span_exporter.export(self.spans_list[:idx])  # type: ignore
  File "/var/lib/juju/agents/unit-mysql-2/charm/venv/opentelemetry/exporter/otlp/proto/http/trace_exporter/__init__.py", line 145, in export
    resp = self._export(serialized_data)
  File "/var/lib/juju/agents/unit-mysql-2/charm/venv/opentelemetry/exporter/otlp/proto/http/trace_exporter/__init__.py", line 114, in _export
    return self._session.post(
  File "/var/lib/juju/agents/unit-mysql-2/charm/venv/requests/sessions.py", line 637, in post
    return self.request("POST", url, data=data, json=json, **kwargs)
  File "/var/lib/juju/agents/unit-mysql-2/charm/venv/requests/sessions.py", line 589, in request
    resp = self.send(prep, **send_kwargs)
  File "/var/lib/juju/agents/unit-mysql-2/charm/venv/requests/sessions.py", line 703, in send
    r = adapter.send(request, **kwargs)
  File "/var/lib/juju/agents/unit-mysql-2/charm/venv/requests/adapters.py", line 519, in send
    raise ConnectionError(e, request=request)
requests.exceptions.ConnectionError: HTTPConnectionPool(host='juju-d6d1fd-4.lxd', port=4318): Max retries exceeded with url: /v1/traces (Caused by NewConnectionError('<urllib3.connection.HTTPConnection object at 0x7fc211641e40>: Failed to establish a new connection: [Errno 111] Connection refused'))
unit-mysql-1: 01:35:58 ERROR unit.mysql/1.juju-log cos-agent:19: Exception while exporting Span batch.
Traceback (most recent call last):
  File "/var/lib/juju/agents/unit-mysql-1/charm/venv/urllib3/connection.py", line 174, in _new_conn
    conn = connection.create_connection(
  File "/var/lib/juju/agents/unit-mysql-1/charm/venv/urllib3/util/connection.py", line 95, in create_connection
    raise err
  File "/var/lib/juju/agents/unit-mysql-1/charm/venv/urllib3/util/connection.py", line 85, in create_connection
    sock.connect(sa)
ConnectionRefusedError: [Errno 111] Connection refused

During handling of the above exception, another exception occurred:

Traceback (most recent call last):
  File "/var/lib/juju/agents/unit-mysql-1/charm/venv/urllib3/connectionpool.py", line 715, in urlopen
    httplib_response = self._make_request(
  File "/var/lib/juju/agents/unit-mysql-1/charm/venv/urllib3/connectionpool.py", line 416, in _make_request
    conn.request(method, url, **httplib_request_kw)
  File "/var/lib/juju/agents/unit-mysql-1/charm/venv/urllib3/connection.py", line 244, in request
    super(HTTPConnection, self).request(method, url, body=body, headers=headers)
  File "/usr/lib/python3.10/http/client.py", line 1283, in request
    self._send_request(method, url, body, headers, encode_chunked)
  File "/usr/lib/python3.10/http/client.py", line 1329, in _send_request
    self.endheaders(body, encode_chunked=encode_chunked)
  File "/usr/lib/python3.10/http/client.py", line 1278, in endheaders
    self._send_output(message_body, encode_chunked=encode_chunked)
  File "/usr/lib/python3.10/http/client.py", line 1038, in _send_output
    self.send(msg)
  File "/usr/lib/python3.10/http/client.py", line 976, in send
    self.connect()
  File "/var/lib/juju/agents/unit-mysql-1/charm/venv/urllib3/connection.py", line 205, in connect
    conn = self._new_conn()
  File "/var/lib/juju/agents/unit-mysql-1/charm/venv/urllib3/connection.py", line 186, in _new_conn
    raise NewConnectionError(
urllib3.exceptions.NewConnectionError: <urllib3.connection.HTTPConnection object at 0x7f41518d5090>: Failed to establish a new connection: [Errno 111] Connection refused

During handling of the above exception, another exception occurred:

Traceback (most recent call last):
  File "/var/lib/juju/agents/unit-mysql-1/charm/venv/requests/adapters.py", line 486, in send
    resp = conn.urlopen(
  File "/var/lib/juju/agents/unit-mysql-1/charm/venv/urllib3/connectionpool.py", line 801, in urlopen
    retries = retries.increment(
  File "/var/lib/juju/agents/unit-mysql-1/charm/venv/urllib3/util/retry.py", line 594, in increment
    raise MaxRetryError(_pool, url, error or ResponseError(cause))
urllib3.exceptions.MaxRetryError: HTTPConnectionPool(host='juju-d6d1fd-3.lxd', port=4318): Max retries exceeded with url: /v1/traces (Caused by NewConnectionError('<urllib3.connection.HTTPConnection object at 0x7f41518d5090>: Failed to establish a new connection: [Errno 111] Connection refused'))

During handling of the above exception, another exception occurred:

Traceback (most recent call last):
  File "/var/lib/juju/agents/unit-mysql-1/charm/venv/opentelemetry/sdk/trace/export/__init__.py", line 368, in _export_batch
    self.span_exporter.export(self.spans_list[:idx])  # type: ignore
  File "/var/lib/juju/agents/unit-mysql-1/charm/venv/opentelemetry/exporter/otlp/proto/http/trace_exporter/__init__.py", line 145, in export
    resp = self._export(serialized_data)
  File "/var/lib/juju/agents/unit-mysql-1/charm/venv/opentelemetry/exporter/otlp/proto/http/trace_exporter/__init__.py", line 114, in _export
    return self._session.post(
  File "/var/lib/juju/agents/unit-mysql-1/charm/venv/requests/sessions.py", line 637, in post
    return self.request("POST", url, data=data, json=json, **kwargs)
  File "/var/lib/juju/agents/unit-mysql-1/charm/venv/requests/sessions.py", line 589, in request
    resp = self.send(prep, **send_kwargs)
  File "/var/lib/juju/agents/unit-mysql-1/charm/venv/requests/sessions.py", line 703, in send
    r = adapter.send(request, **kwargs)
  File "/var/lib/juju/agents/unit-mysql-1/charm/venv/requests/adapters.py", line 519, in send
    raise ConnectionError(e, request=request)
requests.exceptions.ConnectionError: HTTPConnectionPool(host='juju-d6d1fd-3.lxd', port=4318): Max retries exceeded with url: /v1/traces (Caused by NewConnectionError('<urllib3.connection.HTTPConnection object at 0x7f41518d5090>: Failed to establish a new connection: [Errno 111] Connection refused'))
unit-mysql-1: 01:36:02 ERROR unit.mysql/1.juju-log database-peers:1: Exception while exporting Span batch.
Traceback (most recent call last):
  File "/var/lib/juju/agents/unit-mysql-1/charm/venv/urllib3/connection.py", line 174, in _new_conn
    conn = connection.create_connection(
  File "/var/lib/juju/agents/unit-mysql-1/charm/venv/urllib3/util/connection.py", line 95, in create_connection
    raise err
  File "/var/lib/juju/agents/unit-mysql-1/charm/venv/urllib3/util/connection.py", line 85, in create_connection
    sock.connect(sa)
ConnectionRefusedError: [Errno 111] Connection refused

During handling of the above exception, another exception occurred:

Traceback (most recent call last):
  File "/var/lib/juju/agents/unit-mysql-1/charm/venv/urllib3/connectionpool.py", line 715, in urlopen
    httplib_response = self._make_request(
  File "/var/lib/juju/agents/unit-mysql-1/charm/venv/urllib3/connectionpool.py", line 416, in _make_request
    conn.request(method, url, **httplib_request_kw)
  File "/var/lib/juju/agents/unit-mysql-1/charm/venv/urllib3/connection.py", line 244, in request
    super(HTTPConnection, self).request(method, url, body=body, headers=headers)
  File "/usr/lib/python3.10/http/client.py", line 1283, in request
    self._send_request(method, url, body, headers, encode_chunked)
  File "/usr/lib/python3.10/http/client.py", line 1329, in _send_request
    self.endheaders(body, encode_chunked=encode_chunked)
  File "/usr/lib/python3.10/http/client.py", line 1278, in endheaders
    self._send_output(message_body, encode_chunked=encode_chunked)
  File "/usr/lib/python3.10/http/client.py", line 1038, in _send_output
    self.send(msg)
  File "/usr/lib/python3.10/http/client.py", line 976, in send
    self.connect()
  File "/var/lib/juju/agents/unit-mysql-1/charm/venv/urllib3/connection.py", line 205, in connect
    conn = self._new_conn()
  File "/var/lib/juju/agents/unit-mysql-1/charm/venv/urllib3/connection.py", line 186, in _new_conn
    raise NewConnectionError(
urllib3.exceptions.NewConnectionError: <urllib3.connection.HTTPConnection object at 0x7f2ed62c5000>: Failed to establish a new connection: [Errno 111] Connection refused

During handling of the above exception, another exception occurred:

Traceback (most recent call last):
  File "/var/lib/juju/agents/unit-mysql-1/charm/venv/requests/adapters.py", line 486, in send
    resp = conn.urlopen(
  File "/var/lib/juju/agents/unit-mysql-1/charm/venv/urllib3/connectionpool.py", line 801, in urlopen
    retries = retries.increment(
  File "/var/lib/juju/agents/unit-mysql-1/charm/venv/urllib3/util/retry.py", line 594, in increment
    raise MaxRetryError(_pool, url, error or ResponseError(cause))
urllib3.exceptions.MaxRetryError: HTTPConnectionPool(host='juju-d6d1fd-3.lxd', port=4318): Max retries exceeded with url: /v1/traces (Caused by NewConnectionError('<urllib3.connection.HTTPConnection object at 0x7f2ed62c5000>: Failed to establish a new connection: [Errno 111] Connection refused'))

During handling of the above exception, another exception occurred:

Traceback (most recent call last):
  File "/var/lib/juju/agents/unit-mysql-1/charm/venv/opentelemetry/sdk/trace/export/__init__.py", line 368, in _export_batch
    self.span_exporter.export(self.spans_list[:idx])  # type: ignore
  File "/var/lib/juju/agents/unit-mysql-1/charm/venv/opentelemetry/exporter/otlp/proto/http/trace_exporter/__init__.py", line 145, in export
    resp = self._export(serialized_data)
  File "/var/lib/juju/agents/unit-mysql-1/charm/venv/opentelemetry/exporter/otlp/proto/http/trace_exporter/__init__.py", line 114, in _export
    return self._session.post(
  File "/var/lib/juju/agents/unit-mysql-1/charm/venv/requests/sessions.py", line 637, in post
    return self.request("POST", url, data=data, json=json, **kwargs)
  File "/var/lib/juju/agents/unit-mysql-1/charm/venv/requests/sessions.py", line 589, in request
    resp = self.send(prep, **send_kwargs)
  File "/var/lib/juju/agents/unit-mysql-1/charm/venv/requests/sessions.py", line 703, in send
    r = adapter.send(request, **kwargs)
  File "/var/lib/juju/agents/unit-mysql-1/charm/venv/requests/adapters.py", line 519, in send
    raise ConnectionError(e, request=request)
requests.exceptions.ConnectionError: HTTPConnectionPool(host='juju-d6d1fd-3.lxd', port=4318): Max retries exceeded with url: /v1/traces (Caused by NewConnectionError('<urllib3.connection.HTTPConnection object at 0x7f2ed62c5000>: Failed to establish a new connection: [Errno 111] Connection refused'))
unit-mysql-2: 01:36:02 ERROR unit.mysql/2.juju-log database:17: Exception while exporting Span batch.
Traceback (most recent call last):
  File "/var/lib/juju/agents/unit-mysql-2/charm/venv/urllib3/connection.py", line 174, in _new_conn
    conn = connection.create_connection(
  File "/var/lib/juju/agents/unit-mysql-2/charm/venv/urllib3/util/connection.py", line 95, in create_connection
    raise err
  File "/var/lib/juju/agents/unit-mysql-2/charm/venv/urllib3/util/connection.py", line 85, in create_connection
    sock.connect(sa)
ConnectionRefusedError: [Errno 111] Connection refused

During handling of the above exception, another exception occurred:

Traceback (most recent call last):
  File "/var/lib/juju/agents/unit-mysql-2/charm/venv/urllib3/connectionpool.py", line 715, in urlopen
    httplib_response = self._make_request(
  File "/var/lib/juju/agents/unit-mysql-2/charm/venv/urllib3/connectionpool.py", line 416, in _make_request
    conn.request(method, url, **httplib_request_kw)
  File "/var/lib/juju/agents/unit-mysql-2/charm/venv/urllib3/connection.py", line 244, in request
    super(HTTPConnection, self).request(method, url, body=body, headers=headers)
  File "/usr/lib/python3.10/http/client.py", line 1283, in request
    self._send_request(method, url, body, headers, encode_chunked)
  File "/usr/lib/python3.10/http/client.py", line 1329, in _send_request
    self.endheaders(body, encode_chunked=encode_chunked)
  File "/usr/lib/python3.10/http/client.py", line 1278, in endheaders
    self._send_output(message_body, encode_chunked=encode_chunked)
  File "/usr/lib/python3.10/http/client.py", line 1038, in _send_output
    self.send(msg)
  File "/usr/lib/python3.10/http/client.py", line 976, in send
    self.connect()
  File "/var/lib/juju/agents/unit-mysql-2/charm/venv/urllib3/connection.py", line 205, in connect
    conn = self._new_conn()
  File "/var/lib/juju/agents/unit-mysql-2/charm/venv/urllib3/connection.py", line 186, in _new_conn
    raise NewConnectionError(
urllib3.exceptions.NewConnectionError: <urllib3.connection.HTTPConnection object at 0x7f047c5ae410>: Failed to establish a new connection: [Errno 111] Connection refused

During handling of the above exception, another exception occurred:

Traceback (most recent call last):
  File "/var/lib/juju/agents/unit-mysql-2/charm/venv/requests/adapters.py", line 486, in send
    resp = conn.urlopen(
  File "/var/lib/juju/agents/unit-mysql-2/charm/venv/urllib3/connectionpool.py", line 801, in urlopen
    retries = retries.increment(
  File "/var/lib/juju/agents/unit-mysql-2/charm/venv/urllib3/util/retry.py", line 594, in increment
    raise MaxRetryError(_pool, url, error or ResponseError(cause))
urllib3.exceptions.MaxRetryError: HTTPConnectionPool(host='juju-d6d1fd-4.lxd', port=4318): Max retries exceeded with url: /v1/traces (Caused by NewConnectionError('<urllib3.connection.HTTPConnection object at 0x7f047c5ae410>: Failed to establish a new connection: [Errno 111] Connection refused'))

During handling of the above exception, another exception occurred:

Traceback (most recent call last):
  File "/var/lib/juju/agents/unit-mysql-2/charm/venv/opentelemetry/sdk/trace/export/__init__.py", line 368, in _export_batch
    self.span_exporter.export(self.spans_list[:idx])  # type: ignore
  File "/var/lib/juju/agents/unit-mysql-2/charm/venv/opentelemetry/exporter/otlp/proto/http/trace_exporter/__init__.py", line 145, in export
    resp = self._export(serialized_data)
  File "/var/lib/juju/agents/unit-mysql-2/charm/venv/opentelemetry/exporter/otlp/proto/http/trace_exporter/__init__.py", line 114, in _export
    return self._session.post(
  File "/var/lib/juju/agents/unit-mysql-2/charm/venv/requests/sessions.py", line 637, in post
    return self.request("POST", url, data=data, json=json, **kwargs)
  File "/var/lib/juju/agents/unit-mysql-2/charm/venv/requests/sessions.py", line 589, in request
    resp = self.send(prep, **send_kwargs)
  File "/var/lib/juju/agents/unit-mysql-2/charm/venv/requests/sessions.py", line 703, in send
    r = adapter.send(request, **kwargs)
  File "/var/lib/juju/agents/unit-mysql-2/charm/venv/requests/adapters.py", line 519, in send
    raise ConnectionError(e, request=request)
requests.exceptions.ConnectionError: HTTPConnectionPool(host='juju-d6d1fd-4.lxd', port=4318): Max retries exceeded with url: /v1/traces (Caused by NewConnectionError('<urllib3.connection.HTTPConnection object at 0x7f047c5ae410>: Failed to establish a new connection: [Errno 111] Connection refused'))
unit-mysql-1: 01:36:04 ERROR unit.mysql/1.juju-log restart:2: Exception while exporting Span batch.
Traceback (most recent call last):
  File "/var/lib/juju/agents/unit-mysql-1/charm/venv/urllib3/connection.py", line 174, in _new_conn
    conn = connection.create_connection(
  File "/var/lib/juju/agents/unit-mysql-1/charm/venv/urllib3/util/connection.py", line 95, in create_connection
    raise err
  File "/var/lib/juju/agents/unit-mysql-1/charm/venv/urllib3/util/connection.py", line 85, in create_connection
    sock.connect(sa)
ConnectionRefusedError: [Errno 111] Connection refused

During handling of the above exception, another exception occurred:

Traceback (most recent call last):
  File "/var/lib/juju/agents/unit-mysql-1/charm/venv/urllib3/connectionpool.py", line 715, in urlopen
    httplib_response = self._make_request(
  File "/var/lib/juju/agents/unit-mysql-1/charm/venv/urllib3/connectionpool.py", line 416, in _make_request
    conn.request(method, url, **httplib_request_kw)
  File "/var/lib/juju/agents/unit-mysql-1/charm/venv/urllib3/connection.py", line 244, in request
    super(HTTPConnection, self).request(method, url, body=body, headers=headers)
  File "/usr/lib/python3.10/http/client.py", line 1283, in request
    self._send_request(method, url, body, headers, encode_chunked)
  File "/usr/lib/python3.10/http/client.py", line 1329, in _send_request
    self.endheaders(body, encode_chunked=encode_chunked)
  File "/usr/lib/python3.10/http/client.py", line 1278, in endheaders
    self._send_output(message_body, encode_chunked=encode_chunked)
  File "/usr/lib/python3.10/http/client.py", line 1038, in _send_output
    self.send(msg)
  File "/usr/lib/python3.10/http/client.py", line 976, in send
    self.connect()
  File "/var/lib/juju/agents/unit-mysql-1/charm/venv/urllib3/connection.py", line 205, in connect
    conn = self._new_conn()
  File "/var/lib/juju/agents/unit-mysql-1/charm/venv/urllib3/connection.py", line 186, in _new_conn
    raise NewConnectionError(
urllib3.exceptions.NewConnectionError: <urllib3.connection.HTTPConnection object at 0x7f96f7daa410>: Failed to establish a new connection: [Errno 111] Connection refused

During handling of the above exception, another exception occurred:

Traceback (most recent call last):
  File "/var/lib/juju/agents/unit-mysql-1/charm/venv/requests/adapters.py", line 486, in send
    resp = conn.urlopen(
  File "/var/lib/juju/agents/unit-mysql-1/charm/venv/urllib3/connectionpool.py", line 801, in urlopen
    retries = retries.increment(
  File "/var/lib/juju/agents/unit-mysql-1/charm/venv/urllib3/util/retry.py", line 594, in increment
    raise MaxRetryError(_pool, url, error or ResponseError(cause))
urllib3.exceptions.MaxRetryError: HTTPConnectionPool(host='juju-d6d1fd-3.lxd', port=4318): Max retries exceeded with url: /v1/traces (Caused by NewConnectionError('<urllib3.connection.HTTPConnection object at 0x7f96f7daa410>: Failed to establish a new connection: [Errno 111] Connection refused'))

During handling of the above exception, another exception occurred:

Traceback (most recent call last):
  File "/var/lib/juju/agents/unit-mysql-1/charm/venv/opentelemetry/sdk/trace/export/__init__.py", line 368, in _export_batch
    self.span_exporter.export(self.spans_list[:idx])  # type: ignore
  File "/var/lib/juju/agents/unit-mysql-1/charm/venv/opentelemetry/exporter/otlp/proto/http/trace_exporter/__init__.py", line 145, in export
    resp = self._export(serialized_data)
  File "/var/lib/juju/agents/unit-mysql-1/charm/venv/opentelemetry/exporter/otlp/proto/http/trace_exporter/__init__.py", line 114, in _export
    return self._session.post(
  File "/var/lib/juju/agents/unit-mysql-1/charm/venv/requests/sessions.py", line 637, in post
    return self.request("POST", url, data=data, json=json, **kwargs)
  File "/var/lib/juju/agents/unit-mysql-1/charm/venv/requests/sessions.py", line 589, in request
    resp = self.send(prep, **send_kwargs)
  File "/var/lib/juju/agents/unit-mysql-1/charm/venv/requests/sessions.py", line 703, in send
    r = adapter.send(request, **kwargs)
  File "/var/lib/juju/agents/unit-mysql-1/charm/venv/requests/adapters.py", line 519, in send
    raise ConnectionError(e, request=request)
requests.exceptions.ConnectionError: HTTPConnectionPool(host='juju-d6d1fd-3.lxd', port=4318): Max retries exceeded with url: /v1/traces (Caused by NewConnectionError('<urllib3.connection.HTTPConnection object at 0x7f96f7daa410>: Failed to establish a new connection: [Errno 111] Connection refused'))
unit-mysql-2: 01:36:07 ERROR unit.mysql/2.juju-log database:17: Exception while exporting Span batch.
Traceback (most recent call last):
  File "/var/lib/juju/agents/unit-mysql-2/charm/venv/urllib3/connection.py", line 174, in _new_conn
    conn = connection.create_connection(
  File "/var/lib/juju/agents/unit-mysql-2/charm/venv/urllib3/util/connection.py", line 95, in create_connection
    raise err
  File "/var/lib/juju/agents/unit-mysql-2/charm/venv/urllib3/util/connection.py", line 85, in create_connection
    sock.connect(sa)
ConnectionRefusedError: [Errno 111] Connection refused

During handling of the above exception, another exception occurred:

Traceback (most recent call last):
  File "/var/lib/juju/agents/unit-mysql-2/charm/venv/urllib3/connectionpool.py", line 715, in urlopen
    httplib_response = self._make_request(
  File "/var/lib/juju/agents/unit-mysql-2/charm/venv/urllib3/connectionpool.py", line 416, in _make_request
    conn.request(method, url, **httplib_request_kw)
  File "/var/lib/juju/agents/unit-mysql-2/charm/venv/urllib3/connection.py", line 244, in request
    super(HTTPConnection, self).request(method, url, body=body, headers=headers)
  File "/usr/lib/python3.10/http/client.py", line 1283, in request
    self._send_request(method, url, body, headers, encode_chunked)
  File "/usr/lib/python3.10/http/client.py", line 1329, in _send_request
    self.endheaders(body, encode_chunked=encode_chunked)
  File "/usr/lib/python3.10/http/client.py", line 1278, in endheaders
    self._send_output(message_body, encode_chunked=encode_chunked)
  File "/usr/lib/python3.10/http/client.py", line 1038, in _send_output
    self.send(msg)
  File "/usr/lib/python3.10/http/client.py", line 976, in send
    self.connect()
  File "/var/lib/juju/agents/unit-mysql-2/charm/venv/urllib3/connection.py", line 205, in connect
    conn = self._new_conn()
  File "/var/lib/juju/agents/unit-mysql-2/charm/venv/urllib3/connection.py", line 186, in _new_conn
    raise NewConnectionError(
urllib3.exceptions.NewConnectionError: <urllib3.connection.HTTPConnection object at 0x7fa6249e2650>: Failed to establish a new connection: [Errno 111] Connection refused

During handling of the above exception, another exception occurred:

Traceback (most recent call last):
  File "/var/lib/juju/agents/unit-mysql-2/charm/venv/requests/adapters.py", line 486, in send
    resp = conn.urlopen(
  File "/var/lib/juju/agents/unit-mysql-2/charm/venv/urllib3/connectionpool.py", line 801, in urlopen
    retries = retries.increment(
  File "/var/lib/juju/agents/unit-mysql-2/charm/venv/urllib3/util/retry.py", line 594, in increment
    raise MaxRetryError(_pool, url, error or ResponseError(cause))
urllib3.exceptions.MaxRetryError: HTTPConnectionPool(host='juju-d6d1fd-4.lxd', port=4318): Max retries exceeded with url: /v1/traces (Caused by NewConnectionError('<urllib3.connection.HTTPConnection object at 0x7fa6249e2650>: Failed to establish a new connection: [Errno 111] Connection refused'))

During handling of the above exception, another exception occurred:

Traceback (most recent call last):
  File "/var/lib/juju/agents/unit-mysql-2/charm/venv/opentelemetry/sdk/trace/export/__init__.py", line 368, in _export_batch
    self.span_exporter.export(self.spans_list[:idx])  # type: ignore
  File "/var/lib/juju/agents/unit-mysql-2/charm/venv/opentelemetry/exporter/otlp/proto/http/trace_exporter/__init__.py", line 145, in export
    resp = self._export(serialized_data)
  File "/var/lib/juju/agents/unit-mysql-2/charm/venv/opentelemetry/exporter/otlp/proto/http/trace_exporter/__init__.py", line 114, in _export
    return self._session.post(
  File "/var/lib/juju/agents/unit-mysql-2/charm/venv/requests/sessions.py", line 637, in post
    return self.request("POST", url, data=data, json=json, **kwargs)
  File "/var/lib/juju/agents/unit-mysql-2/charm/venv/requests/sessions.py", line 589, in request
    resp = self.send(prep, **send_kwargs)
  File "/var/lib/juju/agents/unit-mysql-2/charm/venv/requests/sessions.py", line 703, in send
    r = adapter.send(request, **kwargs)
  File "/var/lib/juju/agents/unit-mysql-2/charm/venv/requests/adapters.py", line 519, in send
    raise ConnectionError(e, request=request)
requests.exceptions.ConnectionError: HTTPConnectionPool(host='juju-d6d1fd-4.lxd', port=4318): Max retries exceeded with url: /v1/traces (Caused by NewConnectionError('<urllib3.connection.HTTPConnection object at 0x7fa6249e2650>: Failed to establish a new connection: [Errno 111] Connection refused'))
unit-mysql-1: 01:36:09 ERROR unit.mysql/1.juju-log database:18: Exception while exporting Span batch.
Traceback (most recent call last):
  File "/var/lib/juju/agents/unit-mysql-1/charm/venv/urllib3/connection.py", line 174, in _new_conn
    conn = connection.create_connection(
  File "/var/lib/juju/agents/unit-mysql-1/charm/venv/urllib3/util/connection.py", line 95, in create_connection
    raise err
  File "/var/lib/juju/agents/unit-mysql-1/charm/venv/urllib3/util/connection.py", line 85, in create_connection
    sock.connect(sa)
ConnectionRefusedError: [Errno 111] Connection refused

During handling of the above exception, another exception occurred:

Traceback (most recent call last):
  File "/var/lib/juju/agents/unit-mysql-1/charm/venv/urllib3/connectionpool.py", line 715, in urlopen
    httplib_response = self._make_request(
  File "/var/lib/juju/agents/unit-mysql-1/charm/venv/urllib3/connectionpool.py", line 416, in _make_request
    conn.request(method, url, **httplib_request_kw)
  File "/var/lib/juju/agents/unit-mysql-1/charm/venv/urllib3/connection.py", line 244, in request
    super(HTTPConnection, self).request(method, url, body=body, headers=headers)
  File "/usr/lib/python3.10/http/client.py", line 1283, in request
    self._send_request(method, url, body, headers, encode_chunked)
  File "/usr/lib/python3.10/http/client.py", line 1329, in _send_request
    self.endheaders(body, encode_chunked=encode_chunked)
  File "/usr/lib/python3.10/http/client.py", line 1278, in endheaders
    self._send_output(message_body, encode_chunked=encode_chunked)
  File "/usr/lib/python3.10/http/client.py", line 1038, in _send_output
    self.send(msg)
  File "/usr/lib/python3.10/http/client.py", line 976, in send
    self.connect()
  File "/var/lib/juju/agents/unit-mysql-1/charm/venv/urllib3/connection.py", line 205, in connect
    conn = self._new_conn()
  File "/var/lib/juju/agents/unit-mysql-1/charm/venv/urllib3/connection.py", line 186, in _new_conn
    raise NewConnectionError(
urllib3.exceptions.NewConnectionError: <urllib3.connection.HTTPConnection object at 0x7f57562a26e0>: Failed to establish a new connection: [Errno 111] Connection refused

During handling of the above exception, another exception occurred:

Traceback (most recent call last):
  File "/var/lib/juju/agents/unit-mysql-1/charm/venv/requests/adapters.py", line 486, in send
    resp = conn.urlopen(
  File "/var/lib/juju/agents/unit-mysql-1/charm/venv/urllib3/connectionpool.py", line 801, in urlopen
    retries = retries.increment(
  File "/var/lib/juju/agents/unit-mysql-1/charm/venv/urllib3/util/retry.py", line 594, in increment
    raise MaxRetryError(_pool, url, error or ResponseError(cause))
urllib3.exceptions.MaxRetryError: HTTPConnectionPool(host='juju-d6d1fd-3.lxd', port=4318): Max retries exceeded with url: /v1/traces (Caused by NewConnectionError('<urllib3.connection.HTTPConnection object at 0x7f57562a26e0>: Failed to establish a new connection: [Errno 111] Connection refused'))

During handling of the above exception, another exception occurred:

Traceback (most recent call last):
  File "/var/lib/juju/agents/unit-mysql-1/charm/venv/opentelemetry/sdk/trace/export/__init__.py", line 368, in _export_batch
    self.span_exporter.export(self.spans_list[:idx])  # type: ignore
  File "/var/lib/juju/agents/unit-mysql-1/charm/venv/opentelemetry/exporter/otlp/proto/http/trace_exporter/__init__.py", line 145, in export
    resp = self._export(serialized_data)
  File "/var/lib/juju/agents/unit-mysql-1/charm/venv/opentelemetry/exporter/otlp/proto/http/trace_exporter/__init__.py", line 114, in _export
    return self._session.post(
  File "/var/lib/juju/agents/unit-mysql-1/charm/venv/requests/sessions.py", line 637, in post
    return self.request("POST", url, data=data, json=json, **kwargs)
  File "/var/lib/juju/agents/unit-mysql-1/charm/venv/requests/sessions.py", line 589, in request
    resp = self.send(prep, **send_kwargs)
  File "/var/lib/juju/agents/unit-mysql-1/charm/venv/requests/sessions.py", line 703, in send
    r = adapter.send(request, **kwargs)
  File "/var/lib/juju/agents/unit-mysql-1/charm/venv/requests/adapters.py", line 519, in send
    raise ConnectionError(e, request=request)
requests.exceptions.ConnectionError: HTTPConnectionPool(host='juju-d6d1fd-3.lxd', port=4318): Max retries exceeded with url: /v1/traces (Caused by NewConnectionError('<urllib3.connection.HTTPConnection object at 0x7f57562a26e0>: Failed to establish a new connection: [Errno 111] Connection refused'))
unit-mysql-2: 01:36:12 ERROR unit.mysql/2.juju-log database:13: Exception while exporting Span batch.
Traceback (most recent call last):
  File "/var/lib/juju/agents/unit-mysql-2/charm/venv/urllib3/connection.py", line 174, in _new_conn
    conn = connection.create_connection(
  File "/var/lib/juju/agents/unit-mysql-2/charm/venv/urllib3/util/connection.py", line 95, in create_connection
    raise err
  File "/var/lib/juju/agents/unit-mysql-2/charm/venv/urllib3/util/connection.py", line 85, in create_connection
    sock.connect(sa)
ConnectionRefusedError: [Errno 111] Connection refused

During handling of the above exception, another exception occurred:

Traceback (most recent call last):
  File "/var/lib/juju/agents/unit-mysql-2/charm/venv/urllib3/connectionpool.py", line 715, in urlopen
    httplib_response = self._make_request(
  File "/var/lib/juju/agents/unit-mysql-2/charm/venv/urllib3/connectionpool.py", line 416, in _make_request
    conn.request(method, url, **httplib_request_kw)
  File "/var/lib/juju/agents/unit-mysql-2/charm/venv/urllib3/connection.py", line 244, in request
    super(HTTPConnection, self).request(method, url, body=body, headers=headers)
  File "/usr/lib/python3.10/http/client.py", line 1283, in request
    self._send_request(method, url, body, headers, encode_chunked)
  File "/usr/lib/python3.10/http/client.py", line 1329, in _send_request
    self.endheaders(body, encode_chunked=encode_chunked)
  File "/usr/lib/python3.10/http/client.py", line 1278, in endheaders
    self._send_output(message_body, encode_chunked=encode_chunked)
  File "/usr/lib/python3.10/http/client.py", line 1038, in _send_output
    self.send(msg)
  File "/usr/lib/python3.10/http/client.py", line 976, in send
    self.connect()
  File "/var/lib/juju/agents/unit-mysql-2/charm/venv/urllib3/connection.py", line 205, in connect
    conn = self._new_conn()
  File "/var/lib/juju/agents/unit-mysql-2/charm/venv/urllib3/connection.py", line 186, in _new_conn
    raise NewConnectionError(
urllib3.exceptions.NewConnectionError: <urllib3.connection.HTTPConnection object at 0x7f139e26a620>: Failed to establish a new connection: [Errno 111] Connection refused

During handling of the above exception, another exception occurred:

Traceback (most recent call last):
  File "/var/lib/juju/agents/unit-mysql-2/charm/venv/requests/adapters.py", line 486, in send
    resp = conn.urlopen(
  File "/var/lib/juju/agents/unit-mysql-2/charm/venv/urllib3/connectionpool.py", line 801, in urlopen
    retries = retries.increment(
  File "/var/lib/juju/agents/unit-mysql-2/charm/venv/urllib3/util/retry.py", line 594, in increment
    raise MaxRetryError(_pool, url, error or ResponseError(cause))
urllib3.exceptions.MaxRetryError: HTTPConnectionPool(host='juju-d6d1fd-4.lxd', port=4318): Max retries exceeded with url: /v1/traces (Caused by NewConnectionError('<urllib3.connection.HTTPConnection object at 0x7f139e26a620>: Failed to establish a new connection: [Errno 111] Connection refused'))

During handling of the above exception, another exception occurred:

Traceback (most recent call last):
  File "/var/lib/juju/agents/unit-mysql-2/charm/venv/opentelemetry/sdk/trace/export/__init__.py", line 368, in _export_batch
    self.span_exporter.export(self.spans_list[:idx])  # type: ignore
  File "/var/lib/juju/agents/unit-mysql-2/charm/venv/opentelemetry/exporter/otlp/proto/http/trace_exporter/__init__.py", line 145, in export
    resp = self._export(serialized_data)
  File "/var/lib/juju/agents/unit-mysql-2/charm/venv/opentelemetry/exporter/otlp/proto/http/trace_exporter/__init__.py", line 114, in _export
    return self._session.post(
  File "/var/lib/juju/agents/unit-mysql-2/charm/venv/requests/sessions.py", line 637, in post
    return self.request("POST", url, data=data, json=json, **kwargs)
  File "/var/lib/juju/agents/unit-mysql-2/charm/venv/requests/sessions.py", line 589, in request
    resp = self.send(prep, **send_kwargs)
  File "/var/lib/juju/agents/unit-mysql-2/charm/venv/requests/sessions.py", line 703, in send
    r = adapter.send(request, **kwargs)
  File "/var/lib/juju/agents/unit-mysql-2/charm/venv/requests/adapters.py", line 519, in send
    raise ConnectionError(e, request=request)
requests.exceptions.ConnectionError: HTTPConnectionPool(host='juju-d6d1fd-4.lxd', port=4318): Max retries exceeded with url: /v1/traces (Caused by NewConnectionError('<urllib3.connection.HTTPConnection object at 0x7f139e26a620>: Failed to establish a new connection: [Errno 111] Connection refused'))
unit-mysql-1: 01:36:18 ERROR unit.mysql/1.juju-log database-peers:1: Exception while exporting Span batch.
Traceback (most recent call last):
  File "/var/lib/juju/agents/unit-mysql-1/charm/venv/urllib3/connection.py", line 174, in _new_conn
    conn = connection.create_connection(
  File "/var/lib/juju/agents/unit-mysql-1/charm/venv/urllib3/util/connection.py", line 95, in create_connection
    raise err
  File "/var/lib/juju/agents/unit-mysql-1/charm/venv/urllib3/util/connection.py", line 85, in create_connection
    sock.connect(sa)
ConnectionRefusedError: [Errno 111] Connection refused

During handling of the above exception, another exception occurred:

Traceback (most recent call last):
  File "/var/lib/juju/agents/unit-mysql-1/charm/venv/urllib3/connectionpool.py", line 715, in urlopen
    httplib_response = self._make_request(
  File "/var/lib/juju/agents/unit-mysql-1/charm/venv/urllib3/connectionpool.py", line 416, in _make_request
    conn.request(method, url, **httplib_request_kw)
  File "/var/lib/juju/agents/unit-mysql-1/charm/venv/urllib3/connection.py", line 244, in request
    super(HTTPConnection, self).request(method, url, body=body, headers=headers)
  File "/usr/lib/python3.10/http/client.py", line 1283, in request
    self._send_request(method, url, body, headers, encode_chunked)
  File "/usr/lib/python3.10/http/client.py", line 1329, in _send_request
    self.endheaders(body, encode_chunked=encode_chunked)
  File "/usr/lib/python3.10/http/client.py", line 1278, in endheaders
    self._send_output(message_body, encode_chunked=encode_chunked)
  File "/usr/lib/python3.10/http/client.py", line 1038, in _send_output
    self.send(msg)
  File "/usr/lib/python3.10/http/client.py", line 976, in send
    self.connect()
  File "/var/lib/juju/agents/unit-mysql-1/charm/venv/urllib3/connection.py", line 205, in connect
    conn = self._new_conn()
  File "/var/lib/juju/agents/unit-mysql-1/charm/venv/urllib3/connection.py", line 186, in _new_conn
    raise NewConnectionError(
urllib3.exceptions.NewConnectionError: <urllib3.connection.HTTPConnection object at 0x7f7fc88a8760>: Failed to establish a new connection: [Errno 111] Connection refused

During handling of the above exception, another exception occurred:

Traceback (most recent call last):
  File "/var/lib/juju/agents/unit-mysql-1/charm/venv/requests/adapters.py", line 486, in send
    resp = conn.urlopen(
  File "/var/lib/juju/agents/unit-mysql-1/charm/venv/urllib3/connectionpool.py", line 801, in urlopen
    retries = retries.increment(
  File "/var/lib/juju/agents/unit-mysql-1/charm/venv/urllib3/util/retry.py", line 594, in increment
    raise MaxRetryError(_pool, url, error or ResponseError(cause))
urllib3.exceptions.MaxRetryError: HTTPConnectionPool(host='juju-d6d1fd-3.lxd', port=4318): Max retries exceeded with url: /v1/traces (Caused by NewConnectionError('<urllib3.connection.HTTPConnection object at 0x7f7fc88a8760>: Failed to establish a new connection: [Errno 111] Connection refused'))

During handling of the above exception, another exception occurred:

Traceback (most recent call last):
  File "/var/lib/juju/agents/unit-mysql-1/charm/venv/opentelemetry/sdk/trace/export/__init__.py", line 368, in _export_batch
    self.span_exporter.export(self.spans_list[:idx])  # type: ignore
  File "/var/lib/juju/agents/unit-mysql-1/charm/venv/opentelemetry/exporter/otlp/proto/http/trace_exporter/__init__.py", line 145, in export
    resp = self._export(serialized_data)
  File "/var/lib/juju/agents/unit-mysql-1/charm/venv/opentelemetry/exporter/otlp/proto/http/trace_exporter/__init__.py", line 114, in _export
    return self._session.post(
  File "/var/lib/juju/agents/unit-mysql-1/charm/venv/requests/sessions.py", line 637, in post
    return self.request("POST", url, data=data, json=json, **kwargs)
  File "/var/lib/juju/agents/unit-mysql-1/charm/venv/requests/sessions.py", line 589, in request
    resp = self.send(prep, **send_kwargs)
  File "/var/lib/juju/agents/unit-mysql-1/charm/venv/requests/sessions.py", line 703, in send
    r = adapter.send(request, **kwargs)
  File "/var/lib/juju/agents/unit-mysql-1/charm/venv/requests/adapters.py", line 519, in send
    raise ConnectionError(e, request=request)
requests.exceptions.ConnectionError: HTTPConnectionPool(host='juju-d6d1fd-3.lxd', port=4318): Max retries exceeded with url: /v1/traces (Caused by NewConnectionError('<urllib3.connection.HTTPConnection object at 0x7f7fc88a8760>: Failed to establish a new connection: [Errno 111] Connection refused'))
unit-mysql-2: 01:36:19 ERROR unit.mysql/2.juju-log database-peers:1: Exception while exporting Span batch.
Traceback (most recent call last):
  File "/var/lib/juju/agents/unit-mysql-2/charm/venv/urllib3/connection.py", line 174, in _new_conn
    conn = connection.create_connection(
  File "/var/lib/juju/agents/unit-mysql-2/charm/venv/urllib3/util/connection.py", line 95, in create_connection
    raise err
  File "/var/lib/juju/agents/unit-mysql-2/charm/venv/urllib3/util/connection.py", line 85, in create_connection
    sock.connect(sa)
ConnectionRefusedError: [Errno 111] Connection refused

During handling of the above exception, another exception occurred:

Traceback (most recent call last):
  File "/var/lib/juju/agents/unit-mysql-2/charm/venv/urllib3/connectionpool.py", line 715, in urlopen
    httplib_response = self._make_request(
  File "/var/lib/juju/agents/unit-mysql-2/charm/venv/urllib3/connectionpool.py", line 416, in _make_request
    conn.request(method, url, **httplib_request_kw)
  File "/var/lib/juju/agents/unit-mysql-2/charm/venv/urllib3/connection.py", line 244, in request
    super(HTTPConnection, self).request(method, url, body=body, headers=headers)
  File "/usr/lib/python3.10/http/client.py", line 1283, in request
    self._send_request(method, url, body, headers, encode_chunked)
  File "/usr/lib/python3.10/http/client.py", line 1329, in _send_request
    self.endheaders(body, encode_chunked=encode_chunked)
  File "/usr/lib/python3.10/http/client.py", line 1278, in endheaders
    self._send_output(message_body, encode_chunked=encode_chunked)
  File "/usr/lib/python3.10/http/client.py", line 1038, in _send_output
    self.send(msg)
  File "/usr/lib/python3.10/http/client.py", line 976, in send
    self.connect()
  File "/var/lib/juju/agents/unit-mysql-2/charm/venv/urllib3/connection.py", line 205, in connect
    conn = self._new_conn()
  File "/var/lib/juju/agents/unit-mysql-2/charm/venv/urllib3/connection.py", line 186, in _new_conn
    raise NewConnectionError(
urllib3.exceptions.NewConnectionError: <urllib3.connection.HTTPConnection object at 0x7f2d3e0f0670>: Failed to establish a new connection: [Errno 111] Connection refused

During handling of the above exception, another exception occurred:

Traceback (most recent call last):
  File "/var/lib/juju/agents/unit-mysql-2/charm/venv/requests/adapters.py", line 486, in send
    resp = conn.urlopen(
  File "/var/lib/juju/agents/unit-mysql-2/charm/venv/urllib3/connectionpool.py", line 801, in urlopen
    retries = retries.increment(
  File "/var/lib/juju/agents/unit-mysql-2/charm/venv/urllib3/util/retry.py", line 594, in increment
    raise MaxRetryError(_pool, url, error or ResponseError(cause))
urllib3.exceptions.MaxRetryError: HTTPConnectionPool(host='juju-d6d1fd-4.lxd', port=4318): Max retries exceeded with url: /v1/traces (Caused by NewConnectionError('<urllib3.connection.HTTPConnection object at 0x7f2d3e0f0670>: Failed to establish a new connection: [Errno 111] Connection refused'))

During handling of the above exception, another exception occurred:

Traceback (most recent call last):
  File "/var/lib/juju/agents/unit-mysql-2/charm/venv/opentelemetry/sdk/trace/export/__init__.py", line 368, in _export_batch
    self.span_exporter.export(self.spans_list[:idx])  # type: ignore
  File "/var/lib/juju/agents/unit-mysql-2/charm/venv/opentelemetry/exporter/otlp/proto/http/trace_exporter/__init__.py", line 145, in export
    resp = self._export(serialized_data)
  File "/var/lib/juju/agents/unit-mysql-2/charm/venv/opentelemetry/exporter/otlp/proto/http/trace_exporter/__init__.py", line 114, in _export
    return self._session.post(
  File "/var/lib/juju/agents/unit-mysql-2/charm/venv/requests/sessions.py", line 637, in post
    return self.request("POST", url, data=data, json=json, **kwargs)
  File "/var/lib/juju/agents/unit-mysql-2/charm/venv/requests/sessions.py", line 589, in request
    resp = self.send(prep, **send_kwargs)
  File "/var/lib/juju/agents/unit-mysql-2/charm/venv/requests/sessions.py", line 703, in send
    r = adapter.send(request, **kwargs)
  File "/var/lib/juju/agents/unit-mysql-2/charm/venv/requests/adapters.py", line 519, in send
    raise ConnectionError(e, request=request)
requests.exceptions.ConnectionError: HTTPConnectionPool(host='juju-d6d1fd-4.lxd', port=4318): Max retries exceeded with url: /v1/traces (Caused by NewConnectionError('<urllib3.connection.HTTPConnection object at 0x7f2d3e0f0670>: Failed to establish a new connection: [Errno 111] Connection refused'))
unit-mysql-2: 01:36:22 ERROR unit.mysql/2.juju-log upgrade:3: Exception while exporting Span batch.
Traceback (most recent call last):
  File "/var/lib/juju/agents/unit-mysql-2/charm/venv/urllib3/connection.py", line 174, in _new_conn
    conn = connection.create_connection(
  File "/var/lib/juju/agents/unit-mysql-2/charm/venv/urllib3/util/connection.py", line 95, in create_connection
    raise err
  File "/var/lib/juju/agents/unit-mysql-2/charm/venv/urllib3/util/connection.py", line 85, in create_connection
    sock.connect(sa)
ConnectionRefusedError: [Errno 111] Connection refused

During handling of the above exception, another exception occurred:

Traceback (most recent call last):
  File "/var/lib/juju/agents/unit-mysql-2/charm/venv/urllib3/connectionpool.py", line 715, in urlopen
    httplib_response = self._make_request(
  File "/var/lib/juju/agents/unit-mysql-2/charm/venv/urllib3/connectionpool.py", line 416, in _make_request
    conn.request(method, url, **httplib_request_kw)
  File "/var/lib/juju/agents/unit-mysql-2/charm/venv/urllib3/connection.py", line 244, in request
    super(HTTPConnection, self).request(method, url, body=body, headers=headers)
  File "/usr/lib/python3.10/http/client.py", line 1283, in request
    self._send_request(method, url, body, headers, encode_chunked)
  File "/usr/lib/python3.10/http/client.py", line 1329, in _send_request
    self.endheaders(body, encode_chunked=encode_chunked)
  File "/usr/lib/python3.10/http/client.py", line 1278, in endheaders
    self._send_output(message_body, encode_chunked=encode_chunked)
  File "/usr/lib/python3.10/http/client.py", line 1038, in _send_output
    self.send(msg)
  File "/usr/lib/python3.10/http/client.py", line 976, in send
    self.connect()
  File "/var/lib/juju/agents/unit-mysql-2/charm/venv/urllib3/connection.py", line 205, in connect
    conn = self._new_conn()
  File "/var/lib/juju/agents/unit-mysql-2/charm/venv/urllib3/connection.py", line 186, in _new_conn
    raise NewConnectionError(
urllib3.exceptions.NewConnectionError: <urllib3.connection.HTTPConnection object at 0x7ff0fe7ddfc0>: Failed to establish a new connection: [Errno 111] Connection refused

During handling of the above exception, another exception occurred:

Traceback (most recent call last):
  File "/var/lib/juju/agents/unit-mysql-2/charm/venv/requests/adapters.py", line 486, in send
    resp = conn.urlopen(
  File "/var/lib/juju/agents/unit-mysql-2/charm/venv/urllib3/connectionpool.py", line 801, in urlopen
    retries = retries.increment(
  File "/var/lib/juju/agents/unit-mysql-2/charm/venv/urllib3/util/retry.py", line 594, in increment
    raise MaxRetryError(_pool, url, error or ResponseError(cause))
urllib3.exceptions.MaxRetryError: HTTPConnectionPool(host='juju-d6d1fd-4.lxd', port=4318): Max retries exceeded with url: /v1/traces (Caused by NewConnectionError('<urllib3.connection.HTTPConnection object at 0x7ff0fe7ddfc0>: Failed to establish a new connection: [Errno 111] Connection refused'))

During handling of the above exception, another exception occurred:

Traceback (most recent call last):
  File "/var/lib/juju/agents/unit-mysql-2/charm/venv/opentelemetry/sdk/trace/export/__init__.py", line 368, in _export_batch
    self.span_exporter.export(self.spans_list[:idx])  # type: ignore
  File "/var/lib/juju/agents/unit-mysql-2/charm/venv/opentelemetry/exporter/otlp/proto/http/trace_exporter/__init__.py", line 145, in export
    resp = self._export(serialized_data)
  File "/var/lib/juju/agents/unit-mysql-2/charm/venv/opentelemetry/exporter/otlp/proto/http/trace_exporter/__init__.py", line 114, in _export
    return self._session.post(
  File "/var/lib/juju/agents/unit-mysql-2/charm/venv/requests/sessions.py", line 637, in post
    return self.request("POST", url, data=data, json=json, **kwargs)
  File "/var/lib/juju/agents/unit-mysql-2/charm/venv/requests/sessions.py", line 589, in request
    resp = self.send(prep, **send_kwargs)
  File "/var/lib/juju/agents/unit-mysql-2/charm/venv/requests/sessions.py", line 703, in send
    r = adapter.send(request, **kwargs)
  File "/var/lib/juju/agents/unit-mysql-2/charm/venv/requests/adapters.py", line 519, in send
    raise ConnectionError(e, request=request)
requests.exceptions.ConnectionError: HTTPConnectionPool(host='juju-d6d1fd-4.lxd', port=4318): Max retries exceeded with url: /v1/traces (Caused by NewConnectionError('<urllib3.connection.HTTPConnection object at 0x7ff0fe7ddfc0>: Failed to establish a new connection: [Errno 111] Connection refused'))
unit-mysql-1: 01:36:23 ERROR unit.mysql/1.juju-log database-peers:1: Exception while exporting Span batch.
Traceback (most recent call last):
  File "/var/lib/juju/agents/unit-mysql-1/charm/venv/urllib3/connection.py", line 174, in _new_conn
    conn = connection.create_connection(
  File "/var/lib/juju/agents/unit-mysql-1/charm/venv/urllib3/util/connection.py", line 95, in create_connection
    raise err
  File "/var/lib/juju/agents/unit-mysql-1/charm/venv/urllib3/util/connection.py", line 85, in create_connection
    sock.connect(sa)
ConnectionRefusedError: [Errno 111] Connection refused

During handling of the above exception, another exception occurred:

Traceback (most recent call last):
  File "/var/lib/juju/agents/unit-mysql-1/charm/venv/urllib3/connectionpool.py", line 715, in urlopen
    httplib_response = self._make_request(
  File "/var/lib/juju/agents/unit-mysql-1/charm/venv/urllib3/connectionpool.py", line 416, in _make_request
    conn.request(method, url, **httplib_request_kw)
  File "/var/lib/juju/agents/unit-mysql-1/charm/venv/urllib3/connection.py", line 244, in request
    super(HTTPConnection, self).request(method, url, body=body, headers=headers)
  File "/usr/lib/python3.10/http/client.py", line 1283, in request
    self._send_request(method, url, body, headers, encode_chunked)
  File "/usr/lib/python3.10/http/client.py", line 1329, in _send_request
    self.endheaders(body, encode_chunked=encode_chunked)
  File "/usr/lib/python3.10/http/client.py", line 1278, in endheaders
    self._send_output(message_body, encode_chunked=encode_chunked)
  File "/usr/lib/python3.10/http/client.py", line 1038, in _send_output
    self.send(msg)
  File "/usr/lib/python3.10/http/client.py", line 976, in send
    self.connect()
  File "/var/lib/juju/agents/unit-mysql-1/charm/venv/urllib3/connection.py", line 205, in connect
    conn = self._new_conn()
  File "/var/lib/juju/agents/unit-mysql-1/charm/venv/urllib3/connection.py", line 186, in _new_conn
    raise NewConnectionError(
urllib3.exceptions.NewConnectionError: <urllib3.connection.HTTPConnection object at 0x7f7fc88aa770>: Failed to establish a new connection: [Errno 111] Connection refused

During handling of the above exception, another exception occurred:

Traceback (most recent call last):
  File "/var/lib/juju/agents/unit-mysql-1/charm/venv/requests/adapters.py", line 486, in send
    resp = conn.urlopen(
  File "/var/lib/juju/agents/unit-mysql-1/charm/venv/urllib3/connectionpool.py", line 801, in urlopen
    retries = retries.increment(
  File "/var/lib/juju/agents/unit-mysql-1/charm/venv/urllib3/util/retry.py", line 594, in increment
    raise MaxRetryError(_pool, url, error or ResponseError(cause))
urllib3.exceptions.MaxRetryError: HTTPConnectionPool(host='juju-d6d1fd-3.lxd', port=4318): Max retries exceeded with url: /v1/traces (Caused by NewConnectionError('<urllib3.connection.HTTPConnection object at 0x7f7fc88aa770>: Failed to establish a new connection: [Errno 111] Connection refused'))

During handling of the above exception, another exception occurred:

Traceback (most recent call last):
  File "/var/lib/juju/agents/unit-mysql-1/charm/venv/opentelemetry/sdk/trace/export/__init__.py", line 368, in _export_batch
    self.span_exporter.export(self.spans_list[:idx])  # type: ignore
  File "/var/lib/juju/agents/unit-mysql-1/charm/venv/opentelemetry/exporter/otlp/proto/http/trace_exporter/__init__.py", line 145, in export
    resp = self._export(serialized_data)
  File "/var/lib/juju/agents/unit-mysql-1/charm/venv/opentelemetry/exporter/otlp/proto/http/trace_exporter/__init__.py", line 114, in _export
    return self._session.post(
  File "/var/lib/juju/agents/unit-mysql-1/charm/venv/requests/sessions.py", line 637, in post
    return self.request("POST", url, data=data, json=json, **kwargs)
  File "/var/lib/juju/agents/unit-mysql-1/charm/venv/requests/sessions.py", line 589, in request
    resp = self.send(prep, **send_kwargs)
  File "/var/lib/juju/agents/unit-mysql-1/charm/venv/requests/sessions.py", line 703, in send
    r = adapter.send(request, **kwargs)
  File "/var/lib/juju/agents/unit-mysql-1/charm/venv/requests/adapters.py", line 519, in send
    raise ConnectionError(e, request=request)
requests.exceptions.ConnectionError: HTTPConnectionPool(host='juju-d6d1fd-3.lxd', port=4318): Max retries exceeded with url: /v1/traces (Caused by NewConnectionError('<urllib3.connection.HTTPConnection object at 0x7f7fc88aa770>: Failed to establish a new connection: [Errno 111] Connection refused'))
unit-mysql-2: 01:36:27 ERROR unit.mysql/2.juju-log upgrade:3: Exception while exporting Span batch.
Traceback (most recent call last):
  File "/var/lib/juju/agents/unit-mysql-2/charm/venv/urllib3/connection.py", line 174, in _new_conn
    conn = connection.create_connection(
  File "/var/lib/juju/agents/unit-mysql-2/charm/venv/urllib3/util/connection.py", line 95, in create_connection
    raise err
  File "/var/lib/juju/agents/unit-mysql-2/charm/venv/urllib3/util/connection.py", line 85, in create_connection
    sock.connect(sa)
ConnectionRefusedError: [Errno 111] Connection refused

During handling of the above exception, another exception occurred:

Traceback (most recent call last):
  File "/var/lib/juju/agents/unit-mysql-2/charm/venv/urllib3/connectionpool.py", line 715, in urlopen
    httplib_response = self._make_request(
  File "/var/lib/juju/agents/unit-mysql-2/charm/venv/urllib3/connectionpool.py", line 416, in _make_request
    conn.request(method, url, **httplib_request_kw)
  File "/var/lib/juju/agents/unit-mysql-2/charm/venv/urllib3/connection.py", line 244, in request
    super(HTTPConnection, self).request(method, url, body=body, headers=headers)
  File "/usr/lib/python3.10/http/client.py", line 1283, in request
    self._send_request(method, url, body, headers, encode_chunked)
  File "/usr/lib/python3.10/http/client.py", line 1329, in _send_request
    self.endheaders(body, encode_chunked=encode_chunked)
  File "/usr/lib/python3.10/http/client.py", line 1278, in endheaders
    self._send_output(message_body, encode_chunked=encode_chunked)
  File "/usr/lib/python3.10/http/client.py", line 1038, in _send_output
    self.send(msg)
  File "/usr/lib/python3.10/http/client.py", line 976, in send
    self.connect()
  File "/var/lib/juju/agents/unit-mysql-2/charm/venv/urllib3/connection.py", line 205, in connect
    conn = self._new_conn()
  File "/var/lib/juju/agents/unit-mysql-2/charm/venv/urllib3/connection.py", line 186, in _new_conn
    raise NewConnectionError(
urllib3.exceptions.NewConnectionError: <urllib3.connection.HTTPConnection object at 0x7f5f4ee792a0>: Failed to establish a new connection: [Errno 111] Connection refused

During handling of the above exception, another exception occurred:

Traceback (most recent call last):
  File "/var/lib/juju/agents/unit-mysql-2/charm/venv/requests/adapters.py", line 486, in send
    resp = conn.urlopen(
  File "/var/lib/juju/agents/unit-mysql-2/charm/venv/urllib3/connectionpool.py", line 801, in urlopen
    retries = retries.increment(
  File "/var/lib/juju/agents/unit-mysql-2/charm/venv/urllib3/util/retry.py", line 594, in increment
    raise MaxRetryError(_pool, url, error or ResponseError(cause))
urllib3.exceptions.MaxRetryError: HTTPConnectionPool(host='juju-d6d1fd-4.lxd', port=4318): Max retries exceeded with url: /v1/traces (Caused by NewConnectionError('<urllib3.connection.HTTPConnection object at 0x7f5f4ee792a0>: Failed to establish a new connection: [Errno 111] Connection refused'))

During handling of the above exception, another exception occurred:

Traceback (most recent call last):
  File "/var/lib/juju/agents/unit-mysql-2/charm/venv/opentelemetry/sdk/trace/export/__init__.py", line 368, in _export_batch
    self.span_exporter.export(self.spans_list[:idx])  # type: ignore
  File "/var/lib/juju/agents/unit-mysql-2/charm/venv/opentelemetry/exporter/otlp/proto/http/trace_exporter/__init__.py", line 145, in export
    resp = self._export(serialized_data)
  File "/var/lib/juju/agents/unit-mysql-2/charm/venv/opentelemetry/exporter/otlp/proto/http/trace_exporter/__init__.py", line 114, in _export
    return self._session.post(
  File "/var/lib/juju/agents/unit-mysql-2/charm/venv/requests/sessions.py", line 637, in post
    return self.request("POST", url, data=data, json=json, **kwargs)
  File "/var/lib/juju/agents/unit-mysql-2/charm/venv/requests/sessions.py", line 589, in request
    resp = self.send(prep, **send_kwargs)
  File "/var/lib/juju/agents/unit-mysql-2/charm/venv/requests/sessions.py", line 703, in send
    r = adapter.send(request, **kwargs)
  File "/var/lib/juju/agents/unit-mysql-2/charm/venv/requests/adapters.py", line 519, in send
    raise ConnectionError(e, request=request)
requests.exceptions.ConnectionError: HTTPConnectionPool(host='juju-d6d1fd-4.lxd', port=4318): Max retries exceeded with url: /v1/traces (Caused by NewConnectionError('<urllib3.connection.HTTPConnection object at 0x7f5f4ee792a0>: Failed to establish a new connection: [Errno 111] Connection refused'))
unit-mysql-2: 01:36:31 ERROR unit.mysql/2.juju-log database-peers:1: Exception while exporting Span batch.
Traceback (most recent call last):
  File "/var/lib/juju/agents/unit-mysql-2/charm/venv/urllib3/connection.py", line 174, in _new_conn
    conn = connection.create_connection(
  File "/var/lib/juju/agents/unit-mysql-2/charm/venv/urllib3/util/connection.py", line 95, in create_connection
    raise err
  File "/var/lib/juju/agents/unit-mysql-2/charm/venv/urllib3/util/connection.py", line 85, in create_connection
    sock.connect(sa)
ConnectionRefusedError: [Errno 111] Connection refused

During handling of the above exception, another exception occurred:

Traceback (most recent call last):
  File "/var/lib/juju/agents/unit-mysql-2/charm/venv/urllib3/connectionpool.py", line 715, in urlopen
    httplib_response = self._make_request(
  File "/var/lib/juju/agents/unit-mysql-2/charm/venv/urllib3/connectionpool.py", line 416, in _make_request
    conn.request(method, url, **httplib_request_kw)
  File "/var/lib/juju/agents/unit-mysql-2/charm/venv/urllib3/connection.py", line 244, in request
    super(HTTPConnection, self).request(method, url, body=body, headers=headers)
  File "/usr/lib/python3.10/http/client.py", line 1283, in request
    self._send_request(method, url, body, headers, encode_chunked)
  File "/usr/lib/python3.10/http/client.py", line 1329, in _send_request
    self.endheaders(body, encode_chunked=encode_chunked)
  File "/usr/lib/python3.10/http/client.py", line 1278, in endheaders
    self._send_output(message_body, encode_chunked=encode_chunked)
  File "/usr/lib/python3.10/http/client.py", line 1038, in _send_output
    self.send(msg)
  File "/usr/lib/python3.10/http/client.py", line 976, in send
    self.connect()
  File "/var/lib/juju/agents/unit-mysql-2/charm/venv/urllib3/connection.py", line 205, in connect
    conn = self._new_conn()
  File "/var/lib/juju/agents/unit-mysql-2/charm/venv/urllib3/connection.py", line 186, in _new_conn
    raise NewConnectionError(
urllib3.exceptions.NewConnectionError: <urllib3.connection.HTTPConnection object at 0x7fad39535000>: Failed to establish a new connection: [Errno 111] Connection refused

During handling of the above exception, another exception occurred:

Traceback (most recent call last):
  File "/var/lib/juju/agents/unit-mysql-2/charm/venv/requests/adapters.py", line 486, in send
    resp = conn.urlopen(
  File "/var/lib/juju/agents/unit-mysql-2/charm/venv/urllib3/connectionpool.py", line 801, in urlopen
    retries = retries.increment(
  File "/var/lib/juju/agents/unit-mysql-2/charm/venv/urllib3/util/retry.py", line 594, in increment
    raise MaxRetryError(_pool, url, error or ResponseError(cause))
urllib3.exceptions.MaxRetryError: HTTPConnectionPool(host='juju-d6d1fd-4.lxd', port=4318): Max retries exceeded with url: /v1/traces (Caused by NewConnectionError('<urllib3.connection.HTTPConnection object at 0x7fad39535000>: Failed to establish a new connection: [Errno 111] Connection refused'))

During handling of the above exception, another exception occurred:

Traceback (most recent call last):
  File "/var/lib/juju/agents/unit-mysql-2/charm/venv/opentelemetry/sdk/trace/export/__init__.py", line 368, in _export_batch
    self.span_exporter.export(self.spans_list[:idx])  # type: ignore
  File "/var/lib/juju/agents/unit-mysql-2/charm/venv/opentelemetry/exporter/otlp/proto/http/trace_exporter/__init__.py", line 145, in export
    resp = self._export(serialized_data)
  File "/var/lib/juju/agents/unit-mysql-2/charm/venv/opentelemetry/exporter/otlp/proto/http/trace_exporter/__init__.py", line 114, in _export
    return self._session.post(
  File "/var/lib/juju/agents/unit-mysql-2/charm/venv/requests/sessions.py", line 637, in post
    return self.request("POST", url, data=data, json=json, **kwargs)
  File "/var/lib/juju/agents/unit-mysql-2/charm/venv/requests/sessions.py", line 589, in request
    resp = self.send(prep, **send_kwargs)
  File "/var/lib/juju/agents/unit-mysql-2/charm/venv/requests/sessions.py", line 703, in send
    r = adapter.send(request, **kwargs)
  File "/var/lib/juju/agents/unit-mysql-2/charm/venv/requests/adapters.py", line 519, in send
    raise ConnectionError(e, request=request)
requests.exceptions.ConnectionError: HTTPConnectionPool(host='juju-d6d1fd-4.lxd', port=4318): Max retries exceeded with url: /v1/traces (Caused by NewConnectionError('<urllib3.connection.HTTPConnection object at 0x7fad39535000>: Failed to establish a new connection: [Errno 111] Connection refused'))

[32mINFO    [0m pytest_operator.plugin:plugin.py:991 Forgetting model main...