[32mINFO    [0m pytest_operator.plugin:plugin.py:766 Connecting to existing model localhost-localhost:test on unspecified cloud
[32mINFO    [0m integration.test_smoke:test_smoke.py:67 Deploying bundle
[32mINFO    [0m juju.bundle:bundle.py:416 Applying change: upload charm data-integrator for series jammy from channel latest/edge
[32mINFO    [0m juju.bundle:bundle.py:416 Applying change: upload charm mysql-router for series jammy from channel dpe/edge
[32mINFO    [0m juju.bundle:bundle.py:416 Applying change: upload charm mysql-test-app for series jammy from channel latest/edge
[32mINFO    [0m juju.bundle:bundle.py:416 Applying change: upload charm s3-integrator for series jammy from channel latest/edge
[32mINFO    [0m juju.bundle:bundle.py:416 Applying change: upload charm self-signed-certificates for series jammy from channel latest/edge
[32mINFO    [0m juju.bundle:bundle.py:416 Applying change: upload charm sysbench for series jammy from channel latest/edge
[32mINFO    [0m juju.bundle:bundle.py:416 Applying change: upload charm ubuntu-advantage for series jammy from channel latest/edge
[32mINFO    [0m juju.bundle:bundle.py:416 Applying change: upload charm grafana-agent for series jammy from channel latest/edge
[32mINFO    [0m juju.bundle:bundle.py:416 Applying change: upload charm landscape-client for series jammy from channel latest/edge
[32mINFO    [0m juju.bundle:bundle.py:416 Applying change: upload charm mysql for series jammy from channel 8.0/edge
[32mINFO    [0m juju.bundle:bundle.py:416 Applying change: add new machine
[32mINFO    [0m juju.bundle:bundle.py:416 Applying change: add new machine
[32mINFO    [0m juju.bundle:bundle.py:416 Applying change: deploy application data-integrator on jammy using $addCharm-0
[32mINFO    [0m juju.model:model.py:2098 Deploying ch:amd64/jammy/data-integrator-74
[32mINFO    [0m juju.bundle:bundle.py:416 Applying change: deploy application mysql on jammy using $addCharm-9
[32mINFO    [0m juju.model:model.py:2098 Deploying ch:amd64/jammy/mysql-306
[32mINFO    [0m juju.bundle:bundle.py:416 Applying change: deploy application mysql-router on jammy using $addCharm-12
[32mINFO    [0m juju.model:model.py:2098 Deploying ch:amd64/jammy/mysql-router-258
[32mINFO    [0m juju.bundle:bundle.py:416 Applying change: deploy application mysql-router-data-integrator on jammy using $addCharm-0
[32mINFO    [0m juju.model:model.py:2098 Deploying ch:amd64/jammy/data-integrator-74
[32mINFO    [0m juju.bundle:bundle.py:416 Applying change: deploy application mysql-test-app on jammy using $addCharm-17
[32mINFO    [0m juju.model:model.py:2098 Deploying ch:amd64/jammy/mysql-test-app-63
[32mINFO    [0m juju.bundle:bundle.py:416 Applying change: deploy application s3-integrator on jammy using $addCharm-20
[32mINFO    [0m juju.model:model.py:2098 Deploying ch:amd64/jammy/s3-integrator-79
[32mINFO    [0m juju.bundle:bundle.py:416 Applying change: deploy application self-signed-certificates on jammy using $addCharm-23
[32mINFO    [0m juju.model:model.py:2098 Deploying ch:amd64/jammy/self-signed-certificates-206
[32mINFO    [0m juju.bundle:bundle.py:416 Applying change: deploy application sysbench on jammy using $addCharm-26
[32mINFO    [0m juju.model:model.py:2098 Deploying ch:amd64/jammy/sysbench-109
[32mINFO    [0m juju.bundle:bundle.py:416 Applying change: deploy application ubuntu-advantage on jammy using $addCharm-29
[32mINFO    [0m juju.model:model.py:2098 Deploying ch:amd64/jammy/ubuntu-advantage-137
[32mINFO    [0m juju.bundle:bundle.py:416 Applying change: deploy application grafana-agent on jammy using $addCharm-3
[32mINFO    [0m juju.model:model.py:2098 Deploying ch:amd64/jammy/grafana-agent-306
[32mINFO    [0m juju.bundle:bundle.py:416 Applying change: deploy application landscape-client on jammy using $addCharm-6
[32mINFO    [0m juju.model:model.py:2098 Deploying ch:amd64/jammy/landscape-client-70
[32mINFO    [0m juju.bundle:bundle.py:416 Applying change: add new machine
[32mINFO    [0m juju.bundle:bundle.py:416 Applying change: add relation $deploy-10:database - $deploy-13:backend-database
[32mINFO    [0m juju.bundle:bundle.py:865 Relating mysql:database <-> mysql-router:backend-database
[33mWARNING [0m juju.model:model.py:1564 relate is deprecated and will be removed. Use integrate instead.
[32mINFO    [0m juju.bundle:bundle.py:416 Applying change: add relation $deploy-10:certificates - $deploy-24:certificates
[32mINFO    [0m juju.bundle:bundle.py:865 Relating mysql:certificates <-> self-signed-certificates:certificates
[33mWARNING [0m juju.model:model.py:1564 relate is deprecated and will be removed. Use integrate instead.
[32mINFO    [0m juju.bundle:bundle.py:416 Applying change: add relation $deploy-13:certificates - $deploy-24:certificates
[32mINFO    [0m juju.bundle:bundle.py:865 Relating mysql-router:certificates <-> self-signed-certificates:certificates
[33mWARNING [0m juju.model:model.py:1564 relate is deprecated and will be removed. Use integrate instead.
[32mINFO    [0m juju.bundle:bundle.py:416 Applying change: add relation $deploy-10:s3-parameters - $deploy-21:s3-credentials
[32mINFO    [0m juju.bundle:bundle.py:865 Relating mysql:s3-parameters <-> s3-integrator:s3-credentials
[33mWARNING [0m juju.model:model.py:1564 relate is deprecated and will be removed. Use integrate instead.
[32mINFO    [0m juju.bundle:bundle.py:416 Applying change: add relation $deploy-10:database - $deploy-1:mysql
[32mINFO    [0m juju.bundle:bundle.py:865 Relating mysql:database <-> data-integrator:mysql
[33mWARNING [0m juju.model:model.py:1564 relate is deprecated and will be removed. Use integrate instead.
[32mINFO    [0m juju.bundle:bundle.py:416 Applying change: add relation $deploy-10:database - $deploy-27:mysql
[32mINFO    [0m juju.bundle:bundle.py:865 Relating mysql:database <-> sysbench:mysql
[33mWARNING [0m juju.model:model.py:1564 relate is deprecated and will be removed. Use integrate instead.
[32mINFO    [0m juju.bundle:bundle.py:416 Applying change: add relation $deploy-10:cos-agent - $deploy-4:cos-agent
[32mINFO    [0m juju.bundle:bundle.py:865 Relating mysql:cos-agent <-> grafana-agent:cos-agent
[33mWARNING [0m juju.model:model.py:1564 relate is deprecated and will be removed. Use integrate instead.
[32mINFO    [0m juju.bundle:bundle.py:416 Applying change: add relation $deploy-10:juju-info - $deploy-30:juju-info
[32mINFO    [0m juju.bundle:bundle.py:865 Relating mysql:juju-info <-> ubuntu-advantage:juju-info
[33mWARNING [0m juju.model:model.py:1564 relate is deprecated and will be removed. Use integrate instead.
[32mINFO    [0m juju.bundle:bundle.py:416 Applying change: add relation $deploy-10:juju-info - $deploy-7:container
[32mINFO    [0m juju.bundle:bundle.py:865 Relating mysql:juju-info <-> landscape-client:container
[33mWARNING [0m juju.model:model.py:1564 relate is deprecated and will be removed. Use integrate instead.
[32mINFO    [0m juju.bundle:bundle.py:416 Applying change: add relation $deploy-13:database - $deploy-15:mysql
[32mINFO    [0m juju.bundle:bundle.py:865 Relating mysql-router:database <-> mysql-router-data-integrator:mysql
[33mWARNING [0m juju.model:model.py:1564 relate is deprecated and will be removed. Use integrate instead.
[32mINFO    [0m juju.bundle:bundle.py:416 Applying change: add relation $deploy-15:juju-info - $deploy-4:juju-info
[32mINFO    [0m juju.bundle:bundle.py:865 Relating mysql-router-data-integrator:juju-info <-> grafana-agent:juju-info
[33mWARNING [0m juju.model:model.py:1564 relate is deprecated and will be removed. Use integrate instead.
[32mINFO    [0m juju.bundle:bundle.py:416 Applying change: add relation $deploy-13:cos-agent - $deploy-4:cos-agent
[32mINFO    [0m juju.bundle:bundle.py:865 Relating mysql-router:cos-agent <-> grafana-agent:cos-agent
[33mWARNING [0m juju.model:model.py:1564 relate is deprecated and will be removed. Use integrate instead.
[32mINFO    [0m juju.bundle:bundle.py:416 Applying change: add relation $deploy-15:juju-info - $deploy-30:juju-info
[32mINFO    [0m juju.bundle:bundle.py:865 Relating mysql-router-data-integrator:juju-info <-> ubuntu-advantage:juju-info
[33mWARNING [0m juju.model:model.py:1564 relate is deprecated and will be removed. Use integrate instead.
[32mINFO    [0m juju.bundle:bundle.py:416 Applying change: add relation $deploy-15:juju-info - $deploy-7:container
[32mINFO    [0m juju.bundle:bundle.py:865 Relating mysql-router-data-integrator:juju-info <-> landscape-client:container
[33mWARNING [0m juju.model:model.py:1564 relate is deprecated and will be removed. Use integrate instead.
[32mINFO    [0m juju.bundle:bundle.py:416 Applying change: add $deploy-1 unit to $addMachines-32
[32mINFO    [0m juju.bundle:bundle.py:416 Applying change: add $deploy-15 unit to $addMachines-33
[32mINFO    [0m juju.bundle:bundle.py:416 Applying change: set annotations for $deploy-10
[32mINFO    [0m juju.bundle:bundle.py:416 Applying change: set annotations for $deploy-13
[32mINFO    [0m juju.bundle:bundle.py:416 Applying change: set annotations for $deploy-15
[32mINFO    [0m juju.bundle:bundle.py:416 Applying change: set annotations for $deploy-18
[32mINFO    [0m juju.bundle:bundle.py:416 Applying change: set annotations for $deploy-1
[32mINFO    [0m juju.bundle:bundle.py:416 Applying change: set annotations for $deploy-21
[32mINFO    [0m juju.bundle:bundle.py:416 Applying change: set annotations for $deploy-24
[32mINFO    [0m juju.bundle:bundle.py:416 Applying change: set annotations for $deploy-27
[32mINFO    [0m juju.bundle:bundle.py:416 Applying change: set annotations for $deploy-30
[32mINFO    [0m juju.bundle:bundle.py:416 Applying change: set annotations for $deploy-4
[32mINFO    [0m juju.bundle:bundle.py:416 Applying change: set annotations for $deploy-7
[32mINFO    [0m juju.bundle:bundle.py:416 Applying change: add new machine
[32mINFO    [0m juju.bundle:bundle.py:416 Applying change: add $deploy-10 unit to $addMachines-34
[32mINFO    [0m juju.bundle:bundle.py:416 Applying change: add new machine
[32mINFO    [0m juju.bundle:bundle.py:416 Applying change: add $deploy-10 unit to $addMachines-35
[32mINFO    [0m juju.bundle:bundle.py:416 Applying change: add new machine
[32mINFO    [0m juju.bundle:bundle.py:416 Applying change: add $deploy-10 unit to $addMachines-36
[32mINFO    [0m juju.bundle:bundle.py:416 Applying change: add new machine
[32mINFO    [0m juju.bundle:bundle.py:416 Applying change: add $deploy-21 unit to $addMachines-37
[32mINFO    [0m juju.bundle:bundle.py:416 Applying change: add new machine
[32mINFO    [0m juju.bundle:bundle.py:416 Applying change: add $deploy-24 unit to $addMachines-38
[32mINFO    [0m juju.bundle:bundle.py:416 Applying change: add $deploy-27 unit to $addMachines-39
[32mINFO    [0m integration.test_smoke:test_smoke.py:41 Waiting for active: mysql, self-signed-certificates, sysbench
[32mINFO    [0m integration.test_smoke:test_smoke.py:47 Waiting for blocked: data-integrator, grafana-agent, mysql-router-data-integrator, landscape-client, s3-integrator, ubuntu-advantage
[32mINFO    [0m integration.test_smoke:test_smoke.py:54 Waiting for waiting: mysql-router
[32mINFO    [0m integration.test_smoke:test_smoke.py:72 Configuring s3-integrator credentials
[32mINFO    [0m integration.test_smoke:test_smoke.py:41 Waiting for active: mysql, self-signed-certificates, sysbench, s3-integrator
[32mINFO    [0m integration.test_smoke:test_smoke.py:47 Waiting for blocked: data-integrator, grafana-agent, mysql-router-data-integrator, landscape-client, ubuntu-advantage
[32mINFO    [0m integration.test_smoke:test_smoke.py:54 Waiting for waiting: mysql-router
[32mINFO    [0m integration.test_smoke:test_smoke.py:86 Configuring data-integrator
[32mINFO    [0m integration.test_smoke:test_smoke.py:41 Waiting for active: mysql, self-signed-certificates, sysbench, s3-integrator, data-integrator
[32mINFO    [0m integration.test_smoke:test_smoke.py:47 Waiting for blocked: grafana-agent, mysql-router-data-integrator, landscape-client, ubuntu-advantage
[32mINFO    [0m integration.test_smoke:test_smoke.py:54 Waiting for waiting: mysql-router
[32mINFO    [0m integration.test_smoke:test_smoke.py:95 Confirming data-integrator's database exists
[32mINFO    [0m pytest_operator.plugin:plugin.py:903 Model status:

Model  Controller           Cloud/Region         Version  SLA          Timestamp
test   localhost-localhost  localhost/localhost  3.5.4    unsupported  01:34:55Z

App                           Version          Status   Scale  Charm                     Channel      Rev  Exposed  Message
data-integrator                                active       1  data-integrator           latest/edge   74  no       
grafana-agent                                  blocked      4  grafana-agent             latest/edge  306  no       Missing ['grafana-cloud-config']|['grafana-dashboards-provider']|['logging-consumer']|['send-remote-write'] for cos-a...
landscape-client                               blocked      4  landscape-client          latest/edge   70  no       Registration failed!
mysql                         8.0.37-0ubun...  active       3  mysql                     8.0/edge     306  no       
mysql-router                  8.0.37-0ubun...  waiting      1  mysql-router              dpe/edge     258  no       Waiting for mysql-router-data-integrator app on database endpoint
mysql-router-data-integrator                   blocked      1  data-integrator           latest/edge   74  no       Please specify either topic, index, or database name
mysql-test-app                                 unknown      0  mysql-test-app            latest/edge   63  no       
s3-integrator                                  active       1  s3-integrator             latest/edge   79  no       
self-signed-certificates                       active       1  self-signed-certificates  latest/edge  206  no       
sysbench                                       active       1  sysbench                  latest/edge  109  no       
ubuntu-advantage                               blocked      4  ubuntu-advantage          latest/edge  137  no       No token configured

Unit                             Workload  Agent      Machine  Public address  Ports           Message
data-integrator/0*               active    idle       0        10.179.196.133                  
mysql-router-data-integrator/0*  blocked   idle       1        10.179.196.165                  Please specify either topic, index, or database name
  grafana-agent/0*               blocked   idle                10.179.196.165                  Missing ['grafana-cloud-config']|['grafana-dashboards-provider']|['logging-consumer']|['send-remote-write'] for cos-a...
  landscape-client/0*            blocked   idle                10.179.196.165                  Registration failed!
  mysql-router/0*                active    executing           10.179.196.165                  
  ubuntu-advantage/0*            blocked   idle                10.179.196.165                  No token configured
mysql/0                          waiting   executing  2        10.179.196.58                   (get-password) Waiting to join the cluster
  grafana-agent/2                blocked   idle                10.179.196.58                   Missing ['grafana-cloud-config']|['grafana-dashboards-provider']|['logging-consumer']|['send-remote-write'] for cos-a...
  landscape-client/2             blocked   idle                10.179.196.58                   Registration failed!
  ubuntu-advantage/2             blocked   idle                10.179.196.58                   No token configured
mysql/1*                         active    executing  3        10.179.196.190  3306,33060/tcp  Primary
  grafana-agent/1                blocked   executing           10.179.196.190                  Missing ['grafana-cloud-config']|['grafana-dashboards-provider']|['logging-consumer']|['send-remote-write'] for cos-a...
  landscape-client/1             blocked   idle                10.179.196.190                  Registration failed!
  ubuntu-advantage/1             blocked   idle                10.179.196.190                  No token configured
mysql/2                          active    executing  4        10.179.196.98   3306,33060/tcp  
  grafana-agent/3                blocked   idle                10.179.196.98                   Missing ['grafana-cloud-config']|['grafana-dashboards-provider']|['logging-consumer']|['send-remote-write'] for cos-a...
  landscape-client/3             blocked   idle                10.179.196.98                   Registration failed!
  ubuntu-advantage/3             blocked   idle                10.179.196.98                   No token configured
s3-integrator/0*                 active    idle       5        10.179.196.101                  
self-signed-certificates/0*      active    idle       6        10.179.196.82                   
sysbench/0*                      active    idle       7        10.179.196.112                  

Machine  State    Address         Inst id        Base          AZ  Message
0        started  10.179.196.133  juju-612b1f-0  ubuntu@22.04      Running
1        started  10.179.196.165  juju-612b1f-1  ubuntu@22.04      Running
2        started  10.179.196.58   juju-612b1f-2  ubuntu@22.04      Running
3        started  10.179.196.190  juju-612b1f-3  ubuntu@22.04      Running
4        started  10.179.196.98   juju-612b1f-4  ubuntu@22.04      Running
5        started  10.179.196.101  juju-612b1f-5  ubuntu@22.04      Running
6        started  10.179.196.82   juju-612b1f-6  ubuntu@22.04      Running
7        started  10.179.196.112  juju-612b1f-7  ubuntu@22.04      Running

[32mINFO    [0m pytest_operator.plugin:plugin.py:909 Juju error logs:

machine-0: 01:29:31 ERROR juju.worker.dependency "lxd-container-provisioner" manifold worker returned unexpected error: container types not yet available
machine-0: 01:29:32 ERROR juju.worker.dependency "kvm-container-provisioner" manifold worker returned unexpected error: container types not yet available
unit-data-integrator-0: 01:29:33 ERROR juju.worker.meterstatus error running "meter-status-changed": charm missing from disk
machine-1: 01:29:36 ERROR juju.worker.dependency "kvm-container-provisioner" manifold worker returned unexpected error: container types not yet available
machine-1: 01:29:36 ERROR juju.worker.dependency "lxd-container-provisioner" manifold worker returned unexpected error: container types not yet available
unit-mysql-router-data-integrator-0: 01:29:38 ERROR juju.worker.meterstatus error running "meter-status-changed": charm missing from disk
machine-3: 01:29:40 ERROR juju.worker.dependency "kvm-container-provisioner" manifold worker returned unexpected error: container types not yet available
machine-3: 01:29:40 ERROR juju.worker.dependency "lxd-container-provisioner" manifold worker returned unexpected error: container types not yet available
unit-mysql-1: 01:29:41 ERROR juju.worker.meterstatus error running "meter-status-changed": charm missing from disk
machine-6: 01:29:42 ERROR juju.worker.dependency "lxd-container-provisioner" manifold worker returned unexpected error: container types not yet available
machine-6: 01:29:43 ERROR juju.worker.dependency "kvm-container-provisioner" manifold worker returned unexpected error: container types not yet available
unit-self-signed-certificates-0: 01:29:44 ERROR juju.worker.meterstatus error running "meter-status-changed": charm missing from disk
machine-2: 01:29:48 ERROR juju.worker.dependency "kvm-container-provisioner" manifold worker returned unexpected error: container types not yet available
machine-2: 01:29:48 ERROR juju.worker.dependency "lxd-container-provisioner" manifold worker returned unexpected error: container types not yet available
unit-mysql-0: 01:29:49 ERROR juju.worker.meterstatus error running "meter-status-changed": charm missing from disk
machine-4: 01:29:49 ERROR juju.worker.dependency "lxd-container-provisioner" manifold worker returned unexpected error: container types not yet available
machine-4: 01:29:49 ERROR juju.worker.dependency "kvm-container-provisioner" manifold worker returned unexpected error: container types not yet available
unit-mysql-2: 01:29:51 ERROR juju.worker.meterstatus error running "meter-status-changed": charm missing from disk
unit-ubuntu-advantage-0: 01:29:51 ERROR juju.worker.meterstatus error running "meter-status-changed": charm missing from disk
unit-landscape-client-0: 01:29:52 ERROR juju.worker.meterstatus error running "meter-status-changed": charm missing from disk
machine-7: 01:29:52 ERROR juju.worker.dependency "kvm-container-provisioner" manifold worker returned unexpected error: container types not yet available
machine-7: 01:29:52 ERROR juju.worker.dependency "lxd-container-provisioner" manifold worker returned unexpected error: container types not yet available
unit-mysql-router-0: 01:29:53 ERROR juju.worker.meterstatus error running "meter-status-changed": charm missing from disk
unit-sysbench-0: 01:29:54 ERROR juju.worker.meterstatus error running "meter-status-changed": charm missing from disk
unit-grafana-agent-0: 01:29:56 ERROR juju.worker.meterstatus error running "meter-status-changed": charm missing from disk
machine-5: 01:29:59 ERROR juju.worker.dependency "lxd-container-provisioner" manifold worker returned unexpected error: container types not yet available
machine-5: 01:30:00 ERROR juju.worker.dependency "kvm-container-provisioner" manifold worker returned unexpected error: container types not yet available
unit-s3-integrator-0: 01:30:00 ERROR juju.worker.meterstatus error running "meter-status-changed": charm missing from disk
unit-ubuntu-advantage-1: 01:30:54 ERROR juju.worker.meterstatus error running "meter-status-changed": charm missing from disk
unit-grafana-agent-1: 01:30:55 ERROR juju.worker.meterstatus error running "meter-status-changed": charm missing from disk
unit-grafana-agent-2: 01:30:58 ERROR juju.worker.meterstatus error running "meter-status-changed": charm missing from disk
unit-ubuntu-advantage-2: 01:30:59 ERROR juju.worker.meterstatus error running "meter-status-changed": charm missing from disk
unit-landscape-client-2: 01:31:00 ERROR juju.worker.meterstatus error running "meter-status-changed": charm missing from disk
unit-landscape-client-1: 01:31:00 ERROR juju.worker.meterstatus error running "meter-status-changed": exit status 1
unit-landscape-client-3: 01:31:02 ERROR juju.worker.meterstatus error running "meter-status-changed": charm missing from disk
unit-ubuntu-advantage-3: 01:31:03 ERROR juju.worker.meterstatus error running "meter-status-changed": charm missing from disk
unit-landscape-client-0: 01:31:48 CRITICAL unit.landscape-client/0.juju-log   File "/var/lib/juju/agents/unit-landscape-client-0/charm/./src/charm.py", line 274, in <module>
    main(LandscapeClientCharm)
  File "/var/lib/juju/agents/unit-landscape-client-0/charm/venv/ops/main.py", line 45, in main
    return _main.main(charm_class=charm_class, use_juju_for_storage=use_juju_for_storage)
  File "/var/lib/juju/agents/unit-landscape-client-0/charm/venv/ops/_main.py", line 543, in main
    manager.run()
  File "/var/lib/juju/agents/unit-landscape-client-0/charm/venv/ops/_main.py", line 529, in run
    self._emit()
  File "/var/lib/juju/agents/unit-landscape-client-0/charm/venv/ops/_main.py", line 518, in _emit
    _emit_charm_event(self.charm, self.dispatcher.event_name, self._juju_context)
  File "/var/lib/juju/agents/unit-landscape-client-0/charm/venv/ops/_main.py", line 134, in _emit_charm_event
    event_to_emit.emit(*args, **kwargs)
  File "/var/lib/juju/agents/unit-landscape-client-0/charm/venv/ops/framework.py", line 347, in emit
    framework._emit(event)
  File "/var/lib/juju/agents/unit-landscape-client-0/charm/venv/ops/framework.py", line 857, in _emit
    self._reemit(event_path)
  File "/var/lib/juju/agents/unit-landscape-client-0/charm/venv/ops/framework.py", line 947, in _reemit
    custom_handler(event)
  File "/var/lib/juju/agents/unit-landscape-client-0/charm/./src/charm.py", line 228, in _on_config_changed
    self.run_landscape_client()
  File "/var/lib/juju/agents/unit-landscape-client-0/charm/./src/charm.py", line 203, in run_landscape_client
    self.send_registration()
  File "/var/lib/juju/agents/unit-landscape-client-0/charm/./src/charm.py", line 191, in send_registration
    if process_helper([CLIENT_CONFIG_CMD, "--silent"]):
  File "/var/lib/juju/agents/unit-landscape-client-0/charm/./src/charm.py", line 117, in process_helper
    log_error("".join(traceback.format_stack()))

unit-landscape-client-0: 01:31:48 CRITICAL unit.landscape-client/0.juju-log An account name and computer title are required.
Aborting Landscape configuration

unit-landscape-client-1: 01:31:54 CRITICAL unit.landscape-client/1.juju-log   File "/var/lib/juju/agents/unit-landscape-client-1/charm/./src/charm.py", line 274, in <module>
    main(LandscapeClientCharm)
  File "/var/lib/juju/agents/unit-landscape-client-1/charm/venv/ops/main.py", line 45, in main
    return _main.main(charm_class=charm_class, use_juju_for_storage=use_juju_for_storage)
  File "/var/lib/juju/agents/unit-landscape-client-1/charm/venv/ops/_main.py", line 543, in main
    manager.run()
  File "/var/lib/juju/agents/unit-landscape-client-1/charm/venv/ops/_main.py", line 529, in run
    self._emit()
  File "/var/lib/juju/agents/unit-landscape-client-1/charm/venv/ops/_main.py", line 518, in _emit
    _emit_charm_event(self.charm, self.dispatcher.event_name, self._juju_context)
  File "/var/lib/juju/agents/unit-landscape-client-1/charm/venv/ops/_main.py", line 134, in _emit_charm_event
    event_to_emit.emit(*args, **kwargs)
  File "/var/lib/juju/agents/unit-landscape-client-1/charm/venv/ops/framework.py", line 347, in emit
    framework._emit(event)
  File "/var/lib/juju/agents/unit-landscape-client-1/charm/venv/ops/framework.py", line 857, in _emit
    self._reemit(event_path)
  File "/var/lib/juju/agents/unit-landscape-client-1/charm/venv/ops/framework.py", line 947, in _reemit
    custom_handler(event)
  File "/var/lib/juju/agents/unit-landscape-client-1/charm/./src/charm.py", line 228, in _on_config_changed
    self.run_landscape_client()
  File "/var/lib/juju/agents/unit-landscape-client-1/charm/./src/charm.py", line 203, in run_landscape_client
    self.send_registration()
  File "/var/lib/juju/agents/unit-landscape-client-1/charm/./src/charm.py", line 191, in send_registration
    if process_helper([CLIENT_CONFIG_CMD, "--silent"]):
  File "/var/lib/juju/agents/unit-landscape-client-1/charm/./src/charm.py", line 117, in process_helper
    log_error("".join(traceback.format_stack()))

unit-landscape-client-1: 01:31:54 CRITICAL unit.landscape-client/1.juju-log An account name and computer title are required.
Aborting Landscape configuration

unit-landscape-client-3: 01:31:56 CRITICAL unit.landscape-client/3.juju-log   File "/var/lib/juju/agents/unit-landscape-client-3/charm/./src/charm.py", line 274, in <module>
    main(LandscapeClientCharm)
  File "/var/lib/juju/agents/unit-landscape-client-3/charm/venv/ops/main.py", line 45, in main
    return _main.main(charm_class=charm_class, use_juju_for_storage=use_juju_for_storage)
  File "/var/lib/juju/agents/unit-landscape-client-3/charm/venv/ops/_main.py", line 543, in main
    manager.run()
  File "/var/lib/juju/agents/unit-landscape-client-3/charm/venv/ops/_main.py", line 529, in run
    self._emit()
  File "/var/lib/juju/agents/unit-landscape-client-3/charm/venv/ops/_main.py", line 518, in _emit
    _emit_charm_event(self.charm, self.dispatcher.event_name, self._juju_context)
  File "/var/lib/juju/agents/unit-landscape-client-3/charm/venv/ops/_main.py", line 134, in _emit_charm_event
    event_to_emit.emit(*args, **kwargs)
  File "/var/lib/juju/agents/unit-landscape-client-3/charm/venv/ops/framework.py", line 347, in emit
    framework._emit(event)
  File "/var/lib/juju/agents/unit-landscape-client-3/charm/venv/ops/framework.py", line 857, in _emit
    self._reemit(event_path)
  File "/var/lib/juju/agents/unit-landscape-client-3/charm/venv/ops/framework.py", line 947, in _reemit
    custom_handler(event)
  File "/var/lib/juju/agents/unit-landscape-client-3/charm/./src/charm.py", line 228, in _on_config_changed
    self.run_landscape_client()
  File "/var/lib/juju/agents/unit-landscape-client-3/charm/./src/charm.py", line 203, in run_landscape_client
    self.send_registration()
  File "/var/lib/juju/agents/unit-landscape-client-3/charm/./src/charm.py", line 191, in send_registration
    if process_helper([CLIENT_CONFIG_CMD, "--silent"]):
  File "/var/lib/juju/agents/unit-landscape-client-3/charm/./src/charm.py", line 117, in process_helper
    log_error("".join(traceback.format_stack()))

unit-landscape-client-3: 01:31:56 CRITICAL unit.landscape-client/3.juju-log An account name and computer title are required.
Aborting Landscape configuration

unit-landscape-client-2: 01:31:56 CRITICAL unit.landscape-client/2.juju-log   File "/var/lib/juju/agents/unit-landscape-client-2/charm/./src/charm.py", line 274, in <module>
    main(LandscapeClientCharm)
  File "/var/lib/juju/agents/unit-landscape-client-2/charm/venv/ops/main.py", line 45, in main
    return _main.main(charm_class=charm_class, use_juju_for_storage=use_juju_for_storage)
  File "/var/lib/juju/agents/unit-landscape-client-2/charm/venv/ops/_main.py", line 543, in main
    manager.run()
  File "/var/lib/juju/agents/unit-landscape-client-2/charm/venv/ops/_main.py", line 529, in run
    self._emit()
  File "/var/lib/juju/agents/unit-landscape-client-2/charm/venv/ops/_main.py", line 518, in _emit
    _emit_charm_event(self.charm, self.dispatcher.event_name, self._juju_context)
  File "/var/lib/juju/agents/unit-landscape-client-2/charm/venv/ops/_main.py", line 134, in _emit_charm_event
    event_to_emit.emit(*args, **kwargs)
  File "/var/lib/juju/agents/unit-landscape-client-2/charm/venv/ops/framework.py", line 347, in emit
    framework._emit(event)
  File "/var/lib/juju/agents/unit-landscape-client-2/charm/venv/ops/framework.py", line 857, in _emit
    self._reemit(event_path)
  File "/var/lib/juju/agents/unit-landscape-client-2/charm/venv/ops/framework.py", line 947, in _reemit
    custom_handler(event)
  File "/var/lib/juju/agents/unit-landscape-client-2/charm/./src/charm.py", line 228, in _on_config_changed
    self.run_landscape_client()
  File "/var/lib/juju/agents/unit-landscape-client-2/charm/./src/charm.py", line 203, in run_landscape_client
    self.send_registration()
  File "/var/lib/juju/agents/unit-landscape-client-2/charm/./src/charm.py", line 191, in send_registration
    if process_helper([CLIENT_CONFIG_CMD, "--silent"]):
  File "/var/lib/juju/agents/unit-landscape-client-2/charm/./src/charm.py", line 117, in process_helper
    log_error("".join(traceback.format_stack()))

unit-landscape-client-2: 01:31:56 CRITICAL unit.landscape-client/2.juju-log An account name and computer title are required.
Aborting Landscape configuration

unit-mysql-2: 01:33:39 ERROR unit.mysql/2.juju-log cos-agent:19: Exception while exporting Span batch.
Traceback (most recent call last):
  File "/var/lib/juju/agents/unit-mysql-2/charm/venv/urllib3/connection.py", line 174, in _new_conn
    conn = connection.create_connection(
  File "/var/lib/juju/agents/unit-mysql-2/charm/venv/urllib3/util/connection.py", line 95, in create_connection
    raise err
  File "/var/lib/juju/agents/unit-mysql-2/charm/venv/urllib3/util/connection.py", line 85, in create_connection
    sock.connect(sa)
ConnectionRefusedError: [Errno 111] Connection refused

During handling of the above exception, another exception occurred:

Traceback (most recent call last):
  File "/var/lib/juju/agents/unit-mysql-2/charm/venv/urllib3/connectionpool.py", line 715, in urlopen
    httplib_response = self._make_request(
  File "/var/lib/juju/agents/unit-mysql-2/charm/venv/urllib3/connectionpool.py", line 416, in _make_request
    conn.request(method, url, **httplib_request_kw)
  File "/var/lib/juju/agents/unit-mysql-2/charm/venv/urllib3/connection.py", line 244, in request
    super(HTTPConnection, self).request(method, url, body=body, headers=headers)
  File "/usr/lib/python3.10/http/client.py", line 1283, in request
    self._send_request(method, url, body, headers, encode_chunked)
  File "/usr/lib/python3.10/http/client.py", line 1329, in _send_request
    self.endheaders(body, encode_chunked=encode_chunked)
  File "/usr/lib/python3.10/http/client.py", line 1278, in endheaders
    self._send_output(message_body, encode_chunked=encode_chunked)
  File "/usr/lib/python3.10/http/client.py", line 1038, in _send_output
    self.send(msg)
  File "/usr/lib/python3.10/http/client.py", line 976, in send
    self.connect()
  File "/var/lib/juju/agents/unit-mysql-2/charm/venv/urllib3/connection.py", line 205, in connect
    conn = self._new_conn()
  File "/var/lib/juju/agents/unit-mysql-2/charm/venv/urllib3/connection.py", line 186, in _new_conn
    raise NewConnectionError(
urllib3.exceptions.NewConnectionError: <urllib3.connection.HTTPConnection object at 0x7fdc02c518d0>: Failed to establish a new connection: [Errno 111] Connection refused

During handling of the above exception, another exception occurred:

Traceback (most recent call last):
  File "/var/lib/juju/agents/unit-mysql-2/charm/venv/requests/adapters.py", line 486, in send
    resp = conn.urlopen(
  File "/var/lib/juju/agents/unit-mysql-2/charm/venv/urllib3/connectionpool.py", line 801, in urlopen
    retries = retries.increment(
  File "/var/lib/juju/agents/unit-mysql-2/charm/venv/urllib3/util/retry.py", line 594, in increment
    raise MaxRetryError(_pool, url, error or ResponseError(cause))
urllib3.exceptions.MaxRetryError: HTTPConnectionPool(host='juju-612b1f-4.lxd', port=4318): Max retries exceeded with url: /v1/traces (Caused by NewConnectionError('<urllib3.connection.HTTPConnection object at 0x7fdc02c518d0>: Failed to establish a new connection: [Errno 111] Connection refused'))

During handling of the above exception, another exception occurred:

Traceback (most recent call last):
  File "/var/lib/juju/agents/unit-mysql-2/charm/venv/opentelemetry/sdk/trace/export/__init__.py", line 368, in _export_batch
    self.span_exporter.export(self.spans_list[:idx])  # type: ignore
  File "/var/lib/juju/agents/unit-mysql-2/charm/venv/opentelemetry/exporter/otlp/proto/http/trace_exporter/__init__.py", line 145, in export
    resp = self._export(serialized_data)
  File "/var/lib/juju/agents/unit-mysql-2/charm/venv/opentelemetry/exporter/otlp/proto/http/trace_exporter/__init__.py", line 114, in _export
    return self._session.post(
  File "/var/lib/juju/agents/unit-mysql-2/charm/venv/requests/sessions.py", line 637, in post
    return self.request("POST", url, data=data, json=json, **kwargs)
  File "/var/lib/juju/agents/unit-mysql-2/charm/venv/requests/sessions.py", line 589, in request
    resp = self.send(prep, **send_kwargs)
  File "/var/lib/juju/agents/unit-mysql-2/charm/venv/requests/sessions.py", line 703, in send
    r = adapter.send(request, **kwargs)
  File "/var/lib/juju/agents/unit-mysql-2/charm/venv/requests/adapters.py", line 519, in send
    raise ConnectionError(e, request=request)
requests.exceptions.ConnectionError: HTTPConnectionPool(host='juju-612b1f-4.lxd', port=4318): Max retries exceeded with url: /v1/traces (Caused by NewConnectionError('<urllib3.connection.HTTPConnection object at 0x7fdc02c518d0>: Failed to establish a new connection: [Errno 111] Connection refused'))
unit-mysql-2: 01:33:43 ERROR unit.mysql/2.juju-log database:18: Exception while exporting Span batch.
Traceback (most recent call last):
  File "/var/lib/juju/agents/unit-mysql-2/charm/venv/urllib3/connection.py", line 174, in _new_conn
    conn = connection.create_connection(
  File "/var/lib/juju/agents/unit-mysql-2/charm/venv/urllib3/util/connection.py", line 95, in create_connection
    raise err
  File "/var/lib/juju/agents/unit-mysql-2/charm/venv/urllib3/util/connection.py", line 85, in create_connection
    sock.connect(sa)
ConnectionRefusedError: [Errno 111] Connection refused

During handling of the above exception, another exception occurred:

Traceback (most recent call last):
  File "/var/lib/juju/agents/unit-mysql-2/charm/venv/urllib3/connectionpool.py", line 715, in urlopen
    httplib_response = self._make_request(
  File "/var/lib/juju/agents/unit-mysql-2/charm/venv/urllib3/connectionpool.py", line 416, in _make_request
    conn.request(method, url, **httplib_request_kw)
  File "/var/lib/juju/agents/unit-mysql-2/charm/venv/urllib3/connection.py", line 244, in request
    super(HTTPConnection, self).request(method, url, body=body, headers=headers)
  File "/usr/lib/python3.10/http/client.py", line 1283, in request
    self._send_request(method, url, body, headers, encode_chunked)
  File "/usr/lib/python3.10/http/client.py", line 1329, in _send_request
    self.endheaders(body, encode_chunked=encode_chunked)
  File "/usr/lib/python3.10/http/client.py", line 1278, in endheaders
    self._send_output(message_body, encode_chunked=encode_chunked)
  File "/usr/lib/python3.10/http/client.py", line 1038, in _send_output
    self.send(msg)
  File "/usr/lib/python3.10/http/client.py", line 976, in send
    self.connect()
  File "/var/lib/juju/agents/unit-mysql-2/charm/venv/urllib3/connection.py", line 205, in connect
    conn = self._new_conn()
  File "/var/lib/juju/agents/unit-mysql-2/charm/venv/urllib3/connection.py", line 186, in _new_conn
    raise NewConnectionError(
urllib3.exceptions.NewConnectionError: <urllib3.connection.HTTPConnection object at 0x7fe3179db250>: Failed to establish a new connection: [Errno 111] Connection refused

During handling of the above exception, another exception occurred:

Traceback (most recent call last):
  File "/var/lib/juju/agents/unit-mysql-2/charm/venv/requests/adapters.py", line 486, in send
    resp = conn.urlopen(
  File "/var/lib/juju/agents/unit-mysql-2/charm/venv/urllib3/connectionpool.py", line 801, in urlopen
    retries = retries.increment(
  File "/var/lib/juju/agents/unit-mysql-2/charm/venv/urllib3/util/retry.py", line 594, in increment
    raise MaxRetryError(_pool, url, error or ResponseError(cause))
urllib3.exceptions.MaxRetryError: HTTPConnectionPool(host='juju-612b1f-4.lxd', port=4318): Max retries exceeded with url: /v1/traces (Caused by NewConnectionError('<urllib3.connection.HTTPConnection object at 0x7fe3179db250>: Failed to establish a new connection: [Errno 111] Connection refused'))

During handling of the above exception, another exception occurred:

Traceback (most recent call last):
  File "/var/lib/juju/agents/unit-mysql-2/charm/venv/opentelemetry/sdk/trace/export/__init__.py", line 368, in _export_batch
    self.span_exporter.export(self.spans_list[:idx])  # type: ignore
  File "/var/lib/juju/agents/unit-mysql-2/charm/venv/opentelemetry/exporter/otlp/proto/http/trace_exporter/__init__.py", line 145, in export
    resp = self._export(serialized_data)
  File "/var/lib/juju/agents/unit-mysql-2/charm/venv/opentelemetry/exporter/otlp/proto/http/trace_exporter/__init__.py", line 114, in _export
    return self._session.post(
  File "/var/lib/juju/agents/unit-mysql-2/charm/venv/requests/sessions.py", line 637, in post
    return self.request("POST", url, data=data, json=json, **kwargs)
  File "/var/lib/juju/agents/unit-mysql-2/charm/venv/requests/sessions.py", line 589, in request
    resp = self.send(prep, **send_kwargs)
  File "/var/lib/juju/agents/unit-mysql-2/charm/venv/requests/sessions.py", line 703, in send
    r = adapter.send(request, **kwargs)
  File "/var/lib/juju/agents/unit-mysql-2/charm/venv/requests/adapters.py", line 519, in send
    raise ConnectionError(e, request=request)
requests.exceptions.ConnectionError: HTTPConnectionPool(host='juju-612b1f-4.lxd', port=4318): Max retries exceeded with url: /v1/traces (Caused by NewConnectionError('<urllib3.connection.HTTPConnection object at 0x7fe3179db250>: Failed to establish a new connection: [Errno 111] Connection refused'))
unit-mysql-2: 01:33:49 ERROR unit.mysql/2.juju-log database-peers:2: Exception while exporting Span batch.
Traceback (most recent call last):
  File "/var/lib/juju/agents/unit-mysql-2/charm/venv/urllib3/connection.py", line 174, in _new_conn
    conn = connection.create_connection(
  File "/var/lib/juju/agents/unit-mysql-2/charm/venv/urllib3/util/connection.py", line 95, in create_connection
    raise err
  File "/var/lib/juju/agents/unit-mysql-2/charm/venv/urllib3/util/connection.py", line 85, in create_connection
    sock.connect(sa)
ConnectionRefusedError: [Errno 111] Connection refused

During handling of the above exception, another exception occurred:

Traceback (most recent call last):
  File "/var/lib/juju/agents/unit-mysql-2/charm/venv/urllib3/connectionpool.py", line 715, in urlopen
    httplib_response = self._make_request(
  File "/var/lib/juju/agents/unit-mysql-2/charm/venv/urllib3/connectionpool.py", line 416, in _make_request
    conn.request(method, url, **httplib_request_kw)
  File "/var/lib/juju/agents/unit-mysql-2/charm/venv/urllib3/connection.py", line 244, in request
    super(HTTPConnection, self).request(method, url, body=body, headers=headers)
  File "/usr/lib/python3.10/http/client.py", line 1283, in request
    self._send_request(method, url, body, headers, encode_chunked)
  File "/usr/lib/python3.10/http/client.py", line 1329, in _send_request
    self.endheaders(body, encode_chunked=encode_chunked)
  File "/usr/lib/python3.10/http/client.py", line 1278, in endheaders
    self._send_output(message_body, encode_chunked=encode_chunked)
  File "/usr/lib/python3.10/http/client.py", line 1038, in _send_output
    self.send(msg)
  File "/usr/lib/python3.10/http/client.py", line 976, in send
    self.connect()
  File "/var/lib/juju/agents/unit-mysql-2/charm/venv/urllib3/connection.py", line 205, in connect
    conn = self._new_conn()
  File "/var/lib/juju/agents/unit-mysql-2/charm/venv/urllib3/connection.py", line 186, in _new_conn
    raise NewConnectionError(
urllib3.exceptions.NewConnectionError: <urllib3.connection.HTTPConnection object at 0x7f32cecec910>: Failed to establish a new connection: [Errno 111] Connection refused

During handling of the above exception, another exception occurred:

Traceback (most recent call last):
  File "/var/lib/juju/agents/unit-mysql-2/charm/venv/requests/adapters.py", line 486, in send
    resp = conn.urlopen(
  File "/var/lib/juju/agents/unit-mysql-2/charm/venv/urllib3/connectionpool.py", line 801, in urlopen
    retries = retries.increment(
  File "/var/lib/juju/agents/unit-mysql-2/charm/venv/urllib3/util/retry.py", line 594, in increment
    raise MaxRetryError(_pool, url, error or ResponseError(cause))
urllib3.exceptions.MaxRetryError: HTTPConnectionPool(host='juju-612b1f-4.lxd', port=4318): Max retries exceeded with url: /v1/traces (Caused by NewConnectionError('<urllib3.connection.HTTPConnection object at 0x7f32cecec910>: Failed to establish a new connection: [Errno 111] Connection refused'))

During handling of the above exception, another exception occurred:

Traceback (most recent call last):
  File "/var/lib/juju/agents/unit-mysql-2/charm/venv/opentelemetry/sdk/trace/export/__init__.py", line 368, in _export_batch
    self.span_exporter.export(self.spans_list[:idx])  # type: ignore
  File "/var/lib/juju/agents/unit-mysql-2/charm/venv/opentelemetry/exporter/otlp/proto/http/trace_exporter/__init__.py", line 145, in export
    resp = self._export(serialized_data)
  File "/var/lib/juju/agents/unit-mysql-2/charm/venv/opentelemetry/exporter/otlp/proto/http/trace_exporter/__init__.py", line 114, in _export
    return self._session.post(
  File "/var/lib/juju/agents/unit-mysql-2/charm/venv/requests/sessions.py", line 637, in post
    return self.request("POST", url, data=data, json=json, **kwargs)
  File "/var/lib/juju/agents/unit-mysql-2/charm/venv/requests/sessions.py", line 589, in request
    resp = self.send(prep, **send_kwargs)
  File "/var/lib/juju/agents/unit-mysql-2/charm/venv/requests/sessions.py", line 703, in send
    r = adapter.send(request, **kwargs)
  File "/var/lib/juju/agents/unit-mysql-2/charm/venv/requests/adapters.py", line 519, in send
    raise ConnectionError(e, request=request)
requests.exceptions.ConnectionError: HTTPConnectionPool(host='juju-612b1f-4.lxd', port=4318): Max retries exceeded with url: /v1/traces (Caused by NewConnectionError('<urllib3.connection.HTTPConnection object at 0x7f32cecec910>: Failed to establish a new connection: [Errno 111] Connection refused'))
unit-mysql-2: 01:33:53 ERROR unit.mysql/2.juju-log s3-parameters:16: Exception while exporting Span batch.
Traceback (most recent call last):
  File "/var/lib/juju/agents/unit-mysql-2/charm/venv/urllib3/connection.py", line 174, in _new_conn
    conn = connection.create_connection(
  File "/var/lib/juju/agents/unit-mysql-2/charm/venv/urllib3/util/connection.py", line 95, in create_connection
    raise err
  File "/var/lib/juju/agents/unit-mysql-2/charm/venv/urllib3/util/connection.py", line 85, in create_connection
    sock.connect(sa)
ConnectionRefusedError: [Errno 111] Connection refused

During handling of the above exception, another exception occurred:

Traceback (most recent call last):
  File "/var/lib/juju/agents/unit-mysql-2/charm/venv/urllib3/connectionpool.py", line 715, in urlopen
    httplib_response = self._make_request(
  File "/var/lib/juju/agents/unit-mysql-2/charm/venv/urllib3/connectionpool.py", line 416, in _make_request
    conn.request(method, url, **httplib_request_kw)
  File "/var/lib/juju/agents/unit-mysql-2/charm/venv/urllib3/connection.py", line 244, in request
    super(HTTPConnection, self).request(method, url, body=body, headers=headers)
  File "/usr/lib/python3.10/http/client.py", line 1283, in request
    self._send_request(method, url, body, headers, encode_chunked)
  File "/usr/lib/python3.10/http/client.py", line 1329, in _send_request
    self.endheaders(body, encode_chunked=encode_chunked)
  File "/usr/lib/python3.10/http/client.py", line 1278, in endheaders
    self._send_output(message_body, encode_chunked=encode_chunked)
  File "/usr/lib/python3.10/http/client.py", line 1038, in _send_output
    self.send(msg)
  File "/usr/lib/python3.10/http/client.py", line 976, in send
    self.connect()
  File "/var/lib/juju/agents/unit-mysql-2/charm/venv/urllib3/connection.py", line 205, in connect
    conn = self._new_conn()
  File "/var/lib/juju/agents/unit-mysql-2/charm/venv/urllib3/connection.py", line 186, in _new_conn
    raise NewConnectionError(
urllib3.exceptions.NewConnectionError: <urllib3.connection.HTTPConnection object at 0x7ffb479cb3a0>: Failed to establish a new connection: [Errno 111] Connection refused

During handling of the above exception, another exception occurred:

Traceback (most recent call last):
  File "/var/lib/juju/agents/unit-mysql-2/charm/venv/requests/adapters.py", line 486, in send
    resp = conn.urlopen(
  File "/var/lib/juju/agents/unit-mysql-2/charm/venv/urllib3/connectionpool.py", line 801, in urlopen
    retries = retries.increment(
  File "/var/lib/juju/agents/unit-mysql-2/charm/venv/urllib3/util/retry.py", line 594, in increment
    raise MaxRetryError(_pool, url, error or ResponseError(cause))
urllib3.exceptions.MaxRetryError: HTTPConnectionPool(host='juju-612b1f-4.lxd', port=4318): Max retries exceeded with url: /v1/traces (Caused by NewConnectionError('<urllib3.connection.HTTPConnection object at 0x7ffb479cb3a0>: Failed to establish a new connection: [Errno 111] Connection refused'))

During handling of the above exception, another exception occurred:

Traceback (most recent call last):
  File "/var/lib/juju/agents/unit-mysql-2/charm/venv/opentelemetry/sdk/trace/export/__init__.py", line 368, in _export_batch
    self.span_exporter.export(self.spans_list[:idx])  # type: ignore
  File "/var/lib/juju/agents/unit-mysql-2/charm/venv/opentelemetry/exporter/otlp/proto/http/trace_exporter/__init__.py", line 145, in export
    resp = self._export(serialized_data)
  File "/var/lib/juju/agents/unit-mysql-2/charm/venv/opentelemetry/exporter/otlp/proto/http/trace_exporter/__init__.py", line 114, in _export
    return self._session.post(
  File "/var/lib/juju/agents/unit-mysql-2/charm/venv/requests/sessions.py", line 637, in post
    return self.request("POST", url, data=data, json=json, **kwargs)
  File "/var/lib/juju/agents/unit-mysql-2/charm/venv/requests/sessions.py", line 589, in request
    resp = self.send(prep, **send_kwargs)
  File "/var/lib/juju/agents/unit-mysql-2/charm/venv/requests/sessions.py", line 703, in send
    r = adapter.send(request, **kwargs)
  File "/var/lib/juju/agents/unit-mysql-2/charm/venv/requests/adapters.py", line 519, in send
    raise ConnectionError(e, request=request)
requests.exceptions.ConnectionError: HTTPConnectionPool(host='juju-612b1f-4.lxd', port=4318): Max retries exceeded with url: /v1/traces (Caused by NewConnectionError('<urllib3.connection.HTTPConnection object at 0x7ffb479cb3a0>: Failed to establish a new connection: [Errno 111] Connection refused'))
unit-mysql-0: 01:33:56 ERROR unit.mysql/0.juju-log cos-agent:19: Exception while exporting Span batch.
Traceback (most recent call last):
  File "/var/lib/juju/agents/unit-mysql-0/charm/venv/urllib3/connection.py", line 174, in _new_conn
    conn = connection.create_connection(
  File "/var/lib/juju/agents/unit-mysql-0/charm/venv/urllib3/util/connection.py", line 95, in create_connection
    raise err
  File "/var/lib/juju/agents/unit-mysql-0/charm/venv/urllib3/util/connection.py", line 85, in create_connection
    sock.connect(sa)
ConnectionRefusedError: [Errno 111] Connection refused

During handling of the above exception, another exception occurred:

Traceback (most recent call last):
  File "/var/lib/juju/agents/unit-mysql-0/charm/venv/urllib3/connectionpool.py", line 715, in urlopen
    httplib_response = self._make_request(
  File "/var/lib/juju/agents/unit-mysql-0/charm/venv/urllib3/connectionpool.py", line 416, in _make_request
    conn.request(method, url, **httplib_request_kw)
  File "/var/lib/juju/agents/unit-mysql-0/charm/venv/urllib3/connection.py", line 244, in request
    super(HTTPConnection, self).request(method, url, body=body, headers=headers)
  File "/usr/lib/python3.10/http/client.py", line 1283, in request
    self._send_request(method, url, body, headers, encode_chunked)
  File "/usr/lib/python3.10/http/client.py", line 1329, in _send_request
    self.endheaders(body, encode_chunked=encode_chunked)
  File "/usr/lib/python3.10/http/client.py", line 1278, in endheaders
    self._send_output(message_body, encode_chunked=encode_chunked)
  File "/usr/lib/python3.10/http/client.py", line 1038, in _send_output
    self.send(msg)
  File "/usr/lib/python3.10/http/client.py", line 976, in send
    self.connect()
  File "/var/lib/juju/agents/unit-mysql-0/charm/venv/urllib3/connection.py", line 205, in connect
    conn = self._new_conn()
  File "/var/lib/juju/agents/unit-mysql-0/charm/venv/urllib3/connection.py", line 186, in _new_conn
    raise NewConnectionError(
urllib3.exceptions.NewConnectionError: <urllib3.connection.HTTPConnection object at 0x7fd4f2f28fa0>: Failed to establish a new connection: [Errno 111] Connection refused

During handling of the above exception, another exception occurred:

Traceback (most recent call last):
  File "/var/lib/juju/agents/unit-mysql-0/charm/venv/requests/adapters.py", line 486, in send
    resp = conn.urlopen(
  File "/var/lib/juju/agents/unit-mysql-0/charm/venv/urllib3/connectionpool.py", line 801, in urlopen
    retries = retries.increment(
  File "/var/lib/juju/agents/unit-mysql-0/charm/venv/urllib3/util/retry.py", line 594, in increment
    raise MaxRetryError(_pool, url, error or ResponseError(cause))
urllib3.exceptions.MaxRetryError: HTTPConnectionPool(host='juju-612b1f-2.lxd', port=4318): Max retries exceeded with url: /v1/traces (Caused by NewConnectionError('<urllib3.connection.HTTPConnection object at 0x7fd4f2f28fa0>: Failed to establish a new connection: [Errno 111] Connection refused'))

During handling of the above exception, another exception occurred:

Traceback (most recent call last):
  File "/var/lib/juju/agents/unit-mysql-0/charm/venv/opentelemetry/sdk/trace/export/__init__.py", line 368, in _export_batch
    self.span_exporter.export(self.spans_list[:idx])  # type: ignore
  File "/var/lib/juju/agents/unit-mysql-0/charm/venv/opentelemetry/exporter/otlp/proto/http/trace_exporter/__init__.py", line 145, in export
    resp = self._export(serialized_data)
  File "/var/lib/juju/agents/unit-mysql-0/charm/venv/opentelemetry/exporter/otlp/proto/http/trace_exporter/__init__.py", line 114, in _export
    return self._session.post(
  File "/var/lib/juju/agents/unit-mysql-0/charm/venv/requests/sessions.py", line 637, in post
    return self.request("POST", url, data=data, json=json, **kwargs)
  File "/var/lib/juju/agents/unit-mysql-0/charm/venv/requests/sessions.py", line 589, in request
    resp = self.send(prep, **send_kwargs)
  File "/var/lib/juju/agents/unit-mysql-0/charm/venv/requests/sessions.py", line 703, in send
    r = adapter.send(request, **kwargs)
  File "/var/lib/juju/agents/unit-mysql-0/charm/venv/requests/adapters.py", line 519, in send
    raise ConnectionError(e, request=request)
requests.exceptions.ConnectionError: HTTPConnectionPool(host='juju-612b1f-2.lxd', port=4318): Max retries exceeded with url: /v1/traces (Caused by NewConnectionError('<urllib3.connection.HTTPConnection object at 0x7fd4f2f28fa0>: Failed to establish a new connection: [Errno 111] Connection refused'))
unit-mysql-2: 01:33:57 ERROR unit.mysql/2.juju-log database:13: Exception while exporting Span batch.
Traceback (most recent call last):
  File "/var/lib/juju/agents/unit-mysql-2/charm/venv/urllib3/connection.py", line 174, in _new_conn
    conn = connection.create_connection(
  File "/var/lib/juju/agents/unit-mysql-2/charm/venv/urllib3/util/connection.py", line 95, in create_connection
    raise err
  File "/var/lib/juju/agents/unit-mysql-2/charm/venv/urllib3/util/connection.py", line 85, in create_connection
    sock.connect(sa)
ConnectionRefusedError: [Errno 111] Connection refused

During handling of the above exception, another exception occurred:

Traceback (most recent call last):
  File "/var/lib/juju/agents/unit-mysql-2/charm/venv/urllib3/connectionpool.py", line 715, in urlopen
    httplib_response = self._make_request(
  File "/var/lib/juju/agents/unit-mysql-2/charm/venv/urllib3/connectionpool.py", line 416, in _make_request
    conn.request(method, url, **httplib_request_kw)
  File "/var/lib/juju/agents/unit-mysql-2/charm/venv/urllib3/connection.py", line 244, in request
    super(HTTPConnection, self).request(method, url, body=body, headers=headers)
  File "/usr/lib/python3.10/http/client.py", line 1283, in request
    self._send_request(method, url, body, headers, encode_chunked)
  File "/usr/lib/python3.10/http/client.py", line 1329, in _send_request
    self.endheaders(body, encode_chunked=encode_chunked)
  File "/usr/lib/python3.10/http/client.py", line 1278, in endheaders
    self._send_output(message_body, encode_chunked=encode_chunked)
  File "/usr/lib/python3.10/http/client.py", line 1038, in _send_output
    self.send(msg)
  File "/usr/lib/python3.10/http/client.py", line 976, in send
    self.connect()
  File "/var/lib/juju/agents/unit-mysql-2/charm/venv/urllib3/connection.py", line 205, in connect
    conn = self._new_conn()
  File "/var/lib/juju/agents/unit-mysql-2/charm/venv/urllib3/connection.py", line 186, in _new_conn
    raise NewConnectionError(
urllib3.exceptions.NewConnectionError: <urllib3.connection.HTTPConnection object at 0x7efee215b490>: Failed to establish a new connection: [Errno 111] Connection refused

During handling of the above exception, another exception occurred:

Traceback (most recent call last):
  File "/var/lib/juju/agents/unit-mysql-2/charm/venv/requests/adapters.py", line 486, in send
    resp = conn.urlopen(
  File "/var/lib/juju/agents/unit-mysql-2/charm/venv/urllib3/connectionpool.py", line 801, in urlopen
    retries = retries.increment(
  File "/var/lib/juju/agents/unit-mysql-2/charm/venv/urllib3/util/retry.py", line 594, in increment
    raise MaxRetryError(_pool, url, error or ResponseError(cause))
urllib3.exceptions.MaxRetryError: HTTPConnectionPool(host='juju-612b1f-4.lxd', port=4318): Max retries exceeded with url: /v1/traces (Caused by NewConnectionError('<urllib3.connection.HTTPConnection object at 0x7efee215b490>: Failed to establish a new connection: [Errno 111] Connection refused'))

During handling of the above exception, another exception occurred:

Traceback (most recent call last):
  File "/var/lib/juju/agents/unit-mysql-2/charm/venv/opentelemetry/sdk/trace/export/__init__.py", line 368, in _export_batch
    self.span_exporter.export(self.spans_list[:idx])  # type: ignore
  File "/var/lib/juju/agents/unit-mysql-2/charm/venv/opentelemetry/exporter/otlp/proto/http/trace_exporter/__init__.py", line 145, in export
    resp = self._export(serialized_data)
  File "/var/lib/juju/agents/unit-mysql-2/charm/venv/opentelemetry/exporter/otlp/proto/http/trace_exporter/__init__.py", line 114, in _export
    return self._session.post(
  File "/var/lib/juju/agents/unit-mysql-2/charm/venv/requests/sessions.py", line 637, in post
    return self.request("POST", url, data=data, json=json, **kwargs)
  File "/var/lib/juju/agents/unit-mysql-2/charm/venv/requests/sessions.py", line 589, in request
    resp = self.send(prep, **send_kwargs)
  File "/var/lib/juju/agents/unit-mysql-2/charm/venv/requests/sessions.py", line 703, in send
    r = adapter.send(request, **kwargs)
  File "/var/lib/juju/agents/unit-mysql-2/charm/venv/requests/adapters.py", line 519, in send
    raise ConnectionError(e, request=request)
requests.exceptions.ConnectionError: HTTPConnectionPool(host='juju-612b1f-4.lxd', port=4318): Max retries exceeded with url: /v1/traces (Caused by NewConnectionError('<urllib3.connection.HTTPConnection object at 0x7efee215b490>: Failed to establish a new connection: [Errno 111] Connection refused'))
unit-mysql-2: 01:33:58 ERROR unit.mysql/2.juju-log database-peers:2: Exception while exporting Span batch.
Traceback (most recent call last):
  File "/var/lib/juju/agents/unit-mysql-2/charm/venv/urllib3/connection.py", line 174, in _new_conn
    conn = connection.create_connection(
  File "/var/lib/juju/agents/unit-mysql-2/charm/venv/urllib3/util/connection.py", line 95, in create_connection
    raise err
  File "/var/lib/juju/agents/unit-mysql-2/charm/venv/urllib3/util/connection.py", line 85, in create_connection
    sock.connect(sa)
ConnectionRefusedError: [Errno 111] Connection refused

During handling of the above exception, another exception occurred:

Traceback (most recent call last):
  File "/var/lib/juju/agents/unit-mysql-2/charm/venv/urllib3/connectionpool.py", line 715, in urlopen
    httplib_response = self._make_request(
  File "/var/lib/juju/agents/unit-mysql-2/charm/venv/urllib3/connectionpool.py", line 416, in _make_request
    conn.request(method, url, **httplib_request_kw)
  File "/var/lib/juju/agents/unit-mysql-2/charm/venv/urllib3/connection.py", line 244, in request
    super(HTTPConnection, self).request(method, url, body=body, headers=headers)
  File "/usr/lib/python3.10/http/client.py", line 1283, in request
    self._send_request(method, url, body, headers, encode_chunked)
  File "/usr/lib/python3.10/http/client.py", line 1329, in _send_request
    self.endheaders(body, encode_chunked=encode_chunked)
  File "/usr/lib/python3.10/http/client.py", line 1278, in endheaders
    self._send_output(message_body, encode_chunked=encode_chunked)
  File "/usr/lib/python3.10/http/client.py", line 1038, in _send_output
    self.send(msg)
  File "/usr/lib/python3.10/http/client.py", line 976, in send
    self.connect()
  File "/var/lib/juju/agents/unit-mysql-2/charm/venv/urllib3/connection.py", line 205, in connect
    conn = self._new_conn()
  File "/var/lib/juju/agents/unit-mysql-2/charm/venv/urllib3/connection.py", line 186, in _new_conn
    raise NewConnectionError(
urllib3.exceptions.NewConnectionError: <urllib3.connection.HTTPConnection object at 0x7f9c42f8af80>: Failed to establish a new connection: [Errno 111] Connection refused

During handling of the above exception, another exception occurred:

Traceback (most recent call last):
  File "/var/lib/juju/agents/unit-mysql-2/charm/venv/requests/adapters.py", line 486, in send
    resp = conn.urlopen(
  File "/var/lib/juju/agents/unit-mysql-2/charm/venv/urllib3/connectionpool.py", line 801, in urlopen
    retries = retries.increment(
  File "/var/lib/juju/agents/unit-mysql-2/charm/venv/urllib3/util/retry.py", line 594, in increment
    raise MaxRetryError(_pool, url, error or ResponseError(cause))
urllib3.exceptions.MaxRetryError: HTTPConnectionPool(host='juju-612b1f-4.lxd', port=4318): Max retries exceeded with url: /v1/traces (Caused by NewConnectionError('<urllib3.connection.HTTPConnection object at 0x7f9c42f8af80>: Failed to establish a new connection: [Errno 111] Connection refused'))

During handling of the above exception, another exception occurred:

Traceback (most recent call last):
  File "/var/lib/juju/agents/unit-mysql-2/charm/venv/opentelemetry/sdk/trace/export/__init__.py", line 368, in _export_batch
    self.span_exporter.export(self.spans_list[:idx])  # type: ignore
  File "/var/lib/juju/agents/unit-mysql-2/charm/venv/opentelemetry/exporter/otlp/proto/http/trace_exporter/__init__.py", line 145, in export
    resp = self._export(serialized_data)
  File "/var/lib/juju/agents/unit-mysql-2/charm/venv/opentelemetry/exporter/otlp/proto/http/trace_exporter/__init__.py", line 114, in _export
    return self._session.post(
  File "/var/lib/juju/agents/unit-mysql-2/charm/venv/requests/sessions.py", line 637, in post
    return self.request("POST", url, data=data, json=json, **kwargs)
  File "/var/lib/juju/agents/unit-mysql-2/charm/venv/requests/sessions.py", line 589, in request
    resp = self.send(prep, **send_kwargs)
  File "/var/lib/juju/agents/unit-mysql-2/charm/venv/requests/sessions.py", line 703, in send
    r = adapter.send(request, **kwargs)
  File "/var/lib/juju/agents/unit-mysql-2/charm/venv/requests/adapters.py", line 519, in send
    raise ConnectionError(e, request=request)
requests.exceptions.ConnectionError: HTTPConnectionPool(host='juju-612b1f-4.lxd', port=4318): Max retries exceeded with url: /v1/traces (Caused by NewConnectionError('<urllib3.connection.HTTPConnection object at 0x7f9c42f8af80>: Failed to establish a new connection: [Errno 111] Connection refused'))
unit-mysql-0: 01:34:00 ERROR unit.mysql/0.juju-log restart:3: Exception while exporting Span batch.
Traceback (most recent call last):
  File "/var/lib/juju/agents/unit-mysql-0/charm/venv/urllib3/connection.py", line 174, in _new_conn
    conn = connection.create_connection(
  File "/var/lib/juju/agents/unit-mysql-0/charm/venv/urllib3/util/connection.py", line 95, in create_connection
    raise err
  File "/var/lib/juju/agents/unit-mysql-0/charm/venv/urllib3/util/connection.py", line 85, in create_connection
    sock.connect(sa)
ConnectionRefusedError: [Errno 111] Connection refused

During handling of the above exception, another exception occurred:

Traceback (most recent call last):
  File "/var/lib/juju/agents/unit-mysql-0/charm/venv/urllib3/connectionpool.py", line 715, in urlopen
    httplib_response = self._make_request(
  File "/var/lib/juju/agents/unit-mysql-0/charm/venv/urllib3/connectionpool.py", line 416, in _make_request
    conn.request(method, url, **httplib_request_kw)
  File "/var/lib/juju/agents/unit-mysql-0/charm/venv/urllib3/connection.py", line 244, in request
    super(HTTPConnection, self).request(method, url, body=body, headers=headers)
  File "/usr/lib/python3.10/http/client.py", line 1283, in request
    self._send_request(method, url, body, headers, encode_chunked)
  File "/usr/lib/python3.10/http/client.py", line 1329, in _send_request
    self.endheaders(body, encode_chunked=encode_chunked)
  File "/usr/lib/python3.10/http/client.py", line 1278, in endheaders
    self._send_output(message_body, encode_chunked=encode_chunked)
  File "/usr/lib/python3.10/http/client.py", line 1038, in _send_output
    self.send(msg)
  File "/usr/lib/python3.10/http/client.py", line 976, in send
    self.connect()
  File "/var/lib/juju/agents/unit-mysql-0/charm/venv/urllib3/connection.py", line 205, in connect
    conn = self._new_conn()
  File "/var/lib/juju/agents/unit-mysql-0/charm/venv/urllib3/connection.py", line 186, in _new_conn
    raise NewConnectionError(
urllib3.exceptions.NewConnectionError: <urllib3.connection.HTTPConnection object at 0x7f094bc31ed0>: Failed to establish a new connection: [Errno 111] Connection refused

During handling of the above exception, another exception occurred:

Traceback (most recent call last):
  File "/var/lib/juju/agents/unit-mysql-0/charm/venv/requests/adapters.py", line 486, in send
    resp = conn.urlopen(
  File "/var/lib/juju/agents/unit-mysql-0/charm/venv/urllib3/connectionpool.py", line 801, in urlopen
    retries = retries.increment(
  File "/var/lib/juju/agents/unit-mysql-0/charm/venv/urllib3/util/retry.py", line 594, in increment
    raise MaxRetryError(_pool, url, error or ResponseError(cause))
urllib3.exceptions.MaxRetryError: HTTPConnectionPool(host='juju-612b1f-2.lxd', port=4318): Max retries exceeded with url: /v1/traces (Caused by NewConnectionError('<urllib3.connection.HTTPConnection object at 0x7f094bc31ed0>: Failed to establish a new connection: [Errno 111] Connection refused'))

During handling of the above exception, another exception occurred:

Traceback (most recent call last):
  File "/var/lib/juju/agents/unit-mysql-0/charm/venv/opentelemetry/sdk/trace/export/__init__.py", line 368, in _export_batch
    self.span_exporter.export(self.spans_list[:idx])  # type: ignore
  File "/var/lib/juju/agents/unit-mysql-0/charm/venv/opentelemetry/exporter/otlp/proto/http/trace_exporter/__init__.py", line 145, in export
    resp = self._export(serialized_data)
  File "/var/lib/juju/agents/unit-mysql-0/charm/venv/opentelemetry/exporter/otlp/proto/http/trace_exporter/__init__.py", line 114, in _export
    return self._session.post(
  File "/var/lib/juju/agents/unit-mysql-0/charm/venv/requests/sessions.py", line 637, in post
    return self.request("POST", url, data=data, json=json, **kwargs)
  File "/var/lib/juju/agents/unit-mysql-0/charm/venv/requests/sessions.py", line 589, in request
    resp = self.send(prep, **send_kwargs)
  File "/var/lib/juju/agents/unit-mysql-0/charm/venv/requests/sessions.py", line 703, in send
    r = adapter.send(request, **kwargs)
  File "/var/lib/juju/agents/unit-mysql-0/charm/venv/requests/adapters.py", line 519, in send
    raise ConnectionError(e, request=request)
requests.exceptions.ConnectionError: HTTPConnectionPool(host='juju-612b1f-2.lxd', port=4318): Max retries exceeded with url: /v1/traces (Caused by NewConnectionError('<urllib3.connection.HTTPConnection object at 0x7f094bc31ed0>: Failed to establish a new connection: [Errno 111] Connection refused'))
unit-mysql-2: 01:34:01 ERROR unit.mysql/2.juju-log restart:3: Exception while exporting Span batch.
Traceback (most recent call last):
  File "/var/lib/juju/agents/unit-mysql-2/charm/venv/urllib3/connection.py", line 174, in _new_conn
    conn = connection.create_connection(
  File "/var/lib/juju/agents/unit-mysql-2/charm/venv/urllib3/util/connection.py", line 95, in create_connection
    raise err
  File "/var/lib/juju/agents/unit-mysql-2/charm/venv/urllib3/util/connection.py", line 85, in create_connection
    sock.connect(sa)
ConnectionRefusedError: [Errno 111] Connection refused

During handling of the above exception, another exception occurred:

Traceback (most recent call last):
  File "/var/lib/juju/agents/unit-mysql-2/charm/venv/urllib3/connectionpool.py", line 715, in urlopen
    httplib_response = self._make_request(
  File "/var/lib/juju/agents/unit-mysql-2/charm/venv/urllib3/connectionpool.py", line 416, in _make_request
    conn.request(method, url, **httplib_request_kw)
  File "/var/lib/juju/agents/unit-mysql-2/charm/venv/urllib3/connection.py", line 244, in request
    super(HTTPConnection, self).request(method, url, body=body, headers=headers)
  File "/usr/lib/python3.10/http/client.py", line 1283, in request
    self._send_request(method, url, body, headers, encode_chunked)
  File "/usr/lib/python3.10/http/client.py", line 1329, in _send_request
    self.endheaders(body, encode_chunked=encode_chunked)
  File "/usr/lib/python3.10/http/client.py", line 1278, in endheaders
    self._send_output(message_body, encode_chunked=encode_chunked)
  File "/usr/lib/python3.10/http/client.py", line 1038, in _send_output
    self.send(msg)
  File "/usr/lib/python3.10/http/client.py", line 976, in send
    self.connect()
  File "/var/lib/juju/agents/unit-mysql-2/charm/venv/urllib3/connection.py", line 205, in connect
    conn = self._new_conn()
  File "/var/lib/juju/agents/unit-mysql-2/charm/venv/urllib3/connection.py", line 186, in _new_conn
    raise NewConnectionError(
urllib3.exceptions.NewConnectionError: <urllib3.connection.HTTPConnection object at 0x7f1bcd58e8f0>: Failed to establish a new connection: [Errno 111] Connection refused

During handling of the above exception, another exception occurred:

Traceback (most recent call last):
  File "/var/lib/juju/agents/unit-mysql-2/charm/venv/requests/adapters.py", line 486, in send
    resp = conn.urlopen(
  File "/var/lib/juju/agents/unit-mysql-2/charm/venv/urllib3/connectionpool.py", line 801, in urlopen
    retries = retries.increment(
  File "/var/lib/juju/agents/unit-mysql-2/charm/venv/urllib3/util/retry.py", line 594, in increment
    raise MaxRetryError(_pool, url, error or ResponseError(cause))
urllib3.exceptions.MaxRetryError: HTTPConnectionPool(host='juju-612b1f-4.lxd', port=4318): Max retries exceeded with url: /v1/traces (Caused by NewConnectionError('<urllib3.connection.HTTPConnection object at 0x7f1bcd58e8f0>: Failed to establish a new connection: [Errno 111] Connection refused'))

During handling of the above exception, another exception occurred:

Traceback (most recent call last):
  File "/var/lib/juju/agents/unit-mysql-2/charm/venv/opentelemetry/sdk/trace/export/__init__.py", line 368, in _export_batch
    self.span_exporter.export(self.spans_list[:idx])  # type: ignore
  File "/var/lib/juju/agents/unit-mysql-2/charm/venv/opentelemetry/exporter/otlp/proto/http/trace_exporter/__init__.py", line 145, in export
    resp = self._export(serialized_data)
  File "/var/lib/juju/agents/unit-mysql-2/charm/venv/opentelemetry/exporter/otlp/proto/http/trace_exporter/__init__.py", line 114, in _export
    return self._session.post(
  File "/var/lib/juju/agents/unit-mysql-2/charm/venv/requests/sessions.py", line 637, in post
    return self.request("POST", url, data=data, json=json, **kwargs)
  File "/var/lib/juju/agents/unit-mysql-2/charm/venv/requests/sessions.py", line 589, in request
    resp = self.send(prep, **send_kwargs)
  File "/var/lib/juju/agents/unit-mysql-2/charm/venv/requests/sessions.py", line 703, in send
    r = adapter.send(request, **kwargs)
  File "/var/lib/juju/agents/unit-mysql-2/charm/venv/requests/adapters.py", line 519, in send
    raise ConnectionError(e, request=request)
requests.exceptions.ConnectionError: HTTPConnectionPool(host='juju-612b1f-4.lxd', port=4318): Max retries exceeded with url: /v1/traces (Caused by NewConnectionError('<urllib3.connection.HTTPConnection object at 0x7f1bcd58e8f0>: Failed to establish a new connection: [Errno 111] Connection refused'))
unit-mysql-2: 01:34:02 ERROR unit.mysql/2.juju-log s3-parameters:16: Exception while exporting Span batch.
Traceback (most recent call last):
  File "/var/lib/juju/agents/unit-mysql-2/charm/venv/urllib3/connection.py", line 174, in _new_conn
    conn = connection.create_connection(
  File "/var/lib/juju/agents/unit-mysql-2/charm/venv/urllib3/util/connection.py", line 95, in create_connection
    raise err
  File "/var/lib/juju/agents/unit-mysql-2/charm/venv/urllib3/util/connection.py", line 85, in create_connection
    sock.connect(sa)
ConnectionRefusedError: [Errno 111] Connection refused

During handling of the above exception, another exception occurred:

Traceback (most recent call last):
  File "/var/lib/juju/agents/unit-mysql-2/charm/venv/urllib3/connectionpool.py", line 715, in urlopen
    httplib_response = self._make_request(
  File "/var/lib/juju/agents/unit-mysql-2/charm/venv/urllib3/connectionpool.py", line 416, in _make_request
    conn.request(method, url, **httplib_request_kw)
  File "/var/lib/juju/agents/unit-mysql-2/charm/venv/urllib3/connection.py", line 244, in request
    super(HTTPConnection, self).request(method, url, body=body, headers=headers)
  File "/usr/lib/python3.10/http/client.py", line 1283, in request
    self._send_request(method, url, body, headers, encode_chunked)
  File "/usr/lib/python3.10/http/client.py", line 1329, in _send_request
    self.endheaders(body, encode_chunked=encode_chunked)
  File "/usr/lib/python3.10/http/client.py", line 1278, in endheaders
    self._send_output(message_body, encode_chunked=encode_chunked)
  File "/usr/lib/python3.10/http/client.py", line 1038, in _send_output
    self.send(msg)
  File "/usr/lib/python3.10/http/client.py", line 976, in send
    self.connect()
  File "/var/lib/juju/agents/unit-mysql-2/charm/venv/urllib3/connection.py", line 205, in connect
    conn = self._new_conn()
  File "/var/lib/juju/agents/unit-mysql-2/charm/venv/urllib3/connection.py", line 186, in _new_conn
    raise NewConnectionError(
urllib3.exceptions.NewConnectionError: <urllib3.connection.HTTPConnection object at 0x7f4d67b8b340>: Failed to establish a new connection: [Errno 111] Connection refused

During handling of the above exception, another exception occurred:

Traceback (most recent call last):
  File "/var/lib/juju/agents/unit-mysql-2/charm/venv/requests/adapters.py", line 486, in send
    resp = conn.urlopen(
  File "/var/lib/juju/agents/unit-mysql-2/charm/venv/urllib3/connectionpool.py", line 801, in urlopen
    retries = retries.increment(
  File "/var/lib/juju/agents/unit-mysql-2/charm/venv/urllib3/util/retry.py", line 594, in increment
    raise MaxRetryError(_pool, url, error or ResponseError(cause))
urllib3.exceptions.MaxRetryError: HTTPConnectionPool(host='juju-612b1f-4.lxd', port=4318): Max retries exceeded with url: /v1/traces (Caused by NewConnectionError('<urllib3.connection.HTTPConnection object at 0x7f4d67b8b340>: Failed to establish a new connection: [Errno 111] Connection refused'))

During handling of the above exception, another exception occurred:

Traceback (most recent call last):
  File "/var/lib/juju/agents/unit-mysql-2/charm/venv/opentelemetry/sdk/trace/export/__init__.py", line 368, in _export_batch
    self.span_exporter.export(self.spans_list[:idx])  # type: ignore
  File "/var/lib/juju/agents/unit-mysql-2/charm/venv/opentelemetry/exporter/otlp/proto/http/trace_exporter/__init__.py", line 145, in export
    resp = self._export(serialized_data)
  File "/var/lib/juju/agents/unit-mysql-2/charm/venv/opentelemetry/exporter/otlp/proto/http/trace_exporter/__init__.py", line 114, in _export
    return self._session.post(
  File "/var/lib/juju/agents/unit-mysql-2/charm/venv/requests/sessions.py", line 637, in post
    return self.request("POST", url, data=data, json=json, **kwargs)
  File "/var/lib/juju/agents/unit-mysql-2/charm/venv/requests/sessions.py", line 589, in request
    resp = self.send(prep, **send_kwargs)
  File "/var/lib/juju/agents/unit-mysql-2/charm/venv/requests/sessions.py", line 703, in send
    r = adapter.send(request, **kwargs)
  File "/var/lib/juju/agents/unit-mysql-2/charm/venv/requests/adapters.py", line 519, in send
    raise ConnectionError(e, request=request)
requests.exceptions.ConnectionError: HTTPConnectionPool(host='juju-612b1f-4.lxd', port=4318): Max retries exceeded with url: /v1/traces (Caused by NewConnectionError('<urllib3.connection.HTTPConnection object at 0x7f4d67b8b340>: Failed to establish a new connection: [Errno 111] Connection refused'))
unit-mysql-0: 01:34:04 ERROR unit.mysql/0.juju-log upgrade:1: Exception while exporting Span batch.
Traceback (most recent call last):
  File "/var/lib/juju/agents/unit-mysql-0/charm/venv/urllib3/connection.py", line 174, in _new_conn
    conn = connection.create_connection(
  File "/var/lib/juju/agents/unit-mysql-0/charm/venv/urllib3/util/connection.py", line 95, in create_connection
    raise err
  File "/var/lib/juju/agents/unit-mysql-0/charm/venv/urllib3/util/connection.py", line 85, in create_connection
    sock.connect(sa)
ConnectionRefusedError: [Errno 111] Connection refused

During handling of the above exception, another exception occurred:

Traceback (most recent call last):
  File "/var/lib/juju/agents/unit-mysql-0/charm/venv/urllib3/connectionpool.py", line 715, in urlopen
    httplib_response = self._make_request(
  File "/var/lib/juju/agents/unit-mysql-0/charm/venv/urllib3/connectionpool.py", line 416, in _make_request
    conn.request(method, url, **httplib_request_kw)
  File "/var/lib/juju/agents/unit-mysql-0/charm/venv/urllib3/connection.py", line 244, in request
    super(HTTPConnection, self).request(method, url, body=body, headers=headers)
  File "/usr/lib/python3.10/http/client.py", line 1283, in request
    self._send_request(method, url, body, headers, encode_chunked)
  File "/usr/lib/python3.10/http/client.py", line 1329, in _send_request
    self.endheaders(body, encode_chunked=encode_chunked)
  File "/usr/lib/python3.10/http/client.py", line 1278, in endheaders
    self._send_output(message_body, encode_chunked=encode_chunked)
  File "/usr/lib/python3.10/http/client.py", line 1038, in _send_output
    self.send(msg)
  File "/usr/lib/python3.10/http/client.py", line 976, in send
    self.connect()
  File "/var/lib/juju/agents/unit-mysql-0/charm/venv/urllib3/connection.py", line 205, in connect
    conn = self._new_conn()
  File "/var/lib/juju/agents/unit-mysql-0/charm/venv/urllib3/connection.py", line 186, in _new_conn
    raise NewConnectionError(
urllib3.exceptions.NewConnectionError: <urllib3.connection.HTTPConnection object at 0x7fa39ebddf90>: Failed to establish a new connection: [Errno 111] Connection refused

During handling of the above exception, another exception occurred:

Traceback (most recent call last):
  File "/var/lib/juju/agents/unit-mysql-0/charm/venv/requests/adapters.py", line 486, in send
    resp = conn.urlopen(
  File "/var/lib/juju/agents/unit-mysql-0/charm/venv/urllib3/connectionpool.py", line 801, in urlopen
    retries = retries.increment(
  File "/var/lib/juju/agents/unit-mysql-0/charm/venv/urllib3/util/retry.py", line 594, in increment
    raise MaxRetryError(_pool, url, error or ResponseError(cause))
urllib3.exceptions.MaxRetryError: HTTPConnectionPool(host='juju-612b1f-2.lxd', port=4318): Max retries exceeded with url: /v1/traces (Caused by NewConnectionError('<urllib3.connection.HTTPConnection object at 0x7fa39ebddf90>: Failed to establish a new connection: [Errno 111] Connection refused'))

During handling of the above exception, another exception occurred:

Traceback (most recent call last):
  File "/var/lib/juju/agents/unit-mysql-0/charm/venv/opentelemetry/sdk/trace/export/__init__.py", line 368, in _export_batch
    self.span_exporter.export(self.spans_list[:idx])  # type: ignore
  File "/var/lib/juju/agents/unit-mysql-0/charm/venv/opentelemetry/exporter/otlp/proto/http/trace_exporter/__init__.py", line 145, in export
    resp = self._export(serialized_data)
  File "/var/lib/juju/agents/unit-mysql-0/charm/venv/opentelemetry/exporter/otlp/proto/http/trace_exporter/__init__.py", line 114, in _export
    return self._session.post(
  File "/var/lib/juju/agents/unit-mysql-0/charm/venv/requests/sessions.py", line 637, in post
    return self.request("POST", url, data=data, json=json, **kwargs)
  File "/var/lib/juju/agents/unit-mysql-0/charm/venv/requests/sessions.py", line 589, in request
    resp = self.send(prep, **send_kwargs)
  File "/var/lib/juju/agents/unit-mysql-0/charm/venv/requests/sessions.py", line 703, in send
    r = adapter.send(request, **kwargs)
  File "/var/lib/juju/agents/unit-mysql-0/charm/venv/requests/adapters.py", line 519, in send
    raise ConnectionError(e, request=request)
requests.exceptions.ConnectionError: HTTPConnectionPool(host='juju-612b1f-2.lxd', port=4318): Max retries exceeded with url: /v1/traces (Caused by NewConnectionError('<urllib3.connection.HTTPConnection object at 0x7fa39ebddf90>: Failed to establish a new connection: [Errno 111] Connection refused'))
unit-mysql-2: 01:34:06 ERROR unit.mysql/2.juju-log s3-parameters:16: Exception while exporting Span batch.
Traceback (most recent call last):
  File "/var/lib/juju/agents/unit-mysql-2/charm/venv/urllib3/connection.py", line 174, in _new_conn
    conn = connection.create_connection(
  File "/var/lib/juju/agents/unit-mysql-2/charm/venv/urllib3/util/connection.py", line 95, in create_connection
    raise err
  File "/var/lib/juju/agents/unit-mysql-2/charm/venv/urllib3/util/connection.py", line 85, in create_connection
    sock.connect(sa)
ConnectionRefusedError: [Errno 111] Connection refused

During handling of the above exception, another exception occurred:

Traceback (most recent call last):
  File "/var/lib/juju/agents/unit-mysql-2/charm/venv/urllib3/connectionpool.py", line 715, in urlopen
    httplib_response = self._make_request(
  File "/var/lib/juju/agents/unit-mysql-2/charm/venv/urllib3/connectionpool.py", line 416, in _make_request
    conn.request(method, url, **httplib_request_kw)
  File "/var/lib/juju/agents/unit-mysql-2/charm/venv/urllib3/connection.py", line 244, in request
    super(HTTPConnection, self).request(method, url, body=body, headers=headers)
  File "/usr/lib/python3.10/http/client.py", line 1283, in request
    self._send_request(method, url, body, headers, encode_chunked)
  File "/usr/lib/python3.10/http/client.py", line 1329, in _send_request
    self.endheaders(body, encode_chunked=encode_chunked)
  File "/usr/lib/python3.10/http/client.py", line 1278, in endheaders
    self._send_output(message_body, encode_chunked=encode_chunked)
  File "/usr/lib/python3.10/http/client.py", line 1038, in _send_output
    self.send(msg)
  File "/usr/lib/python3.10/http/client.py", line 976, in send
    self.connect()
  File "/var/lib/juju/agents/unit-mysql-2/charm/venv/urllib3/connection.py", line 205, in connect
    conn = self._new_conn()
  File "/var/lib/juju/agents/unit-mysql-2/charm/venv/urllib3/connection.py", line 186, in _new_conn
    raise NewConnectionError(
urllib3.exceptions.NewConnectionError: <urllib3.connection.HTTPConnection object at 0x7f5bc92e3400>: Failed to establish a new connection: [Errno 111] Connection refused

During handling of the above exception, another exception occurred:

Traceback (most recent call last):
  File "/var/lib/juju/agents/unit-mysql-2/charm/venv/requests/adapters.py", line 486, in send
    resp = conn.urlopen(
  File "/var/lib/juju/agents/unit-mysql-2/charm/venv/urllib3/connectionpool.py", line 801, in urlopen
    retries = retries.increment(
  File "/var/lib/juju/agents/unit-mysql-2/charm/venv/urllib3/util/retry.py", line 594, in increment
    raise MaxRetryError(_pool, url, error or ResponseError(cause))
urllib3.exceptions.MaxRetryError: HTTPConnectionPool(host='juju-612b1f-4.lxd', port=4318): Max retries exceeded with url: /v1/traces (Caused by NewConnectionError('<urllib3.connection.HTTPConnection object at 0x7f5bc92e3400>: Failed to establish a new connection: [Errno 111] Connection refused'))

During handling of the above exception, another exception occurred:

Traceback (most recent call last):
  File "/var/lib/juju/agents/unit-mysql-2/charm/venv/opentelemetry/sdk/trace/export/__init__.py", line 368, in _export_batch
    self.span_exporter.export(self.spans_list[:idx])  # type: ignore
  File "/var/lib/juju/agents/unit-mysql-2/charm/venv/opentelemetry/exporter/otlp/proto/http/trace_exporter/__init__.py", line 145, in export
    resp = self._export(serialized_data)
  File "/var/lib/juju/agents/unit-mysql-2/charm/venv/opentelemetry/exporter/otlp/proto/http/trace_exporter/__init__.py", line 114, in _export
    return self._session.post(
  File "/var/lib/juju/agents/unit-mysql-2/charm/venv/requests/sessions.py", line 637, in post
    return self.request("POST", url, data=data, json=json, **kwargs)
  File "/var/lib/juju/agents/unit-mysql-2/charm/venv/requests/sessions.py", line 589, in request
    resp = self.send(prep, **send_kwargs)
  File "/var/lib/juju/agents/unit-mysql-2/charm/venv/requests/sessions.py", line 703, in send
    r = adapter.send(request, **kwargs)
  File "/var/lib/juju/agents/unit-mysql-2/charm/venv/requests/adapters.py", line 519, in send
    raise ConnectionError(e, request=request)
requests.exceptions.ConnectionError: HTTPConnectionPool(host='juju-612b1f-4.lxd', port=4318): Max retries exceeded with url: /v1/traces (Caused by NewConnectionError('<urllib3.connection.HTTPConnection object at 0x7f5bc92e3400>: Failed to establish a new connection: [Errno 111] Connection refused'))
unit-mysql-2: 01:34:09 ERROR unit.mysql/2.juju-log certificates:14: Exception while exporting Span batch.
Traceback (most recent call last):
  File "/var/lib/juju/agents/unit-mysql-2/charm/venv/urllib3/connection.py", line 174, in _new_conn
    conn = connection.create_connection(
  File "/var/lib/juju/agents/unit-mysql-2/charm/venv/urllib3/util/connection.py", line 95, in create_connection
    raise err
  File "/var/lib/juju/agents/unit-mysql-2/charm/venv/urllib3/util/connection.py", line 85, in create_connection
    sock.connect(sa)
ConnectionRefusedError: [Errno 111] Connection refused

During handling of the above exception, another exception occurred:

Traceback (most recent call last):
  File "/var/lib/juju/agents/unit-mysql-2/charm/venv/urllib3/connectionpool.py", line 715, in urlopen
    httplib_response = self._make_request(
  File "/var/lib/juju/agents/unit-mysql-2/charm/venv/urllib3/connectionpool.py", line 416, in _make_request
    conn.request(method, url, **httplib_request_kw)
  File "/var/lib/juju/agents/unit-mysql-2/charm/venv/urllib3/connection.py", line 244, in request
    super(HTTPConnection, self).request(method, url, body=body, headers=headers)
  File "/usr/lib/python3.10/http/client.py", line 1283, in request
    self._send_request(method, url, body, headers, encode_chunked)
  File "/usr/lib/python3.10/http/client.py", line 1329, in _send_request
    self.endheaders(body, encode_chunked=encode_chunked)
  File "/usr/lib/python3.10/http/client.py", line 1278, in endheaders
    self._send_output(message_body, encode_chunked=encode_chunked)
  File "/usr/lib/python3.10/http/client.py", line 1038, in _send_output
    self.send(msg)
  File "/usr/lib/python3.10/http/client.py", line 976, in send
    self.connect()
  File "/var/lib/juju/agents/unit-mysql-2/charm/venv/urllib3/connection.py", line 205, in connect
    conn = self._new_conn()
  File "/var/lib/juju/agents/unit-mysql-2/charm/venv/urllib3/connection.py", line 186, in _new_conn
    raise NewConnectionError(
urllib3.exceptions.NewConnectionError: <urllib3.connection.HTTPConnection object at 0x7f43e63ee4d0>: Failed to establish a new connection: [Errno 111] Connection refused

During handling of the above exception, another exception occurred:

Traceback (most recent call last):
  File "/var/lib/juju/agents/unit-mysql-2/charm/venv/requests/adapters.py", line 486, in send
    resp = conn.urlopen(
  File "/var/lib/juju/agents/unit-mysql-2/charm/venv/urllib3/connectionpool.py", line 801, in urlopen
    retries = retries.increment(
  File "/var/lib/juju/agents/unit-mysql-2/charm/venv/urllib3/util/retry.py", line 594, in increment
    raise MaxRetryError(_pool, url, error or ResponseError(cause))
urllib3.exceptions.MaxRetryError: HTTPConnectionPool(host='juju-612b1f-4.lxd', port=4318): Max retries exceeded with url: /v1/traces (Caused by NewConnectionError('<urllib3.connection.HTTPConnection object at 0x7f43e63ee4d0>: Failed to establish a new connection: [Errno 111] Connection refused'))

During handling of the above exception, another exception occurred:

Traceback (most recent call last):
  File "/var/lib/juju/agents/unit-mysql-2/charm/venv/opentelemetry/sdk/trace/export/__init__.py", line 368, in _export_batch
    self.span_exporter.export(self.spans_list[:idx])  # type: ignore
  File "/var/lib/juju/agents/unit-mysql-2/charm/venv/opentelemetry/exporter/otlp/proto/http/trace_exporter/__init__.py", line 145, in export
    resp = self._export(serialized_data)
  File "/var/lib/juju/agents/unit-mysql-2/charm/venv/opentelemetry/exporter/otlp/proto/http/trace_exporter/__init__.py", line 114, in _export
    return self._session.post(
  File "/var/lib/juju/agents/unit-mysql-2/charm/venv/requests/sessions.py", line 637, in post
    return self.request("POST", url, data=data, json=json, **kwargs)
  File "/var/lib/juju/agents/unit-mysql-2/charm/venv/requests/sessions.py", line 589, in request
    resp = self.send(prep, **send_kwargs)
  File "/var/lib/juju/agents/unit-mysql-2/charm/venv/requests/sessions.py", line 703, in send
    r = adapter.send(request, **kwargs)
  File "/var/lib/juju/agents/unit-mysql-2/charm/venv/requests/adapters.py", line 519, in send
    raise ConnectionError(e, request=request)
requests.exceptions.ConnectionError: HTTPConnectionPool(host='juju-612b1f-4.lxd', port=4318): Max retries exceeded with url: /v1/traces (Caused by NewConnectionError('<urllib3.connection.HTTPConnection object at 0x7f43e63ee4d0>: Failed to establish a new connection: [Errno 111] Connection refused'))
unit-mysql-0: 01:34:09 ERROR unit.mysql/0.juju-log upgrade:1: Exception while exporting Span batch.
Traceback (most recent call last):
  File "/var/lib/juju/agents/unit-mysql-0/charm/venv/urllib3/connection.py", line 174, in _new_conn
    conn = connection.create_connection(
  File "/var/lib/juju/agents/unit-mysql-0/charm/venv/urllib3/util/connection.py", line 95, in create_connection
    raise err
  File "/var/lib/juju/agents/unit-mysql-0/charm/venv/urllib3/util/connection.py", line 85, in create_connection
    sock.connect(sa)
ConnectionRefusedError: [Errno 111] Connection refused

During handling of the above exception, another exception occurred:

Traceback (most recent call last):
  File "/var/lib/juju/agents/unit-mysql-0/charm/venv/urllib3/connectionpool.py", line 715, in urlopen
    httplib_response = self._make_request(
  File "/var/lib/juju/agents/unit-mysql-0/charm/venv/urllib3/connectionpool.py", line 416, in _make_request
    conn.request(method, url, **httplib_request_kw)
  File "/var/lib/juju/agents/unit-mysql-0/charm/venv/urllib3/connection.py", line 244, in request
    super(HTTPConnection, self).request(method, url, body=body, headers=headers)
  File "/usr/lib/python3.10/http/client.py", line 1283, in request
    self._send_request(method, url, body, headers, encode_chunked)
  File "/usr/lib/python3.10/http/client.py", line 1329, in _send_request
    self.endheaders(body, encode_chunked=encode_chunked)
  File "/usr/lib/python3.10/http/client.py", line 1278, in endheaders
    self._send_output(message_body, encode_chunked=encode_chunked)
  File "/usr/lib/python3.10/http/client.py", line 1038, in _send_output
    self.send(msg)
  File "/usr/lib/python3.10/http/client.py", line 976, in send
    self.connect()
  File "/var/lib/juju/agents/unit-mysql-0/charm/venv/urllib3/connection.py", line 205, in connect
    conn = self._new_conn()
  File "/var/lib/juju/agents/unit-mysql-0/charm/venv/urllib3/connection.py", line 186, in _new_conn
    raise NewConnectionError(
urllib3.exceptions.NewConnectionError: <urllib3.connection.HTTPConnection object at 0x7efddce75270>: Failed to establish a new connection: [Errno 111] Connection refused

During handling of the above exception, another exception occurred:

Traceback (most recent call last):
  File "/var/lib/juju/agents/unit-mysql-0/charm/venv/requests/adapters.py", line 486, in send
    resp = conn.urlopen(
  File "/var/lib/juju/agents/unit-mysql-0/charm/venv/urllib3/connectionpool.py", line 801, in urlopen
    retries = retries.increment(
  File "/var/lib/juju/agents/unit-mysql-0/charm/venv/urllib3/util/retry.py", line 594, in increment
    raise MaxRetryError(_pool, url, error or ResponseError(cause))
urllib3.exceptions.MaxRetryError: HTTPConnectionPool(host='juju-612b1f-2.lxd', port=4318): Max retries exceeded with url: /v1/traces (Caused by NewConnectionError('<urllib3.connection.HTTPConnection object at 0x7efddce75270>: Failed to establish a new connection: [Errno 111] Connection refused'))

During handling of the above exception, another exception occurred:

Traceback (most recent call last):
  File "/var/lib/juju/agents/unit-mysql-0/charm/venv/opentelemetry/sdk/trace/export/__init__.py", line 368, in _export_batch
    self.span_exporter.export(self.spans_list[:idx])  # type: ignore
  File "/var/lib/juju/agents/unit-mysql-0/charm/venv/opentelemetry/exporter/otlp/proto/http/trace_exporter/__init__.py", line 145, in export
    resp = self._export(serialized_data)
  File "/var/lib/juju/agents/unit-mysql-0/charm/venv/opentelemetry/exporter/otlp/proto/http/trace_exporter/__init__.py", line 114, in _export
    return self._session.post(
  File "/var/lib/juju/agents/unit-mysql-0/charm/venv/requests/sessions.py", line 637, in post
    return self.request("POST", url, data=data, json=json, **kwargs)
  File "/var/lib/juju/agents/unit-mysql-0/charm/venv/requests/sessions.py", line 589, in request
    resp = self.send(prep, **send_kwargs)
  File "/var/lib/juju/agents/unit-mysql-0/charm/venv/requests/sessions.py", line 703, in send
    r = adapter.send(request, **kwargs)
  File "/var/lib/juju/agents/unit-mysql-0/charm/venv/requests/adapters.py", line 519, in send
    raise ConnectionError(e, request=request)
requests.exceptions.ConnectionError: HTTPConnectionPool(host='juju-612b1f-2.lxd', port=4318): Max retries exceeded with url: /v1/traces (Caused by NewConnectionError('<urllib3.connection.HTTPConnection object at 0x7efddce75270>: Failed to establish a new connection: [Errno 111] Connection refused'))
unit-mysql-2: 01:34:12 ERROR unit.mysql/2.juju-log certificates:14: Exception while exporting Span batch.
Traceback (most recent call last):
  File "/var/lib/juju/agents/unit-mysql-2/charm/venv/urllib3/connection.py", line 174, in _new_conn
    conn = connection.create_connection(
  File "/var/lib/juju/agents/unit-mysql-2/charm/venv/urllib3/util/connection.py", line 95, in create_connection
    raise err
  File "/var/lib/juju/agents/unit-mysql-2/charm/venv/urllib3/util/connection.py", line 85, in create_connection
    sock.connect(sa)
ConnectionRefusedError: [Errno 111] Connection refused

During handling of the above exception, another exception occurred:

Traceback (most recent call last):
  File "/var/lib/juju/agents/unit-mysql-2/charm/venv/urllib3/connectionpool.py", line 715, in urlopen
    httplib_response = self._make_request(
  File "/var/lib/juju/agents/unit-mysql-2/charm/venv/urllib3/connectionpool.py", line 416, in _make_request
    conn.request(method, url, **httplib_request_kw)
  File "/var/lib/juju/agents/unit-mysql-2/charm/venv/urllib3/connection.py", line 244, in request
    super(HTTPConnection, self).request(method, url, body=body, headers=headers)
  File "/usr/lib/python3.10/http/client.py", line 1283, in request
    self._send_request(method, url, body, headers, encode_chunked)
  File "/usr/lib/python3.10/http/client.py", line 1329, in _send_request
    self.endheaders(body, encode_chunked=encode_chunked)
  File "/usr/lib/python3.10/http/client.py", line 1278, in endheaders
    self._send_output(message_body, encode_chunked=encode_chunked)
  File "/usr/lib/python3.10/http/client.py", line 1038, in _send_output
    self.send(msg)
  File "/usr/lib/python3.10/http/client.py", line 976, in send
    self.connect()
  File "/var/lib/juju/agents/unit-mysql-2/charm/venv/urllib3/connection.py", line 205, in connect
    conn = self._new_conn()
  File "/var/lib/juju/agents/unit-mysql-2/charm/venv/urllib3/connection.py", line 186, in _new_conn
    raise NewConnectionError(
urllib3.exceptions.NewConnectionError: <urllib3.connection.HTTPConnection object at 0x7f8998c3de40>: Failed to establish a new connection: [Errno 111] Connection refused

During handling of the above exception, another exception occurred:

Traceback (most recent call last):
  File "/var/lib/juju/agents/unit-mysql-2/charm/venv/requests/adapters.py", line 486, in send
    resp = conn.urlopen(
  File "/var/lib/juju/agents/unit-mysql-2/charm/venv/urllib3/connectionpool.py", line 801, in urlopen
    retries = retries.increment(
  File "/var/lib/juju/agents/unit-mysql-2/charm/venv/urllib3/util/retry.py", line 594, in increment
    raise MaxRetryError(_pool, url, error or ResponseError(cause))
urllib3.exceptions.MaxRetryError: HTTPConnectionPool(host='juju-612b1f-4.lxd', port=4318): Max retries exceeded with url: /v1/traces (Caused by NewConnectionError('<urllib3.connection.HTTPConnection object at 0x7f8998c3de40>: Failed to establish a new connection: [Errno 111] Connection refused'))

During handling of the above exception, another exception occurred:

Traceback (most recent call last):
  File "/var/lib/juju/agents/unit-mysql-2/charm/venv/opentelemetry/sdk/trace/export/__init__.py", line 368, in _export_batch
    self.span_exporter.export(self.spans_list[:idx])  # type: ignore
  File "/var/lib/juju/agents/unit-mysql-2/charm/venv/opentelemetry/exporter/otlp/proto/http/trace_exporter/__init__.py", line 145, in export
    resp = self._export(serialized_data)
  File "/var/lib/juju/agents/unit-mysql-2/charm/venv/opentelemetry/exporter/otlp/proto/http/trace_exporter/__init__.py", line 114, in _export
    return self._session.post(
  File "/var/lib/juju/agents/unit-mysql-2/charm/venv/requests/sessions.py", line 637, in post
    return self.request("POST", url, data=data, json=json, **kwargs)
  File "/var/lib/juju/agents/unit-mysql-2/charm/venv/requests/sessions.py", line 589, in request
    resp = self.send(prep, **send_kwargs)
  File "/var/lib/juju/agents/unit-mysql-2/charm/venv/requests/sessions.py", line 703, in send
    r = adapter.send(request, **kwargs)
  File "/var/lib/juju/agents/unit-mysql-2/charm/venv/requests/adapters.py", line 519, in send
    raise ConnectionError(e, request=request)
requests.exceptions.ConnectionError: HTTPConnectionPool(host='juju-612b1f-4.lxd', port=4318): Max retries exceeded with url: /v1/traces (Caused by NewConnectionError('<urllib3.connection.HTTPConnection object at 0x7f8998c3de40>: Failed to establish a new connection: [Errno 111] Connection refused'))
unit-mysql-1: 01:34:13 ERROR unit.mysql/1.juju-log cos-agent:19: Exception while exporting Span batch.
Traceback (most recent call last):
  File "/var/lib/juju/agents/unit-mysql-1/charm/venv/urllib3/connection.py", line 174, in _new_conn
    conn = connection.create_connection(
  File "/var/lib/juju/agents/unit-mysql-1/charm/venv/urllib3/util/connection.py", line 95, in create_connection
    raise err
  File "/var/lib/juju/agents/unit-mysql-1/charm/venv/urllib3/util/connection.py", line 85, in create_connection
    sock.connect(sa)
ConnectionRefusedError: [Errno 111] Connection refused

During handling of the above exception, another exception occurred:

Traceback (most recent call last):
  File "/var/lib/juju/agents/unit-mysql-1/charm/venv/urllib3/connectionpool.py", line 715, in urlopen
    httplib_response = self._make_request(
  File "/var/lib/juju/agents/unit-mysql-1/charm/venv/urllib3/connectionpool.py", line 416, in _make_request
    conn.request(method, url, **httplib_request_kw)
  File "/var/lib/juju/agents/unit-mysql-1/charm/venv/urllib3/connection.py", line 244, in request
    super(HTTPConnection, self).request(method, url, body=body, headers=headers)
  File "/usr/lib/python3.10/http/client.py", line 1283, in request
    self._send_request(method, url, body, headers, encode_chunked)
  File "/usr/lib/python3.10/http/client.py", line 1329, in _send_request
    self.endheaders(body, encode_chunked=encode_chunked)
  File "/usr/lib/python3.10/http/client.py", line 1278, in endheaders
    self._send_output(message_body, encode_chunked=encode_chunked)
  File "/usr/lib/python3.10/http/client.py", line 1038, in _send_output
    self.send(msg)
  File "/usr/lib/python3.10/http/client.py", line 976, in send
    self.connect()
  File "/var/lib/juju/agents/unit-mysql-1/charm/venv/urllib3/connection.py", line 205, in connect
    conn = self._new_conn()
  File "/var/lib/juju/agents/unit-mysql-1/charm/venv/urllib3/connection.py", line 186, in _new_conn
    raise NewConnectionError(
urllib3.exceptions.NewConnectionError: <urllib3.connection.HTTPConnection object at 0x7fe24c8d2ef0>: Failed to establish a new connection: [Errno 111] Connection refused

During handling of the above exception, another exception occurred:

Traceback (most recent call last):
  File "/var/lib/juju/agents/unit-mysql-1/charm/venv/requests/adapters.py", line 486, in send
    resp = conn.urlopen(
  File "/var/lib/juju/agents/unit-mysql-1/charm/venv/urllib3/connectionpool.py", line 801, in urlopen
    retries = retries.increment(
  File "/var/lib/juju/agents/unit-mysql-1/charm/venv/urllib3/util/retry.py", line 594, in increment
    raise MaxRetryError(_pool, url, error or ResponseError(cause))
urllib3.exceptions.MaxRetryError: HTTPConnectionPool(host='juju-612b1f-3.lxd', port=4318): Max retries exceeded with url: /v1/traces (Caused by NewConnectionError('<urllib3.connection.HTTPConnection object at 0x7fe24c8d2ef0>: Failed to establish a new connection: [Errno 111] Connection refused'))

During handling of the above exception, another exception occurred:

Traceback (most recent call last):
  File "/var/lib/juju/agents/unit-mysql-1/charm/venv/opentelemetry/sdk/trace/export/__init__.py", line 368, in _export_batch
    self.span_exporter.export(self.spans_list[:idx])  # type: ignore
  File "/var/lib/juju/agents/unit-mysql-1/charm/venv/opentelemetry/exporter/otlp/proto/http/trace_exporter/__init__.py", line 145, in export
    resp = self._export(serialized_data)
  File "/var/lib/juju/agents/unit-mysql-1/charm/venv/opentelemetry/exporter/otlp/proto/http/trace_exporter/__init__.py", line 114, in _export
    return self._session.post(
  File "/var/lib/juju/agents/unit-mysql-1/charm/venv/requests/sessions.py", line 637, in post
    return self.request("POST", url, data=data, json=json, **kwargs)
  File "/var/lib/juju/agents/unit-mysql-1/charm/venv/requests/sessions.py", line 589, in request
    resp = self.send(prep, **send_kwargs)
  File "/var/lib/juju/agents/unit-mysql-1/charm/venv/requests/sessions.py", line 703, in send
    r = adapter.send(request, **kwargs)
  File "/var/lib/juju/agents/unit-mysql-1/charm/venv/requests/adapters.py", line 519, in send
    raise ConnectionError(e, request=request)
requests.exceptions.ConnectionError: HTTPConnectionPool(host='juju-612b1f-3.lxd', port=4318): Max retries exceeded with url: /v1/traces (Caused by NewConnectionError('<urllib3.connection.HTTPConnection object at 0x7fe24c8d2ef0>: Failed to establish a new connection: [Errno 111] Connection refused'))
unit-mysql-0: 01:34:13 ERROR unit.mysql/0.juju-log database:13: Exception while exporting Span batch.
Traceback (most recent call last):
  File "/var/lib/juju/agents/unit-mysql-0/charm/venv/urllib3/connection.py", line 174, in _new_conn
    conn = connection.create_connection(
  File "/var/lib/juju/agents/unit-mysql-0/charm/venv/urllib3/util/connection.py", line 95, in create_connection
    raise err
  File "/var/lib/juju/agents/unit-mysql-0/charm/venv/urllib3/util/connection.py", line 85, in create_connection
    sock.connect(sa)
ConnectionRefusedError: [Errno 111] Connection refused

During handling of the above exception, another exception occurred:

Traceback (most recent call last):
  File "/var/lib/juju/agents/unit-mysql-0/charm/venv/urllib3/connectionpool.py", line 715, in urlopen
    httplib_response = self._make_request(
  File "/var/lib/juju/agents/unit-mysql-0/charm/venv/urllib3/connectionpool.py", line 416, in _make_request
    conn.request(method, url, **httplib_request_kw)
  File "/var/lib/juju/agents/unit-mysql-0/charm/venv/urllib3/connection.py", line 244, in request
    super(HTTPConnection, self).request(method, url, body=body, headers=headers)
  File "/usr/lib/python3.10/http/client.py", line 1283, in request
    self._send_request(method, url, body, headers, encode_chunked)
  File "/usr/lib/python3.10/http/client.py", line 1329, in _send_request
    self.endheaders(body, encode_chunked=encode_chunked)
  File "/usr/lib/python3.10/http/client.py", line 1278, in endheaders
    self._send_output(message_body, encode_chunked=encode_chunked)
  File "/usr/lib/python3.10/http/client.py", line 1038, in _send_output
    self.send(msg)
  File "/usr/lib/python3.10/http/client.py", line 976, in send
    self.connect()
  File "/var/lib/juju/agents/unit-mysql-0/charm/venv/urllib3/connection.py", line 205, in connect
    conn = self._new_conn()
  File "/var/lib/juju/agents/unit-mysql-0/charm/venv/urllib3/connection.py", line 186, in _new_conn
    raise NewConnectionError(
urllib3.exceptions.NewConnectionError: <urllib3.connection.HTTPConnection object at 0x7f924f5e2590>: Failed to establish a new connection: [Errno 111] Connection refused

During handling of the above exception, another exception occurred:

Traceback (most recent call last):
  File "/var/lib/juju/agents/unit-mysql-0/charm/venv/requests/adapters.py", line 486, in send
    resp = conn.urlopen(
  File "/var/lib/juju/agents/unit-mysql-0/charm/venv/urllib3/connectionpool.py", line 801, in urlopen
    retries = retries.increment(
  File "/var/lib/juju/agents/unit-mysql-0/charm/venv/urllib3/util/retry.py", line 594, in increment
    raise MaxRetryError(_pool, url, error or ResponseError(cause))
urllib3.exceptions.MaxRetryError: HTTPConnectionPool(host='juju-612b1f-2.lxd', port=4318): Max retries exceeded with url: /v1/traces (Caused by NewConnectionError('<urllib3.connection.HTTPConnection object at 0x7f924f5e2590>: Failed to establish a new connection: [Errno 111] Connection refused'))

During handling of the above exception, another exception occurred:

Traceback (most recent call last):
  File "/var/lib/juju/agents/unit-mysql-0/charm/venv/opentelemetry/sdk/trace/export/__init__.py", line 368, in _export_batch
    self.span_exporter.export(self.spans_list[:idx])  # type: ignore
  File "/var/lib/juju/agents/unit-mysql-0/charm/venv/opentelemetry/exporter/otlp/proto/http/trace_exporter/__init__.py", line 145, in export
    resp = self._export(serialized_data)
  File "/var/lib/juju/agents/unit-mysql-0/charm/venv/opentelemetry/exporter/otlp/proto/http/trace_exporter/__init__.py", line 114, in _export
    return self._session.post(
  File "/var/lib/juju/agents/unit-mysql-0/charm/venv/requests/sessions.py", line 637, in post
    return self.request("POST", url, data=data, json=json, **kwargs)
  File "/var/lib/juju/agents/unit-mysql-0/charm/venv/requests/sessions.py", line 589, in request
    resp = self.send(prep, **send_kwargs)
  File "/var/lib/juju/agents/unit-mysql-0/charm/venv/requests/sessions.py", line 703, in send
    r = adapter.send(request, **kwargs)
  File "/var/lib/juju/agents/unit-mysql-0/charm/venv/requests/adapters.py", line 519, in send
    raise ConnectionError(e, request=request)
requests.exceptions.ConnectionError: HTTPConnectionPool(host='juju-612b1f-2.lxd', port=4318): Max retries exceeded with url: /v1/traces (Caused by NewConnectionError('<urllib3.connection.HTTPConnection object at 0x7f924f5e2590>: Failed to establish a new connection: [Errno 111] Connection refused'))
unit-mysql-2: 01:34:16 ERROR unit.mysql/2.juju-log certificates:14: Exception while exporting Span batch.
Traceback (most recent call last):
  File "/var/lib/juju/agents/unit-mysql-2/charm/venv/urllib3/connection.py", line 174, in _new_conn
    conn = connection.create_connection(
  File "/var/lib/juju/agents/unit-mysql-2/charm/venv/urllib3/util/connection.py", line 95, in create_connection
    raise err
  File "/var/lib/juju/agents/unit-mysql-2/charm/venv/urllib3/util/connection.py", line 85, in create_connection
    sock.connect(sa)
ConnectionRefusedError: [Errno 111] Connection refused

During handling of the above exception, another exception occurred:

Traceback (most recent call last):
  File "/var/lib/juju/agents/unit-mysql-2/charm/venv/urllib3/connectionpool.py", line 715, in urlopen
    httplib_response = self._make_request(
  File "/var/lib/juju/agents/unit-mysql-2/charm/venv/urllib3/connectionpool.py", line 416, in _make_request
    conn.request(method, url, **httplib_request_kw)
  File "/var/lib/juju/agents/unit-mysql-2/charm/venv/urllib3/connection.py", line 244, in request
    super(HTTPConnection, self).request(method, url, body=body, headers=headers)
  File "/usr/lib/python3.10/http/client.py", line 1283, in request
    self._send_request(method, url, body, headers, encode_chunked)
  File "/usr/lib/python3.10/http/client.py", line 1329, in _send_request
    self.endheaders(body, encode_chunked=encode_chunked)
  File "/usr/lib/python3.10/http/client.py", line 1278, in endheaders
    self._send_output(message_body, encode_chunked=encode_chunked)
  File "/usr/lib/python3.10/http/client.py", line 1038, in _send_output
    self.send(msg)
  File "/usr/lib/python3.10/http/client.py", line 976, in send
    self.connect()
  File "/var/lib/juju/agents/unit-mysql-2/charm/venv/urllib3/connection.py", line 205, in connect
    conn = self._new_conn()
  File "/var/lib/juju/agents/unit-mysql-2/charm/venv/urllib3/connection.py", line 186, in _new_conn
    raise NewConnectionError(
urllib3.exceptions.NewConnectionError: <urllib3.connection.HTTPConnection object at 0x7f48f2e3df90>: Failed to establish a new connection: [Errno 111] Connection refused

During handling of the above exception, another exception occurred:

Traceback (most recent call last):
  File "/var/lib/juju/agents/unit-mysql-2/charm/venv/requests/adapters.py", line 486, in send
    resp = conn.urlopen(
  File "/var/lib/juju/agents/unit-mysql-2/charm/venv/urllib3/connectionpool.py", line 801, in urlopen
    retries = retries.increment(
  File "/var/lib/juju/agents/unit-mysql-2/charm/venv/urllib3/util/retry.py", line 594, in increment
    raise MaxRetryError(_pool, url, error or ResponseError(cause))
urllib3.exceptions.MaxRetryError: HTTPConnectionPool(host='juju-612b1f-4.lxd', port=4318): Max retries exceeded with url: /v1/traces (Caused by NewConnectionError('<urllib3.connection.HTTPConnection object at 0x7f48f2e3df90>: Failed to establish a new connection: [Errno 111] Connection refused'))

During handling of the above exception, another exception occurred:

Traceback (most recent call last):
  File "/var/lib/juju/agents/unit-mysql-2/charm/venv/opentelemetry/sdk/trace/export/__init__.py", line 368, in _export_batch
    self.span_exporter.export(self.spans_list[:idx])  # type: ignore
  File "/var/lib/juju/agents/unit-mysql-2/charm/venv/opentelemetry/exporter/otlp/proto/http/trace_exporter/__init__.py", line 145, in export
    resp = self._export(serialized_data)
  File "/var/lib/juju/agents/unit-mysql-2/charm/venv/opentelemetry/exporter/otlp/proto/http/trace_exporter/__init__.py", line 114, in _export
    return self._session.post(
  File "/var/lib/juju/agents/unit-mysql-2/charm/venv/requests/sessions.py", line 637, in post
    return self.request("POST", url, data=data, json=json, **kwargs)
  File "/var/lib/juju/agents/unit-mysql-2/charm/venv/requests/sessions.py", line 589, in request
    resp = self.send(prep, **send_kwargs)
  File "/var/lib/juju/agents/unit-mysql-2/charm/venv/requests/sessions.py", line 703, in send
    r = adapter.send(request, **kwargs)
  File "/var/lib/juju/agents/unit-mysql-2/charm/venv/requests/adapters.py", line 519, in send
    raise ConnectionError(e, request=request)
requests.exceptions.ConnectionError: HTTPConnectionPool(host='juju-612b1f-4.lxd', port=4318): Max retries exceeded with url: /v1/traces (Caused by NewConnectionError('<urllib3.connection.HTTPConnection object at 0x7f48f2e3df90>: Failed to establish a new connection: [Errno 111] Connection refused'))
unit-mysql-0: 01:34:17 ERROR unit.mysql/0.juju-log database:13: Exception while exporting Span batch.
Traceback (most recent call last):
  File "/var/lib/juju/agents/unit-mysql-0/charm/venv/urllib3/connection.py", line 174, in _new_conn
    conn = connection.create_connection(
  File "/var/lib/juju/agents/unit-mysql-0/charm/venv/urllib3/util/connection.py", line 95, in create_connection
    raise err
  File "/var/lib/juju/agents/unit-mysql-0/charm/venv/urllib3/util/connection.py", line 85, in create_connection
    sock.connect(sa)
ConnectionRefusedError: [Errno 111] Connection refused

During handling of the above exception, another exception occurred:

Traceback (most recent call last):
  File "/var/lib/juju/agents/unit-mysql-0/charm/venv/urllib3/connectionpool.py", line 715, in urlopen
    httplib_response = self._make_request(
  File "/var/lib/juju/agents/unit-mysql-0/charm/venv/urllib3/connectionpool.py", line 416, in _make_request
    conn.request(method, url, **httplib_request_kw)
  File "/var/lib/juju/agents/unit-mysql-0/charm/venv/urllib3/connection.py", line 244, in request
    super(HTTPConnection, self).request(method, url, body=body, headers=headers)
  File "/usr/lib/python3.10/http/client.py", line 1283, in request
    self._send_request(method, url, body, headers, encode_chunked)
  File "/usr/lib/python3.10/http/client.py", line 1329, in _send_request
    self.endheaders(body, encode_chunked=encode_chunked)
  File "/usr/lib/python3.10/http/client.py", line 1278, in endheaders
    self._send_output(message_body, encode_chunked=encode_chunked)
  File "/usr/lib/python3.10/http/client.py", line 1038, in _send_output
    self.send(msg)
  File "/usr/lib/python3.10/http/client.py", line 976, in send
    self.connect()
  File "/var/lib/juju/agents/unit-mysql-0/charm/venv/urllib3/connection.py", line 205, in connect
    conn = self._new_conn()
  File "/var/lib/juju/agents/unit-mysql-0/charm/venv/urllib3/connection.py", line 186, in _new_conn
    raise NewConnectionError(
urllib3.exceptions.NewConnectionError: <urllib3.connection.HTTPConnection object at 0x7f4c43eda3b0>: Failed to establish a new connection: [Errno 111] Connection refused

During handling of the above exception, another exception occurred:

Traceback (most recent call last):
  File "/var/lib/juju/agents/unit-mysql-0/charm/venv/requests/adapters.py", line 486, in send
    resp = conn.urlopen(
  File "/var/lib/juju/agents/unit-mysql-0/charm/venv/urllib3/connectionpool.py", line 801, in urlopen
    retries = retries.increment(
  File "/var/lib/juju/agents/unit-mysql-0/charm/venv/urllib3/util/retry.py", line 594, in increment
    raise MaxRetryError(_pool, url, error or ResponseError(cause))
urllib3.exceptions.MaxRetryError: HTTPConnectionPool(host='juju-612b1f-2.lxd', port=4318): Max retries exceeded with url: /v1/traces (Caused by NewConnectionError('<urllib3.connection.HTTPConnection object at 0x7f4c43eda3b0>: Failed to establish a new connection: [Errno 111] Connection refused'))

During handling of the above exception, another exception occurred:

Traceback (most recent call last):
  File "/var/lib/juju/agents/unit-mysql-0/charm/venv/opentelemetry/sdk/trace/export/__init__.py", line 368, in _export_batch
    self.span_exporter.export(self.spans_list[:idx])  # type: ignore
  File "/var/lib/juju/agents/unit-mysql-0/charm/venv/opentelemetry/exporter/otlp/proto/http/trace_exporter/__init__.py", line 145, in export
    resp = self._export(serialized_data)
  File "/var/lib/juju/agents/unit-mysql-0/charm/venv/opentelemetry/exporter/otlp/proto/http/trace_exporter/__init__.py", line 114, in _export
    return self._session.post(
  File "/var/lib/juju/agents/unit-mysql-0/charm/venv/requests/sessions.py", line 637, in post
    return self.request("POST", url, data=data, json=json, **kwargs)
  File "/var/lib/juju/agents/unit-mysql-0/charm/venv/requests/sessions.py", line 589, in request
    resp = self.send(prep, **send_kwargs)
  File "/var/lib/juju/agents/unit-mysql-0/charm/venv/requests/sessions.py", line 703, in send
    r = adapter.send(request, **kwargs)
  File "/var/lib/juju/agents/unit-mysql-0/charm/venv/requests/adapters.py", line 519, in send
    raise ConnectionError(e, request=request)
requests.exceptions.ConnectionError: HTTPConnectionPool(host='juju-612b1f-2.lxd', port=4318): Max retries exceeded with url: /v1/traces (Caused by NewConnectionError('<urllib3.connection.HTTPConnection object at 0x7f4c43eda3b0>: Failed to establish a new connection: [Errno 111] Connection refused'))
unit-mysql-1: 01:34:20 ERROR unit.mysql/1.juju-log Exception while exporting Span batch.
Traceback (most recent call last):
  File "/var/lib/juju/agents/unit-mysql-1/charm/venv/urllib3/connection.py", line 174, in _new_conn
    conn = connection.create_connection(
  File "/var/lib/juju/agents/unit-mysql-1/charm/venv/urllib3/util/connection.py", line 95, in create_connection
    raise err
  File "/var/lib/juju/agents/unit-mysql-1/charm/venv/urllib3/util/connection.py", line 85, in create_connection
    sock.connect(sa)
ConnectionRefusedError: [Errno 111] Connection refused

During handling of the above exception, another exception occurred:

Traceback (most recent call last):
  File "/var/lib/juju/agents/unit-mysql-1/charm/venv/urllib3/connectionpool.py", line 715, in urlopen
    httplib_response = self._make_request(
  File "/var/lib/juju/agents/unit-mysql-1/charm/venv/urllib3/connectionpool.py", line 416, in _make_request
    conn.request(method, url, **httplib_request_kw)
  File "/var/lib/juju/agents/unit-mysql-1/charm/venv/urllib3/connection.py", line 244, in request
    super(HTTPConnection, self).request(method, url, body=body, headers=headers)
  File "/usr/lib/python3.10/http/client.py", line 1283, in request
    self._send_request(method, url, body, headers, encode_chunked)
  File "/usr/lib/python3.10/http/client.py", line 1329, in _send_request
    self.endheaders(body, encode_chunked=encode_chunked)
  File "/usr/lib/python3.10/http/client.py", line 1278, in endheaders
    self._send_output(message_body, encode_chunked=encode_chunked)
  File "/usr/lib/python3.10/http/client.py", line 1038, in _send_output
    self.send(msg)
  File "/usr/lib/python3.10/http/client.py", line 976, in send
    self.connect()
  File "/var/lib/juju/agents/unit-mysql-1/charm/venv/urllib3/connection.py", line 205, in connect
    conn = self._new_conn()
  File "/var/lib/juju/agents/unit-mysql-1/charm/venv/urllib3/connection.py", line 186, in _new_conn
    raise NewConnectionError(
urllib3.exceptions.NewConnectionError: <urllib3.connection.HTTPConnection object at 0x7f7de90c8670>: Failed to establish a new connection: [Errno 111] Connection refused

During handling of the above exception, another exception occurred:

Traceback (most recent call last):
  File "/var/lib/juju/agents/unit-mysql-1/charm/venv/requests/adapters.py", line 486, in send
    resp = conn.urlopen(
  File "/var/lib/juju/agents/unit-mysql-1/charm/venv/urllib3/connectionpool.py", line 801, in urlopen
    retries = retries.increment(
  File "/var/lib/juju/agents/unit-mysql-1/charm/venv/urllib3/util/retry.py", line 594, in increment
    raise MaxRetryError(_pool, url, error or ResponseError(cause))
urllib3.exceptions.MaxRetryError: HTTPConnectionPool(host='juju-612b1f-3.lxd', port=4318): Max retries exceeded with url: /v1/traces (Caused by NewConnectionError('<urllib3.connection.HTTPConnection object at 0x7f7de90c8670>: Failed to establish a new connection: [Errno 111] Connection refused'))

During handling of the above exception, another exception occurred:

Traceback (most recent call last):
  File "/var/lib/juju/agents/unit-mysql-1/charm/venv/opentelemetry/sdk/trace/export/__init__.py", line 368, in _export_batch
    self.span_exporter.export(self.spans_list[:idx])  # type: ignore
  File "/var/lib/juju/agents/unit-mysql-1/charm/venv/opentelemetry/exporter/otlp/proto/http/trace_exporter/__init__.py", line 145, in export
    resp = self._export(serialized_data)
  File "/var/lib/juju/agents/unit-mysql-1/charm/venv/opentelemetry/exporter/otlp/proto/http/trace_exporter/__init__.py", line 114, in _export
    return self._session.post(
  File "/var/lib/juju/agents/unit-mysql-1/charm/venv/requests/sessions.py", line 637, in post
    return self.request("POST", url, data=data, json=json, **kwargs)
  File "/var/lib/juju/agents/unit-mysql-1/charm/venv/requests/sessions.py", line 589, in request
    resp = self.send(prep, **send_kwargs)
  File "/var/lib/juju/agents/unit-mysql-1/charm/venv/requests/sessions.py", line 703, in send
    r = adapter.send(request, **kwargs)
  File "/var/lib/juju/agents/unit-mysql-1/charm/venv/requests/adapters.py", line 519, in send
    raise ConnectionError(e, request=request)
requests.exceptions.ConnectionError: HTTPConnectionPool(host='juju-612b1f-3.lxd', port=4318): Max retries exceeded with url: /v1/traces (Caused by NewConnectionError('<urllib3.connection.HTTPConnection object at 0x7f7de90c8670>: Failed to establish a new connection: [Errno 111] Connection refused'))
unit-mysql-0: 01:34:22 ERROR unit.mysql/0.juju-log database:18: Exception while exporting Span batch.
Traceback (most recent call last):
  File "/var/lib/juju/agents/unit-mysql-0/charm/venv/urllib3/connection.py", line 174, in _new_conn
    conn = connection.create_connection(
  File "/var/lib/juju/agents/unit-mysql-0/charm/venv/urllib3/util/connection.py", line 95, in create_connection
    raise err
  File "/var/lib/juju/agents/unit-mysql-0/charm/venv/urllib3/util/connection.py", line 85, in create_connection
    sock.connect(sa)
ConnectionRefusedError: [Errno 111] Connection refused

During handling of the above exception, another exception occurred:

Traceback (most recent call last):
  File "/var/lib/juju/agents/unit-mysql-0/charm/venv/urllib3/connectionpool.py", line 715, in urlopen
    httplib_response = self._make_request(
  File "/var/lib/juju/agents/unit-mysql-0/charm/venv/urllib3/connectionpool.py", line 416, in _make_request
    conn.request(method, url, **httplib_request_kw)
  File "/var/lib/juju/agents/unit-mysql-0/charm/venv/urllib3/connection.py", line 244, in request
    super(HTTPConnection, self).request(method, url, body=body, headers=headers)
  File "/usr/lib/python3.10/http/client.py", line 1283, in request
    self._send_request(method, url, body, headers, encode_chunked)
  File "/usr/lib/python3.10/http/client.py", line 1329, in _send_request
    self.endheaders(body, encode_chunked=encode_chunked)
  File "/usr/lib/python3.10/http/client.py", line 1278, in endheaders
    self._send_output(message_body, encode_chunked=encode_chunked)
  File "/usr/lib/python3.10/http/client.py", line 1038, in _send_output
    self.send(msg)
  File "/usr/lib/python3.10/http/client.py", line 976, in send
    self.connect()
  File "/var/lib/juju/agents/unit-mysql-0/charm/venv/urllib3/connection.py", line 205, in connect
    conn = self._new_conn()
  File "/var/lib/juju/agents/unit-mysql-0/charm/venv/urllib3/connection.py", line 186, in _new_conn
    raise NewConnectionError(
urllib3.exceptions.NewConnectionError: <urllib3.connection.HTTPConnection object at 0x7fc5679de5f0>: Failed to establish a new connection: [Errno 111] Connection refused

During handling of the above exception, another exception occurred:

Traceback (most recent call last):
  File "/var/lib/juju/agents/unit-mysql-0/charm/venv/requests/adapters.py", line 486, in send
    resp = conn.urlopen(
  File "/var/lib/juju/agents/unit-mysql-0/charm/venv/urllib3/connectionpool.py", line 801, in urlopen
    retries = retries.increment(
  File "/var/lib/juju/agents/unit-mysql-0/charm/venv/urllib3/util/retry.py", line 594, in increment
    raise MaxRetryError(_pool, url, error or ResponseError(cause))
urllib3.exceptions.MaxRetryError: HTTPConnectionPool(host='juju-612b1f-2.lxd', port=4318): Max retries exceeded with url: /v1/traces (Caused by NewConnectionError('<urllib3.connection.HTTPConnection object at 0x7fc5679de5f0>: Failed to establish a new connection: [Errno 111] Connection refused'))

During handling of the above exception, another exception occurred:

Traceback (most recent call last):
  File "/var/lib/juju/agents/unit-mysql-0/charm/venv/opentelemetry/sdk/trace/export/__init__.py", line 368, in _export_batch
    self.span_exporter.export(self.spans_list[:idx])  # type: ignore
  File "/var/lib/juju/agents/unit-mysql-0/charm/venv/opentelemetry/exporter/otlp/proto/http/trace_exporter/__init__.py", line 145, in export
    resp = self._export(serialized_data)
  File "/var/lib/juju/agents/unit-mysql-0/charm/venv/opentelemetry/exporter/otlp/proto/http/trace_exporter/__init__.py", line 114, in _export
    return self._session.post(
  File "/var/lib/juju/agents/unit-mysql-0/charm/venv/requests/sessions.py", line 637, in post
    return self.request("POST", url, data=data, json=json, **kwargs)
  File "/var/lib/juju/agents/unit-mysql-0/charm/venv/requests/sessions.py", line 589, in request
    resp = self.send(prep, **send_kwargs)
  File "/var/lib/juju/agents/unit-mysql-0/charm/venv/requests/sessions.py", line 703, in send
    r = adapter.send(request, **kwargs)
  File "/var/lib/juju/agents/unit-mysql-0/charm/venv/requests/adapters.py", line 519, in send
    raise ConnectionError(e, request=request)
requests.exceptions.ConnectionError: HTTPConnectionPool(host='juju-612b1f-2.lxd', port=4318): Max retries exceeded with url: /v1/traces (Caused by NewConnectionError('<urllib3.connection.HTTPConnection object at 0x7fc5679de5f0>: Failed to establish a new connection: [Errno 111] Connection refused'))
unit-mysql-2: 01:34:23 ERROR unit.mysql/2.juju-log database-peers:2: Exception while exporting Span batch.
Traceback (most recent call last):
  File "/var/lib/juju/agents/unit-mysql-2/charm/venv/urllib3/connection.py", line 174, in _new_conn
    conn = connection.create_connection(
  File "/var/lib/juju/agents/unit-mysql-2/charm/venv/urllib3/util/connection.py", line 95, in create_connection
    raise err
  File "/var/lib/juju/agents/unit-mysql-2/charm/venv/urllib3/util/connection.py", line 85, in create_connection
    sock.connect(sa)
ConnectionRefusedError: [Errno 111] Connection refused

During handling of the above exception, another exception occurred:

Traceback (most recent call last):
  File "/var/lib/juju/agents/unit-mysql-2/charm/venv/urllib3/connectionpool.py", line 715, in urlopen
    httplib_response = self._make_request(
  File "/var/lib/juju/agents/unit-mysql-2/charm/venv/urllib3/connectionpool.py", line 416, in _make_request
    conn.request(method, url, **httplib_request_kw)
  File "/var/lib/juju/agents/unit-mysql-2/charm/venv/urllib3/connection.py", line 244, in request
    super(HTTPConnection, self).request(method, url, body=body, headers=headers)
  File "/usr/lib/python3.10/http/client.py", line 1283, in request
    self._send_request(method, url, body, headers, encode_chunked)
  File "/usr/lib/python3.10/http/client.py", line 1329, in _send_request
    self.endheaders(body, encode_chunked=encode_chunked)
  File "/usr/lib/python3.10/http/client.py", line 1278, in endheaders
    self._send_output(message_body, encode_chunked=encode_chunked)
  File "/usr/lib/python3.10/http/client.py", line 1038, in _send_output
    self.send(msg)
  File "/usr/lib/python3.10/http/client.py", line 976, in send
    self.connect()
  File "/var/lib/juju/agents/unit-mysql-2/charm/venv/urllib3/connection.py", line 205, in connect
    conn = self._new_conn()
  File "/var/lib/juju/agents/unit-mysql-2/charm/venv/urllib3/connection.py", line 186, in _new_conn
    raise NewConnectionError(
urllib3.exceptions.NewConnectionError: <urllib3.connection.HTTPConnection object at 0x7f6e86570730>: Failed to establish a new connection: [Errno 111] Connection refused

During handling of the above exception, another exception occurred:

Traceback (most recent call last):
  File "/var/lib/juju/agents/unit-mysql-2/charm/venv/requests/adapters.py", line 486, in send
    resp = conn.urlopen(
  File "/var/lib/juju/agents/unit-mysql-2/charm/venv/urllib3/connectionpool.py", line 801, in urlopen
    retries = retries.increment(
  File "/var/lib/juju/agents/unit-mysql-2/charm/venv/urllib3/util/retry.py", line 594, in increment
    raise MaxRetryError(_pool, url, error or ResponseError(cause))
urllib3.exceptions.MaxRetryError: HTTPConnectionPool(host='juju-612b1f-4.lxd', port=4318): Max retries exceeded with url: /v1/traces (Caused by NewConnectionError('<urllib3.connection.HTTPConnection object at 0x7f6e86570730>: Failed to establish a new connection: [Errno 111] Connection refused'))

During handling of the above exception, another exception occurred:

Traceback (most recent call last):
  File "/var/lib/juju/agents/unit-mysql-2/charm/venv/opentelemetry/sdk/trace/export/__init__.py", line 368, in _export_batch
    self.span_exporter.export(self.spans_list[:idx])  # type: ignore
  File "/var/lib/juju/agents/unit-mysql-2/charm/venv/opentelemetry/exporter/otlp/proto/http/trace_exporter/__init__.py", line 145, in export
    resp = self._export(serialized_data)
  File "/var/lib/juju/agents/unit-mysql-2/charm/venv/opentelemetry/exporter/otlp/proto/http/trace_exporter/__init__.py", line 114, in _export
    return self._session.post(
  File "/var/lib/juju/agents/unit-mysql-2/charm/venv/requests/sessions.py", line 637, in post
    return self.request("POST", url, data=data, json=json, **kwargs)
  File "/var/lib/juju/agents/unit-mysql-2/charm/venv/requests/sessions.py", line 589, in request
    resp = self.send(prep, **send_kwargs)
  File "/var/lib/juju/agents/unit-mysql-2/charm/venv/requests/sessions.py", line 703, in send
    r = adapter.send(request, **kwargs)
  File "/var/lib/juju/agents/unit-mysql-2/charm/venv/requests/adapters.py", line 519, in send
    raise ConnectionError(e, request=request)
requests.exceptions.ConnectionError: HTTPConnectionPool(host='juju-612b1f-4.lxd', port=4318): Max retries exceeded with url: /v1/traces (Caused by NewConnectionError('<urllib3.connection.HTTPConnection object at 0x7f6e86570730>: Failed to establish a new connection: [Errno 111] Connection refused'))
unit-mysql-1: 01:34:26 ERROR unit.mysql/1.juju-log database-peers:2: Exception while exporting Span batch.
Traceback (most recent call last):
  File "/var/lib/juju/agents/unit-mysql-1/charm/venv/urllib3/connection.py", line 174, in _new_conn
    conn = connection.create_connection(
  File "/var/lib/juju/agents/unit-mysql-1/charm/venv/urllib3/util/connection.py", line 95, in create_connection
    raise err
  File "/var/lib/juju/agents/unit-mysql-1/charm/venv/urllib3/util/connection.py", line 85, in create_connection
    sock.connect(sa)
ConnectionRefusedError: [Errno 111] Connection refused

During handling of the above exception, another exception occurred:

Traceback (most recent call last):
  File "/var/lib/juju/agents/unit-mysql-1/charm/venv/urllib3/connectionpool.py", line 715, in urlopen
    httplib_response = self._make_request(
  File "/var/lib/juju/agents/unit-mysql-1/charm/venv/urllib3/connectionpool.py", line 416, in _make_request
    conn.request(method, url, **httplib_request_kw)
  File "/var/lib/juju/agents/unit-mysql-1/charm/venv/urllib3/connection.py", line 244, in request
    super(HTTPConnection, self).request(method, url, body=body, headers=headers)
  File "/usr/lib/python3.10/http/client.py", line 1283, in request
    self._send_request(method, url, body, headers, encode_chunked)
  File "/usr/lib/python3.10/http/client.py", line 1329, in _send_request
    self.endheaders(body, encode_chunked=encode_chunked)
  File "/usr/lib/python3.10/http/client.py", line 1278, in endheaders
    self._send_output(message_body, encode_chunked=encode_chunked)
  File "/usr/lib/python3.10/http/client.py", line 1038, in _send_output
    self.send(msg)
  File "/usr/lib/python3.10/http/client.py", line 976, in send
    self.connect()
  File "/var/lib/juju/agents/unit-mysql-1/charm/venv/urllib3/connection.py", line 205, in connect
    conn = self._new_conn()
  File "/var/lib/juju/agents/unit-mysql-1/charm/venv/urllib3/connection.py", line 186, in _new_conn
    raise NewConnectionError(
urllib3.exceptions.NewConnectionError: <urllib3.connection.HTTPConnection object at 0x7fc9551d0f70>: Failed to establish a new connection: [Errno 111] Connection refused

During handling of the above exception, another exception occurred:

Traceback (most recent call last):
  File "/var/lib/juju/agents/unit-mysql-1/charm/venv/requests/adapters.py", line 486, in send
    resp = conn.urlopen(
  File "/var/lib/juju/agents/unit-mysql-1/charm/venv/urllib3/connectionpool.py", line 801, in urlopen
    retries = retries.increment(
  File "/var/lib/juju/agents/unit-mysql-1/charm/venv/urllib3/util/retry.py", line 594, in increment
    raise MaxRetryError(_pool, url, error or ResponseError(cause))
urllib3.exceptions.MaxRetryError: HTTPConnectionPool(host='juju-612b1f-3.lxd', port=4318): Max retries exceeded with url: /v1/traces (Caused by NewConnectionError('<urllib3.connection.HTTPConnection object at 0x7fc9551d0f70>: Failed to establish a new connection: [Errno 111] Connection refused'))

During handling of the above exception, another exception occurred:

Traceback (most recent call last):
  File "/var/lib/juju/agents/unit-mysql-1/charm/venv/opentelemetry/sdk/trace/export/__init__.py", line 368, in _export_batch
    self.span_exporter.export(self.spans_list[:idx])  # type: ignore
  File "/var/lib/juju/agents/unit-mysql-1/charm/venv/opentelemetry/exporter/otlp/proto/http/trace_exporter/__init__.py", line 145, in export
    resp = self._export(serialized_data)
  File "/var/lib/juju/agents/unit-mysql-1/charm/venv/opentelemetry/exporter/otlp/proto/http/trace_exporter/__init__.py", line 114, in _export
    return self._session.post(
  File "/var/lib/juju/agents/unit-mysql-1/charm/venv/requests/sessions.py", line 637, in post
    return self.request("POST", url, data=data, json=json, **kwargs)
  File "/var/lib/juju/agents/unit-mysql-1/charm/venv/requests/sessions.py", line 589, in request
    resp = self.send(prep, **send_kwargs)
  File "/var/lib/juju/agents/unit-mysql-1/charm/venv/requests/sessions.py", line 703, in send
    r = adapter.send(request, **kwargs)
  File "/var/lib/juju/agents/unit-mysql-1/charm/venv/requests/adapters.py", line 519, in send
    raise ConnectionError(e, request=request)
requests.exceptions.ConnectionError: HTTPConnectionPool(host='juju-612b1f-3.lxd', port=4318): Max retries exceeded with url: /v1/traces (Caused by NewConnectionError('<urllib3.connection.HTTPConnection object at 0x7fc9551d0f70>: Failed to establish a new connection: [Errno 111] Connection refused'))
unit-mysql-0: 01:34:26 ERROR unit.mysql/0.juju-log cos-agent:19: Exception while exporting Span batch.
Traceback (most recent call last):
  File "/var/lib/juju/agents/unit-mysql-0/charm/venv/urllib3/connection.py", line 174, in _new_conn
    conn = connection.create_connection(
  File "/var/lib/juju/agents/unit-mysql-0/charm/venv/urllib3/util/connection.py", line 95, in create_connection
    raise err
  File "/var/lib/juju/agents/unit-mysql-0/charm/venv/urllib3/util/connection.py", line 85, in create_connection
    sock.connect(sa)
ConnectionRefusedError: [Errno 111] Connection refused

During handling of the above exception, another exception occurred:

Traceback (most recent call last):
  File "/var/lib/juju/agents/unit-mysql-0/charm/venv/urllib3/connectionpool.py", line 715, in urlopen
    httplib_response = self._make_request(
  File "/var/lib/juju/agents/unit-mysql-0/charm/venv/urllib3/connectionpool.py", line 416, in _make_request
    conn.request(method, url, **httplib_request_kw)
  File "/var/lib/juju/agents/unit-mysql-0/charm/venv/urllib3/connection.py", line 244, in request
    super(HTTPConnection, self).request(method, url, body=body, headers=headers)
  File "/usr/lib/python3.10/http/client.py", line 1283, in request
    self._send_request(method, url, body, headers, encode_chunked)
  File "/usr/lib/python3.10/http/client.py", line 1329, in _send_request
    self.endheaders(body, encode_chunked=encode_chunked)
  File "/usr/lib/python3.10/http/client.py", line 1278, in endheaders
    self._send_output(message_body, encode_chunked=encode_chunked)
  File "/usr/lib/python3.10/http/client.py", line 1038, in _send_output
    self.send(msg)
  File "/usr/lib/python3.10/http/client.py", line 976, in send
    self.connect()
  File "/var/lib/juju/agents/unit-mysql-0/charm/venv/urllib3/connection.py", line 205, in connect
    conn = self._new_conn()
  File "/var/lib/juju/agents/unit-mysql-0/charm/venv/urllib3/connection.py", line 186, in _new_conn
    raise NewConnectionError(
urllib3.exceptions.NewConnectionError: <urllib3.connection.HTTPConnection object at 0x7f9908c3d090>: Failed to establish a new connection: [Errno 111] Connection refused

During handling of the above exception, another exception occurred:

Traceback (most recent call last):
  File "/var/lib/juju/agents/unit-mysql-0/charm/venv/requests/adapters.py", line 486, in send
    resp = conn.urlopen(
  File "/var/lib/juju/agents/unit-mysql-0/charm/venv/urllib3/connectionpool.py", line 801, in urlopen
    retries = retries.increment(
  File "/var/lib/juju/agents/unit-mysql-0/charm/venv/urllib3/util/retry.py", line 594, in increment
    raise MaxRetryError(_pool, url, error or ResponseError(cause))
urllib3.exceptions.MaxRetryError: HTTPConnectionPool(host='juju-612b1f-2.lxd', port=4318): Max retries exceeded with url: /v1/traces (Caused by NewConnectionError('<urllib3.connection.HTTPConnection object at 0x7f9908c3d090>: Failed to establish a new connection: [Errno 111] Connection refused'))

During handling of the above exception, another exception occurred:

Traceback (most recent call last):
  File "/var/lib/juju/agents/unit-mysql-0/charm/venv/opentelemetry/sdk/trace/export/__init__.py", line 368, in _export_batch
    self.span_exporter.export(self.spans_list[:idx])  # type: ignore
  File "/var/lib/juju/agents/unit-mysql-0/charm/venv/opentelemetry/exporter/otlp/proto/http/trace_exporter/__init__.py", line 145, in export
    resp = self._export(serialized_data)
  File "/var/lib/juju/agents/unit-mysql-0/charm/venv/opentelemetry/exporter/otlp/proto/http/trace_exporter/__init__.py", line 114, in _export
    return self._session.post(
  File "/var/lib/juju/agents/unit-mysql-0/charm/venv/requests/sessions.py", line 637, in post
    return self.request("POST", url, data=data, json=json, **kwargs)
  File "/var/lib/juju/agents/unit-mysql-0/charm/venv/requests/sessions.py", line 589, in request
    resp = self.send(prep, **send_kwargs)
  File "/var/lib/juju/agents/unit-mysql-0/charm/venv/requests/sessions.py", line 703, in send
    r = adapter.send(request, **kwargs)
  File "/var/lib/juju/agents/unit-mysql-0/charm/venv/requests/adapters.py", line 519, in send
    raise ConnectionError(e, request=request)
requests.exceptions.ConnectionError: HTTPConnectionPool(host='juju-612b1f-2.lxd', port=4318): Max retries exceeded with url: /v1/traces (Caused by NewConnectionError('<urllib3.connection.HTTPConnection object at 0x7f9908c3d090>: Failed to establish a new connection: [Errno 111] Connection refused'))
unit-mysql-2: 01:34:28 ERROR unit.mysql/2.juju-log database-peers:2: Exception while exporting Span batch.
Traceback (most recent call last):
  File "/var/lib/juju/agents/unit-mysql-2/charm/venv/urllib3/connection.py", line 174, in _new_conn
    conn = connection.create_connection(
  File "/var/lib/juju/agents/unit-mysql-2/charm/venv/urllib3/util/connection.py", line 95, in create_connection
    raise err
  File "/var/lib/juju/agents/unit-mysql-2/charm/venv/urllib3/util/connection.py", line 85, in create_connection
    sock.connect(sa)
ConnectionRefusedError: [Errno 111] Connection refused

During handling of the above exception, another exception occurred:

Traceback (most recent call last):
  File "/var/lib/juju/agents/unit-mysql-2/charm/venv/urllib3/connectionpool.py", line 715, in urlopen
    httplib_response = self._make_request(
  File "/var/lib/juju/agents/unit-mysql-2/charm/venv/urllib3/connectionpool.py", line 416, in _make_request
    conn.request(method, url, **httplib_request_kw)
  File "/var/lib/juju/agents/unit-mysql-2/charm/venv/urllib3/connection.py", line 244, in request
    super(HTTPConnection, self).request(method, url, body=body, headers=headers)
  File "/usr/lib/python3.10/http/client.py", line 1283, in request
    self._send_request(method, url, body, headers, encode_chunked)
  File "/usr/lib/python3.10/http/client.py", line 1329, in _send_request
    self.endheaders(body, encode_chunked=encode_chunked)
  File "/usr/lib/python3.10/http/client.py", line 1278, in endheaders
    self._send_output(message_body, encode_chunked=encode_chunked)
  File "/usr/lib/python3.10/http/client.py", line 1038, in _send_output
    self.send(msg)
  File "/usr/lib/python3.10/http/client.py", line 976, in send
    self.connect()
  File "/var/lib/juju/agents/unit-mysql-2/charm/venv/urllib3/connection.py", line 205, in connect
    conn = self._new_conn()
  File "/var/lib/juju/agents/unit-mysql-2/charm/venv/urllib3/connection.py", line 186, in _new_conn
    raise NewConnectionError(
urllib3.exceptions.NewConnectionError: <urllib3.connection.HTTPConnection object at 0x7f6e87740ca0>: Failed to establish a new connection: [Errno 111] Connection refused

During handling of the above exception, another exception occurred:

Traceback (most recent call last):
  File "/var/lib/juju/agents/unit-mysql-2/charm/venv/requests/adapters.py", line 486, in send
    resp = conn.urlopen(
  File "/var/lib/juju/agents/unit-mysql-2/charm/venv/urllib3/connectionpool.py", line 801, in urlopen
    retries = retries.increment(
  File "/var/lib/juju/agents/unit-mysql-2/charm/venv/urllib3/util/retry.py", line 594, in increment
    raise MaxRetryError(_pool, url, error or ResponseError(cause))
urllib3.exceptions.MaxRetryError: HTTPConnectionPool(host='juju-612b1f-4.lxd', port=4318): Max retries exceeded with url: /v1/traces (Caused by NewConnectionError('<urllib3.connection.HTTPConnection object at 0x7f6e87740ca0>: Failed to establish a new connection: [Errno 111] Connection refused'))

During handling of the above exception, another exception occurred:

Traceback (most recent call last):
  File "/var/lib/juju/agents/unit-mysql-2/charm/venv/opentelemetry/sdk/trace/export/__init__.py", line 368, in _export_batch
    self.span_exporter.export(self.spans_list[:idx])  # type: ignore
  File "/var/lib/juju/agents/unit-mysql-2/charm/venv/opentelemetry/exporter/otlp/proto/http/trace_exporter/__init__.py", line 145, in export
    resp = self._export(serialized_data)
  File "/var/lib/juju/agents/unit-mysql-2/charm/venv/opentelemetry/exporter/otlp/proto/http/trace_exporter/__init__.py", line 114, in _export
    return self._session.post(
  File "/var/lib/juju/agents/unit-mysql-2/charm/venv/requests/sessions.py", line 637, in post
    return self.request("POST", url, data=data, json=json, **kwargs)
  File "/var/lib/juju/agents/unit-mysql-2/charm/venv/requests/sessions.py", line 589, in request
    resp = self.send(prep, **send_kwargs)
  File "/var/lib/juju/agents/unit-mysql-2/charm/venv/requests/sessions.py", line 703, in send
    r = adapter.send(request, **kwargs)
  File "/var/lib/juju/agents/unit-mysql-2/charm/venv/requests/adapters.py", line 519, in send
    raise ConnectionError(e, request=request)
requests.exceptions.ConnectionError: HTTPConnectionPool(host='juju-612b1f-4.lxd', port=4318): Max retries exceeded with url: /v1/traces (Caused by NewConnectionError('<urllib3.connection.HTTPConnection object at 0x7f6e87740ca0>: Failed to establish a new connection: [Errno 111] Connection refused'))
unit-mysql-0: 01:34:33 ERROR unit.mysql/0.juju-log database-peers:2: Exception while exporting Span batch.
Traceback (most recent call last):
  File "/var/lib/juju/agents/unit-mysql-0/charm/venv/urllib3/connection.py", line 174, in _new_conn
    conn = connection.create_connection(
  File "/var/lib/juju/agents/unit-mysql-0/charm/venv/urllib3/util/connection.py", line 95, in create_connection
    raise err
  File "/var/lib/juju/agents/unit-mysql-0/charm/venv/urllib3/util/connection.py", line 85, in create_connection
    sock.connect(sa)
ConnectionRefusedError: [Errno 111] Connection refused

During handling of the above exception, another exception occurred:

Traceback (most recent call last):
  File "/var/lib/juju/agents/unit-mysql-0/charm/venv/urllib3/connectionpool.py", line 715, in urlopen
    httplib_response = self._make_request(
  File "/var/lib/juju/agents/unit-mysql-0/charm/venv/urllib3/connectionpool.py", line 416, in _make_request
    conn.request(method, url, **httplib_request_kw)
  File "/var/lib/juju/agents/unit-mysql-0/charm/venv/urllib3/connection.py", line 244, in request
    super(HTTPConnection, self).request(method, url, body=body, headers=headers)
  File "/usr/lib/python3.10/http/client.py", line 1283, in request
    self._send_request(method, url, body, headers, encode_chunked)
  File "/usr/lib/python3.10/http/client.py", line 1329, in _send_request
    self.endheaders(body, encode_chunked=encode_chunked)
  File "/usr/lib/python3.10/http/client.py", line 1278, in endheaders
    self._send_output(message_body, encode_chunked=encode_chunked)
  File "/usr/lib/python3.10/http/client.py", line 1038, in _send_output
    self.send(msg)
  File "/usr/lib/python3.10/http/client.py", line 976, in send
    self.connect()
  File "/var/lib/juju/agents/unit-mysql-0/charm/venv/urllib3/connection.py", line 205, in connect
    conn = self._new_conn()
  File "/var/lib/juju/agents/unit-mysql-0/charm/venv/urllib3/connection.py", line 186, in _new_conn
    raise NewConnectionError(
urllib3.exceptions.NewConnectionError: <urllib3.connection.HTTPConnection object at 0x7fa7432ec6a0>: Failed to establish a new connection: [Errno 111] Connection refused

During handling of the above exception, another exception occurred:

Traceback (most recent call last):
  File "/var/lib/juju/agents/unit-mysql-0/charm/venv/requests/adapters.py", line 486, in send
    resp = conn.urlopen(
  File "/var/lib/juju/agents/unit-mysql-0/charm/venv/urllib3/connectionpool.py", line 801, in urlopen
    retries = retries.increment(
  File "/var/lib/juju/agents/unit-mysql-0/charm/venv/urllib3/util/retry.py", line 594, in increment
    raise MaxRetryError(_pool, url, error or ResponseError(cause))
urllib3.exceptions.MaxRetryError: HTTPConnectionPool(host='juju-612b1f-2.lxd', port=4318): Max retries exceeded with url: /v1/traces (Caused by NewConnectionError('<urllib3.connection.HTTPConnection object at 0x7fa7432ec6a0>: Failed to establish a new connection: [Errno 111] Connection refused'))

During handling of the above exception, another exception occurred:

Traceback (most recent call last):
  File "/var/lib/juju/agents/unit-mysql-0/charm/venv/opentelemetry/sdk/trace/export/__init__.py", line 368, in _export_batch
    self.span_exporter.export(self.spans_list[:idx])  # type: ignore
  File "/var/lib/juju/agents/unit-mysql-0/charm/venv/opentelemetry/exporter/otlp/proto/http/trace_exporter/__init__.py", line 145, in export
    resp = self._export(serialized_data)
  File "/var/lib/juju/agents/unit-mysql-0/charm/venv/opentelemetry/exporter/otlp/proto/http/trace_exporter/__init__.py", line 114, in _export
    return self._session.post(
  File "/var/lib/juju/agents/unit-mysql-0/charm/venv/requests/sessions.py", line 637, in post
    return self.request("POST", url, data=data, json=json, **kwargs)
  File "/var/lib/juju/agents/unit-mysql-0/charm/venv/requests/sessions.py", line 589, in request
    resp = self.send(prep, **send_kwargs)
  File "/var/lib/juju/agents/unit-mysql-0/charm/venv/requests/sessions.py", line 703, in send
    r = adapter.send(request, **kwargs)
  File "/var/lib/juju/agents/unit-mysql-0/charm/venv/requests/adapters.py", line 519, in send
    raise ConnectionError(e, request=request)
requests.exceptions.ConnectionError: HTTPConnectionPool(host='juju-612b1f-2.lxd', port=4318): Max retries exceeded with url: /v1/traces (Caused by NewConnectionError('<urllib3.connection.HTTPConnection object at 0x7fa7432ec6a0>: Failed to establish a new connection: [Errno 111] Connection refused'))
unit-mysql-2: 01:34:33 ERROR unit.mysql/2.juju-log database-peers:2: Exception while exporting Span batch.
Traceback (most recent call last):
  File "/var/lib/juju/agents/unit-mysql-2/charm/venv/urllib3/connection.py", line 174, in _new_conn
    conn = connection.create_connection(
  File "/var/lib/juju/agents/unit-mysql-2/charm/venv/urllib3/util/connection.py", line 95, in create_connection
    raise err
  File "/var/lib/juju/agents/unit-mysql-2/charm/venv/urllib3/util/connection.py", line 85, in create_connection
    sock.connect(sa)
ConnectionRefusedError: [Errno 111] Connection refused

During handling of the above exception, another exception occurred:

Traceback (most recent call last):
  File "/var/lib/juju/agents/unit-mysql-2/charm/venv/urllib3/connectionpool.py", line 715, in urlopen
    httplib_response = self._make_request(
  File "/var/lib/juju/agents/unit-mysql-2/charm/venv/urllib3/connectionpool.py", line 416, in _make_request
    conn.request(method, url, **httplib_request_kw)
  File "/var/lib/juju/agents/unit-mysql-2/charm/venv/urllib3/connection.py", line 244, in request
    super(HTTPConnection, self).request(method, url, body=body, headers=headers)
  File "/usr/lib/python3.10/http/client.py", line 1283, in request
    self._send_request(method, url, body, headers, encode_chunked)
  File "/usr/lib/python3.10/http/client.py", line 1329, in _send_request
    self.endheaders(body, encode_chunked=encode_chunked)
  File "/usr/lib/python3.10/http/client.py", line 1278, in endheaders
    self._send_output(message_body, encode_chunked=encode_chunked)
  File "/usr/lib/python3.10/http/client.py", line 1038, in _send_output
    self.send(msg)
  File "/usr/lib/python3.10/http/client.py", line 976, in send
    self.connect()
  File "/var/lib/juju/agents/unit-mysql-2/charm/venv/urllib3/connection.py", line 205, in connect
    conn = self._new_conn()
  File "/var/lib/juju/agents/unit-mysql-2/charm/venv/urllib3/connection.py", line 186, in _new_conn
    raise NewConnectionError(
urllib3.exceptions.NewConnectionError: <urllib3.connection.HTTPConnection object at 0x7f6e877407f0>: Failed to establish a new connection: [Errno 111] Connection refused

During handling of the above exception, another exception occurred:

Traceback (most recent call last):
  File "/var/lib/juju/agents/unit-mysql-2/charm/venv/requests/adapters.py", line 486, in send
    resp = conn.urlopen(
  File "/var/lib/juju/agents/unit-mysql-2/charm/venv/urllib3/connectionpool.py", line 801, in urlopen
    retries = retries.increment(
  File "/var/lib/juju/agents/unit-mysql-2/charm/venv/urllib3/util/retry.py", line 594, in increment
    raise MaxRetryError(_pool, url, error or ResponseError(cause))
urllib3.exceptions.MaxRetryError: HTTPConnectionPool(host='juju-612b1f-4.lxd', port=4318): Max retries exceeded with url: /v1/traces (Caused by NewConnectionError('<urllib3.connection.HTTPConnection object at 0x7f6e877407f0>: Failed to establish a new connection: [Errno 111] Connection refused'))

During handling of the above exception, another exception occurred:

Traceback (most recent call last):
  File "/var/lib/juju/agents/unit-mysql-2/charm/venv/opentelemetry/sdk/trace/export/__init__.py", line 368, in _export_batch
    self.span_exporter.export(self.spans_list[:idx])  # type: ignore
  File "/var/lib/juju/agents/unit-mysql-2/charm/venv/opentelemetry/exporter/otlp/proto/http/trace_exporter/__init__.py", line 145, in export
    resp = self._export(serialized_data)
  File "/var/lib/juju/agents/unit-mysql-2/charm/venv/opentelemetry/exporter/otlp/proto/http/trace_exporter/__init__.py", line 114, in _export
    return self._session.post(
  File "/var/lib/juju/agents/unit-mysql-2/charm/venv/requests/sessions.py", line 637, in post
    return self.request("POST", url, data=data, json=json, **kwargs)
  File "/var/lib/juju/agents/unit-mysql-2/charm/venv/requests/sessions.py", line 589, in request
    resp = self.send(prep, **send_kwargs)
  File "/var/lib/juju/agents/unit-mysql-2/charm/venv/requests/sessions.py", line 703, in send
    r = adapter.send(request, **kwargs)
  File "/var/lib/juju/agents/unit-mysql-2/charm/venv/requests/adapters.py", line 519, in send
    raise ConnectionError(e, request=request)
requests.exceptions.ConnectionError: HTTPConnectionPool(host='juju-612b1f-4.lxd', port=4318): Max retries exceeded with url: /v1/traces (Caused by NewConnectionError('<urllib3.connection.HTTPConnection object at 0x7f6e877407f0>: Failed to establish a new connection: [Errno 111] Connection refused'))
unit-mysql-1: 01:34:34 ERROR unit.mysql/1.juju-log Exception while exporting Span batch.
Traceback (most recent call last):
  File "/var/lib/juju/agents/unit-mysql-1/charm/venv/urllib3/connection.py", line 174, in _new_conn
    conn = connection.create_connection(
  File "/var/lib/juju/agents/unit-mysql-1/charm/venv/urllib3/util/connection.py", line 95, in create_connection
    raise err
  File "/var/lib/juju/agents/unit-mysql-1/charm/venv/urllib3/util/connection.py", line 85, in create_connection
    sock.connect(sa)
ConnectionRefusedError: [Errno 111] Connection refused

During handling of the above exception, another exception occurred:

Traceback (most recent call last):
  File "/var/lib/juju/agents/unit-mysql-1/charm/venv/urllib3/connectionpool.py", line 715, in urlopen
    httplib_response = self._make_request(
  File "/var/lib/juju/agents/unit-mysql-1/charm/venv/urllib3/connectionpool.py", line 416, in _make_request
    conn.request(method, url, **httplib_request_kw)
  File "/var/lib/juju/agents/unit-mysql-1/charm/venv/urllib3/connection.py", line 244, in request
    super(HTTPConnection, self).request(method, url, body=body, headers=headers)
  File "/usr/lib/python3.10/http/client.py", line 1283, in request
    self._send_request(method, url, body, headers, encode_chunked)
  File "/usr/lib/python3.10/http/client.py", line 1329, in _send_request
    self.endheaders(body, encode_chunked=encode_chunked)
  File "/usr/lib/python3.10/http/client.py", line 1278, in endheaders
    self._send_output(message_body, encode_chunked=encode_chunked)
  File "/usr/lib/python3.10/http/client.py", line 1038, in _send_output
    self.send(msg)
  File "/usr/lib/python3.10/http/client.py", line 976, in send
    self.connect()
  File "/var/lib/juju/agents/unit-mysql-1/charm/venv/urllib3/connection.py", line 205, in connect
    conn = self._new_conn()
  File "/var/lib/juju/agents/unit-mysql-1/charm/venv/urllib3/connection.py", line 186, in _new_conn
    raise NewConnectionError(
urllib3.exceptions.NewConnectionError: <urllib3.connection.HTTPConnection object at 0x7f3079ccd3c0>: Failed to establish a new connection: [Errno 111] Connection refused

During handling of the above exception, another exception occurred:

Traceback (most recent call last):
  File "/var/lib/juju/agents/unit-mysql-1/charm/venv/requests/adapters.py", line 486, in send
    resp = conn.urlopen(
  File "/var/lib/juju/agents/unit-mysql-1/charm/venv/urllib3/connectionpool.py", line 801, in urlopen
    retries = retries.increment(
  File "/var/lib/juju/agents/unit-mysql-1/charm/venv/urllib3/util/retry.py", line 594, in increment
    raise MaxRetryError(_pool, url, error or ResponseError(cause))
urllib3.exceptions.MaxRetryError: HTTPConnectionPool(host='juju-612b1f-3.lxd', port=4318): Max retries exceeded with url: /v1/traces (Caused by NewConnectionError('<urllib3.connection.HTTPConnection object at 0x7f3079ccd3c0>: Failed to establish a new connection: [Errno 111] Connection refused'))

During handling of the above exception, another exception occurred:

Traceback (most recent call last):
  File "/var/lib/juju/agents/unit-mysql-1/charm/venv/opentelemetry/sdk/trace/export/__init__.py", line 368, in _export_batch
    self.span_exporter.export(self.spans_list[:idx])  # type: ignore
  File "/var/lib/juju/agents/unit-mysql-1/charm/venv/opentelemetry/exporter/otlp/proto/http/trace_exporter/__init__.py", line 145, in export
    resp = self._export(serialized_data)
  File "/var/lib/juju/agents/unit-mysql-1/charm/venv/opentelemetry/exporter/otlp/proto/http/trace_exporter/__init__.py", line 114, in _export
    return self._session.post(
  File "/var/lib/juju/agents/unit-mysql-1/charm/venv/requests/sessions.py", line 637, in post
    return self.request("POST", url, data=data, json=json, **kwargs)
  File "/var/lib/juju/agents/unit-mysql-1/charm/venv/requests/sessions.py", line 589, in request
    resp = self.send(prep, **send_kwargs)
  File "/var/lib/juju/agents/unit-mysql-1/charm/venv/requests/sessions.py", line 703, in send
    r = adapter.send(request, **kwargs)
  File "/var/lib/juju/agents/unit-mysql-1/charm/venv/requests/adapters.py", line 519, in send
    raise ConnectionError(e, request=request)
requests.exceptions.ConnectionError: HTTPConnectionPool(host='juju-612b1f-3.lxd', port=4318): Max retries exceeded with url: /v1/traces (Caused by NewConnectionError('<urllib3.connection.HTTPConnection object at 0x7f3079ccd3c0>: Failed to establish a new connection: [Errno 111] Connection refused'))
unit-mysql-0: 01:34:36 ERROR unit.mysql/0.juju-log restart:3: Exception while exporting Span batch.
Traceback (most recent call last):
  File "/var/lib/juju/agents/unit-mysql-0/charm/venv/urllib3/connection.py", line 174, in _new_conn
    conn = connection.create_connection(
  File "/var/lib/juju/agents/unit-mysql-0/charm/venv/urllib3/util/connection.py", line 95, in create_connection
    raise err
  File "/var/lib/juju/agents/unit-mysql-0/charm/venv/urllib3/util/connection.py", line 85, in create_connection
    sock.connect(sa)
ConnectionRefusedError: [Errno 111] Connection refused

During handling of the above exception, another exception occurred:

Traceback (most recent call last):
  File "/var/lib/juju/agents/unit-mysql-0/charm/venv/urllib3/connectionpool.py", line 715, in urlopen
    httplib_response = self._make_request(
  File "/var/lib/juju/agents/unit-mysql-0/charm/venv/urllib3/connectionpool.py", line 416, in _make_request
    conn.request(method, url, **httplib_request_kw)
  File "/var/lib/juju/agents/unit-mysql-0/charm/venv/urllib3/connection.py", line 244, in request
    super(HTTPConnection, self).request(method, url, body=body, headers=headers)
  File "/usr/lib/python3.10/http/client.py", line 1283, in request
    self._send_request(method, url, body, headers, encode_chunked)
  File "/usr/lib/python3.10/http/client.py", line 1329, in _send_request
    self.endheaders(body, encode_chunked=encode_chunked)
  File "/usr/lib/python3.10/http/client.py", line 1278, in endheaders
    self._send_output(message_body, encode_chunked=encode_chunked)
  File "/usr/lib/python3.10/http/client.py", line 1038, in _send_output
    self.send(msg)
  File "/usr/lib/python3.10/http/client.py", line 976, in send
    self.connect()
  File "/var/lib/juju/agents/unit-mysql-0/charm/venv/urllib3/connection.py", line 205, in connect
    conn = self._new_conn()
  File "/var/lib/juju/agents/unit-mysql-0/charm/venv/urllib3/connection.py", line 186, in _new_conn
    raise NewConnectionError(
urllib3.exceptions.NewConnectionError: <urllib3.connection.HTTPConnection object at 0x7f49f153a260>: Failed to establish a new connection: [Errno 111] Connection refused

During handling of the above exception, another exception occurred:

Traceback (most recent call last):
  File "/var/lib/juju/agents/unit-mysql-0/charm/venv/requests/adapters.py", line 486, in send
    resp = conn.urlopen(
  File "/var/lib/juju/agents/unit-mysql-0/charm/venv/urllib3/connectionpool.py", line 801, in urlopen
    retries = retries.increment(
  File "/var/lib/juju/agents/unit-mysql-0/charm/venv/urllib3/util/retry.py", line 594, in increment
    raise MaxRetryError(_pool, url, error or ResponseError(cause))
urllib3.exceptions.MaxRetryError: HTTPConnectionPool(host='juju-612b1f-2.lxd', port=4318): Max retries exceeded with url: /v1/traces (Caused by NewConnectionError('<urllib3.connection.HTTPConnection object at 0x7f49f153a260>: Failed to establish a new connection: [Errno 111] Connection refused'))

During handling of the above exception, another exception occurred:

Traceback (most recent call last):
  File "/var/lib/juju/agents/unit-mysql-0/charm/venv/opentelemetry/sdk/trace/export/__init__.py", line 368, in _export_batch
    self.span_exporter.export(self.spans_list[:idx])  # type: ignore
  File "/var/lib/juju/agents/unit-mysql-0/charm/venv/opentelemetry/exporter/otlp/proto/http/trace_exporter/__init__.py", line 145, in export
    resp = self._export(serialized_data)
  File "/var/lib/juju/agents/unit-mysql-0/charm/venv/opentelemetry/exporter/otlp/proto/http/trace_exporter/__init__.py", line 114, in _export
    return self._session.post(
  File "/var/lib/juju/agents/unit-mysql-0/charm/venv/requests/sessions.py", line 637, in post
    return self.request("POST", url, data=data, json=json, **kwargs)
  File "/var/lib/juju/agents/unit-mysql-0/charm/venv/requests/sessions.py", line 589, in request
    resp = self.send(prep, **send_kwargs)
  File "/var/lib/juju/agents/unit-mysql-0/charm/venv/requests/sessions.py", line 703, in send
    r = adapter.send(request, **kwargs)
  File "/var/lib/juju/agents/unit-mysql-0/charm/venv/requests/adapters.py", line 519, in send
    raise ConnectionError(e, request=request)
requests.exceptions.ConnectionError: HTTPConnectionPool(host='juju-612b1f-2.lxd', port=4318): Max retries exceeded with url: /v1/traces (Caused by NewConnectionError('<urllib3.connection.HTTPConnection object at 0x7f49f153a260>: Failed to establish a new connection: [Errno 111] Connection refused'))
unit-mysql-0: 01:34:40 ERROR unit.mysql/0.juju-log database:13: Exception while exporting Span batch.
Traceback (most recent call last):
  File "/var/lib/juju/agents/unit-mysql-0/charm/venv/urllib3/connection.py", line 174, in _new_conn
    conn = connection.create_connection(
  File "/var/lib/juju/agents/unit-mysql-0/charm/venv/urllib3/util/connection.py", line 95, in create_connection
    raise err
  File "/var/lib/juju/agents/unit-mysql-0/charm/venv/urllib3/util/connection.py", line 85, in create_connection
    sock.connect(sa)
ConnectionRefusedError: [Errno 111] Connection refused

During handling of the above exception, another exception occurred:

Traceback (most recent call last):
  File "/var/lib/juju/agents/unit-mysql-0/charm/venv/urllib3/connectionpool.py", line 715, in urlopen
    httplib_response = self._make_request(
  File "/var/lib/juju/agents/unit-mysql-0/charm/venv/urllib3/connectionpool.py", line 416, in _make_request
    conn.request(method, url, **httplib_request_kw)
  File "/var/lib/juju/agents/unit-mysql-0/charm/venv/urllib3/connection.py", line 244, in request
    super(HTTPConnection, self).request(method, url, body=body, headers=headers)
  File "/usr/lib/python3.10/http/client.py", line 1283, in request
    self._send_request(method, url, body, headers, encode_chunked)
  File "/usr/lib/python3.10/http/client.py", line 1329, in _send_request
    self.endheaders(body, encode_chunked=encode_chunked)
  File "/usr/lib/python3.10/http/client.py", line 1278, in endheaders
    self._send_output(message_body, encode_chunked=encode_chunked)
  File "/usr/lib/python3.10/http/client.py", line 1038, in _send_output
    self.send(msg)
  File "/usr/lib/python3.10/http/client.py", line 976, in send
    self.connect()
  File "/var/lib/juju/agents/unit-mysql-0/charm/venv/urllib3/connection.py", line 205, in connect
    conn = self._new_conn()
  File "/var/lib/juju/agents/unit-mysql-0/charm/venv/urllib3/connection.py", line 186, in _new_conn
    raise NewConnectionError(
urllib3.exceptions.NewConnectionError: <urllib3.connection.HTTPConnection object at 0x7f59b03de5f0>: Failed to establish a new connection: [Errno 111] Connection refused

During handling of the above exception, another exception occurred:

Traceback (most recent call last):
  File "/var/lib/juju/agents/unit-mysql-0/charm/venv/requests/adapters.py", line 486, in send
    resp = conn.urlopen(
  File "/var/lib/juju/agents/unit-mysql-0/charm/venv/urllib3/connectionpool.py", line 801, in urlopen
    retries = retries.increment(
  File "/var/lib/juju/agents/unit-mysql-0/charm/venv/urllib3/util/retry.py", line 594, in increment
    raise MaxRetryError(_pool, url, error or ResponseError(cause))
urllib3.exceptions.MaxRetryError: HTTPConnectionPool(host='juju-612b1f-2.lxd', port=4318): Max retries exceeded with url: /v1/traces (Caused by NewConnectionError('<urllib3.connection.HTTPConnection object at 0x7f59b03de5f0>: Failed to establish a new connection: [Errno 111] Connection refused'))

During handling of the above exception, another exception occurred:

Traceback (most recent call last):
  File "/var/lib/juju/agents/unit-mysql-0/charm/venv/opentelemetry/sdk/trace/export/__init__.py", line 368, in _export_batch
    self.span_exporter.export(self.spans_list[:idx])  # type: ignore
  File "/var/lib/juju/agents/unit-mysql-0/charm/venv/opentelemetry/exporter/otlp/proto/http/trace_exporter/__init__.py", line 145, in export
    resp = self._export(serialized_data)
  File "/var/lib/juju/agents/unit-mysql-0/charm/venv/opentelemetry/exporter/otlp/proto/http/trace_exporter/__init__.py", line 114, in _export
    return self._session.post(
  File "/var/lib/juju/agents/unit-mysql-0/charm/venv/requests/sessions.py", line 637, in post
    return self.request("POST", url, data=data, json=json, **kwargs)
  File "/var/lib/juju/agents/unit-mysql-0/charm/venv/requests/sessions.py", line 589, in request
    resp = self.send(prep, **send_kwargs)
  File "/var/lib/juju/agents/unit-mysql-0/charm/venv/requests/sessions.py", line 703, in send
    r = adapter.send(request, **kwargs)
  File "/var/lib/juju/agents/unit-mysql-0/charm/venv/requests/adapters.py", line 519, in send
    raise ConnectionError(e, request=request)
requests.exceptions.ConnectionError: HTTPConnectionPool(host='juju-612b1f-2.lxd', port=4318): Max retries exceeded with url: /v1/traces (Caused by NewConnectionError('<urllib3.connection.HTTPConnection object at 0x7f59b03de5f0>: Failed to establish a new connection: [Errno 111] Connection refused'))
unit-mysql-1: 01:34:42 ERROR unit.mysql/1.juju-log database:17: Exception while exporting Span batch.
Traceback (most recent call last):
  File "/var/lib/juju/agents/unit-mysql-1/charm/venv/urllib3/connection.py", line 174, in _new_conn
    conn = connection.create_connection(
  File "/var/lib/juju/agents/unit-mysql-1/charm/venv/urllib3/util/connection.py", line 95, in create_connection
    raise err
  File "/var/lib/juju/agents/unit-mysql-1/charm/venv/urllib3/util/connection.py", line 85, in create_connection
    sock.connect(sa)
ConnectionRefusedError: [Errno 111] Connection refused

During handling of the above exception, another exception occurred:

Traceback (most recent call last):
  File "/var/lib/juju/agents/unit-mysql-1/charm/venv/urllib3/connectionpool.py", line 715, in urlopen
    httplib_response = self._make_request(
  File "/var/lib/juju/agents/unit-mysql-1/charm/venv/urllib3/connectionpool.py", line 416, in _make_request
    conn.request(method, url, **httplib_request_kw)
  File "/var/lib/juju/agents/unit-mysql-1/charm/venv/urllib3/connection.py", line 244, in request
    super(HTTPConnection, self).request(method, url, body=body, headers=headers)
  File "/usr/lib/python3.10/http/client.py", line 1283, in request
    self._send_request(method, url, body, headers, encode_chunked)
  File "/usr/lib/python3.10/http/client.py", line 1329, in _send_request
    self.endheaders(body, encode_chunked=encode_chunked)
  File "/usr/lib/python3.10/http/client.py", line 1278, in endheaders
    self._send_output(message_body, encode_chunked=encode_chunked)
  File "/usr/lib/python3.10/http/client.py", line 1038, in _send_output
    self.send(msg)
  File "/usr/lib/python3.10/http/client.py", line 976, in send
    self.connect()
  File "/var/lib/juju/agents/unit-mysql-1/charm/venv/urllib3/connection.py", line 205, in connect
    conn = self._new_conn()
  File "/var/lib/juju/agents/unit-mysql-1/charm/venv/urllib3/connection.py", line 186, in _new_conn
    raise NewConnectionError(
urllib3.exceptions.NewConnectionError: <urllib3.connection.HTTPConnection object at 0x7fd2f1838460>: Failed to establish a new connection: [Errno 111] Connection refused

During handling of the above exception, another exception occurred:

Traceback (most recent call last):
  File "/var/lib/juju/agents/unit-mysql-1/charm/venv/requests/adapters.py", line 486, in send
    resp = conn.urlopen(
  File "/var/lib/juju/agents/unit-mysql-1/charm/venv/urllib3/connectionpool.py", line 801, in urlopen
    retries = retries.increment(
  File "/var/lib/juju/agents/unit-mysql-1/charm/venv/urllib3/util/retry.py", line 594, in increment
    raise MaxRetryError(_pool, url, error or ResponseError(cause))
urllib3.exceptions.MaxRetryError: HTTPConnectionPool(host='juju-612b1f-3.lxd', port=4318): Max retries exceeded with url: /v1/traces (Caused by NewConnectionError('<urllib3.connection.HTTPConnection object at 0x7fd2f1838460>: Failed to establish a new connection: [Errno 111] Connection refused'))

During handling of the above exception, another exception occurred:

Traceback (most recent call last):
  File "/var/lib/juju/agents/unit-mysql-1/charm/venv/opentelemetry/sdk/trace/export/__init__.py", line 368, in _export_batch
    self.span_exporter.export(self.spans_list[:idx])  # type: ignore
  File "/var/lib/juju/agents/unit-mysql-1/charm/venv/opentelemetry/exporter/otlp/proto/http/trace_exporter/__init__.py", line 145, in export
    resp = self._export(serialized_data)
  File "/var/lib/juju/agents/unit-mysql-1/charm/venv/opentelemetry/exporter/otlp/proto/http/trace_exporter/__init__.py", line 114, in _export
    return self._session.post(
  File "/var/lib/juju/agents/unit-mysql-1/charm/venv/requests/sessions.py", line 637, in post
    return self.request("POST", url, data=data, json=json, **kwargs)
  File "/var/lib/juju/agents/unit-mysql-1/charm/venv/requests/sessions.py", line 589, in request
    resp = self.send(prep, **send_kwargs)
  File "/var/lib/juju/agents/unit-mysql-1/charm/venv/requests/sessions.py", line 703, in send
    r = adapter.send(request, **kwargs)
  File "/var/lib/juju/agents/unit-mysql-1/charm/venv/requests/adapters.py", line 519, in send
    raise ConnectionError(e, request=request)
requests.exceptions.ConnectionError: HTTPConnectionPool(host='juju-612b1f-3.lxd', port=4318): Max retries exceeded with url: /v1/traces (Caused by NewConnectionError('<urllib3.connection.HTTPConnection object at 0x7fd2f1838460>: Failed to establish a new connection: [Errno 111] Connection refused'))
unit-mysql-0: 01:34:45 ERROR unit.mysql/0.juju-log restart:3: Exception while exporting Span batch.
Traceback (most recent call last):
  File "/var/lib/juju/agents/unit-mysql-0/charm/venv/urllib3/connection.py", line 174, in _new_conn
    conn = connection.create_connection(
  File "/var/lib/juju/agents/unit-mysql-0/charm/venv/urllib3/util/connection.py", line 95, in create_connection
    raise err
  File "/var/lib/juju/agents/unit-mysql-0/charm/venv/urllib3/util/connection.py", line 85, in create_connection
    sock.connect(sa)
ConnectionRefusedError: [Errno 111] Connection refused

During handling of the above exception, another exception occurred:

Traceback (most recent call last):
  File "/var/lib/juju/agents/unit-mysql-0/charm/venv/urllib3/connectionpool.py", line 715, in urlopen
    httplib_response = self._make_request(
  File "/var/lib/juju/agents/unit-mysql-0/charm/venv/urllib3/connectionpool.py", line 416, in _make_request
    conn.request(method, url, **httplib_request_kw)
  File "/var/lib/juju/agents/unit-mysql-0/charm/venv/urllib3/connection.py", line 244, in request
    super(HTTPConnection, self).request(method, url, body=body, headers=headers)
  File "/usr/lib/python3.10/http/client.py", line 1283, in request
    self._send_request(method, url, body, headers, encode_chunked)
  File "/usr/lib/python3.10/http/client.py", line 1329, in _send_request
    self.endheaders(body, encode_chunked=encode_chunked)
  File "/usr/lib/python3.10/http/client.py", line 1278, in endheaders
    self._send_output(message_body, encode_chunked=encode_chunked)
  File "/usr/lib/python3.10/http/client.py", line 1038, in _send_output
    self.send(msg)
  File "/usr/lib/python3.10/http/client.py", line 976, in send
    self.connect()
  File "/var/lib/juju/agents/unit-mysql-0/charm/venv/urllib3/connection.py", line 205, in connect
    conn = self._new_conn()
  File "/var/lib/juju/agents/unit-mysql-0/charm/venv/urllib3/connection.py", line 186, in _new_conn
    raise NewConnectionError(
urllib3.exceptions.NewConnectionError: <urllib3.connection.HTTPConnection object at 0x7fc6b99e1f30>: Failed to establish a new connection: [Errno 111] Connection refused

During handling of the above exception, another exception occurred:

Traceback (most recent call last):
  File "/var/lib/juju/agents/unit-mysql-0/charm/venv/requests/adapters.py", line 486, in send
    resp = conn.urlopen(
  File "/var/lib/juju/agents/unit-mysql-0/charm/venv/urllib3/connectionpool.py", line 801, in urlopen
    retries = retries.increment(
  File "/var/lib/juju/agents/unit-mysql-0/charm/venv/urllib3/util/retry.py", line 594, in increment
    raise MaxRetryError(_pool, url, error or ResponseError(cause))
urllib3.exceptions.MaxRetryError: HTTPConnectionPool(host='juju-612b1f-2.lxd', port=4318): Max retries exceeded with url: /v1/traces (Caused by NewConnectionError('<urllib3.connection.HTTPConnection object at 0x7fc6b99e1f30>: Failed to establish a new connection: [Errno 111] Connection refused'))

During handling of the above exception, another exception occurred:

Traceback (most recent call last):
  File "/var/lib/juju/agents/unit-mysql-0/charm/venv/opentelemetry/sdk/trace/export/__init__.py", line 368, in _export_batch
    self.span_exporter.export(self.spans_list[:idx])  # type: ignore
  File "/var/lib/juju/agents/unit-mysql-0/charm/venv/opentelemetry/exporter/otlp/proto/http/trace_exporter/__init__.py", line 145, in export
    resp = self._export(serialized_data)
  File "/var/lib/juju/agents/unit-mysql-0/charm/venv/opentelemetry/exporter/otlp/proto/http/trace_exporter/__init__.py", line 114, in _export
    return self._session.post(
  File "/var/lib/juju/agents/unit-mysql-0/charm/venv/requests/sessions.py", line 637, in post
    return self.request("POST", url, data=data, json=json, **kwargs)
  File "/var/lib/juju/agents/unit-mysql-0/charm/venv/requests/sessions.py", line 589, in request
    resp = self.send(prep, **send_kwargs)
  File "/var/lib/juju/agents/unit-mysql-0/charm/venv/requests/sessions.py", line 703, in send
    r = adapter.send(request, **kwargs)
  File "/var/lib/juju/agents/unit-mysql-0/charm/venv/requests/adapters.py", line 519, in send
    raise ConnectionError(e, request=request)
requests.exceptions.ConnectionError: HTTPConnectionPool(host='juju-612b1f-2.lxd', port=4318): Max retries exceeded with url: /v1/traces (Caused by NewConnectionError('<urllib3.connection.HTTPConnection object at 0x7fc6b99e1f30>: Failed to establish a new connection: [Errno 111] Connection refused'))
unit-mysql-1: 01:34:49 ERROR unit.mysql/1.juju-log database:17: Exception while exporting Span batch.
Traceback (most recent call last):
  File "/var/lib/juju/agents/unit-mysql-1/charm/venv/urllib3/connection.py", line 174, in _new_conn
    conn = connection.create_connection(
  File "/var/lib/juju/agents/unit-mysql-1/charm/venv/urllib3/util/connection.py", line 95, in create_connection
    raise err
  File "/var/lib/juju/agents/unit-mysql-1/charm/venv/urllib3/util/connection.py", line 85, in create_connection
    sock.connect(sa)
ConnectionRefusedError: [Errno 111] Connection refused

During handling of the above exception, another exception occurred:

Traceback (most recent call last):
  File "/var/lib/juju/agents/unit-mysql-1/charm/venv/urllib3/connectionpool.py", line 715, in urlopen
    httplib_response = self._make_request(
  File "/var/lib/juju/agents/unit-mysql-1/charm/venv/urllib3/connectionpool.py", line 416, in _make_request
    conn.request(method, url, **httplib_request_kw)
  File "/var/lib/juju/agents/unit-mysql-1/charm/venv/urllib3/connection.py", line 244, in request
    super(HTTPConnection, self).request(method, url, body=body, headers=headers)
  File "/usr/lib/python3.10/http/client.py", line 1283, in request
    self._send_request(method, url, body, headers, encode_chunked)
  File "/usr/lib/python3.10/http/client.py", line 1329, in _send_request
    self.endheaders(body, encode_chunked=encode_chunked)
  File "/usr/lib/python3.10/http/client.py", line 1278, in endheaders
    self._send_output(message_body, encode_chunked=encode_chunked)
  File "/usr/lib/python3.10/http/client.py", line 1038, in _send_output
    self.send(msg)
  File "/usr/lib/python3.10/http/client.py", line 976, in send
    self.connect()
  File "/var/lib/juju/agents/unit-mysql-1/charm/venv/urllib3/connection.py", line 205, in connect
    conn = self._new_conn()
  File "/var/lib/juju/agents/unit-mysql-1/charm/venv/urllib3/connection.py", line 186, in _new_conn
    raise NewConnectionError(
urllib3.exceptions.NewConnectionError: <urllib3.connection.HTTPConnection object at 0x7f213e6b4c10>: Failed to establish a new connection: [Errno 111] Connection refused

During handling of the above exception, another exception occurred:

Traceback (most recent call last):
  File "/var/lib/juju/agents/unit-mysql-1/charm/venv/requests/adapters.py", line 486, in send
    resp = conn.urlopen(
  File "/var/lib/juju/agents/unit-mysql-1/charm/venv/urllib3/connectionpool.py", line 801, in urlopen
    retries = retries.increment(
  File "/var/lib/juju/agents/unit-mysql-1/charm/venv/urllib3/util/retry.py", line 594, in increment
    raise MaxRetryError(_pool, url, error or ResponseError(cause))
urllib3.exceptions.MaxRetryError: HTTPConnectionPool(host='juju-612b1f-3.lxd', port=4318): Max retries exceeded with url: /v1/traces (Caused by NewConnectionError('<urllib3.connection.HTTPConnection object at 0x7f213e6b4c10>: Failed to establish a new connection: [Errno 111] Connection refused'))

During handling of the above exception, another exception occurred:

Traceback (most recent call last):
  File "/var/lib/juju/agents/unit-mysql-1/charm/venv/opentelemetry/sdk/trace/export/__init__.py", line 368, in _export_batch
    self.span_exporter.export(self.spans_list[:idx])  # type: ignore
  File "/var/lib/juju/agents/unit-mysql-1/charm/venv/opentelemetry/exporter/otlp/proto/http/trace_exporter/__init__.py", line 145, in export
    resp = self._export(serialized_data)
  File "/var/lib/juju/agents/unit-mysql-1/charm/venv/opentelemetry/exporter/otlp/proto/http/trace_exporter/__init__.py", line 114, in _export
    return self._session.post(
  File "/var/lib/juju/agents/unit-mysql-1/charm/venv/requests/sessions.py", line 637, in post
    return self.request("POST", url, data=data, json=json, **kwargs)
  File "/var/lib/juju/agents/unit-mysql-1/charm/venv/requests/sessions.py", line 589, in request
    resp = self.send(prep, **send_kwargs)
  File "/var/lib/juju/agents/unit-mysql-1/charm/venv/requests/sessions.py", line 703, in send
    r = adapter.send(request, **kwargs)
  File "/var/lib/juju/agents/unit-mysql-1/charm/venv/requests/adapters.py", line 519, in send
    raise ConnectionError(e, request=request)
requests.exceptions.ConnectionError: HTTPConnectionPool(host='juju-612b1f-3.lxd', port=4318): Max retries exceeded with url: /v1/traces (Caused by NewConnectionError('<urllib3.connection.HTTPConnection object at 0x7f213e6b4c10>: Failed to establish a new connection: [Errno 111] Connection refused'))
unit-mysql-0: 01:34:50 ERROR unit.mysql/0.juju-log restart:3: Exception while exporting Span batch.
Traceback (most recent call last):
  File "/var/lib/juju/agents/unit-mysql-0/charm/venv/urllib3/connection.py", line 174, in _new_conn
    conn = connection.create_connection(
  File "/var/lib/juju/agents/unit-mysql-0/charm/venv/urllib3/util/connection.py", line 95, in create_connection
    raise err
  File "/var/lib/juju/agents/unit-mysql-0/charm/venv/urllib3/util/connection.py", line 85, in create_connection
    sock.connect(sa)
ConnectionRefusedError: [Errno 111] Connection refused

During handling of the above exception, another exception occurred:

Traceback (most recent call last):
  File "/var/lib/juju/agents/unit-mysql-0/charm/venv/urllib3/connectionpool.py", line 715, in urlopen
    httplib_response = self._make_request(
  File "/var/lib/juju/agents/unit-mysql-0/charm/venv/urllib3/connectionpool.py", line 416, in _make_request
    conn.request(method, url, **httplib_request_kw)
  File "/var/lib/juju/agents/unit-mysql-0/charm/venv/urllib3/connection.py", line 244, in request
    super(HTTPConnection, self).request(method, url, body=body, headers=headers)
  File "/usr/lib/python3.10/http/client.py", line 1283, in request
    self._send_request(method, url, body, headers, encode_chunked)
  File "/usr/lib/python3.10/http/client.py", line 1329, in _send_request
    self.endheaders(body, encode_chunked=encode_chunked)
  File "/usr/lib/python3.10/http/client.py", line 1278, in endheaders
    self._send_output(message_body, encode_chunked=encode_chunked)
  File "/usr/lib/python3.10/http/client.py", line 1038, in _send_output
    self.send(msg)
  File "/usr/lib/python3.10/http/client.py", line 976, in send
    self.connect()
  File "/var/lib/juju/agents/unit-mysql-0/charm/venv/urllib3/connection.py", line 205, in connect
    conn = self._new_conn()
  File "/var/lib/juju/agents/unit-mysql-0/charm/venv/urllib3/connection.py", line 186, in _new_conn
    raise NewConnectionError(
urllib3.exceptions.NewConnectionError: <urllib3.connection.HTTPConnection object at 0x7f531da3e320>: Failed to establish a new connection: [Errno 111] Connection refused

During handling of the above exception, another exception occurred:

Traceback (most recent call last):
  File "/var/lib/juju/agents/unit-mysql-0/charm/venv/requests/adapters.py", line 486, in send
    resp = conn.urlopen(
  File "/var/lib/juju/agents/unit-mysql-0/charm/venv/urllib3/connectionpool.py", line 801, in urlopen
    retries = retries.increment(
  File "/var/lib/juju/agents/unit-mysql-0/charm/venv/urllib3/util/retry.py", line 594, in increment
    raise MaxRetryError(_pool, url, error or ResponseError(cause))
urllib3.exceptions.MaxRetryError: HTTPConnectionPool(host='juju-612b1f-2.lxd', port=4318): Max retries exceeded with url: /v1/traces (Caused by NewConnectionError('<urllib3.connection.HTTPConnection object at 0x7f531da3e320>: Failed to establish a new connection: [Errno 111] Connection refused'))

During handling of the above exception, another exception occurred:

Traceback (most recent call last):
  File "/var/lib/juju/agents/unit-mysql-0/charm/venv/opentelemetry/sdk/trace/export/__init__.py", line 368, in _export_batch
    self.span_exporter.export(self.spans_list[:idx])  # type: ignore
  File "/var/lib/juju/agents/unit-mysql-0/charm/venv/opentelemetry/exporter/otlp/proto/http/trace_exporter/__init__.py", line 145, in export
    resp = self._export(serialized_data)
  File "/var/lib/juju/agents/unit-mysql-0/charm/venv/opentelemetry/exporter/otlp/proto/http/trace_exporter/__init__.py", line 114, in _export
    return self._session.post(
  File "/var/lib/juju/agents/unit-mysql-0/charm/venv/requests/sessions.py", line 637, in post
    return self.request("POST", url, data=data, json=json, **kwargs)
  File "/var/lib/juju/agents/unit-mysql-0/charm/venv/requests/sessions.py", line 589, in request
    resp = self.send(prep, **send_kwargs)
  File "/var/lib/juju/agents/unit-mysql-0/charm/venv/requests/sessions.py", line 703, in send
    r = adapter.send(request, **kwargs)
  File "/var/lib/juju/agents/unit-mysql-0/charm/venv/requests/adapters.py", line 519, in send
    raise ConnectionError(e, request=request)
requests.exceptions.ConnectionError: HTTPConnectionPool(host='juju-612b1f-2.lxd', port=4318): Max retries exceeded with url: /v1/traces (Caused by NewConnectionError('<urllib3.connection.HTTPConnection object at 0x7f531da3e320>: Failed to establish a new connection: [Errno 111] Connection refused'))
unit-mysql-2: 01:34:52 ERROR unit.mysql/2.juju-log database-peers:2: Exception while exporting Span batch.
Traceback (most recent call last):
  File "/var/lib/juju/agents/unit-mysql-2/charm/venv/urllib3/connection.py", line 174, in _new_conn
    conn = connection.create_connection(
  File "/var/lib/juju/agents/unit-mysql-2/charm/venv/urllib3/util/connection.py", line 95, in create_connection
    raise err
  File "/var/lib/juju/agents/unit-mysql-2/charm/venv/urllib3/util/connection.py", line 85, in create_connection
    sock.connect(sa)
ConnectionRefusedError: [Errno 111] Connection refused

During handling of the above exception, another exception occurred:

Traceback (most recent call last):
  File "/var/lib/juju/agents/unit-mysql-2/charm/venv/urllib3/connectionpool.py", line 715, in urlopen
    httplib_response = self._make_request(
  File "/var/lib/juju/agents/unit-mysql-2/charm/venv/urllib3/connectionpool.py", line 416, in _make_request
    conn.request(method, url, **httplib_request_kw)
  File "/var/lib/juju/agents/unit-mysql-2/charm/venv/urllib3/connection.py", line 244, in request
    super(HTTPConnection, self).request(method, url, body=body, headers=headers)
  File "/usr/lib/python3.10/http/client.py", line 1283, in request
    self._send_request(method, url, body, headers, encode_chunked)
  File "/usr/lib/python3.10/http/client.py", line 1329, in _send_request
    self.endheaders(body, encode_chunked=encode_chunked)
  File "/usr/lib/python3.10/http/client.py", line 1278, in endheaders
    self._send_output(message_body, encode_chunked=encode_chunked)
  File "/usr/lib/python3.10/http/client.py", line 1038, in _send_output
    self.send(msg)
  File "/usr/lib/python3.10/http/client.py", line 976, in send
    self.connect()
  File "/var/lib/juju/agents/unit-mysql-2/charm/venv/urllib3/connection.py", line 205, in connect
    conn = self._new_conn()
  File "/var/lib/juju/agents/unit-mysql-2/charm/venv/urllib3/connection.py", line 186, in _new_conn
    raise NewConnectionError(
urllib3.exceptions.NewConnectionError: <urllib3.connection.HTTPConnection object at 0x7f6e87737190>: Failed to establish a new connection: [Errno 111] Connection refused

During handling of the above exception, another exception occurred:

Traceback (most recent call last):
  File "/var/lib/juju/agents/unit-mysql-2/charm/venv/requests/adapters.py", line 486, in send
    resp = conn.urlopen(
  File "/var/lib/juju/agents/unit-mysql-2/charm/venv/urllib3/connectionpool.py", line 801, in urlopen
    retries = retries.increment(
  File "/var/lib/juju/agents/unit-mysql-2/charm/venv/urllib3/util/retry.py", line 594, in increment
    raise MaxRetryError(_pool, url, error or ResponseError(cause))
urllib3.exceptions.MaxRetryError: HTTPConnectionPool(host='juju-612b1f-4.lxd', port=4318): Max retries exceeded with url: /v1/traces (Caused by NewConnectionError('<urllib3.connection.HTTPConnection object at 0x7f6e87737190>: Failed to establish a new connection: [Errno 111] Connection refused'))

During handling of the above exception, another exception occurred:

Traceback (most recent call last):
  File "/var/lib/juju/agents/unit-mysql-2/charm/venv/opentelemetry/sdk/trace/export/__init__.py", line 368, in _export_batch
    self.span_exporter.export(self.spans_list[:idx])  # type: ignore
  File "/var/lib/juju/agents/unit-mysql-2/charm/venv/opentelemetry/exporter/otlp/proto/http/trace_exporter/__init__.py", line 145, in export
    resp = self._export(serialized_data)
  File "/var/lib/juju/agents/unit-mysql-2/charm/venv/opentelemetry/exporter/otlp/proto/http/trace_exporter/__init__.py", line 114, in _export
    return self._session.post(
  File "/var/lib/juju/agents/unit-mysql-2/charm/venv/requests/sessions.py", line 637, in post
    return self.request("POST", url, data=data, json=json, **kwargs)
  File "/var/lib/juju/agents/unit-mysql-2/charm/venv/requests/sessions.py", line 589, in request
    resp = self.send(prep, **send_kwargs)
  File "/var/lib/juju/agents/unit-mysql-2/charm/venv/requests/sessions.py", line 703, in send
    r = adapter.send(request, **kwargs)
  File "/var/lib/juju/agents/unit-mysql-2/charm/venv/requests/adapters.py", line 519, in send
    raise ConnectionError(e, request=request)
requests.exceptions.ConnectionError: HTTPConnectionPool(host='juju-612b1f-4.lxd', port=4318): Max retries exceeded with url: /v1/traces (Caused by NewConnectionError('<urllib3.connection.HTTPConnection object at 0x7f6e87737190>: Failed to establish a new connection: [Errno 111] Connection refused'))
unit-mysql-0: 01:34:53 ERROR unit.mysql/0.juju-log Exception while exporting Span batch.
Traceback (most recent call last):
  File "/var/lib/juju/agents/unit-mysql-0/charm/venv/urllib3/connection.py", line 174, in _new_conn
    conn = connection.create_connection(
  File "/var/lib/juju/agents/unit-mysql-0/charm/venv/urllib3/util/connection.py", line 95, in create_connection
    raise err
  File "/var/lib/juju/agents/unit-mysql-0/charm/venv/urllib3/util/connection.py", line 85, in create_connection
    sock.connect(sa)
ConnectionRefusedError: [Errno 111] Connection refused

During handling of the above exception, another exception occurred:

Traceback (most recent call last):
  File "/var/lib/juju/agents/unit-mysql-0/charm/venv/urllib3/connectionpool.py", line 715, in urlopen
    httplib_response = self._make_request(
  File "/var/lib/juju/agents/unit-mysql-0/charm/venv/urllib3/connectionpool.py", line 416, in _make_request
    conn.request(method, url, **httplib_request_kw)
  File "/var/lib/juju/agents/unit-mysql-0/charm/venv/urllib3/connection.py", line 244, in request
    super(HTTPConnection, self).request(method, url, body=body, headers=headers)
  File "/usr/lib/python3.10/http/client.py", line 1283, in request
    self._send_request(method, url, body, headers, encode_chunked)
  File "/usr/lib/python3.10/http/client.py", line 1329, in _send_request
    self.endheaders(body, encode_chunked=encode_chunked)
  File "/usr/lib/python3.10/http/client.py", line 1278, in endheaders
    self._send_output(message_body, encode_chunked=encode_chunked)
  File "/usr/lib/python3.10/http/client.py", line 1038, in _send_output
    self.send(msg)
  File "/usr/lib/python3.10/http/client.py", line 976, in send
    self.connect()
  File "/var/lib/juju/agents/unit-mysql-0/charm/venv/urllib3/connection.py", line 205, in connect
    conn = self._new_conn()
  File "/var/lib/juju/agents/unit-mysql-0/charm/venv/urllib3/connection.py", line 186, in _new_conn
    raise NewConnectionError(
urllib3.exceptions.NewConnectionError: <urllib3.connection.HTTPConnection object at 0x7f32646c9240>: Failed to establish a new connection: [Errno 111] Connection refused

During handling of the above exception, another exception occurred:

Traceback (most recent call last):
  File "/var/lib/juju/agents/unit-mysql-0/charm/venv/requests/adapters.py", line 486, in send
    resp = conn.urlopen(
  File "/var/lib/juju/agents/unit-mysql-0/charm/venv/urllib3/connectionpool.py", line 801, in urlopen
    retries = retries.increment(
  File "/var/lib/juju/agents/unit-mysql-0/charm/venv/urllib3/util/retry.py", line 594, in increment
    raise MaxRetryError(_pool, url, error or ResponseError(cause))
urllib3.exceptions.MaxRetryError: HTTPConnectionPool(host='juju-612b1f-2.lxd', port=4318): Max retries exceeded with url: /v1/traces (Caused by NewConnectionError('<urllib3.connection.HTTPConnection object at 0x7f32646c9240>: Failed to establish a new connection: [Errno 111] Connection refused'))

During handling of the above exception, another exception occurred:

Traceback (most recent call last):
  File "/var/lib/juju/agents/unit-mysql-0/charm/venv/opentelemetry/sdk/trace/export/__init__.py", line 368, in _export_batch
    self.span_exporter.export(self.spans_list[:idx])  # type: ignore
  File "/var/lib/juju/agents/unit-mysql-0/charm/venv/opentelemetry/exporter/otlp/proto/http/trace_exporter/__init__.py", line 145, in export
    resp = self._export(serialized_data)
  File "/var/lib/juju/agents/unit-mysql-0/charm/venv/opentelemetry/exporter/otlp/proto/http/trace_exporter/__init__.py", line 114, in _export
    return self._session.post(
  File "/var/lib/juju/agents/unit-mysql-0/charm/venv/requests/sessions.py", line 637, in post
    return self.request("POST", url, data=data, json=json, **kwargs)
  File "/var/lib/juju/agents/unit-mysql-0/charm/venv/requests/sessions.py", line 589, in request
    resp = self.send(prep, **send_kwargs)
  File "/var/lib/juju/agents/unit-mysql-0/charm/venv/requests/sessions.py", line 703, in send
    r = adapter.send(request, **kwargs)
  File "/var/lib/juju/agents/unit-mysql-0/charm/venv/requests/adapters.py", line 519, in send
    raise ConnectionError(e, request=request)
requests.exceptions.ConnectionError: HTTPConnectionPool(host='juju-612b1f-2.lxd', port=4318): Max retries exceeded with url: /v1/traces (Caused by NewConnectionError('<urllib3.connection.HTTPConnection object at 0x7f32646c9240>: Failed to establish a new connection: [Errno 111] Connection refused'))

[32mINFO    [0m pytest_operator.plugin:plugin.py:991 Forgetting model main...